Workbook
Name 沓_形: #REF!
Name 祝日リスト: #REF!

Sheet 祝日リスト (2)
A1: 46141 | B1: 昭和の日 | C1: 2026
A2: 46145 | B2: 憲法記念日
A3: 46146 | B3: みどりの日
A4: 46147 | B4: こどもの日
A5: 46148 | B5: 振替休日
A6: 46223 | B6: 海の日
A7: 46245 | B7: 山の日
A8: 46286 | B8: 敬老の日
A9: 46287 | B9: 国民の休日
A10: 46288 | B10: 秋分の日
A11: 46307 | B11: スポーツの日
A12: 46329 | B12: 文化の日
A13: 46349 | B13: 勤労感謝の日
... A19: 46468 | B19: 振替休日

Sheet 表紙
A1: 令和 3 年度
A3: 6 月分
A5: 業 務 日 誌
A7: ごみ焼却処理場

Sheet 1
A1: 課長 | C1: 庶務係長 | E1: =DATE(祝日リスト!C1, 4, 1) -> 46113 | I1: =TEXT(E1,"aaaa") -> 水曜日 | N1: 業務係長 | O1: 主任
F3: 天候 | G3: 晴れ | J3: 気温 | K3: 6 | L3: ℃
A5: 可燃 | B5: 地区 | C5: １回目収集 | E5: ２回目収集 | G5: ３回目収集 | I5: ４回目収集 | K5: ５回目収集 | N5: 焼却量 | O5: 埋立量
A6: 富士 | B6: 鬼 脇 | C6: 渡邉 | D6: 1460 | N6: =IF(SUM(D6,F6,H6,J6,L6)>0,IF(SUM(D6,F6,H6,J6,L6)-O6=0,"",SUM(D6,F6,H6,J6,L6)-O6),"") -> 1460
B7: 鴛 泊 | C7: 塚本 | D7: 1420 | E7: 塚本 | F7: 890 | N7: =IF(SUM(D7,F7,H7,J7,L7)>0,IF(SUM(D7,F7,H7,J7,L7)-O7=0,"",SUM(D7,F7,H7,J7,L7)-O7),"") -> 2310
A8: 利尻 | B8: 仙法志 | N8: =IF(SUM(D8,F8,H8,J8,L8)>0,IF(SUM(D8,F8,H8,J8,L8)-O8=0,"",SUM(D8,F8,H8,J8,L8)-O8),"")
B9: 沓 形 | N9: =IF(SUM(D9,F9,H9,J9,L9)>0,IF(SUM(D9,F9,H9,J9,L9)-O9=0,"",SUM(D9,F9,H9,J9,L9)-O9),"")
A10: 不燃 | B10: 地区 | C10: １回目収集 | E10: ２回目収集 | G10: ３回目収集 | I10: ４回目収集 | K10: ５回目収集 | N10: 有価回収 | O10: 埋立量
A11: 富士 | B11: 鬼 脇 | O11: =IF(SUM(D11,F11,H11,J11,L11)>0,SUM(D11,F11,H11,J11,L11)-N11,"")
B12: 鴛 泊 | O12: =IF(SUM(D12,F12,H12,J12,L12)>0,SUM(D12,F12,H12,J12,L12)-N12,"")
A13: 利尻 | B13: 仙法志 | O13: =IF(SUM(D13,F13,H13,J13,L13)>0,SUM(D13,F13,H13,J13,L13)-N13,"")
B14: 沓 形 | O14: =IF(SUM(D14,F14,H14,J14,L14)>0,SUM(D14,F14,H14,J14,L14)-N14,"")
A15: ペット | B15: 地区 | C15: １回目収集 | E15: ２回目収集 | G15: ３回目収集 | I15: ４回目収集 | K15: ５回目収集 | N15: 有価回収 | O15: 埋立量
A16: 富士 | B16: 鬼 脇 | N16: =IF(SUM(D16,F16,H16,J16,L16)>0,IF(SUM(D16,F16,H16,J16,L16)-O16=0,"",SUM(D16,F16,H16,J16,L16)-O16),"")
B17: 鴛 泊 | N17: =IF(SUM(D17,F17,H17,J17,L17)>0,IF(SUM(D17,F17,H17,J17,L17)-O17=0,"",SUM(D17,F17,H17,J17,L17)-O17),"")
A18: 利尻 | B18: 仙法志 | N18: =IF(SUM(D18,F18,H18,J18,L18)>0,IF(SUM(D18,F18,H18,J18,L18)-O18=0,"",SUM(D18,F18,H18,J18,L18)-O18),"")
B19: 沓 形 | N19: =IF(SUM(D19,F19,H19,J19,L19)>0,IF(SUM(D19,F19,H19,J19,L19)-O19=0,"",SUM(D19,F19,H19,J19,L19)-O19),"")
A20: 缶類 | B20: 地区 | C20: １回目収集 | E20: ２回目収集 | G20: ３回目収集 | I20: ４回目収集 | K20: ５回目収集 | N20: 有価回収 | O20: 埋立量
A21: 富士 | B21: 鬼 脇 | N21: =IF(SUM(D21,F21,H21,J21,L21)>0,IF(SUM(D21,F21,H21,J21,L21)-O21=0,"",SUM(D21,F21,H21,J21,L21)-O21),"")
B22: 鴛 泊 | N22: =IF(SUM(D22,F22,H22,J22,L22)>0,IF(SUM(D22,F22,H22,J22,L22)-O22=0,"",SUM(D22,F22,H22,J22,L22)-O22),"")
A23: 利尻 | B23: 仙法志 | N23: =IF(SUM(D23,F23,H23,J23,L23)>0,IF(SUM(D23,F23,H23,J23,L23)-O23=0,"",SUM(D23,F23,H23,J23,L23)-O23),"")
B24: 沓 形 | N24: =IF(SUM(D24,F24,H24,J24,L24)>0,IF(SUM(D24,F24,H24,J24,L24)-O24=0,"",SUM(D24,F24,H24,J24,L24)-O24),"")
A25: ビン | B25: 地区 | C25: １回目収集 | E25: ２回目収集 | G25: ３回目収集 | I25: ４回目収集 | K25: ５回目収集 | N25: 有価回収 | O25: 埋立量
A26: 富士 | B26: 鬼 脇 | O26: =IF(SUM(D26,F26,H26,J26,L26)>0,SUM(D26,F26,H26,J26,L26)-N26,"")
B27: 鴛 泊 | O27: =IF(SUM(D27,F27,H27,J27,L27)>0,SUM(D27,F27,H27,J27,L27)-N27,"")
A28: 利尻 | B28: 仙法志 | O28: =IF(SUM(D28,F28,H28,J28,L28)>0,SUM(D28,F28,H28,J28,L28)-N28,"")
B29: 沓 形 | O29: =IF(SUM(D29,F29,H29,J29,L29)>0,SUM(D29,F29,H29,J29,L29)-N29,"")
A30: 紙類 | B30: 地区 | C30: １回目収集 | E30: ２回目収集 | G30: ３回目収集 | I30: ４回目収集 | K30: ５回目収集 | N30: 有価回収 | O30: 埋立量
A31: 富士 | B31: 鬼 脇 | N31: =IF(SUM(D31,F31,H31,J31,L31)>0,IF(SUM(D31,F31,H31,J31,L31)-O31=0,"",SUM(D31,F31,H31,J31,L31)-O31),"")
B32: 鴛 泊 | N32: =IF(SUM(D32,F32,H32,J32,L32)>0,IF(SUM(D32,F32,H32,J32,L32)-O32=0,"",SUM(D32,F32,H32,J32,L32)-O32),"")
A33: 利尻 | B33: 仙法志 | C33: 高橋 | D33: 640 | N33: =IF(SUM(D33,F33,H33,J33,L33)>0,IF(SUM(D33,F33,H33,J33,L33)-O33=0,"",SUM(D33,F33,H33,J33,L33)-O33),"") -> 640
B34: 沓 形 | C34: 高橋 | D34: 1800 | N34: =IF(SUM(D34,F34,H34,J34,L34)>0,IF(SUM(D34,F34,H34,J34,L34)-O34=0,"",SUM(D34,F34,H34,J34,L34)-O34),"") -> 1800
A35: 収集粗大 | C35: 鬼 脇 | E35: 鴛 泊 | G35: 仙法志 | I35: 沓 形 | K35: その他 | N35: 有価回収 | O35: 埋立量
A36: 埋 立 分 | O36: =IF(SUM(C36:L36)>0,SUM(C36:L36),"")
A37: 有 価 物 | N37: =IF(SUM(C37:L37)>0,SUM(C37:L37),"")
A38: 持込（焼却） | C38: 鬼 脇 | E38: 鴛 泊 | G38: 仙法志 | I38: 沓 形 | K38: その他 | N38: 焼却量 | O38: 埋立量
A39: 可燃物(木・紙) | N39: =IF(SUM(C39:L39)>0,SUM(C39:L39),"")
A40: 併せ産廃（水産） | I40: 240 | N40: =IF(SUM(C40:L40)>0,SUM(C40:L40),"") -> 240
A41: 併せ産廃（医療） | N41: =IF(SUM(C41:L41)>0,SUM(C41:L41),"")
A42: 一般持込（埋立） | C42: 鬼 脇 | E42: 鴛 泊 | G42: 仙法志 | I42: 沓 形 | K42: その他 | N42: 有価回収 | O42: 埋立量
...

Sheet 2
A1: 課長 | C1: 庶務係長 | E1: =DATE(祝日リスト!C1, 4, 2) -> 46114 | I1: =TEXT(E1,"aaaa") -> 木曜日 | N1: 業務係長 | O1: 主任
F3: 天候 | G3: 曇り | J3: 気温 | K3: 6 | L3: ℃
A5: 可燃 | B5: 地区 | C5: １回目収集 | E5: ２回目収集 | G5: ３回目収集 | I5: ４回目収集 | K5: ５回目収集 | N5: 焼却量 | O5: 埋立量
A6: 富士 | B6: 鬼 脇 | N6: =IF(SUM(D6,F6,H6,J6,L6)>0,IF(SUM(D6,F6,H6,J6,L6)-O6=0,"",SUM(D6,F6,H6,J6,L6)-O6),"")
B7: 鴛 泊 | N7: =IF(SUM(D7,F7,H7,J7,L7)>0,IF(SUM(D7,F7,H7,J7,L7)-O7=0,"",SUM(D7,F7,H7,J7,L7)-O7),"")
A8: 利尻 | B8: 仙法志 | C8: 渡邉 | D8: 1370 | N8: =IF(SUM(D8,F8,H8,J8,L8)>0,IF(SUM(D8,F8,H8,J8,L8)-O8=0,"",SUM(D8,F8,H8,J8,L8)-O8),"") -> 1370
B9: 沓 形 | C9: 塚本 | D9: 1880 | E9: 塚本 | F9: 520 | N9: =IF(SUM(D9,F9,H9,J9,L9)>0,IF(SUM(D9,F9,H9,J9,L9)-O9=0,"",SUM(D9,F9,H9,J9,L9)-O9),"") -> 2400
A10: 不燃 | B10: 地区 | C10: １回目収集 | E10: ２回目収集 | G10: ３回目収集 | I10: ４回目収集 | K10: ５回目収集 | N10: 有価回収 | O10: 埋立量
A11: 富士 | B11: 鬼 脇 | O11: =IF(SUM(D11,F11,H11,J11,L11)>0,SUM(D11,F11,H11,J11,L11)-N11,"")
B12: 鴛 泊 | O12: =IF(SUM(D12,F12,H12,J12,L12)>0,SUM(D12,F12,H12,J12,L12)-N12,"")
A13: 利尻 | B13: 仙法志 | O13: =IF(SUM(D13,F13,H13,J13,L13)>0,SUM(D13,F13,H13,J13,L13)-N13,"")
B14: 沓 形 | O14: =IF(SUM(D14,F14,H14,J14,L14)>0,SUM(D14,F14,H14,J14,L14)-N14,"")
A15: ペット | B15: 地区 | C15: １回目収集 | E15: ２回目収集 | G15: ３回目収集 | I15: ４回目収集 | K15: ５回目収集 | N15: 有価回収 | O15: 埋立量
A16: 富士 | B16: 鬼 脇 | N16: =IF(SUM(D16,F16,H16,J16,L16)>0,IF(SUM(D16,F16,H16,J16,L16)-O16=0,"",SUM(D16,F16,H16,J16,L16)-O16),"")
B17: 鴛 泊 | N17: =IF(SUM(D17,F17,H17,J17,L17)>0,IF(SUM(D17,F17,H17,J17,L17)-O17=0,"",SUM(D17,F17,H17,J17,L17)-O17),"")
A18: 利尻 | B18: 仙法志 | N18: =IF(SUM(D18,F18,H18,J18,L18)>0,IF(SUM(D18,F18,H18,J18,L18)-O18=0,"",SUM(D18,F18,H18,J18,L18)-O18),"")
B19: 沓 形 | N19: =IF(SUM(D19,F19,H19,J19,L19)>0,IF(SUM(D19,F19,H19,J19,L19)-O19=0,"",SUM(D19,F19,H19,J19,L19)-O19),"")
A20: 缶類 | B20: 地区 | C20: １回目収集 | E20: ２回目収集 | G20: ３回目収集 | I20: ４回目収集 | K20: ５回目収集 | N20: 有価回収 | O20: 埋立量
A21: 富士 | B21: 鬼 脇 | N21: =IF(SUM(D21,F21,H21,J21,L21)>0,IF(SUM(D21,F21,H21,J21,L21)-O21=0,"",SUM(D21,F21,H21,J21,L21)-O21),"")
B22: 鴛 泊 | N22: =IF(SUM(D22,F22,H22,J22,L22)>0,IF(SUM(D22,F22,H22,J22,L22)-O22=0,"",SUM(D22,F22,H22,J22,L22)-O22),"")
A23: 利尻 | B23: 仙法志 | N23: =IF(SUM(D23,F23,H23,J23,L23)>0,IF(SUM(D23,F23,H23,J23,L23)-O23=0,"",SUM(D23,F23,H23,J23,L23)-O23),"")
B24: 沓 形 | N24: =IF(SUM(D24,F24,H24,J24,L24)>0,IF(SUM(D24,F24,H24,J24,L24)-O24=0,"",SUM(D24,F24,H24,J24,L24)-O24),"")
A25: ビン | B25: 地区 | C25: １回目収集 | E25: ２回目収集 | G25: ３回目収集 | I25: ４回目収集 | K25: ５回目収集 | N25: 有価回収 | O25: 埋立量
A26: 富士 | B26: 鬼 脇 | C26: 高橋 | D26: 200 | O26: =IF(SUM(D26,F26,H26,J26,L26)>0,SUM(D26,F26,H26,J26,L26)-N26,"") -> 200
B27: 鴛 泊 | C27: 高橋 | D27: 630 | O27: =IF(SUM(D27,F27,H27,J27,L27)>0,SUM(D27,F27,H27,J27,L27)-N27,"") -> 630
A28: 利尻 | B28: 仙法志 | O28: =IF(SUM(D28,F28,H28,J28,L28)>0,SUM(D28,F28,H28,J28,L28)-N28,"")
B29: 沓 形 | O29: =IF(SUM(D29,F29,H29,J29,L29)>0,SUM(D29,F29,H29,J29,L29)-N29,"")
A30: 紙類 | B30: 地区 | C30: １回目収集 | E30: ２回目収集 | G30: ３回目収集 | I30: ４回目収集 | K30: ５回目収集 | N30: 有価回収 | O30: 埋立量
A31: 富士 | B31: 鬼 脇 | N31: =IF(SUM(D31,F31,H31,J31,L31)>0,IF(SUM(D31,F31,H31,J31,L31)-O31=0,"",SUM(D31,F31,H31,J31,L31)-O31),"")
B32: 鴛 泊 | N32: =IF(SUM(D32,F32,H32,J32,L32)>0,IF(SUM(D32,F32,H32,J32,L32)-O32=0,"",SUM(D32,F32,H32,J32,L32)-O32),"")
A33: 利尻 | B33: 仙法志 | N33: =IF(SUM(D33,F33,H33,J33,L33)>0,IF(SUM(D33,F33,H33,J33,L33)-O33=0,"",SUM(D33,F33,H33,J33,L33)-O33),"")
B34: 沓 形 | N34: =IF(SUM(D34,F34,H34,J34,L34)>0,IF(SUM(D34,F34,H34,J34,L34)-O34=0,"",SUM(D34,F34,H34,J34,L34)-O34),"")
A35: 収集粗大 | C35: 鬼 脇 | E35: 鴛 泊 | G35: 仙法志 | I35: 沓 形 | K35: その他 | N35: 有価回収 | O35: 埋立量
A36: 埋 立 分 | O36: =IF(SUM(C36:L36)>0,SUM(C36:L36),"")
A37: 有 価 物 | N37: =IF(SUM(C37:L37)>0,SUM(C37:L37),"")
A38: 持込（焼却） | C38: 鬼 脇 | E38: 鴛 泊 | G38: 仙法志 | I38: 沓 形 | K38: その他 | N38: 焼却量 | O38: 埋立量
A39: 可燃物(木・紙) | N39: =IF(SUM(C39:L39)>0,SUM(C39:L39),"")
A40: 併せ産廃（水産） | N40: =IF(SUM(C40:L40)>0,SUM(C40:L40),"")
A41: 併せ産廃（医療） | N41: =IF(SUM(C41:L41)>0,SUM(C41:L41),"")
A42: 一般持込（埋立） | C42: 鬼 脇 | E42: 鴛 泊 | G42: 仙法志 | I42: 沓 形 | K42: その他 | N42: 有価回収 | O42: 埋立量
...

Sheet 3
A1: 課長 | C1: 庶務係長 | E1: =DATE(祝日リスト!C1, 4, 3) -> 46115 | I1: =TEXT(E1,"aaaa") -> 金曜日 | N1: 業務係長 | O1: 主任
F3: 天候 | G3: 晴れ | J3: 気温 | K3: 4 | L3: ℃
A5: 可燃 | B5: 地区 | C5: １回目収集 | E5: ２回目収集 | G5: ３回目収集 | I5: ４回目収集 | K5: ５回目収集 | N5: 焼却量 | O5: 埋立量
A6: 富士 | B6: 鬼 脇 | C6: 渡邉 | D6: 1260 | N6: =IF(SUM(D6,F6,H6,J6,L6)>0,IF(SUM(D6,F6,H6,J6,L6)-O6=0,"",SUM(D6,F6,H6,J6,L6)-O6),"") -> 1260
B7: 鴛 泊 | C7: 塚本 | D7: 1040 | E7: 塚本 | F7: 1080 | N7: =IF(SUM(D7,F7,H7,J7,L7)>0,IF(SUM(D7,F7,H7,J7,L7)-O7=0,"",SUM(D7,F7,H7,J7,L7)-O7),"") -> 2120
A8: 利尻 | B8: 仙法志 | N8: =IF(SUM(D8,F8,H8,J8,L8)>0,IF(SUM(D8,F8,H8,J8,L8)-O8=0,"",SUM(D8,F8,H8,J8,L8)-O8),"")
B9: 沓 形 | N9: =IF(SUM(D9,F9,H9,J9,L9)>0,IF(SUM(D9,F9,H9,J9,L9)-O9=0,"",SUM(D9,F9,H9,J9,L9)-O9),"")
A10: 不燃 | B10: 地区 | C10: １回目収集 | E10: ２回目収集 | G10: ３回目収集 | I10: ４回目収集 | K10: ５回目収集 | N10: 有価回収 | O10: 埋立量
A11: 富士 | B11: 鬼 脇 | O11: =IF(SUM(D11,F11,H11,J11,L11)>0,SUM(D11,F11,H11,J11,L11)-N11,"")
B12: 鴛 泊 | O12: =IF(SUM(D12,F12,H12,J12,L12)>0,SUM(D12,F12,H12,J12,L12)-N12,"")
A13: 利尻 | B13: 仙法志 | O13: =IF(SUM(D13,F13,H13,J13,L13)>0,SUM(D13,F13,H13,J13,L13)-N13,"")
B14: 沓 形 | O14: =IF(SUM(D14,F14,H14,J14,L14)>0,SUM(D14,F14,H14,J14,L14)-N14,"")
A15: ペット | B15: 地区 | C15: １回目収集 | E15: ２回目収集 | G15: ３回目収集 | I15: ４回目収集 | K15: ５回目収集 | N15: 有価回収 | O15: 埋立量
A16: 富士 | B16: 鬼 脇 | N16: =IF(SUM(D16,F16,H16,J16,L16)>0,IF(SUM(D16,F16,H16,J16,L16)-O16=0,"",SUM(D16,F16,H16,J16,L16)-O16),"")
B17: 鴛 泊 | N17: =IF(SUM(D17,F17,H17,J17,L17)>0,IF(SUM(D17,F17,H17,J17,L17)-O17=0,"",SUM(D17,F17,H17,J17,L17)-O17),"")
A18: 利尻 | B18: 仙法志 | C18: 高橋 | D18: 30 | N18: =IF(SUM(D18,F18,H18,J18,L18)>0,IF(SUM(D18,F18,H18,J18,L18)-O18=0,"",SUM(D18,F18,H18,J18,L18)-O18),"") -> 30
B19: 沓 形 | C19: 高橋 | D19: 90 | N19: =IF(SUM(D19,F19,H19,J19,L19)>0,IF(SUM(D19,F19,H19,J19,L19)-O19=0,"",SUM(D19,F19,H19,J19,L19)-O19),"") -> 90
A20: 缶類 | B20: 地区 | C20: １回目収集 | E20: ２回目収集 | G20: ３回目収集 | I20: ４回目収集 | K20: ５回目収集 | N20: 有価回収 | O20: 埋立量
A21: 富士 | B21: 鬼 脇 | N21: =IF(SUM(D21,F21,H21,J21,L21)>0,IF(SUM(D21,F21,H21,J21,L21)-O21=0,"",SUM(D21,F21,H21,J21,L21)-O21),"")
B22: 鴛 泊 | N22: =IF(SUM(D22,F22,H22,J22,L22)>0,IF(SUM(D22,F22,H22,J22,L22)-O22=0,"",SUM(D22,F22,H22,J22,L22)-O22),"")
A23: 利尻 | B23: 仙法志 | N23: =IF(SUM(D23,F23,H23,J23,L23)>0,IF(SUM(D23,F23,H23,J23,L23)-O23=0,"",SUM(D23,F23,H23,J23,L23)-O23),"")
B24: 沓 形 | N24: =IF(SUM(D24,F24,H24,J24,L24)>0,IF(SUM(D24,F24,H24,J24,L24)-O24=0,"",SUM(D24,F24,H24,J24,L24)-O24),"")
A25: ビン | B25: 地区 | C25: １回目収集 | E25: ２回目収集 | G25: ３回目収集 | I25: ４回目収集 | K25: ５回目収集 | N25: 有価回収 | O25: 埋立量
A26: 富士 | B26: 鬼 脇 | O26: =IF(SUM(D26,F26,H26,J26,L26)>0,SUM(D26,F26,H26,J26,L26)-N26,"")
B27: 鴛 泊 | O27: =IF(SUM(D27,F27,H27,J27,L27)>0,SUM(D27,F27,H27,J27,L27)-N27,"")
A28: 利尻 | B28: 仙法志 | O28: =IF(SUM(D28,F28,H28,J28,L28)>0,SUM(D28,F28,H28,J28,L28)-N28,"")
B29: 沓 形 | O29: =IF(SUM(D29,F29,H29,J29,L29)>0,SUM(D29,F29,H29,J29,L29)-N29,"")
A30: 紙類 | B30: 地区 | C30: １回目収集 | E30: ２回目収集 | G30: ３回目収集 | I30: ４回目収集 | K30: ５回目収集 | N30: 有価回収 | O30: 埋立量
A31: 富士 | B31: 鬼 脇 | N31: =IF(SUM(D31,F31,H31,J31,L31)>0,IF(SUM(D31,F31,H31,J31,L31)-O31=0,"",SUM(D31,F31,H31,J31,L31)-O31),"")
B32: 鴛 泊 | N32: =IF(SUM(D32,F32,H32,J32,L32)>0,IF(SUM(D32,F32,H32,J32,L32)-O32=0,"",SUM(D32,F32,H32,J32,L32)-O32),"")
A33: 利尻 | B33: 仙法志 | N33: =IF(SUM(D33,F33,H33,J33,L33)>0,IF(SUM(D33,F33,H33,J33,L33)-O33=0,"",SUM(D33,F33,H33,J33,L33)-O33),"")
B34: 沓 形 | N34: =IF(SUM(D34,F34,H34,J34,L34)>0,IF(SUM(D34,F34,H34,J34,L34)-O34=0,"",SUM(D34,F34,H34,J34,L34)-O34),"")
A35: 収集粗大 | C35: 鬼 脇 | E35: 鴛 泊 | G35: 仙法志 | I35: 沓 形 | K35: その他 | N35: 有価回収 | O35: 埋立量
A36: 埋 立 分 | O36: =IF(SUM(C36:L36)>0,SUM(C36:L36),"")
A37: 有 価 物 | N37: =IF(SUM(C37:L37)>0,SUM(C37:L37),"")
A38: 持込（焼却） | C38: 鬼 脇 | E38: 鴛 泊 | G38: 仙法志 | I38: 沓 形 | K38: その他 | N38: 焼却量 | O38: 埋立量
A39: 可燃物(木・紙) | N39: =IF(SUM(C39:L39)>0,SUM(C39:L39),"")
A40: 併せ産廃（水産） | I40: 220 | N40: =IF(SUM(C40:L40)>0,SUM(C40:L40),"") -> 220
A41: 併せ産廃（医療） | N41: =IF(SUM(C41:L41)>0,SUM(C41:L41),"")
A42: 一般持込（埋立） | C42: 鬼 脇 | E42: 鴛 泊 | G42: 仙法志 | I42: 沓 形 | K42: その他 | N42: 有価回収 | O42: 埋立量
...

Sheet 4
A1: 課長 | C1: 庶務係長 | E1: =DATE(祝日リスト!C1, 4, 4) -> 46116 | I1: =TEXT(E1,"aaaa") -> 土曜日 | N1: 業務係長 | O1: 主任
F3: 天候 | J3: 気温 | L3: ℃
A5: 可燃 | B5: 地区 | C5: １回目収集 | E5: ２回目収集 | G5: ３回目収集 | I5: ４回目収集 | K5: ５回目収集 | N5: 焼却量 | O5: 埋立量
A6: 富士 | B6: 鬼 脇 | N6: =IF(SUM(D6,F6,H6,J6,L6)>0,IF(SUM(D6,F6,H6,J6,L6)-O6=0,"",SUM(D6,F6,H6,J6,L6)-O6),"")
B7: 鴛 泊 | N7: =IF(SUM(D7,F7,H7,J7,L7)>0,IF(SUM(D7,F7,H7,J7,L7)-O7=0,"",SUM(D7,F7,H7,J7,L7)-O7),"")
A8: 利尻 | B8: 仙法志 | N8: =IF(SUM(D8,F8,H8,J8,L8)>0,IF(SUM(D8,F8,H8,J8,L8)-O8=0,"",SUM(D8,F8,H8,J8,L8)-O8),"")
B9: 沓 形 | N9: =IF(SUM(D9,F9,H9,J9,L9)>0,IF(SUM(D9,F9,H9,J9,L9)-O9=0,"",SUM(D9,F9,H9,J9,L9)-O9),"")
A10: 不燃 | B10: 地区 | C10: １回目収集 | E10: ２回目収集 | G10: ３回目収集 | I10: ４回目収集 | K10: ５回目収集 | N10: 有価回収 | O10: 埋立量
A11: 富士 | B11: 鬼 脇 | O11: =IF(SUM(D11,F11,H11,J11,L11)>0,SUM(D11,F11,H11,J11,L11)-N11,"")
B12: 鴛 泊 | O12: =IF(SUM(D12,F12,H12,J12,L12)>0,SUM(D12,F12,H12,J12,L12)-N12,"")
A13: 利尻 | B13: 仙法志 | O13: =IF(SUM(D13,F13,H13,J13,L13)>0,SUM(D13,F13,H13,J13,L13)-N13,"")
B14: 沓 形 | O14: =IF(SUM(D14,F14,H14,J14,L14)>0,SUM(D14,F14,H14,J14,L14)-N14,"")
A15: ペット | B15: 地区 | C15: １回目収集 | E15: ２回目収集 | G15: ３回目収集 | I15: ４回目収集 | K15: ５回目収集 | N15: 有価回収 | O15: 埋立量
A16: 富士 | B16: 鬼 脇 | N16: =IF(SUM(D16,F16,H16,J16,L16)>0,IF(SUM(D16,F16,H16,J16,L16)-O16=0,"",SUM(D16,F16,H16,J16,L16)-O16),"")
B17: 鴛 泊 | N17: =IF(SUM(D17,F17,H17,J17,L17)>0,IF(SUM(D17,F17,H17,J17,L17)-O17=0,"",SUM(D17,F17,H17,J17,L17)-O17),"")
A18: 利尻 | B18: 仙法志 | N18: =IF(SUM(D18,F18,H18,J18,L18)>0,IF(SUM(D18,F18,H18,J18,L18)-O18=0,"",SUM(D18,F18,H18,J18,L18)-O18),"")
B19: 沓 形 | N19: =IF(SUM(D19,F19,H19,J19,L19)>0,IF(SUM(D19,F19,H19,J19,L19)-O19=0,"",SUM(D19,F19,H19,J19,L19)-O19),"")
A20: 缶類 | B20: 地区 | C20: １回目収集 | E20: ２回目収集 | G20: ３回目収集 | I20: ４回目収集 | K20: ５回目収集 | N20: 有価回収 | O20: 埋立量
A21: 富士 | B21: 鬼 脇 | N21: =IF(SUM(D21,F21,H21,J21,L21)>0,IF(SUM(D21,F21,H21,J21,L21)-O21=0,"",SUM(D21,F21,H21,J21,L21)-O21),"")
B22: 鴛 泊 | N22: =IF(SUM(D22,F22,H22,J22,L22)>0,IF(SUM(D22,F22,H22,J22,L22)-O22=0,"",SUM(D22,F22,H22,J22,L22)-O22),"")
A23: 利尻 | B23: 仙法志 | N23: =IF(SUM(D23,F23,H23,J23,L23)>0,IF(SUM(D23,F23,H23,J23,L23)-O23=0,"",SUM(D23,F23,H23,J23,L23)-O23),"")
B24: 沓 形 | N24: =IF(SUM(D24,F24,H24,J24,L24)>0,IF(SUM(D24,F24,H24,J24,L24)-O24=0,"",SUM(D24,F24,H24,J24,L24)-O24),"")
A25: ビン | B25: 地区 | C25: １回目収集 | E25: ２回目収集 | G25: ３回目収集 | I25: ４回目収集 | K25: ５回目収集 | N25: 有価回収 | O25: 埋立量
A26: 富士 | B26: 鬼 脇 | O26: =IF(SUM(D26,F26,H26,J26,L26)>0,SUM(D26,F26,H26,J26,L26)-N26,"")
B27: 鴛 泊 | O27: =IF(SUM(D27,F27,H27,J27,L27)>0,SUM(D27,F27,H27,J27,L27)-N27,"")
A28: 利尻 | B28: 仙法志 | O28: =IF(SUM(D28,F28,H28,J28,L28)>0,SUM(D28,F28,H28,J28,L28)-N28,"")
B29: 沓 形 | O29: =IF(SUM(D29,F29,H29,J29,L29)>0,SUM(D29,F29,H29,J29,L29)-N29,"")
A30: 紙類 | B30: 地区 | C30: １回目収集 | E30: ２回目収集 | G30: ３回目収集 | I30: ４回目収集 | K30: ５回目収集 | N30: 有価回収 | O30: 埋立量
A31: 富士 | B31: 鬼 脇 | N31: =IF(SUM(D31,F31,H31,J31,L31)>0,IF(SUM(D31,F31,H31,J31,L31)-O31=0,"",SUM(D31,F31,H31,J31,L31)-O31),"")
B32: 鴛 泊 | N32: =IF(SUM(D32,F32,H32,J32,L32)>0,IF(SUM(D32,F32,H32,J32,L32)-O32=0,"",SUM(D32,F32,H32,J32,L32)-O32),"")
A33: 利尻 | B33: 仙法志 | N33: =IF(SUM(D33,F33,H33,J33,L33)>0,IF(SUM(D33,F33,H33,J33,L33)-O33=0,"",SUM(D33,F33,H33,J33,L33)-O33),"")
B34: 沓 形 | N34: =IF(SUM(D34,F34,H34,J34,L34)>0,IF(SUM(D34,F34,H34,J34,L34)-O34=0,"",SUM(D34,F34,H34,J34,L34)-O34),"")
A35: 収集粗大 | C35: 鬼 脇 | E35: 鴛 泊 | G35: 仙法志 | I35: 沓 形 | K35: その他 | N35: 有価回収 | O35: 埋立量
A36: 埋 立 分 | O36: =IF(SUM(C36:L36)>0,SUM(C36:L36),"")
A37: 有 価 物 | N37: =IF(SUM(C37:L37)>0,SUM(C37:L37),"")
A38: 持込（焼却） | C38: 鬼 脇 | E38: 鴛 泊 | G38: 仙法志 | I38: 沓 形 | K38: その他 | N38: 焼却量 | O38: 埋立量
A39: 可燃物(木・紙) | N39: =IF(SUM(C39:L39)>0,SUM(C39:L39),"")
A40: 併せ産廃（水産） | N40: =IF(SUM(C40:L40)>0,SUM(C40:L40),"")
A41: 併せ産廃（医療） | N41: =IF(SUM(C41:L41)>0,SUM(C41:L41),"")
A42: 一般持込（埋立） | C42: 鬼 脇 | E42: 鴛 泊 | G42: 仙法志 | I42: 沓 形 | K42: その他 | N42: 有価回収 | O42: 埋立量
...

Sheet 5
A1: 課長 | C1: 庶務係長 | E1: =DATE(祝日リスト!C1, 4, 5) -> 46117 | I1: =TEXT(E1,"aaaa") -> 日曜日 | N1: 業務係長 | O1: 主任
F3: 天候 | J3: 気温 | L3: ℃
A5: 可燃 | B5: 地区 | C5: １回目収集 | E5: ２回目収集 | G5: ３回目収集 | I5: ４回目収集 | K5: ５回目収集 | N5: 焼却量 | O5: 埋立量
A6: 富士 | B6: 鬼 脇 | N6: =IF(SUM(D6,F6,H6,J6,L6)>0,IF(SUM(D6,F6,H6,J6,L6)-O6=0,"",SUM(D6,F6,H6,J6,L6)-O6),"")
B7: 鴛 泊 | N7: =IF(SUM(D7,F7,H7,J7,L7)>0,IF(SUM(D7,F7,H7,J7,L7)-O7=0,"",SUM(D7,F7,H7,J7,L7)-O7),"")
A8: 利尻 | B8: 仙法志 | N8: =IF(SUM(D8,F8,H8,J8,L8)>0,IF(SUM(D8,F8,H8,J8,L8)-O8=0,"",SUM(D8,F8,H8,J8,L8)-O8),"")
B9: 沓 形 | N9: =IF(SUM(D9,F9,H9,J9,L9)>0,IF(SUM(D9,F9,H9,J9,L9)-O9=0,"",SUM(D9,F9,H9,J9,L9)-O9),"")
A10: 不燃 | B10: 地区 | C10: １回目収集 | E10: ２回目収集 | G10: ３回目収集 | I10: ４回目収集 | K10: ５回目収集 | N10: 有価回収 | O10: 埋立量
A11: 富士 | B11: 鬼 脇 | O11: =IF(SUM(D11,F11,H11,J11,L11)>0,SUM(D11,F11,H11,J11,L11)-N11,"")
B12: 鴛 泊 | O12: =IF(SUM(D12,F12,H12,J12,L12)>0,SUM(D12,F12,H12,J12,L12)-N12,"")
A13: 利尻 | B13: 仙法志 | O13: =IF(SUM(D13,F13,H13,J13,L13)>0,SUM(D13,F13,H13,J13,L13)-N13,"")
B14: 沓 形 | O14: =IF(SUM(D14,F14,H14,J14,L14)>0,SUM(D14,F14,H14,J14,L14)-N14,"")
A15: ペット | B15: 地区 | C15: １回目収集 | E15: ２回目収集 | G15: ３回目収集 | I15: ４回目収集 | K15: ５回目収集 | N15: 有価回収 | O15: 埋立量
A16: 富士 | B16: 鬼 脇 | N16: =IF(SUM(D16,F16,H16,J16,L16)>0,IF(SUM(D16,F16,H16,J16,L16)-O16=0,"",SUM(D16,F16,H16,J16,L16)-O16),"")
B17: 鴛 泊 | N17: =IF(SUM(D17,F17,H17,J17,L17)>0,IF(SUM(D17,F17,H17,J17,L17)-O17=0,"",SUM(D17,F17,H17,J17,L17)-O17),"")
A18: 利尻 | B18: 仙法志 | N18: =IF(SUM(D18,F18,H18,J18,L18)>0,IF(SUM(D18,F18,H18,J18,L18)-O18=0,"",SUM(D18,F18,H18,J18,L18)-O18),"")
B19: 沓 形 | N19: =IF(SUM(D19,F19,H19,J19,L19)>0,IF(SUM(D19,F19,H19,J19,L19)-O19=0,"",SUM(D19,F19,H19,J19,L19)-O19),"")
A20: 缶類 | B20: 地区 | C20: １回目収集 | E20: ２回目収集 | G20: ３回目収集 | I20: ４回目収集 | K20: ５回目収集 | N20: 有価回収 | O20: 埋立量
A21: 富士 | B21: 鬼 脇 | N21: =IF(SUM(D21,F21,H21,J21,L21)>0,IF(SUM(D21,F21,H21,J21,L21)-O21=0,"",SUM(D21,F21,H21,J21,L21)-O21),"")
B22: 鴛 泊 | N22: =IF(SUM(D22,F22,H22,J22,L22)>0,IF(SUM(D22,F22,H22,J22,L22)-O22=0,"",SUM(D22,F22,H22,J22,L22)-O22),"")
A23: 利尻 | B23: 仙法志 | N23: =IF(SUM(D23,F23,H23,J23,L23)>0,IF(SUM(D23,F23,H23,J23,L23)-O23=0,"",SUM(D23,F23,H23,J23,L23)-O23),"")
B24: 沓 形 | N24: =IF(SUM(D24,F24,H24,J24,L24)>0,IF(SUM(D24,F24,H24,J24,L24)-O24=0,"",SUM(D24,F24,H24,J24,L24)-O24),"")
A25: ビン | B25: 地区 | C25: １回目収集 | E25: ２回目収集 | G25: ３回目収集 | I25: ４回目収集 | K25: ５回目収集 | N25: 有価回収 | O25: 埋立量
A26: 富士 | B26: 鬼 脇 | O26: =IF(SUM(D26,F26,H26,J26,L26)>0,SUM(D26,F26,H26,J26,L26)-N26,"")
B27: 鴛 泊 | O27: =IF(SUM(D27,F27,H27,J27,L27)>0,SUM(D27,F27,H27,J27,L27)-N27,"")
A28: 利尻 | B28: 仙法志 | O28: =IF(SUM(D28,F28,H28,J28,L28)>0,SUM(D28,F28,H28,J28,L28)-N28,"")
B29: 沓 形 | O29: =IF(SUM(D29,F29,H29,J29,L29)>0,SUM(D29,F29,H29,J29,L29)-N29,"")
A30: 紙類 | B30: 地区 | C30: １回目収集 | E30: ２回目収集 | G30: ３回目収集 | I30: ４回目収集 | K30: ５回目収集 | N30: 有価回収 | O30: 埋立量
A31: 富士 | B31: 鬼 脇 | N31: =IF(SUM(D31,F31,H31,J31,L31)>0,IF(SUM(D31,F31,H31,J31,L31)-O31=0,"",SUM(D31,F31,H31,J31,L31)-O31),"")
B32: 鴛 泊 | N32: =IF(SUM(D32,F32,H32,J32,L32)>0,IF(SUM(D32,F32,H32,J32,L32)-O32=0,"",SUM(D32,F32,H32,J32,L32)-O32),"")
A33: 利尻 | B33: 仙法志 | N33: =IF(SUM(D33,F33,H33,J33,L33)>0,IF(SUM(D33,F33,H33,J33,L33)-O33=0,"",SUM(D33,F33,H33,J33,L33)-O33),"")
B34: 沓 形 | N34: =IF(SUM(D34,F34,H34,J34,L34)>0,IF(SUM(D34,F34,H34,J34,L34)-O34=0,"",SUM(D34,F34,H34,J34,L34)-O34),"")
A35: 収集粗大 | C35: 鬼 脇 | E35: 鴛 泊 | G35: 仙法志 | I35: 沓 形 | K35: その他 | N35: 有価回収 | O35: 埋立量
A36: 埋 立 分 | O36: =IF(SUM(C36:L36)>0,SUM(C36:L36),"")
A37: 有 価 物 | N37: =IF(SUM(C37:L37)>0,SUM(C37:L37),"")
A38: 持込（焼却） | C38: 鬼 脇 | E38: 鴛 泊 | G38: 仙法志 | I38: 沓 形 | K38: その他 | N38: 焼却量 | O38: 埋立量
A39: 可燃物(木・紙) | N39: =IF(SUM(C39:L39)>0,SUM(C39:L39),"")
A40: 併せ産廃（水産） | N40: =IF(SUM(C40:L40)>0,SUM(C40:L40),"")
A41: 併せ産廃（医療） | N41: =IF(SUM(C41:L41)>0,SUM(C41:L41),"")
A42: 一般持込（埋立） | C42: 鬼 脇 | E42: 鴛 泊 | G42: 仙法志 | I42: 沓 形 | K42: その他 | N42: 有価回収 | O42: 埋立量
...

Sheet 6
A1: 課長 | C1: 庶務係長 | E1: =DATE(祝日リスト!C1, 4, 6) -> 46118 | I1: =TEXT(E1,"aaaa") -> 月曜日 | N1: 業務係長 | O1: 主任
F3: 天候 | J3: 気温 | L3: ℃
A5: 可燃 | B5: 地区 | C5: １回目収集 | E5: ２回目収集 | G5: ３回目収集 | I5: ４回目収集 | K5: ５回目収集 | N5: 焼却量 | O5: 埋立量
A6: 富士 | B6: 鬼 脇 | N6: =IF(SUM(D6,F6,H6,J6,L6)>0,IF(SUM(D6,F6,H6,J6,L6)-O6=0,"",SUM(D6,F6,H6,J6,L6)-O6),"")
B7: 鴛 泊 | N7: =IF(SUM(D7,F7,H7,J7,L7)>0,IF(SUM(D7,F7,H7,J7,L7)-O7=0,"",SUM(D7,F7,H7,J7,L7)-O7),"")
A8: 利尻 | B8: 仙法志 | N8: =IF(SUM(D8,F8,H8,J8,L8)>0,IF(SUM(D8,F8,H8,J8,L8)-O8=0,"",SUM(D8,F8,H8,J8,L8)-O8),"")
B9: 沓 形 | N9: =IF(SUM(D9,F9,H9,J9,L9)>0,IF(SUM(D9,F9,H9,J9,L9)-O9=0,"",SUM(D9,F9,H9,J9,L9)-O9),"")
A10: 不燃 | B10: 地区 | C10: １回目収集 | E10: ２回目収集 | G10: ３回目収集 | I10: ４回目収集 | K10: ５回目収集 | N10: 有価回収 | O10: 埋立量
A11: 富士 | B11: 鬼 脇 | O11: =IF(SUM(D11,F11,H11,J11,L11)>0,SUM(D11,F11,H11,J11,L11)-N11,"")
B12: 鴛 泊 | O12: =IF(SUM(D12,F12,H12,J12,L12)>0,SUM(D12,F12,H12,J12,L12)-N12,"")
A13: 利尻 | B13: 仙法志 | O13: =IF(SUM(D13,F13,H13,J13,L13)>0,SUM(D13,F13,H13,J13,L13)-N13,"")
B14: 沓 形 | O14: =IF(SUM(D14,F14,H14,J14,L14)>0,SUM(D14,F14,H14,J14,L14)-N14,"")
A15: ペット | B15: 地区 | C15: １回目収集 | E15: ２回目収集 | G15: ３回目収集 | I15: ４回目収集 | K15: ５回目収集 | N15: 有価回収 | O15: 埋立量
A16: 富士 | B16: 鬼 脇 | N16: =IF(SUM(D16,F16,H16,J16,L16)>0,IF(SUM(D16,F16,H16,J16,L16)-O16=0,"",SUM(D16,F16,H16,J16,L16)-O16),"")
B17: 鴛 泊 | N17: =IF(SUM(D17,F17,H17,J17,L17)>0,IF(SUM(D17,F17,H17,J17,L17)-O17=0,"",SUM(D17,F17,H17,J17,L17)-O17),"")
A18: 利尻 | B18: 仙法志 | N18: =IF(SUM(D18,F18,H18,J18,L18)>0,IF(SUM(D18,F18,H18,J18,L18)-O18=0,"",SUM(D18,F18,H18,J18,L18)-O18),"")
B19: 沓 形 | N19: =IF(SUM(D19,F19,H19,J19,L19)>0,IF(SUM(D19,F19,H19,J19,L19)-O19=0,"",SUM(D19,F19,H19,J19,L19)-O19),"")
A20: 缶類 | B20: 地区 | C20: １回目収集 | E20: ２回目収集 | G20: ３回目収集 | I20: ４回目収集 | K20: ５回目収集 | N20: 有価回収 | O20: 埋立量
A21: 富士 | B21: 鬼 脇 | N21: =IF(SUM(D21,F21,H21,J21,L21)>0,IF(SUM(D21,F21,H21,J21,L21)-O21=0,"",SUM(D21,F21,H21,J21,L21)-O21),"")
B22: 鴛 泊 | N22: =IF(SUM(D22,F22,H22,J22,L22)>0,IF(SUM(D22,F22,H22,J22,L22)-O22=0,"",SUM(D22,F22,H22,J22,L22)-O22),"")
A23: 利尻 | B23: 仙法志 | N23: =IF(SUM(D23,F23,H23,J23,L23)>0,IF(SUM(D23,F23,H23,J23,L23)-O23=0,"",SUM(D23,F23,H23,J23,L23)-O23),"")
B24: 沓 形 | N24: =IF(SUM(D24,F24,H24,J24,L24)>0,IF(SUM(D24,F24,H24,J24,L24)-O24=0,"",SUM(D24,F24,H24,J24,L24)-O24),"")
A25: ビン | B25: 地区 | C25: １回目収集 | E25: ２回目収集 | G25: ３回目収集 | I25: ４回目収集 | K25: ５回目収集 | N25: 有価回収 | O25: 埋立量
A26: 富士 | B26: 鬼 脇 | O26: =IF(SUM(D26,F26,H26,J26,L26)>0,SUM(D26,F26,H26,J26,L26)-N26,"")
B27: 鴛 泊 | O27: =IF(SUM(D27,F27,H27,J27,L27)>0,SUM(D27,F27,H27,J27,L27)-N27,"")
A28: 利尻 | B28: 仙法志 | O28: =IF(SUM(D28,F28,H28,J28,L28)>0,SUM(D28,F28,H28,J28,L28)-N28,"")
B29: 沓 形 | O29: =IF(SUM(D29,F29,H29,J29,L29)>0,SUM(D29,F29,H29,J29,L29)-N29,"")
A30: 紙類 | B30: 地区 | C30: １回目収集 | E30: ２回目収集 | G30: ３回目収集 | I30: ４回目収集 | K30: ５回目収集 | N30: 有価回収 | O30: 埋立量
A31: 富士 | B31: 鬼 脇 | N31: =IF(SUM(D31,F31,H31,J31,L31)>0,IF(SUM(D31,F31,H31,J31,L31)-O31=0,"",SUM(D31,F31,H31,J31,L31)-O31),"")
B32: 鴛 泊 | N32: =IF(SUM(D32,F32,H32,J32,L32)>0,IF(SUM(D32,F32,H32,J32,L32)-O32=0,"",SUM(D32,F32,H32,J32,L32)-O32),"")
A33: 利尻 | B33: 仙法志 | N33: =IF(SUM(D33,F33,H33,J33,L33)>0,IF(SUM(D33,F33,H33,J33,L33)-O33=0,"",SUM(D33,F33,H33,J33,L33)-O33),"")
B34: 沓 形 | N34: =IF(SUM(D34,F34,H34,J34,L34)>0,IF(SUM(D34,F34,H34,J34,L34)-O34=0,"",SUM(D34,F34,H34,J34,L34)-O34),"")
A35: 収集粗大 | C35: 鬼 脇 | E35: 鴛 泊 | G35: 仙法志 | I35: 沓 形 | K35: その他 | N35: 有価回収 | O35: 埋立量
A36: 埋 立 分 | O36: =IF(SUM(C36:L36)>0,SUM(C36:L36),"")
A37: 有 価 物 | N37: =IF(SUM(C37:L37)>0,SUM(C37:L37),"")
A38: 持込（焼却） | C38: 鬼 脇 | E38: 鴛 泊 | G38: 仙法志 | I38: 沓 形 | K38: その他 | N38: 焼却量 | O38: 埋立量
A39: 可燃物(木・紙) | N39: =IF(SUM(C39:L39)>0,SUM(C39:L39),"")
A40: 併せ産廃（水産） | N40: =IF(SUM(C40:L40)>0,SUM(C40:L40),"")
A41: 併せ産廃（医療） | N41: =IF(SUM(C41:L41)>0,SUM(C41:L41),"")
A42: 一般持込（埋立） | C42: 鬼 脇 | E42: 鴛 泊 | G42: 仙法志 | I42: 沓 形 | K42: その他 | N42: 有価回収 | O42: 埋立量
...

Sheet 7
A1: 課長 | C1: 庶務係長 | E1: =DATE(祝日リスト!C1, 4, 7) -> 46119 | I1: =TEXT(E1,"aaaa") -> 火曜日 | N1: 業務係長 | O1: 主任
F3: 天候 | J3: 気温 | L3: ℃
A5: 可燃 | B5: 地区 | C5: １回目収集 | E5: ２回目収集 | G5: ３回目収集 | I5: ４回目収集 | K5: ５回目収集 | N5: 焼却量 | O5: 埋立量
A6: 富士 | B6: 鬼 脇 | N6: =IF(SUM(D6,F6,H6,J6,L6)>0,IF(SUM(D6,F6,H6,J6,L6)-O6=0,"",SUM(D6,F6,H6,J6,L6)-O6),"")
B7: 鴛 泊 | N7: =IF(SUM(D7,F7,H7,J7,L7)>0,IF(SUM(D7,F7,H7,J7,L7)-O7=0,"",SUM(D7,F7,H7,J7,L7)-O7),"")
A8: 利尻 | B8: 仙法志 | N8: =IF(SUM(D8,F8,H8,J8,L8)>0,IF(SUM(D8,F8,H8,J8,L8)-O8=0,"",SUM(D8,F8,H8,J8,L8)-O8),"")
B9: 沓 形 | N9: =IF(SUM(D9,F9,H9,J9,L9)>0,IF(SUM(D9,F9,H9,J9,L9)-O9=0,"",SUM(D9,F9,H9,J9,L9)-O9),"")
A10: 不燃 | B10: 地区 | C10: １回目収集 | E10: ２回目収集 | G10: ３回目収集 | I10: ４回目収集 | K10: ５回目収集 | N10: 有価回収 | O10: 埋立量
A11: 富士 | B11: 鬼 脇 | O11: =IF(SUM(D11,F11,H11,J11,L11)>0,SUM(D11,F11,H11,J11,L11)-N11,"")
B12: 鴛 泊 | O12: =IF(SUM(D12,F12,H12,J12,L12)>0,SUM(D12,F12,H12,J12,L12)-N12,"")
A13: 利尻 | B13: 仙法志 | O13: =IF(SUM(D13,F13,H13,J13,L13)>0,SUM(D13,F13,H13,J13,L13)-N13,"")
B14: 沓 形 | O14: =IF(SUM(D14,F14,H14,J14,L14)>0,SUM(D14,F14,H14,J14,L14)-N14,"")
A15: ペット | B15: 地区 | C15: １回目収集 | E15: ２回目収集 | G15: ３回目収集 | I15: ４回目収集 | K15: ５回目収集 | N15: 有価回収 | O15: 埋立量
A16: 富士 | B16: 鬼 脇 | N16: =IF(SUM(D16,F16,H16,J16,L16)>0,IF(SUM(D16,F16,H16,J16,L16)-O16=0,"",SUM(D16,F16,H16,J16,L16)-O16),"")
B17: 鴛 泊 | N17: =IF(SUM(D17,F17,H17,J17,L17)>0,IF(SUM(D17,F17,H17,J17,L17)-O17=0,"",SUM(D17,F17,H17,J17,L17)-O17),"")
A18: 利尻 | B18: 仙法志 | N18: =IF(SUM(D18,F18,H18,J18,L18)>0,IF(SUM(D18,F18,H18,J18,L18)-O18=0,"",SUM(D18,F18,H18,J18,L18)-O18),"")
B19: 沓 形 | N19: =IF(SUM(D19,F19,H19,J19,L19)>0,IF(SUM(D19,F19,H19,J19,L19)-O19=0,"",SUM(D19,F19,H19,J19,L19)-O19),"")
A20: 缶類 | B20: 地区 | C20: １回目収集 | E20: ２回目収集 | G20: ３回目収集 | I20: ４回目収集 | K20: ５回目収集 | N20: 有価回収 | O20: 埋立量
A21: 富士 | B21: 鬼 脇 | N21: =IF(SUM(D21,F21,H21,J21,L21)>0,IF(SUM(D21,F21,H21,J21,L21)-O21=0,"",SUM(D21,F21,H21,J21,L21)-O21),"")
B22: 鴛 泊 | N22: =IF(SUM(D22,F22,H22,J22,L22)>0,IF(SUM(D22,F22,H22,J22,L22)-O22=0,"",SUM(D22,F22,H22,J22,L22)-O22),"")
A23: 利尻 | B23: 仙法志 | N23: =IF(SUM(D23,F23,H23,J23,L23)>0,IF(SUM(D23,F23,H23,J23,L23)-O23=0,"",SUM(D23,F23,H23,J23,L23)-O23),"")
B24: 沓 形 | N24: =IF(SUM(D24,F24,H24,J24,L24)>0,IF(SUM(D24,F24,H24,J24,L24)-O24=0,"",SUM(D24,F24,H24,J24,L24)-O24),"")
A25: ビン | B25: 地区 | C25: １回目収集 | E25: ２回目収集 | G25: ３回目収集 | I25: ４回目収集 | K25: ５回目収集 | N25: 有価回収 | O25: 埋立量
A26: 富士 | B26: 鬼 脇 | O26: =IF(SUM(D26,F26,H26,J26,L26)>0,SUM(D26,F26,H26,J26,L26)-N26,"")
B27: 鴛 泊 | O27: =IF(SUM(D27,F27,H27,J27,L27)>0,SUM(D27,F27,H27,J27,L27)-N27,"")
A28: 利尻 | B28: 仙法志 | O28: =IF(SUM(D28,F28,H28,J28,L28)>0,SUM(D28,F28,H28,J28,L28)-N28,"")
B29: 沓 形 | O29: =IF(SUM(D29,F29,H29,J29,L29)>0,SUM(D29,F29,H29,J29,L29)-N29,"")
A30: 紙類 | B30: 地区 | C30: １回目収集 | E30: ２回目収集 | G30: ３回目収集 | I30: ４回目収集 | K30: ５回目収集 | N30: 有価回収 | O30: 埋立量
A31: 富士 | B31: 鬼 脇 | N31: =IF(SUM(D31,F31,H31,J31,L31)>0,IF(SUM(D31,F31,H31,J31,L31)-O31=0,"",SUM(D31,F31,H31,J31,L31)-O31),"")
B32: 鴛 泊 | N32: =IF(SUM(D32,F32,H32,J32,L32)>0,IF(SUM(D32,F32,H32,J32,L32)-O32=0,"",SUM(D32,F32,H32,J32,L32)-O32),"")
A33: 利尻 | B33: 仙法志 | N33: =IF(SUM(D33,F33,H33,J33,L33)>0,IF(SUM(D33,F33,H33,J33,L33)-O33=0,"",SUM(D33,F33,H33,J33,L33)-O33),"")
B34: 沓 形 | N34: =IF(SUM(D34,F34,H34,J34,L34)>0,IF(SUM(D34,F34,H34,J34,L34)-O34=0,"",SUM(D34,F34,H34,J34,L34)-O34),"")
A35: 収集粗大 | C35: 鬼 脇 | E35: 鴛 泊 | G35: 仙法志 | I35: 沓 形 | K35: その他 | N35: 有価回収 | O35: 埋立量
A36: 埋 立 分 | O36: =IF(SUM(C36:L36)>0,SUM(C36:L36),"")
A37: 有 価 物 | N37: =IF(SUM(C37:L37)>0,SUM(C37:L37),"")
A38: 持込（焼却） | C38: 鬼 脇 | E38: 鴛 泊 | G38: 仙法志 | I38: 沓 形 | K38: その他 | N38: 焼却量 | O38: 埋立量
A39: 可燃物(木・紙) | N39: =IF(SUM(C39:L39)>0,SUM(C39:L39),"")
A40: 併せ産廃（水産） | N40: =IF(SUM(C40:L40)>0,SUM(C40:L40),"")
A41: 併せ産廃（医療） | N41: =IF(SUM(C41:L41)>0,SUM(C41:L41),"")
A42: 一般持込（埋立） | C42: 鬼 脇 | E42: 鴛 泊 | G42: 仙法志 | I42: 沓 形 | K42: その他 | N42: 有価回収 | O42: 埋立量
...

Sheet 8
A1: 課長 | C1: 庶務係長 | E1: =DATE(祝日リスト!C1, 4, 8) -> 46120 | I1: =TEXT(E1,"aaaa") -> 水曜日 | N1: 業務係長 | O1: 主任
F3: 天候 | J3: 気温 | L3: ℃
A5: 可燃 | B5: 地区 | C5: １回目収集 | E5: ２回目収集 | G5: ３回目収集 | I5: ４回目収集 | K5: ５回目収集 | N5: 焼却量 | O5: 埋立量
A6: 富士 | B6: 鬼 脇 | N6: =IF(SUM(D6,F6,H6,J6,L6)>0,IF(SUM(D6,F6,H6,J6,L6)-O6=0,"",SUM(D6,F6,H6,J6,L6)-O6),"")
B7: 鴛 泊 | N7: =IF(SUM(D7,F7,H7,J7,L7)>0,IF(SUM(D7,F7,H7,J7,L7)-O7=0,"",SUM(D7,F7,H7,J7,L7)-O7),"")
A8: 利尻 | B8: 仙法志 | N8: =IF(SUM(D8,F8,H8,J8,L8)>0,IF(SUM(D8,F8,H8,J8,L8)-O8=0,"",SUM(D8,F8,H8,J8,L8)-O8),"")
B9: 沓 形 | N9: =IF(SUM(D9,F9,H9,J9,L9)>0,IF(SUM(D9,F9,H9,J9,L9)-O9=0,"",SUM(D9,F9,H9,J9,L9)-O9),"")
A10: 不燃 | B10: 地区 | C10: １回目収集 | E10: ２回目収集 | G10: ３回目収集 | I10: ４回目収集 | K10: ５回目収集 | N10: 有価回収 | O10: 埋立量
A11: 富士 | B11: 鬼 脇 | O11: =IF(SUM(D11,F11,H11,J11,L11)>0,SUM(D11,F11,H11,J11,L11)-N11,"")
B12: 鴛 泊 | O12: =IF(SUM(D12,F12,H12,J12,L12)>0,SUM(D12,F12,H12,J12,L12)-N12,"")
A13: 利尻 | B13: 仙法志 | O13: =IF(SUM(D13,F13,H13,J13,L13)>0,SUM(D13,F13,H13,J13,L13)-N13,"")
B14: 沓 形 | O14: =IF(SUM(D14,F14,H14,J14,L14)>0,SUM(D14,F14,H14,J14,L14)-N14,"")
A15: ペット | B15: 地区 | C15: １回目収集 | E15: ２回目収集 | G15: ３回目収集 | I15: ４回目収集 | K15: ５回目収集 | N15: 有価回収 | O15: 埋立量
A16: 富士 | B16: 鬼 脇 | N16: =IF(SUM(D16,F16,H16,J16,L16)>0,IF(SUM(D16,F16,H16,J16,L16)-O16=0,"",SUM(D16,F16,H16,J16,L16)-O16),"")
B17: 鴛 泊 | N17: =IF(SUM(D17,F17,H17,J17,L17)>0,IF(SUM(D17,F17,H17,J17,L17)-O17=0,"",SUM(D17,F17,H17,J17,L17)-O17),"")
A18: 利尻 | B18: 仙法志 | N18: =IF(SUM(D18,F18,H18,J18,L18)>0,IF(SUM(D18,F18,H18,J18,L18)-O18=0,"",SUM(D18,F18,H18,J18,L18)-O18),"")
B19: 沓 形 | N19: =IF(SUM(D19,F19,H19,J19,L19)>0,IF(SUM(D19,F19,H19,J19,L19)-O19=0,"",SUM(D19,F19,H19,J19,L19)-O19),"")
A20: 缶類 | B20: 地区 | C20: １回目収集 | E20: ２回目収集 | G20: ３回目収集 | I20: ４回目収集 | K20: ５回目収集 | N20: 有価回収 | O20: 埋立量
A21: 富士 | B21: 鬼 脇 | N21: =IF(SUM(D21,F21,H21,J21,L21)>0,IF(SUM(D21,F21,H21,J21,L21)-O21=0,"",SUM(D21,F21,H21,J21,L21)-O21),"")
B22: 鴛 泊 | N22: =IF(SUM(D22,F22,H22,J22,L22)>0,IF(SUM(D22,F22,H22,J22,L22)-O22=0,"",SUM(D22,F22,H22,J22,L22)-O22),"")
A23: 利尻 | B23: 仙法志 | N23: =IF(SUM(D23,F23,H23,J23,L23)>0,IF(SUM(D23,F23,H23,J23,L23)-O23=0,"",SUM(D23,F23,H23,J23,L23)-O23),"")
B24: 沓 形 | N24: =IF(SUM(D24,F24,H24,J24,L24)>0,IF(SUM(D24,F24,H24,J24,L24)-O24=0,"",SUM(D24,F24,H24,J24,L24)-O24),"")
A25: ビン | B25: 地区 | C25: １回目収集 | E25: ２回目収集 | G25: ３回目収集 | I25: ４回目収集 | K25: ５回目収集 | N25: 有価回収 | O25: 埋立量
A26: 富士 | B26: 鬼 脇 | O26: =IF(SUM(D26,F26,H26,J26,L26)>0,SUM(D26,F26,H26,J26,L26)-N26,"")
B27: 鴛 泊 | O27: =IF(SUM(D27,F27,H27,J27,L27)>0,SUM(D27,F27,H27,J27,L27)-N27,"")
A28: 利尻 | B28: 仙法志 | O28: =IF(SUM(D28,F28,H28,J28,L28)>0,SUM(D28,F28,H28,J28,L28)-N28,"")
B29: 沓 形 | O29: =IF(SUM(D29,F29,H29,J29,L29)>0,SUM(D29,F29,H29,J29,L29)-N29,"")
A30: 紙類 | B30: 地区 | C30: １回目収集 | E30: ２回目収集 | G30: ３回目収集 | I30: ４回目収集 | K30: ５回目収集 | N30: 有価回収 | O30: 埋立量
A31: 富士 | B31: 鬼 脇 | N31: =IF(SUM(D31,F31,H31,J31,L31)>0,IF(SUM(D31,F31,H31,J31,L31)-O31=0,"",SUM(D31,F31,H31,J31,L31)-O31),"")
B32: 鴛 泊 | N32: =IF(SUM(D32,F32,H32,J32,L32)>0,IF(SUM(D32,F32,H32,J32,L32)-O32=0,"",SUM(D32,F32,H32,J32,L32)-O32),"")
A33: 利尻 | B33: 仙法志 | N33: =IF(SUM(D33,F33,H33,J33,L33)>0,IF(SUM(D33,F33,H33,J33,L33)-O33=0,"",SUM(D33,F33,H33,J33,L33)-O33),"")
B34: 沓 形 | N34: =IF(SUM(D34,F34,H34,J34,L34)>0,IF(SUM(D34,F34,H34,J34,L34)-O34=0,"",SUM(D34,F34,H34,J34,L34)-O34),"")
A35: 収集粗大 | C35: 鬼 脇 | E35: 鴛 泊 | G35: 仙法志 | I35: 沓 形 | K35: その他 | N35: 有価回収 | O35: 埋立量
A36: 埋 立 分 | O36: =IF(SUM(C36:L36)>0,SUM(C36:L36),"")
A37: 有 価 物 | N37: =IF(SUM(C37:L37)>0,SUM(C37:L37),"")
A38: 持込（焼却） | C38: 鬼 脇 | E38: 鴛 泊 | G38: 仙法志 | I38: 沓 形 | K38: その他 | N38: 焼却量 | O38: 埋立量
A39: 可燃物(木・紙) | N39: =IF(SUM(C39:L39)>0,SUM(C39:L39),"")
A40: 併せ産廃（水産） | N40: =IF(SUM(C40:L40)>0,SUM(C40:L40),"")
A41: 併せ産廃（医療） | N41: =IF(SUM(C41:L41)>0,SUM(C41:L41),"")
A42: 一般持込（埋立） | C42: 鬼 脇 | E42: 鴛 泊 | G42: 仙法志 | I42: 沓 形 | K42: その他 | N42: 有価回収 | O42: 埋立量
...

Sheet 9
A1: 課長 | C1: 庶務係長 | E1: =DATE(祝日リスト!C1, 4, 9) -> 46121 | I1: =TEXT(E1,"aaaa") -> 木曜日 | N1: 業務係長 | O1: 主任
F3: 天候 | J3: 気温 | L3: ℃
A5: 可燃 | B5: 地区 | C5: １回目収集 | E5: ２回目収集 | G5: ３回目収集 | I5: ４回目収集 | K5: ５回目収集 | N5: 焼却量 | O5: 埋立量
A6: 富士 | B6: 鬼 脇 | N6: =IF(SUM(D6,F6,H6,J6,L6)>0,IF(SUM(D6,F6,H6,J6,L6)-O6=0,"",SUM(D6,F6,H6,J6,L6)-O6),"")
B7: 鴛 泊 | N7: =IF(SUM(D7,F7,H7,J7,L7)>0,IF(SUM(D7,F7,H7,J7,L7)-O7=0,"",SUM(D7,F7,H7,J7,L7)-O7),"")
A8: 利尻 | B8: 仙法志 | N8: =IF(SUM(D8,F8,H8,J8,L8)>0,IF(SUM(D8,F8,H8,J8,L8)-O8=0,"",SUM(D8,F8,H8,J8,L8)-O8),"")
B9: 沓 形 | N9: =IF(SUM(D9,F9,H9,J9,L9)>0,IF(SUM(D9,F9,H9,J9,L9)-O9=0,"",SUM(D9,F9,H9,J9,L9)-O9),"")
A10: 不燃 | B10: 地区 | C10: １回目収集 | E10: ２回目収集 | G10: ３回目収集 | I10: ４回目収集 | K10: ５回目収集 | N10: 有価回収 | O10: 埋立量
A11: 富士 | B11: 鬼 脇 | O11: =IF(SUM(D11,F11,H11,J11,L11)>0,SUM(D11,F11,H11,J11,L11)-N11,"")
B12: 鴛 泊 | O12: =IF(SUM(D12,F12,H12,J12,L12)>0,SUM(D12,F12,H12,J12,L12)-N12,"")
A13: 利尻 | B13: 仙法志 | O13: =IF(SUM(D13,F13,H13,J13,L13)>0,SUM(D13,F13,H13,J13,L13)-N13,"")
B14: 沓 形 | O14: =IF(SUM(D14,F14,H14,J14,L14)>0,SUM(D14,F14,H14,J14,L14)-N14,"")
A15: ペット | B15: 地区 | C15: １回目収集 | E15: ２回目収集 | G15: ３回目収集 | I15: ４回目収集 | K15: ５回目収集 | N15: 有価回収 | O15: 埋立量
A16: 富士 | B16: 鬼 脇 | N16: =IF(SUM(D16,F16,H16,J16,L16)>0,IF(SUM(D16,F16,H16,J16,L16)-O16=0,"",SUM(D16,F16,H16,J16,L16)-O16),"")
B17: 鴛 泊 | N17: =IF(SUM(D17,F17,H17,J17,L17)>0,IF(SUM(D17,F17,H17,J17,L17)-O17=0,"",SUM(D17,F17,H17,J17,L17)-O17),"")
A18: 利尻 | B18: 仙法志 | N18: =IF(SUM(D18,F18,H18,J18,L18)>0,IF(SUM(D18,F18,H18,J18,L18)-O18=0,"",SUM(D18,F18,H18,J18,L18)-O18),"")
B19: 沓 形 | N19: =IF(SUM(D19,F19,H19,J19,L19)>0,IF(SUM(D19,F19,H19,J19,L19)-O19=0,"",SUM(D19,F19,H19,J19,L19)-O19),"")
A20: 缶類 | B20: 地区 | C20: １回目収集 | E20: ２回目収集 | G20: ３回目収集 | I20: ４回目収集 | K20: ５回目収集 | N20: 有価回収 | O20: 埋立量
A21: 富士 | B21: 鬼 脇 | N21: =IF(SUM(D21,F21,H21,J21,L21)>0,IF(SUM(D21,F21,H21,J21,L21)-O21=0,"",SUM(D21,F21,H21,J21,L21)-O21),"")
B22: 鴛 泊 | N22: =IF(SUM(D22,F22,H22,J22,L22)>0,IF(SUM(D22,F22,H22,J22,L22)-O22=0,"",SUM(D22,F22,H22,J22,L22)-O22),"")
A23: 利尻 | B23: 仙法志 | N23: =IF(SUM(D23,F23,H23,J23,L23)>0,IF(SUM(D23,F23,H23,J23,L23)-O23=0,"",SUM(D23,F23,H23,J23,L23)-O23),"")
B24: 沓 形 | N24: =IF(SUM(D24,F24,H24,J24,L24)>0,IF(SUM(D24,F24,H24,J24,L24)-O24=0,"",SUM(D24,F24,H24,J24,L24)-O24),"")
A25: ビン | B25: 地区 | C25: １回目収集 | E25: ２回目収集 | G25: ３回目収集 | I25: ４回目収集 | K25: ５回目収集 | N25: 有価回収 | O25: 埋立量
A26: 富士 | B26: 鬼 脇 | O26: =IF(SUM(D26,F26,H26,J26,L26)>0,SUM(D26,F26,H26,J26,L26)-N26,"")
B27: 鴛 泊 | O27: =IF(SUM(D27,F27,H27,J27,L27)>0,SUM(D27,F27,H27,J27,L27)-N27,"")
A28: 利尻 | B28: 仙法志 | O28: =IF(SUM(D28,F28,H28,J28,L28)>0,SUM(D28,F28,H28,J28,L28)-N28,"")
B29: 沓 形 | O29: =IF(SUM(D29,F29,H29,J29,L29)>0,SUM(D29,F29,H29,J29,L29)-N29,"")
A30: 紙類 | B30: 地区 | C30: １回目収集 | E30: ２回目収集 | G30: ３回目収集 | I30: ４回目収集 | K30: ５回目収集 | N30: 有価回収 | O30: 埋立量
A31: 富士 | B31: 鬼 脇 | N31: =IF(SUM(D31,F31,H31,J31,L31)>0,IF(SUM(D31,F31,H31,J31,L31)-O31=0,"",SUM(D31,F31,H31,J31,L31)-O31),"")
B32: 鴛 泊 | N32: =IF(SUM(D32,F32,H32,J32,L32)>0,IF(SUM(D32,F32,H32,J32,L32)-O32=0,"",SUM(D32,F32,H32,J32,L32)-O32),"")
A33: 利尻 | B33: 仙法志 | N33: =IF(SUM(D33,F33,H33,J33,L33)>0,IF(SUM(D33,F33,H33,J33,L33)-O33=0,"",SUM(D33,F33,H33,J33,L33)-O33),"")
B34: 沓 形 | N34: =IF(SUM(D34,F34,H34,J34,L34)>0,IF(SUM(D34,F34,H34,J34,L34)-O34=0,"",SUM(D34,F34,H34,J34,L34)-O34),"")
A35: 収集粗大 | C35: 鬼 脇 | E35: 鴛 泊 | G35: 仙法志 | I35: 沓 形 | K35: その他 | N35: 有価回収 | O35: 埋立量
A36: 埋 立 分 | O36: =IF(SUM(C36:L36)>0,SUM(C36:L36),"")
A37: 有 価 物 | N37: =IF(SUM(C37:L37)>0,SUM(C37:L37),"")
A38: 持込（焼却） | C38: 鬼 脇 | E38: 鴛 泊 | G38: 仙法志 | I38: 沓 形 | K38: その他 | N38: 焼却量 | O38: 埋立量
A39: 可燃物(木・紙) | N39: =IF(SUM(C39:L39)>0,SUM(C39:L39),"")
A40: 併せ産廃（水産） | N40: =IF(SUM(C40:L40)>0,SUM(C40:L40),"")
A41: 併せ産廃（医療） | N41: =IF(SUM(C41:L41)>0,SUM(C41:L41),"")
A42: 一般持込（埋立） | C42: 鬼 脇 | E42: 鴛 泊 | G42: 仙法志 | I42: 沓 形 | K42: その他 | N42: 有価回収 | O42: 埋立量
...

Sheet 10
A1: 課長 | C1: 庶務係長 | E1: =DATE(祝日リスト!C1, 4, 10) -> 46122 | I1: =TEXT(E1,"aaaa") -> 金曜日 | N1: 業務係長 | O1: 主任
F3: 天候 | J3: 気温 | L3: ℃
A5: 可燃 | B5: 地区 | C5: １回目収集 | E5: ２回目収集 | G5: ３回目収集 | I5: ４回目収集 | K5: ５回目収集 | N5: 焼却量 | O5: 埋立量
A6: 富士 | B6: 鬼 脇 | N6: =IF(SUM(D6,F6,H6,J6,L6)>0,IF(SUM(D6,F6,H6,J6,L6)-O6=0,"",SUM(D6,F6,H6,J6,L6)-O6),"")
B7: 鴛 泊 | N7: =IF(SUM(D7,F7,H7,J7,L7)>0,IF(SUM(D7,F7,H7,J7,L7)-O7=0,"",SUM(D7,F7,H7,J7,L7)-O7),"")
A8: 利尻 | B8: 仙法志 | N8: =IF(SUM(D8,F8,H8,J8,L8)>0,IF(SUM(D8,F8,H8,J8,L8)-O8=0,"",SUM(D8,F8,H8,J8,L8)-O8),"")
B9: 沓 形 | N9: =IF(SUM(D9,F9,H9,J9,L9)>0,IF(SUM(D9,F9,H9,J9,L9)-O9=0,"",SUM(D9,F9,H9,J9,L9)-O9),"")
A10: 不燃 | B10: 地区 | C10: １回目収集 | E10: ２回目収集 | G10: ３回目収集 | I10: ４回目収集 | K10: ５回目収集 | N10: 有価回収 | O10: 埋立量
A11: 富士 | B11: 鬼 脇 | O11: =IF(SUM(D11,F11,H11,J11,L11)>0,SUM(D11,F11,H11,J11,L11)-N11,"")
B12: 鴛 泊 | O12: =IF(SUM(D12,F12,H12,J12,L12)>0,SUM(D12,F12,H12,J12,L12)-N12,"")
A13: 利尻 | B13: 仙法志 | O13: =IF(SUM(D13,F13,H13,J13,L13)>0,SUM(D13,F13,H13,J13,L13)-N13,"")
B14: 沓 形 | O14: =IF(SUM(D14,F14,H14,J14,L14)>0,SUM(D14,F14,H14,J14,L14)-N14,"")
A15: ペット | B15: 地区 | C15: １回目収集 | E15: ２回目収集 | G15: ３回目収集 | I15: ４回目収集 | K15: ５回目収集 | N15: 有価回収 | O15: 埋立量
A16: 富士 | B16: 鬼 脇 | N16: =IF(SUM(D16,F16,H16,J16,L16)>0,IF(SUM(D16,F16,H16,J16,L16)-O16=0,"",SUM(D16,F16,H16,J16,L16)-O16),"")
B17: 鴛 泊 | N17: =IF(SUM(D17,F17,H17,J17,L17)>0,IF(SUM(D17,F17,H17,J17,L17)-O17=0,"",SUM(D17,F17,H17,J17,L17)-O17),"")
A18: 利尻 | B18: 仙法志 | N18: =IF(SUM(D18,F18,H18,J18,L18)>0,IF(SUM(D18,F18,H18,J18,L18)-O18=0,"",SUM(D18,F18,H18,J18,L18)-O18),"")
B19: 沓 形 | N19: =IF(SUM(D19,F19,H19,J19,L19)>0,IF(SUM(D19,F19,H19,J19,L19)-O19=0,"",SUM(D19,F19,H19,J19,L19)-O19),"")
A20: 缶類 | B20: 地区 | C20: １回目収集 | E20: ２回目収集 | G20: ３回目収集 | I20: ４回目収集 | K20: ５回目収集 | N20: 有価回収 | O20: 埋立量
A21: 富士 | B21: 鬼 脇 | N21: =IF(SUM(D21,F21,H21,J21,L21)>0,IF(SUM(D21,F21,H21,J21,L21)-O21=0,"",SUM(D21,F21,H21,J21,L21)-O21),"")
B22: 鴛 泊 | N22: =IF(SUM(D22,F22,H22,J22,L22)>0,IF(SUM(D22,F22,H22,J22,L22)-O22=0,"",SUM(D22,F22,H22,J22,L22)-O22),"")
A23: 利尻 | B23: 仙法志 | N23: =IF(SUM(D23,F23,H23,J23,L23)>0,IF(SUM(D23,F23,H23,J23,L23)-O23=0,"",SUM(D23,F23,H23,J23,L23)-O23),"")
B24: 沓 形 | N24: =IF(SUM(D24,F24,H24,J24,L24)>0,IF(SUM(D24,F24,H24,J24,L24)-O24=0,"",SUM(D24,F24,H24,J24,L24)-O24),"")
A25: ビン | B25: 地区 | C25: １回目収集 | E25: ２回目収集 | G25: ３回目収集 | I25: ４回目収集 | K25: ５回目収集 | N25: 有価回収 | O25: 埋立量
A26: 富士 | B26: 鬼 脇 | O26: =IF(SUM(D26,F26,H26,J26,L26)>0,SUM(D26,F26,H26,J26,L26)-N26,"")
B27: 鴛 泊 | O27: =IF(SUM(D27,F27,H27,J27,L27)>0,SUM(D27,F27,H27,J27,L27)-N27,"")
A28: 利尻 | B28: 仙法志 | O28: =IF(SUM(D28,F28,H28,J28,L28)>0,SUM(D28,F28,H28,J28,L28)-N28,"")
B29: 沓 形 | O29: =IF(SUM(D29,F29,H29,J29,L29)>0,SUM(D29,F29,H29,J29,L29)-N29,"")
A30: 紙類 | B30: 地区 | C30: １回目収集 | E30: ２回目収集 | G30: ３回目収集 | I30: ４回目収集 | K30: ５回目収集 | N30: 有価回収 | O30: 埋立量
A31: 富士 | B31: 鬼 脇 | N31: =IF(SUM(D31,F31,H31,J31,L31)>0,IF(SUM(D31,F31,H31,J31,L31)-O31=0,"",SUM(D31,F31,H31,J31,L31)-O31),"")
B32: 鴛 泊 | N32: =IF(SUM(D32,F32,H32,J32,L32)>0,IF(SUM(D32,F32,H32,J32,L32)-O32=0,"",SUM(D32,F32,H32,J32,L32)-O32),"")
A33: 利尻 | B33: 仙法志 | N33: =IF(SUM(D33,F33,H33,J33,L33)>0,IF(SUM(D33,F33,H33,J33,L33)-O33=0,"",SUM(D33,F33,H33,J33,L33)-O33),"")
B34: 沓 形 | N34: =IF(SUM(D34,F34,H34,J34,L34)>0,IF(SUM(D34,F34,H34,J34,L34)-O34=0,"",SUM(D34,F34,H34,J34,L34)-O34),"")
A35: 収集粗大 | C35: 鬼 脇 | E35: 鴛 泊 | G35: 仙法志 | I35: 沓 形 | K35: その他 | N35: 有価回収 | O35: 埋立量
A36: 埋 立 分 | O36: =IF(SUM(C36:L36)>0,SUM(C36:L36),"")
A37: 有 価 物 | N37: =IF(SUM(C37:L37)>0,SUM(C37:L37),"")
A38: 持込（焼却） | C38: 鬼 脇 | E38: 鴛 泊 | G38: 仙法志 | I38: 沓 形 | K38: その他 | N38: 焼却量 | O38: 埋立量
A39: 可燃物(木・紙) | N39: =IF(SUM(C39:L39)>0,SUM(C39:L39),"")
A40: 併せ産廃（水産） | N40: =IF(SUM(C40:L40)>0,SUM(C40:L40),"")
A41: 併せ産廃（医療） | N41: =IF(SUM(C41:L41)>0,SUM(C41:L41),"")
A42: 一般持込（埋立） | C42: 鬼 脇 | E42: 鴛 泊 | G42: 仙法志 | I42: 沓 形 | K42: その他 | N42: 有価回収 | O42: 埋立量
...

Sheet 11
A1: 課長 | C1: 庶務係長 | E1: =DATE(祝日リスト!C1, 4, 11) -> 46123 | I1: =TEXT(E1,"aaaa") -> 土曜日 | N1: 業務係長 | O1: 主任
F3: 天候 | J3: 気温 | L3: ℃
A5: 可燃 | B5: 地区 | C5: １回目収集 | E5: ２回目収集 | G5: ３回目収集 | I5: ４回目収集 | K5: ５回目収集 | N5: 焼却量 | O5: 埋立量
A6: 富士 | B6: 鬼 脇 | N6: =IF(SUM(D6,F6,H6,J6,L6)>0,IF(SUM(D6,F6,H6,J6,L6)-O6=0,"",SUM(D6,F6,H6,J6,L6)-O6),"")
B7: 鴛 泊 | N7: =IF(SUM(D7,F7,H7,J7,L7)>0,IF(SUM(D7,F7,H7,J7,L7)-O7=0,"",SUM(D7,F7,H7,J7,L7)-O7),"")
A8: 利尻 | B8: 仙法志 | N8: =IF(SUM(D8,F8,H8,J8,L8)>0,IF(SUM(D8,F8,H8,J8,L8)-O8=0,"",SUM(D8,F8,H8,J8,L8)-O8),"")
B9: 沓 形 | N9: =IF(SUM(D9,F9,H9,J9,L9)>0,IF(SUM(D9,F9,H9,J9,L9)-O9=0,"",SUM(D9,F9,H9,J9,L9)-O9),"")
A10: 不燃 | B10: 地区 | C10: １回目収集 | E10: ２回目収集 | G10: ３回目収集 | I10: ４回目収集 | K10: ５回目収集 | N10: 有価回収 | O10: 埋立量
A11: 富士 | B11: 鬼 脇 | O11: =IF(SUM(D11,F11,H11,J11,L11)>0,SUM(D11,F11,H11,J11,L11)-N11,"")
B12: 鴛 泊 | O12: =IF(SUM(D12,F12,H12,J12,L12)>0,SUM(D12,F12,H12,J12,L12)-N12,"")
A13: 利尻 | B13: 仙法志 | O13: =IF(SUM(D13,F13,H13,J13,L13)>0,SUM(D13,F13,H13,J13,L13)-N13,"")
B14: 沓 形 | O14: =IF(SUM(D14,F14,H14,J14,L14)>0,SUM(D14,F14,H14,J14,L14)-N14,"")
A15: ペット | B15: 地区 | C15: １回目収集 | E15: ２回目収集 | G15: ３回目収集 | I15: ４回目収集 | K15: ５回目収集 | N15: 有価回収 | O15: 埋立量
A16: 富士 | B16: 鬼 脇 | N16: =IF(SUM(D16,F16,H16,J16,L16)>0,IF(SUM(D16,F16,H16,J16,L16)-O16=0,"",SUM(D16,F16,H16,J16,L16)-O16),"")
B17: 鴛 泊 | N17: =IF(SUM(D17,F17,H17,J17,L17)>0,IF(SUM(D17,F17,H17,J17,L17)-O17=0,"",SUM(D17,F17,H17,J17,L17)-O17),"")
A18: 利尻 | B18: 仙法志 | N18: =IF(SUM(D18,F18,H18,J18,L18)>0,IF(SUM(D18,F18,H18,J18,L18)-O18=0,"",SUM(D18,F18,H18,J18,L18)-O18),"")
B19: 沓 形 | N19: =IF(SUM(D19,F19,H19,J19,L19)>0,IF(SUM(D19,F19,H19,J19,L19)-O19=0,"",SUM(D19,F19,H19,J19,L19)-O19),"")
A20: 缶類 | B20: 地区 | C20: １回目収集 | E20: ２回目収集 | G20: ３回目収集 | I20: ４回目収集 | K20: ５回目収集 | N20: 有価回収 | O20: 埋立量
A21: 富士 | B21: 鬼 脇 | N21: =IF(SUM(D21,F21,H21,J21,L21)>0,IF(SUM(D21,F21,H21,J21,L21)-O21=0,"",SUM(D21,F21,H21,J21,L21)-O21),"")
B22: 鴛 泊 | N22: =IF(SUM(D22,F22,H22,J22,L22)>0,IF(SUM(D22,F22,H22,J22,L22)-O22=0,"",SUM(D22,F22,H22,J22,L22)-O22),"")
A23: 利尻 | B23: 仙法志 | N23: =IF(SUM(D23,F23,H23,J23,L23)>0,IF(SUM(D23,F23,H23,J23,L23)-O23=0,"",SUM(D23,F23,H23,J23,L23)-O23),"")
B24: 沓 形 | N24: =IF(SUM(D24,F24,H24,J24,L24)>0,IF(SUM(D24,F24,H24,J24,L24)-O24=0,"",SUM(D24,F24,H24,J24,L24)-O24),"")
A25: ビン | B25: 地区 | C25: １回目収集 | E25: ２回目収集 | G25: ３回目収集 | I25: ４回目収集 | K25: ５回目収集 | N25: 有価回収 | O25: 埋立量
A26: 富士 | B26: 鬼 脇 | O26: =IF(SUM(D26,F26,H26,J26,L26)>0,SUM(D26,F26,H26,J26,L26)-N26,"")
B27: 鴛 泊 | O27: =IF(SUM(D27,F27,H27,J27,L27)>0,SUM(D27,F27,H27,J27,L27)-N27,"")
A28: 利尻 | B28: 仙法志 | O28: =IF(SUM(D28,F28,H28,J28,L28)>0,SUM(D28,F28,H28,J28,L28)-N28,"")
B29: 沓 形 | O29: =IF(SUM(D29,F29,H29,J29,L29)>0,SUM(D29,F29,H29,J29,L29)-N29,"")
A30: 紙類 | B30: 地区 | C30: １回目収集 | E30: ２回目収集 | G30: ３回目収集 | I30: ４回目収集 | K30: ５回目収集 | N30: 有価回収 | O30: 埋立量
A31: 富士 | B31: 鬼 脇 | N31: =IF(SUM(D31,F31,H31,J31,L31)>0,IF(SUM(D31,F31,H31,J31,L31)-O31=0,"",SUM(D31,F31,H31,J31,L31)-O31),"")
B32: 鴛 泊 | N32: =IF(SUM(D32,F32,H32,J32,L32)>0,IF(SUM(D32,F32,H32,J32,L32)-O32=0,"",SUM(D32,F32,H32,J32,L32)-O32),"")
A33: 利尻 | B33: 仙法志 | N33: =IF(SUM(D33,F33,H33,J33,L33)>0,IF(SUM(D33,F33,H33,J33,L33)-O33=0,"",SUM(D33,F33,H33,J33,L33)-O33),"")
B34: 沓 形 | N34: =IF(SUM(D34,F34,H34,J34,L34)>0,IF(SUM(D34,F34,H34,J34,L34)-O34=0,"",SUM(D34,F34,H34,J34,L34)-O34),"")
A35: 収集粗大 | C35: 鬼 脇 | E35: 鴛 泊 | G35: 仙法志 | I35: 沓 形 | K35: その他 | N35: 有価回収 | O35: 埋立量
A36: 埋 立 分 | O36: =IF(SUM(C36:L36)>0,SUM(C36:L36),"")
A37: 有 価 物 | N37: =IF(SUM(C37:L37)>0,SUM(C37:L37),"")
A38: 持込（焼却） | C38: 鬼 脇 | E38: 鴛 泊 | G38: 仙法志 | I38: 沓 形 | K38: その他 | N38: 焼却量 | O38: 埋立量
A39: 可燃物(木・紙) | N39: =IF(SUM(C39:L39)>0,SUM(C39:L39),"")
A40: 併せ産廃（水産） | N40: =IF(SUM(C40:L40)>0,SUM(C40:L40),"")
A41: 併せ産廃（医療） | N41: =IF(SUM(C41:L41)>0,SUM(C41:L41),"")
A42: 一般持込（埋立） | C42: 鬼 脇 | E42: 鴛 泊 | G42: 仙法志 | I42: 沓 形 | K42: その他 | N42: 有価回収 | O42: 埋立量
...

Sheet 12
A1: 課長 | C1: 庶務係長 | E1: =DATE(祝日リスト!C1, 4, 12) -> 46124 | I1: =TEXT(E1,"aaaa") -> 日曜日 | N1: 業務係長 | O1: 主任
F3: 天候 | J3: 気温 | L3: ℃
A5: 可燃 | B5: 地区 | C5: １回目収集 | E5: ２回目収集 | G5: ３回目収集 | I5: ４回目収集 | K5: ５回目収集 | N5: 焼却量 | O5: 埋立量
A6: 富士 | B6: 鬼 脇 | N6: =IF(SUM(D6,F6,H6,J6,L6)>0,IF(SUM(D6,F6,H6,J6,L6)-O6=0,"",SUM(D6,F6,H6,J6,L6)-O6),"")
B7: 鴛 泊 | N7: =IF(SUM(D7,F7,H7,J7,L7)>0,IF(SUM(D7,F7,H7,J7,L7)-O7=0,"",SUM(D7,F7,H7,J7,L7)-O7),"")
A8: 利尻 | B8: 仙法志 | N8: =IF(SUM(D8,F8,H8,J8,L8)>0,IF(SUM(D8,F8,H8,J8,L8)-O8=0,"",SUM(D8,F8,H8,J8,L8)-O8),"")
B9: 沓 形 | N9: =IF(SUM(D9,F9,H9,J9,L9)>0,IF(SUM(D9,F9,H9,J9,L9)-O9=0,"",SUM(D9,F9,H9,J9,L9)-O9),"")
A10: 不燃 | B10: 地区 | C10: １回目収集 | E10: ２回目収集 | G10: ３回目収集 | I10: ４回目収集 | K10: ５回目収集 | N10: 有価回収 | O10: 埋立量
A11: 富士 | B11: 鬼 脇 | O11: =IF(SUM(D11,F11,H11,J11,L11)>0,SUM(D11,F11,H11,J11,L11)-N11,"")
B12: 鴛 泊 | O12: =IF(SUM(D12,F12,H12,J12,L12)>0,SUM(D12,F12,H12,J12,L12)-N12,"")
A13: 利尻 | B13: 仙法志 | O13: =IF(SUM(D13,F13,H13,J13,L13)>0,SUM(D13,F13,H13,J13,L13)-N13,"")
B14: 沓 形 | O14: =IF(SUM(D14,F14,H14,J14,L14)>0,SUM(D14,F14,H14,J14,L14)-N14,"")
A15: ペット | B15: 地区 | C15: １回目収集 | E15: ２回目収集 | G15: ３回目収集 | I15: ４回目収集 | K15: ５回目収集 | N15: 有価回収 | O15: 埋立量
A16: 富士 | B16: 鬼 脇 | N16: =IF(SUM(D16,F16,H16,J16,L16)>0,IF(SUM(D16,F16,H16,J16,L16)-O16=0,"",SUM(D16,F16,H16,J16,L16)-O16),"")
B17: 鴛 泊 | N17: =IF(SUM(D17,F17,H17,J17,L17)>0,IF(SUM(D17,F17,H17,J17,L17)-O17=0,"",SUM(D17,F17,H17,J17,L17)-O17),"")
A18: 利尻 | B18: 仙法志 | N18: =IF(SUM(D18,F18,H18,J18,L18)>0,IF(SUM(D18,F18,H18,J18,L18)-O18=0,"",SUM(D18,F18,H18,J18,L18)-O18),"")
B19: 沓 形 | N19: =IF(SUM(D19,F19,H19,J19,L19)>0,IF(SUM(D19,F19,H19,J19,L19)-O19=0,"",SUM(D19,F19,H19,J19,L19)-O19),"")
A20: 缶類 | B20: 地区 | C20: １回目収集 | E20: ２回目収集 | G20: ３回目収集 | I20: ４回目収集 | K20: ５回目収集 | N20: 有価回収 | O20: 埋立量
A21: 富士 | B21: 鬼 脇 | N21: =IF(SUM(D21,F21,H21,J21,L21)>0,IF(SUM(D21,F21,H21,J21,L21)-O21=0,"",SUM(D21,F21,H21,J21,L21)-O21),"")
B22: 鴛 泊 | N22: =IF(SUM(D22,F22,H22,J22,L22)>0,IF(SUM(D22,F22,H22,J22,L22)-O22=0,"",SUM(D22,F22,H22,J22,L22)-O22),"")
A23: 利尻 | B23: 仙法志 | N23: =IF(SUM(D23,F23,H23,J23,L23)>0,IF(SUM(D23,F23,H23,J23,L23)-O23=0,"",SUM(D23,F23,H23,J23,L23)-O23),"")
B24: 沓 形 | N24: =IF(SUM(D24,F24,H24,J24,L24)>0,IF(SUM(D24,F24,H24,J24,L24)-O24=0,"",SUM(D24,F24,H24,J24,L24)-O24),"")
A25: ビン | B25: 地区 | C25: １回目収集 | E25: ２回目収集 | G25: ３回目収集 | I25: ４回目収集 | K25: ５回目収集 | N25: 有価回収 | O25: 埋立量
A26: 富士 | B26: 鬼 脇 | O26: =IF(SUM(D26,F26,H26,J26,L26)>0,SUM(D26,F26,H26,J26,L26)-N26,"")
B27: 鴛 泊 | O27: =IF(SUM(D27,F27,H27,J27,L27)>0,SUM(D27,F27,H27,J27,L27)-N27,"")
A28: 利尻 | B28: 仙法志 | O28: =IF(SUM(D28,F28,H28,J28,L28)>0,SUM(D28,F28,H28,J28,L28)-N28,"")
B29: 沓 形 | O29: =IF(SUM(D29,F29,H29,J29,L29)>0,SUM(D29,F29,H29,J29,L29)-N29,"")
A30: 紙類 | B30: 地区 | C30: １回目収集 | E30: ２回目収集 | G30: ３回目収集 | I30: ４回目収集 | K30: ５回目収集 | N30: 有価回収 | O30: 埋立量
A31: 富士 | B31: 鬼 脇 | N31: =IF(SUM(D31,F31,H31,J31,L31)>0,IF(SUM(D31,F31,H31,J31,L31)-O31=0,"",SUM(D31,F31,H31,J31,L31)-O31),"")
B32: 鴛 泊 | N32: =IF(SUM(D32,F32,H32,J32,L32)>0,IF(SUM(D32,F32,H32,J32,L32)-O32=0,"",SUM(D32,F32,H32,J32,L32)-O32),"")
A33: 利尻 | B33: 仙法志 | N33: =IF(SUM(D33,F33,H33,J33,L33)>0,IF(SUM(D33,F33,H33,J33,L33)-O33=0,"",SUM(D33,F33,H33,J33,L33)-O33),"")
B34: 沓 形 | N34: =IF(SUM(D34,F34,H34,J34,L34)>0,IF(SUM(D34,F34,H34,J34,L34)-O34=0,"",SUM(D34,F34,H34,J34,L34)-O34),"")
A35: 収集粗大 | C35: 鬼 脇 | E35: 鴛 泊 | G35: 仙法志 | I35: 沓 形 | K35: その他 | N35: 有価回収 | O35: 埋立量
A36: 埋 立 分 | O36: =IF(SUM(C36:L36)>0,SUM(C36:L36),"")
A37: 有 価 物 | N37: =IF(SUM(C37:L37)>0,SUM(C37:L37),"")
A38: 持込（焼却） | C38: 鬼 脇 | E38: 鴛 泊 | G38: 仙法志 | I38: 沓 形 | K38: その他 | N38: 焼却量 | O38: 埋立量
A39: 可燃物(木・紙) | N39: =IF(SUM(C39:L39)>0,SUM(C39:L39),"")
A40: 併せ産廃（水産） | N40: =IF(SUM(C40:L40)>0,SUM(C40:L40),"")
A41: 併せ産廃（医療） | N41: =IF(SUM(C41:L41)>0,SUM(C41:L41),"")
A42: 一般持込（埋立） | C42: 鬼 脇 | E42: 鴛 泊 | G42: 仙法志 | I42: 沓 形 | K42: その他 | N42: 有価回収 | O42: 埋立量
...

Sheet 13
A1: 課長 | C1: 庶務係長 | E1: =DATE(祝日リスト!C1, 4, 13) -> 46125 | I1: =TEXT(E1,"aaaa") -> 月曜日 | N1: 業務係長 | O1: 主任
F3: 天候 | J3: 気温 | L3: ℃
A5: 可燃 | B5: 地区 | C5: １回目収集 | E5: ２回目収集 | G5: ３回目収集 | I5: ４回目収集 | K5: ５回目収集 | N5: 焼却量 | O5: 埋立量
A6: 富士 | B6: 鬼 脇 | N6: =IF(SUM(D6,F6,H6,J6,L6)>0,IF(SUM(D6,F6,H6,J6,L6)-O6=0,"",SUM(D6,F6,H6,J6,L6)-O6),"")
B7: 鴛 泊 | N7: =IF(SUM(D7,F7,H7,J7,L7)>0,IF(SUM(D7,F7,H7,J7,L7)-O7=0,"",SUM(D7,F7,H7,J7,L7)-O7),"")
A8: 利尻 | B8: 仙法志 | N8: =IF(SUM(D8,F8,H8,J8,L8)>0,IF(SUM(D8,F8,H8,J8,L8)-O8=0,"",SUM(D8,F8,H8,J8,L8)-O8),"")
B9: 沓 形 | N9: =IF(SUM(D9,F9,H9,J9,L9)>0,IF(SUM(D9,F9,H9,J9,L9)-O9=0,"",SUM(D9,F9,H9,J9,L9)-O9),"")
A10: 不燃 | B10: 地区 | C10: １回目収集 | E10: ２回目収集 | G10: ３回目収集 | I10: ４回目収集 | K10: ５回目収集 | N10: 有価回収 | O10: 埋立量
A11: 富士 | B11: 鬼 脇 | O11: =IF(SUM(D11,F11,H11,J11,L11)>0,SUM(D11,F11,H11,J11,L11)-N11,"")
B12: 鴛 泊 | O12: =IF(SUM(D12,F12,H12,J12,L12)>0,SUM(D12,F12,H12,J12,L12)-N12,"")
A13: 利尻 | B13: 仙法志 | O13: =IF(SUM(D13,F13,H13,J13,L13)>0,SUM(D13,F13,H13,J13,L13)-N13,"")
B14: 沓 形 | O14: =IF(SUM(D14,F14,H14,J14,L14)>0,SUM(D14,F14,H14,J14,L14)-N14,"")
A15: ペット | B15: 地区 | C15: １回目収集 | E15: ２回目収集 | G15: ３回目収集 | I15: ４回目収集 | K15: ５回目収集 | N15: 有価回収 | O15: 埋立量
A16: 富士 | B16: 鬼 脇 | N16: =IF(SUM(D16,F16,H16,J16,L16)>0,IF(SUM(D16,F16,H16,J16,L16)-O16=0,"",SUM(D16,F16,H16,J16,L16)-O16),"")
B17: 鴛 泊 | N17: =IF(SUM(D17,F17,H17,J17,L17)>0,IF(SUM(D17,F17,H17,J17,L17)-O17=0,"",SUM(D17,F17,H17,J17,L17)-O17),"")
A18: 利尻 | B18: 仙法志 | N18: =IF(SUM(D18,F18,H18,J18,L18)>0,IF(SUM(D18,F18,H18,J18,L18)-O18=0,"",SUM(D18,F18,H18,J18,L18)-O18),"")
B19: 沓 形 | N19: =IF(SUM(D19,F19,H19,J19,L19)>0,IF(SUM(D19,F19,H19,J19,L19)-O19=0,"",SUM(D19,F19,H19,J19,L19)-O19),"")
A20: 缶類 | B20: 地区 | C20: １回目収集 | E20: ２回目収集 | G20: ３回目収集 | I20: ４回目収集 | K20: ５回目収集 | N20: 有価回収 | O20: 埋立量
A21: 富士 | B21: 鬼 脇 | N21: =IF(SUM(D21,F21,H21,J21,L21)>0,IF(SUM(D21,F21,H21,J21,L21)-O21=0,"",SUM(D21,F21,H21,J21,L21)-O21),"")
B22: 鴛 泊 | N22: =IF(SUM(D22,F22,H22,J22,L22)>0,IF(SUM(D22,F22,H22,J22,L22)-O22=0,"",SUM(D22,F22,H22,J22,L22)-O22),"")
A23: 利尻 | B23: 仙法志 | N23: =IF(SUM(D23,F23,H23,J23,L23)>0,IF(SUM(D23,F23,H23,J23,L23)-O23=0,"",SUM(D23,F23,H23,J23,L23)-O23),"")
B24: 沓 形 | N24: =IF(SUM(D24,F24,H24,J24,L24)>0,IF(SUM(D24,F24,H24,J24,L24)-O24=0,"",SUM(D24,F24,H24,J24,L24)-O24),"")
A25: ビン | B25: 地区 | C25: １回目収集 | E25: ２回目収集 | G25: ３回目収集 | I25: ４回目収集 | K25: ５回目収集 | N25: 有価回収 | O25: 埋立量
A26: 富士 | B26: 鬼 脇 | O26: =IF(SUM(D26,F26,H26,J26,L26)>0,SUM(D26,F26,H26,J26,L26)-N26,"")
B27: 鴛 泊 | O27: =IF(SUM(D27,F27,H27,J27,L27)>0,SUM(D27,F27,H27,J27,L27)-N27,"")
A28: 利尻 | B28: 仙法志 | O28: =IF(SUM(D28,F28,H28,J28,L28)>0,SUM(D28,F28,H28,J28,L28)-N28,"")
B29: 沓 形 | O29: =IF(SUM(D29,F29,H29,J29,L29)>0,SUM(D29,F29,H29,J29,L29)-N29,"")
A30: 紙類 | B30: 地区 | C30: １回目収集 | E30: ２回目収集 | G30: ３回目収集 | I30: ４回目収集 | K30: ５回目収集 | N30: 有価回収 | O30: 埋立量
A31: 富士 | B31: 鬼 脇 | N31: =IF(SUM(D31,F31,H31,J31,L31)>0,IF(SUM(D31,F31,H31,J31,L31)-O31=0,"",SUM(D31,F31,H31,J31,L31)-O31),"")
B32: 鴛 泊 | N32: =IF(SUM(D32,F32,H32,J32,L32)>0,IF(SUM(D32,F32,H32,J32,L32)-O32=0,"",SUM(D32,F32,H32,J32,L32)-O32),"")
A33: 利尻 | B33: 仙法志 | N33: =IF(SUM(D33,F33,H33,J33,L33)>0,IF(SUM(D33,F33,H33,J33,L33)-O33=0,"",SUM(D33,F33,H33,J33,L33)-O33),"")
B34: 沓 形 | N34: =IF(SUM(D34,F34,H34,J34,L34)>0,IF(SUM(D34,F34,H34,J34,L34)-O34=0,"",SUM(D34,F34,H34,J34,L34)-O34),"")
A35: 収集粗大 | C35: 鬼 脇 | E35: 鴛 泊 | G35: 仙法志 | I35: 沓 形 | K35: その他 | N35: 有価回収 | O35: 埋立量
A36: 埋 立 分 | O36: =IF(SUM(C36:L36)>0,SUM(C36:L36),"")
A37: 有 価 物 | N37: =IF(SUM(C37:L37)>0,SUM(C37:L37),"")
A38: 持込（焼却） | C38: 鬼 脇 | E38: 鴛 泊 | G38: 仙法志 | I38: 沓 形 | K38: その他 | N38: 焼却量 | O38: 埋立量
A39: 可燃物(木・紙) | N39: =IF(SUM(C39:L39)>0,SUM(C39:L39),"")
A40: 併せ産廃（水産） | N40: =IF(SUM(C40:L40)>0,SUM(C40:L40),"")
A41: 併せ産廃（医療） | N41: =IF(SUM(C41:L41)>0,SUM(C41:L41),"")
A42: 一般持込（埋立） | C42: 鬼 脇 | E42: 鴛 泊 | G42: 仙法志 | I42: 沓 形 | K42: その他 | N42: 有価回収 | O42: 埋立量
...

Sheet 14
A1: 課長 | C1: 庶務係長 | E1: =DATE(祝日リスト!C1, 4, 14) -> 46126 | I1: =TEXT(E1,"aaaa") -> 火曜日 | N1: 業務係長 | O1: 主任
F3: 天候 | J3: 気温 | L3: ℃
A5: 可燃 | B5: 地区 | C5: １回目収集 | E5: ２回目収集 | G5: ３回目収集 | I5: ４回目収集 | K5: ５回目収集 | N5: 焼却量 | O5: 埋立量
A6: 富士 | B6: 鬼 脇 | N6: =IF(SUM(D6,F6,H6,J6,L6)>0,IF(SUM(D6,F6,H6,J6,L6)-O6=0,"",SUM(D6,F6,H6,J6,L6)-O6),"")
B7: 鴛 泊 | N7: =IF(SUM(D7,F7,H7,J7,L7)>0,IF(SUM(D7,F7,H7,J7,L7)-O7=0,"",SUM(D7,F7,H7,J7,L7)-O7),"")
A8: 利尻 | B8: 仙法志 | N8: =IF(SUM(D8,F8,H8,J8,L8)>0,IF(SUM(D8,F8,H8,J8,L8)-O8=0,"",SUM(D8,F8,H8,J8,L8)-O8),"")
B9: 沓 形 | N9: =IF(SUM(D9,F9,H9,J9,L9)>0,IF(SUM(D9,F9,H9,J9,L9)-O9=0,"",SUM(D9,F9,H9,J9,L9)-O9),"")
A10: 不燃 | B10: 地区 | C10: １回目収集 | E10: ２回目収集 | G10: ３回目収集 | I10: ４回目収集 | K10: ５回目収集 | N10: 有価回収 | O10: 埋立量
A11: 富士 | B11: 鬼 脇 | O11: =IF(SUM(D11,F11,H11,J11,L11)>0,SUM(D11,F11,H11,J11,L11)-N11,"")
B12: 鴛 泊 | O12: =IF(SUM(D12,F12,H12,J12,L12)>0,SUM(D12,F12,H12,J12,L12)-N12,"")
A13: 利尻 | B13: 仙法志 | O13: =IF(SUM(D13,F13,H13,J13,L13)>0,SUM(D13,F13,H13,J13,L13)-N13,"")
B14: 沓 形 | O14: =IF(SUM(D14,F14,H14,J14,L14)>0,SUM(D14,F14,H14,J14,L14)-N14,"")
A15: ペット | B15: 地区 | C15: １回目収集 | E15: ２回目収集 | G15: ３回目収集 | I15: ４回目収集 | K15: ５回目収集 | N15: 有価回収 | O15: 埋立量
A16: 富士 | B16: 鬼 脇 | N16: =IF(SUM(D16,F16,H16,J16,L16)>0,IF(SUM(D16,F16,H16,J16,L16)-O16=0,"",SUM(D16,F16,H16,J16,L16)-O16),"")
B17: 鴛 泊 | N17: =IF(SUM(D17,F17,H17,J17,L17)>0,IF(SUM(D17,F17,H17,J17,L17)-O17=0,"",SUM(D17,F17,H17,J17,L17)-O17),"")
A18: 利尻 | B18: 仙法志 | N18: =IF(SUM(D18,F18,H18,J18,L18)>0,IF(SUM(D18,F18,H18,J18,L18)-O18=0,"",SUM(D18,F18,H18,J18,L18)-O18),"")
B19: 沓 形 | N19: =IF(SUM(D19,F19,H19,J19,L19)>0,IF(SUM(D19,F19,H19,J19,L19)-O19=0,"",SUM(D19,F19,H19,J19,L19)-O19),"")
A20: 缶類 | B20: 地区 | C20: １回目収集 | E20: ２回目収集 | G20: ３回目収集 | I20: ４回目収集 | K20: ５回目収集 | N20: 有価回収 | O20: 埋立量
A21: 富士 | B21: 鬼 脇 | N21: =IF(SUM(D21,F21,H21,J21,L21)>0,IF(SUM(D21,F21,H21,J21,L21)-O21=0,"",SUM(D21,F21,H21,J21,L21)-O21),"")
B22: 鴛 泊 | N22: =IF(SUM(D22,F22,H22,J22,L22)>0,IF(SUM(D22,F22,H22,J22,L22)-O22=0,"",SUM(D22,F22,H22,J22,L22)-O22),"")
A23: 利尻 | B23: 仙法志 | N23: =IF(SUM(D23,F23,H23,J23,L23)>0,IF(SUM(D23,F23,H23,J23,L23)-O23=0,"",SUM(D23,F23,H23,J23,L23)-O23),"")
B24: 沓 形 | N24: =IF(SUM(D24,F24,H24,J24,L24)>0,IF(SUM(D24,F24,H24,J24,L24)-O24=0,"",SUM(D24,F24,H24,J24,L24)-O24),"")
A25: ビン | B25: 地区 | C25: １回目収集 | E25: ２回目収集 | G25: ３回目収集 | I25: ４回目収集 | K25: ５回目収集 | N25: 有価回収 | O25: 埋立量
A26: 富士 | B26: 鬼 脇 | O26: =IF(SUM(D26,F26,H26,J26,L26)>0,SUM(D26,F26,H26,J26,L26)-N26,"")
B27: 鴛 泊 | O27: =IF(SUM(D27,F27,H27,J27,L27)>0,SUM(D27,F27,H27,J27,L27)-N27,"")
A28: 利尻 | B28: 仙法志 | O28: =IF(SUM(D28,F28,H28,J28,L28)>0,SUM(D28,F28,H28,J28,L28)-N28,"")
B29: 沓 形 | O29: =IF(SUM(D29,F29,H29,J29,L29)>0,SUM(D29,F29,H29,J29,L29)-N29,"")
A30: 紙類 | B30: 地区 | C30: １回目収集 | E30: ２回目収集 | G30: ３回目収集 | I30: ４回目収集 | K30: ５回目収集 | N30: 有価回収 | O30: 埋立量
A31: 富士 | B31: 鬼 脇 | N31: =IF(SUM(D31,F31,H31,J31,L31)>0,IF(SUM(D31,F31,H31,J31,L31)-O31=0,"",SUM(D31,F31,H31,J31,L31)-O31),"")
B32: 鴛 泊 | N32: =IF(SUM(D32,F32,H32,J32,L32)>0,IF(SUM(D32,F32,H32,J32,L32)-O32=0,"",SUM(D32,F32,H32,J32,L32)-O32),"")
A33: 利尻 | B33: 仙法志 | N33: =IF(SUM(D33,F33,H33,J33,L33)>0,IF(SUM(D33,F33,H33,J33,L33)-O33=0,"",SUM(D33,F33,H33,J33,L33)-O33),"")
B34: 沓 形 | N34: =IF(SUM(D34,F34,H34,J34,L34)>0,IF(SUM(D34,F34,H34,J34,L34)-O34=0,"",SUM(D34,F34,H34,J34,L34)-O34),"")
A35: 収集粗大 | C35: 鬼 脇 | E35: 鴛 泊 | G35: 仙法志 | I35: 沓 形 | K35: その他 | N35: 有価回収 | O35: 埋立量
A36: 埋 立 分 | O36: =IF(SUM(C36:L36)>0,SUM(C36:L36),"")
A37: 有 価 物 | N37: =IF(SUM(C37:L37)>0,SUM(C37:L37),"")
A38: 持込（焼却） | C38: 鬼 脇 | E38: 鴛 泊 | G38: 仙法志 | I38: 沓 形 | K38: その他 | N38: 焼却量 | O38: 埋立量
A39: 可燃物(木・紙) | N39: =IF(SUM(C39:L39)>0,SUM(C39:L39),"")
A40: 併せ産廃（水産） | N40: =IF(SUM(C40:L40)>0,SUM(C40:L40),"")
A41: 併せ産廃（医療） | N41: =IF(SUM(C41:L41)>0,SUM(C41:L41),"")
A42: 一般持込（埋立） | C42: 鬼 脇 | E42: 鴛 泊 | G42: 仙法志 | I42: 沓 形 | K42: その他 | N42: 有価回収 | O42: 埋立量
...

Sheet 15
A1: 課長 | C1: 庶務係長 | E1: =DATE(祝日リスト!C1, 4, 15) -> 46127 | I1: =TEXT(E1,"aaaa") -> 水曜日 | N1: 業務係長 | O1: 主任
F3: 天候 | J3: 気温 | L3: ℃
A5: 可燃 | B5: 地区 | C5: １回目収集 | E5: ２回目収集 | G5: ３回目収集 | I5: ４回目収集 | K5: ５回目収集 | N5: 焼却量 | O5: 埋立量
A6: 富士 | B6: 鬼 脇 | N6: =IF(SUM(D6,F6,H6,J6,L6)>0,IF(SUM(D6,F6,H6,J6,L6)-O6=0,"",SUM(D6,F6,H6,J6,L6)-O6),"")
B7: 鴛 泊 | N7: =IF(SUM(D7,F7,H7,J7,L7)>0,IF(SUM(D7,F7,H7,J7,L7)-O7=0,"",SUM(D7,F7,H7,J7,L7)-O7),"")
A8: 利尻 | B8: 仙法志 | N8: =IF(SUM(D8,F8,H8,J8,L8)>0,IF(SUM(D8,F8,H8,J8,L8)-O8=0,"",SUM(D8,F8,H8,J8,L8)-O8),"")
B9: 沓 形 | N9: =IF(SUM(D9,F9,H9,J9,L9)>0,IF(SUM(D9,F9,H9,J9,L9)-O9=0,"",SUM(D9,F9,H9,J9,L9)-O9),"")
A10: 不燃 | B10: 地区 | C10: １回目収集 | E10: ２回目収集 | G10: ３回目収集 | I10: ４回目収集 | K10: ５回目収集 | N10: 有価回収 | O10: 埋立量
A11: 富士 | B11: 鬼 脇 | O11: =IF(SUM(D11,F11,H11,J11,L11)>0,SUM(D11,F11,H11,J11,L11)-N11,"")
B12: 鴛 泊 | O12: =IF(SUM(D12,F12,H12,J12,L12)>0,SUM(D12,F12,H12,J12,L12)-N12,"")
A13: 利尻 | B13: 仙法志 | O13: =IF(SUM(D13,F13,H13,J13,L13)>0,SUM(D13,F13,H13,J13,L13)-N13,"")
B14: 沓 形 | O14: =IF(SUM(D14,F14,H14,J14,L14)>0,SUM(D14,F14,H14,J14,L14)-N14,"")
A15: ペット | B15: 地区 | C15: １回目収集 | E15: ２回目収集 | G15: ３回目収集 | I15: ４回目収集 | K15: ５回目収集 | N15: 有価回収 | O15: 埋立量
A16: 富士 | B16: 鬼 脇 | N16: =IF(SUM(D16,F16,H16,J16,L16)>0,IF(SUM(D16,F16,H16,J16,L16)-O16=0,"",SUM(D16,F16,H16,J16,L16)-O16),"")
B17: 鴛 泊 | N17: =IF(SUM(D17,F17,H17,J17,L17)>0,IF(SUM(D17,F17,H17,J17,L17)-O17=0,"",SUM(D17,F17,H17,J17,L17)-O17),"")
A18: 利尻 | B18: 仙法志 | N18: =IF(SUM(D18,F18,H18,J18,L18)>0,IF(SUM(D18,F18,H18,J18,L18)-O18=0,"",SUM(D18,F18,H18,J18,L18)-O18),"")
B19: 沓 形 | N19: =IF(SUM(D19,F19,H19,J19,L19)>0,IF(SUM(D19,F19,H19,J19,L19)-O19=0,"",SUM(D19,F19,H19,J19,L19)-O19),"")
A20: 缶類 | B20: 地区 | C20: １回目収集 | E20: ２回目収集 | G20: ３回目収集 | I20: ４回目収集 | K20: ５回目収集 | N20: 有価回収 | O20: 埋立量
A21: 富士 | B21: 鬼 脇 | N21: =IF(SUM(D21,F21,H21,J21,L21)>0,IF(SUM(D21,F21,H21,J21,L21)-O21=0,"",SUM(D21,F21,H21,J21,L21)-O21),"")
B22: 鴛 泊 | N22: =IF(SUM(D22,F22,H22,J22,L22)>0,IF(SUM(D22,F22,H22,J22,L22)-O22=0,"",SUM(D22,F22,H22,J22,L22)-O22),"")
A23: 利尻 | B23: 仙法志 | N23: =IF(SUM(D23,F23,H23,J23,L23)>0,IF(SUM(D23,F23,H23,J23,L23)-O23=0,"",SUM(D23,F23,H23,J23,L23)-O23),"")
B24: 沓 形 | N24: =IF(SUM(D24,F24,H24,J24,L24)>0,IF(SUM(D24,F24,H24,J24,L24)-O24=0,"",SUM(D24,F24,H24,J24,L24)-O24),"")
A25: ビン | B25: 地区 | C25: １回目収集 | E25: ２回目収集 | G25: ３回目収集 | I25: ４回目収集 | K25: ５回目収集 | N25: 有価回収 | O25: 埋立量
A26: 富士 | B26: 鬼 脇 | O26: =IF(SUM(D26,F26,H26,J26,L26)>0,SUM(D26,F26,H26,J26,L26)-N26,"")
B27: 鴛 泊 | O27: =IF(SUM(D27,F27,H27,J27,L27)>0,SUM(D27,F27,H27,J27,L27)-N27,"")
A28: 利尻 | B28: 仙法志 | O28: =IF(SUM(D28,F28,H28,J28,L28)>0,SUM(D28,F28,H28,J28,L28)-N28,"")
B29: 沓 形 | O29: =IF(SUM(D29,F29,H29,J29,L29)>0,SUM(D29,F29,H29,J29,L29)-N29,"")
A30: 紙類 | B30: 地区 | C30: １回目収集 | E30: ２回目収集 | G30: ３回目収集 | I30: ４回目収集 | K30: ５回目収集 | N30: 有価回収 | O30: 埋立量
A31: 富士 | B31: 鬼 脇 | N31: =IF(SUM(D31,F31,H31,J31,L31)>0,IF(SUM(D31,F31,H31,J31,L31)-O31=0,"",SUM(D31,F31,H31,J31,L31)-O31),"")
B32: 鴛 泊 | N32: =IF(SUM(D32,F32,H32,J32,L32)>0,IF(SUM(D32,F32,H32,J32,L32)-O32=0,"",SUM(D32,F32,H32,J32,L32)-O32),"")
A33: 利尻 | B33: 仙法志 | N33: =IF(SUM(D33,F33,H33,J33,L33)>0,IF(SUM(D33,F33,H33,J33,L33)-O33=0,"",SUM(D33,F33,H33,J33,L33)-O33),"")
B34: 沓 形 | N34: =IF(SUM(D34,F34,H34,J34,L34)>0,IF(SUM(D34,F34,H34,J34,L34)-O34=0,"",SUM(D34,F34,H34,J34,L34)-O34),"")
A35: 収集粗大 | C35: 鬼 脇 | E35: 鴛 泊 | G35: 仙法志 | I35: 沓 形 | K35: その他 | N35: 有価回収 | O35: 埋立量
A36: 埋 立 分 | O36: =IF(SUM(C36:L36)>0,SUM(C36:L36),"")
A37: 有 価 物 | N37: =IF(SUM(C37:L37)>0,SUM(C37:L37),"")
A38: 持込（焼却） | C38: 鬼 脇 | E38: 鴛 泊 | G38: 仙法志 | I38: 沓 形 | K38: その他 | N38: 焼却量 | O38: 埋立量
A39: 可燃物(木・紙) | N39: =IF(SUM(C39:L39)>0,SUM(C39:L39),"")
A40: 併せ産廃（水産） | N40: =IF(SUM(C40:L40)>0,SUM(C40:L40),"")
A41: 併せ産廃（医療） | N41: =IF(SUM(C41:L41)>0,SUM(C41:L41),"")
A42: 一般持込（埋立） | C42: 鬼 脇 | E42: 鴛 泊 | G42: 仙法志 | I42: 沓 形 | K42: その他 | N42: 有価回収 | O42: 埋立量
...

Sheet 16
A1: 課長 | C1: 庶務係長 | E1: =DATE(祝日リスト!C1, 4, 16) -> 46128 | I1: =TEXT(E1,"aaaa") -> 木曜日 | N1: 業務係長 | O1: 主任
F3: 天候 | J3: 気温 | L3: ℃
A5: 可燃 | B5: 地区 | C5: １回目収集 | E5: ２回目収集 | G5: ３回目収集 | I5: ４回目収集 | K5: ５回目収集 | N5: 焼却量 | O5: 埋立量
A6: 富士 | B6: 鬼 脇 | N6: =IF(SUM(D6,F6,H6,J6,L6)>0,IF(SUM(D6,F6,H6,J6,L6)-O6=0,"",SUM(D6,F6,H6,J6,L6)-O6),"")
B7: 鴛 泊 | N7: =IF(SUM(D7,F7,H7,J7,L7)>0,IF(SUM(D7,F7,H7,J7,L7)-O7=0,"",SUM(D7,F7,H7,J7,L7)-O7),"")
A8: 利尻 | B8: 仙法志 | N8: =IF(SUM(D8,F8,H8,J8,L8)>0,IF(SUM(D8,F8,H8,J8,L8)-O8=0,"",SUM(D8,F8,H8,J8,L8)-O8),"")
B9: 沓 形 | N9: =IF(SUM(D9,F9,H9,J9,L9)>0,IF(SUM(D9,F9,H9,J9,L9)-O9=0,"",SUM(D9,F9,H9,J9,L9)-O9),"")
A10: 不燃 | B10: 地区 | C10: １回目収集 | E10: ２回目収集 | G10: ３回目収集 | I10: ４回目収集 | K10: ５回目収集 | N10: 有価回収 | O10: 埋立量
