Workbook

Sheet 発送済Ａ
A1: =[1]Sheet1!$B$2&"年度家電リサイクル一覧表 （Ａグループ） ※発送済み" -> 2026年度家電リサイクル一覧表 （Ａグループ） ※発送済み
A2: 番号 | B2: 日付 | C2: 利尻 | D2: 富士 | E2: 排 出 者 | F2: 管理票番号 | I2: 製造業者 | J2: 品目 | K2: 交付日 | L2: 確認 | M2: 備考
A3: 1 | H3: =IF(G3="","",(F3*100000000+G3)-7*INT((F3*100000000+G3)/7))
A4: 2 | H4: =IF(G4="","",(F4*100000000+G4)-7*INT((F4*100000000+G4)/7))
A5: 3 | H5: =IF(G5="","",(F5*100000000+G5)-7*INT((F5*100000000+G5)/7))
A6: 4 | H6: =IF(G6="","",(F6*100000000+G6)-7*INT((F6*100000000+G6)/7))
A7: 5 | H7: =IF(G7="","",(F7*100000000+G7)-7*INT((F7*100000000+G7)/7))
A8: 6 | H8: =IF(G8="","",(F8*100000000+G8)-7*INT((F8*100000000+G8)/7))
A9: 7 | H9: =IF(G9="","",(F9*100000000+G9)-7*INT((F9*100000000+G9)/7))
A10: 8 | H10: =IF(G10="","",(F10*100000000+G10)-7*INT((F10*100000000+G10)/7))
A11: 9 | H11: =IF(G11="","",(F11*100000000+G11)-7*INT((F11*100000000+G11)/7))
A12: 10 | H12: =IF(G12="","",(F12*100000000+G12)-7*INT((F12*100000000+G12)/7))
A13: 11 | H13: =IF(G13="","",(F13*100000000+G13)-7*INT((F13*100000000+G13)/7))
A14: 12 | H14: =IF(G14="","",(F14*100000000+G14)-7*INT((F14*100000000+G14)/7))
... A227: 225 | H227: =IF(G227="","",(F227*100000000+G227)-7*INT((F227*100000000+G227)/7))
H326: =IF(G326="","",MOD(F326*100000000+G326,7))
H327: =IF(G327="","",MOD(F327*100000000+G327,7))
H328: =IF(G328="","",MOD(F328*100000000+G328,7))
H329: =IF(G329="","",MOD(F329*100000000+G329,7))
H330: =IF(G330="","",MOD(F330*100000000+G330,7))
H331: =IF(G331="","",MOD(F331*100000000+G331,7))
H332: =IF(G332="","",MOD(F332*100000000+G332,7))
H333: =IF(G333="","",MOD(F333*100000000+G333,7))
H334: =IF(G334="","",MOD(F334*100000000+G334,7))
H335: =IF(G335="","",MOD(F335*100000000+G335,7))
H336: =IF(G336="","",MOD(F336*100000000+G336,7))
H337: =IF(G337="","",MOD(F337*100000000+G337,7))
... H387: =IF(G387="","",MOD(F387*100000000+G387,7))

Sheet 発送済Ｂ
A1: =[1]Sheet1!$B$2&"年度家電リサイクル一覧表 （Ｂグループ） ※発送済み" -> 2026年度家電リサイクル一覧表 （Ｂグループ） ※発送済み
A2: 番号 | B2: 日付 | C2: 利尻 | D2: 富士 | E2: 排 出 者 | F2: 管理票番号 | I2: 製造業者 | J2: 品目 | K2: 交付日 | L2: 確認 | M2: 備考
A3: 1 | H3: =IF(G3="","",(F3*100000000+G3)-7*INT((F3*100000000+G3)/7))
A4: 2 | H4: =IF(G4="","",(F4*100000000+G4)-7*INT((F4*100000000+G4)/7))
A5: 3 | H5: =IF(G5="","",(F5*100000000+G5)-7*INT((F5*100000000+G5)/7))
A6: 4 | H6: =IF(G6="","",(F6*100000000+G6)-7*INT((F6*100000000+G6)/7))
A7: 5 | H7: =IF(G7="","",(F7*100000000+G7)-7*INT((F7*100000000+G7)/7))
A8: 6 | H8: =IF(G8="","",(F8*100000000+G8)-7*INT((F8*100000000+G8)/7))
A9: 7 | H9: =IF(G9="","",(F9*100000000+G9)-7*INT((F9*100000000+G9)/7))
A10: 8 | H10: =IF(G10="","",(F10*100000000+G10)-7*INT((F10*100000000+G10)/7))
A11: 9 | H11: =IF(G11="","",(F11*100000000+G11)-7*INT((F11*100000000+G11)/7))
A12: 10 | H12: =IF(G12="","",(F12*100000000+G12)-7*INT((F12*100000000+G12)/7))
A13: 11 | H13: =IF(G13="","",(F13*100000000+G13)-7*INT((F13*100000000+G13)/7))
A14: 12 | H14: =IF(G14="","",(F14*100000000+G14)-7*INT((F14*100000000+G14)/7))
... A172: 170 | H172: =IF(G172="","",(F172*100000000+G172)-7*INT((F172*100000000+G172)/7))
H303: =IF(G303="","",MOD(F303*100000000+G303,7))
H304: =IF(G304="","",MOD(F304*100000000+G304,7))
H305: =IF(G305="","",MOD(F305*100000000+G305,7))
H306: =IF(G306="","",MOD(F306*100000000+G306,7))
H307: =IF(G307="","",MOD(F307*100000000+G307,7))
H308: =IF(G308="","",MOD(F308*100000000+G308,7))
H309: =IF(G309="","",MOD(F309*100000000+G309,7))
H310: =IF(G310="","",MOD(F310*100000000+G310,7))
H311: =IF(G311="","",MOD(F311*100000000+G311,7))
H312: =IF(G312="","",MOD(F312*100000000+G312,7))
H313: =IF(G313="","",MOD(F313*100000000+G313,7))
H314: =IF(G314="","",MOD(F314*100000000+G314,7))
... H355: =IF(G355="","",MOD(F355*100000000+G355,7))

Sheet 発送済A控え
A1: =[1]Sheet1!$B$2&"年度家電リサイクル一覧表 （Ａグループ）" -> 2026年度家電リサイクル一覧表 （Ａグループ）
A2: 発送済 | E2: 品 目 | F2: 個数
E3: エ ア コ ン | F3: =COUNTIF(J10:J185,10) -> 0
A4: 内 訳 | E4: テレビ(薄型含) | F4: =COUNTIF(J10:J185,20)+COUNTIF(J10:J185,21)+COUNTIF(J10:J185,22)+COUNTIF(J10:J185,51)+COUNTIF(J10:J185,52)+COUNTIF(J10:J185,50) -> 0
E5: 冷蔵・冷凍庫 | F5: =COUNTIF(J10:J185,30)+COUNTIF(J10:J185,31)+COUNTIF(J10:J185,32) -> 0
E6: 洗濯・乾燥機 | F6: =COUNTIF(J10:J185,40) -> 0
E7: 合 計 | F7: =SUM(F3:F6) -> 0
A9: 番号 | B9: 日付 | C9: 利尻 | D9: 富士 | E9: 排 出 者 | F9: 管理票番号 | I9: 製造業者 | J9: 品目 | K9: 交付日 | L9: 確認 | M9: 備考
A10: 1 | H10: =IF(G10="","",(F10*100000000+G10)-7*INT((F10*100000000+G10)/7))
A11: 2 | H11: =IF(G11="","",(F11*100000000+G11)-7*INT((F11*100000000+G11)/7))
A12: 3 | H12: =IF(G12="","",(F12*100000000+G12)-7*INT((F12*100000000+G12)/7))
A13: 4 | H13: =IF(G13="","",(F13*100000000+G13)-7*INT((F13*100000000+G13)/7))
A14: 5 | H14: =IF(G14="","",(F14*100000000+G14)-7*INT((F14*100000000+G14)/7))
A15: 6
A16: 7
A17: 8
A18: 9
A19: 10
A20: 11
A21: 12
A22: 13
A23: 14
A24: 15
A25: 16
A26: 17
... A90: 81
H92: =IF(G92="","",(F92*100000000+G92)-7*INT((F92*100000000+G92)/7))
H93: =IF(G93="","",(F93*100000000+G93)-7*INT((F93*100000000+G93)/7))
H94: =IF(G94="","",(F94*100000000+G94)-7*INT((F94*100000000+G94)/7))
H95: =IF(G95="","",(F95*100000000+G95)-7*INT((F95*100000000+G95)/7))
H96: =IF(G96="","",(F96*100000000+G96)-7*INT((F96*100000000+G96)/7))
H97: =IF(G97="","",(F97*100000000+G97)-7*INT((F97*100000000+G97)/7))
H98: =IF(G98="","",(F98*100000000+G98)-7*INT((F98*100000000+G98)/7))
H99: =IF(G99="","",(F99*100000000+G99)-7*INT((F99*100000000+G99)/7))
H100: =IF(G100="","",(F100*100000000+G100)-7*INT((F100*100000000+G100)/7))
H101: =IF(G101="","",(F101*100000000+G101)-7*INT((F101*100000000+G101)/7))
H102: =IF(G102="","",(F102*100000000+G102)-7*INT((F102*100000000+G102)/7))
H103: =IF(G103="","",(F103*100000000+G103)-7*INT((F103*100000000+G103)/7))
... H210: =IF(G210="","",(F210*100000000+G210)-7*INT((F210*100000000+G210)/7))

Sheet 発送済Ｂ控え
A1: =[1]Sheet1!$B$2&"年度家電リサイクル一覧表 （Ｂグループ）" -> 2026年度家電リサイクル一覧表 （Ｂグループ）
A2: 発送済 | E2: 品 目 | F2: 個数
E3: エ ア コ ン | F3: =COUNTIF(J10:J157,10) -> 0
A4: 内 訳 | E4: テレビ(薄型含) | F4: =COUNTIF(J10:J157,20)+COUNTIF(J10:J157,21)+COUNTIF(J10:J157,22)+COUNTIF(J10:J157,51)+COUNTIF(J10:J157,52)+COUNTIF(J10:J157,50) -> 0
E5: 冷蔵・冷凍庫 | F5: =COUNTIF(J10:J157,30)+COUNTIF(J10:J157,31)+COUNTIF(J10:J157,32) -> 0
E6: 洗濯・乾燥機 | F6: =COUNTIF(J10:J157,40) -> 0
E7: 合 計 | F7: =SUM(F3:F6) -> 0
A9: 番号 | B9: 日付 | C9: 利尻 | D9: 富士 | E9: 排 出 者 | F9: 管理票番号 | I9: 製造業者 | J9: 品目 | K9: 交付日 | L9: 確認 | M9: 備考
A10: 1 | H10: =IF(G10="","",(F10*100000000+G10)-7*INT((F10*100000000+G10)/7))
A11: 2 | H11: =IF(G11="","",(F11*100000000+G11)-7*INT((F11*100000000+G11)/7))
A12: 3 | H12: =IF(G12="","",(F12*100000000+G12)-7*INT((F12*100000000+G12)/7))
A13: 4 | H13: =IF(G13="","",(F13*100000000+G13)-7*INT((F13*100000000+G13)/7))
A14: 5 | H14: =IF(G14="","",(F14*100000000+G14)-7*INT((F14*100000000+G14)/7))
A15: 6 | H15: =IF(G15="","",(F15*100000000+G15)-7*INT((F15*100000000+G15)/7))
A16: 7 | H16: =IF(G16="","",(F16*100000000+G16)-7*INT((F16*100000000+G16)/7))
A17: 8 | H17: =IF(G17="","",(F17*100000000+G17)-7*INT((F17*100000000+G17)/7))
A18: 9
A19: 10
A20: 11
A21: 12
A22: 13
A23: 14
A24: 15
A25: 16
A26: 17
A27: 18
A28: 19
A29: 20
... A56: 47
A57: 48 | H57: =IF(G57="","",(F57*100000000+G57)-7*INT((F57*100000000+G57)/7))
A58: 49 | H58: =IF(G58="","",(F58*100000000+G58)-7*INT((F58*100000000+G58)/7))
A59: 50 | H59: =IF(G59="","",(F59*100000000+G59)-7*INT((F59*100000000+G59)/7))
A60: 51 | H60: =IF(G60="","",(F60*100000000+G60)-7*INT((F60*100000000+G60)/7))
A61: 52 | H61: =IF(G61="","",(F61*100000000+G61)-7*INT((F61*100000000+G61)/7))
H62: =IF(G62="","",(F62*100000000+G62)-7*INT((F62*100000000+G62)/7))
H63: =IF(G63="","",(F63*100000000+G63)-7*INT((F63*100000000+G63)/7))
H64: =IF(G64="","",(F64*100000000+G64)-7*INT((F64*100000000+G64)/7))
H65: =IF(G65="","",(F65*100000000+G65)-7*INT((F65*100000000+G65)/7))
H66: =IF(G66="","",(F66*100000000+G66)-7*INT((F66*100000000+G66)/7))
H67: =IF(G67="","",(F67*100000000+G67)-7*INT((F67*100000000+G67)/7))
...

Sheet 発送前A
A1: =[1]Sheet1!$B$2&"年度家電リサイクル一覧表 （Ａグループ）" -> 2026年度家電リサイクル一覧表 （Ａグループ）
E2: 品 目 | F2: 個数
A3: 発送前 | E3: エ ア コ ン | F3: =COUNTIF(J10:J185,10) -> 0
A4: 内 訳 | E4: テレビ(薄型含) | F4: =COUNTIF(J10:J185,20)+COUNTIF(J10:J185,21)+COUNTIF(J10:J185,22)+COUNTIF(J10:J185,51)+COUNTIF(J10:J185,52)+COUNTIF(J10:J185,50) -> 0
B5: ○ | E5: 冷蔵・冷凍庫 | F5: =COUNTIF(J10:J185,30)+COUNTIF(J10:J185,31)+COUNTIF(J10:J185,32) -> 0
E6: 洗濯・乾燥機 | F6: =COUNTIF(J10:J185,40) -> 0
E7: 合 計 | F7: =SUM(F3:F6) -> 0
A9: 番号 | B9: 日付 | C9: 利尻 | D9: 富士 | E9: 排 出 者 | F9: 管理票番号 | I9: 製造業者 | J9: 品目 | K9: 交付日 | L9: 確認 | M9: 備考
A10: 1 | H10: =IF(G10="","",(F10*100000000+G10)-7*INT((F10*100000000+G10)/7))
A11: 2 | H11: =IF(G11="","",(F11*100000000+G11)-7*INT((F11*100000000+G11)/7))
A12: 3 | H12: =IF(G12="","",(F12*100000000+G12)-7*INT((F12*100000000+G12)/7))
A13: 4 | H13: =IF(G13="","",(F13*100000000+G13)-7*INT((F13*100000000+G13)/7))
A14: 5 | H14: =IF(G14="","",(F14*100000000+G14)-7*INT((F14*100000000+G14)/7))
A15: 6 | H15: =IF(G15="","",(F15*100000000+G15)-7*INT((F15*100000000+G15)/7))
A16: 7 | H16: =IF(G16="","",(F16*100000000+G16)-7*INT((F16*100000000+G16)/7))
A17: 8 | H17: =IF(G17="","",(F17*100000000+G17)-7*INT((F17*100000000+G17)/7))
A18: 9 | H18: =IF(G18="","",(F18*100000000+G18)-7*INT((F18*100000000+G18)/7))
A19: 10 | H19: =IF(G19="","",(F19*100000000+G19)-7*INT((F19*100000000+G19)/7))
A20: 11 | H20: =IF(G20="","",(F20*100000000+G20)-7*INT((F20*100000000+G20)/7))
A21: 12 | H21: =IF(G21="","",(F21*100000000+G21)-7*INT((F21*100000000+G21)/7))
... A92: 83 | H92: =IF(G92="","",(F92*100000000+G92)-7*INT((F92*100000000+G92)/7))
A93: 84
A94: 85
A95: 86
A96: 87
A97: 88
A98: 89
A99: 90
A100: 91
A101: 92
A102: 93
A103: 94
A104: 95
... A111: 102
H112: =IF(G112="","",(F112*100000000+G112)-7*INT((F112*100000000+G112)/7))
H113: =IF(G113="","",(F113*100000000+G113)-7*INT((F113*100000000+G113)/7))
H114: =IF(G114="","",(F114*100000000+G114)-7*INT((F114*100000000+G114)/7))
H115: =IF(G115="","",(F115*100000000+G115)-7*INT((F115*100000000+G115)/7))
H116: =IF(G116="","",(F116*100000000+G116)-7*INT((F116*100000000+G116)/7))
H117: =IF(G117="","",(F117*100000000+G117)-7*INT((F117*100000000+G117)/7))
...

Sheet 発送前Ｂ
A1: =[1]Sheet1!$B$2&"年度家電リサイクル一覧表 （Ｂグループ）" -> 2026年度家電リサイクル一覧表 （Ｂグループ）
E2: 品 目 | F2: 個数
A3: 発送前 | E3: エ ア コ ン | F3: =COUNTIF(J10:J157,10) -> 0
A4: 内 訳 | E4: テレビ(薄型含) | F4: =COUNTIF(J10:J157,20)+COUNTIF(J10:J157,21)+COUNTIF(J10:J157,22)+COUNTIF(J10:J157,51)+COUNTIF(J10:J157,52)+COUNTIF(J10:J157,50) -> 0
B5: ○ | E5: 冷蔵・冷凍庫 | F5: =COUNTIF(J10:J157,30)+COUNTIF(J10:J157,31)+COUNTIF(J10:J157,32) -> 0
E6: 洗濯・乾燥機 | F6: =COUNTIF(J10:J157,40) -> 0
E7: 合 計 | F7: =SUM(F3:F6) -> 0
A9: 番号 | B9: 日付 | C9: 利尻 | D9: 富士 | E9: 排 出 者 | F9: 管理票番号 | I9: 製造業者 | J9: 品目 | K9: 交付日 | L9: 確認 | M9: 備考
A10: 1 | H10: =IF(G10="","",(F10*100000000+G10)-7*INT((F10*100000000+G10)/7))
A11: 2 | H11: =IF(G11="","",(F11*100000000+G11)-7*INT((F11*100000000+G11)/7))
A12: 3 | H12: =IF(G12="","",(F12*100000000+G12)-7*INT((F12*100000000+G12)/7))
A13: 4 | H13: =IF(G13="","",(F13*100000000+G13)-7*INT((F13*100000000+G13)/7))
A14: 5 | H14: =IF(G14="","",(F14*100000000+G14)-7*INT((F14*100000000+G14)/7))
A15: 6 | H15: =IF(G15="","",(F15*100000000+G15)-7*INT((F15*100000000+G15)/7))
A16: 7 | H16: =IF(G16="","",(F16*100000000+G16)-7*INT((F16*100000000+G16)/7))
A17: 8 | H17: =IF(G17="","",(F17*100000000+G17)-7*INT((F17*100000000+G17)/7))
A18: 9 | H18: =IF(G18="","",(F18*100000000+G18)-7*INT((F18*100000000+G18)/7))
A19: 10 | H19: =IF(G19="","",(F19*100000000+G19)-7*INT((F19*100000000+G19)/7))
A20: 11 | H20: =IF(G20="","",(F20*100000000+G20)-7*INT((F20*100000000+G20)/7))
A21: 12 | H21: =IF(G21="","",(F21*100000000+G21)-7*INT((F21*100000000+G21)/7))
... A58: 49 | H58: =IF(G58="","",(F58*100000000+G58)-7*INT((F58*100000000+G58)/7))
A59: 50
A60: 51
A61: 52
A62: 53
A63: 54
A64: 55
A65: 56
A66: 57
A67: 58
A68: 59
A69: 60
A70: 61
... A92: 83
A93: 84 | H93: =IF(G93="","",(F93*100000000+G93)-7*INT((F93*100000000+G93)/7))
A94: 85 | H94: =IF(G94="","",(F94*100000000+G94)-7*INT((F94*100000000+G94)/7))
A95: 86 | H95: =IF(G95="","",(F95*100000000+G95)-7*INT((F95*100000000+G95)/7))
A96: 87 | H96: =IF(G96="","",(F96*100000000+G96)-7*INT((F96*100000000+G96)/7))
A97: 88 | H97: =IF(G97="","",(F97*100000000+G97)-7*INT((F97*100000000+G97)/7))
A98: 89 | H98: =IF(G98="","",(F98*100000000+G98)-7*INT((F98*100000000+G98)/7))
...

Sheet 実績表
A1: =[1]Sheet1!$B$2&"年度 家電リサイクル実績表" -> 2026年度 家電リサイクル実績表
A2: 発送済
A3: 品 目 | B3: エアコン | E3: テレビ | H3: 薄型テレビ | K3: 冷蔵・冷凍庫 | N3: 洗濯・乾燥機
A4: ｸﾞﾙｰﾌﾟ | B4: Ａ | C4: Ｂ | D4: 計 | E4: Ａ | F4: Ｂ | G4: 計 | H4: Ａ | I4: Ｂ | J4: 計 | K4: Ａ | L4: Ｂ | M4: 計 | N4: Ａ | O4: Ｂ | P4: 計 | Q4: 合計
A5: 前年度残 | D5: =SUM(B5:C5) -> 0 | G5: =SUM(E5:F5) -> 0 | J5: =SUM(H5:I5) -> 0 | M5: =SUM(K5:L5) -> 0 | P5: =SUM(N5:O5) -> 0 | Q5: =D5+G5+J5+M5+P5 -> 0
A6: 富士町 | B6: =SUMPRODUCT((発送済Ａ!$D$3:$D$999="○")*(発送済Ａ!$J$3:$J$999=10)) -> 0 | C6: =SUMPRODUCT((発送済Ｂ!$D$3:$D$999="○")*(発送済Ｂ!$J$3:$J$999=10)) -> 0 | D6: =SUM(B6:C6) -> 0 | E6: =SUMPRODUCT((発送済Ａ!$D$3:$D$999="○")*(発送済Ａ!$J$3:$J$999=20))+SUMPRODUCT((発送済Ａ!$D$3:$D$999="○")*(発送済Ａ!$J$3:$J$999=21))+SUMPRODUCT((発送済Ａ!$D$3:$D$999="○")*(発送済Ａ!$J$3:$J$999=22)) -> 0 | F6: =SUMPRODUCT((発送済Ｂ!$D$3:$D$999="○")*(発送済Ｂ!$J$3:$J$999=20))+SUMPRODUCT((発送済Ｂ!$D$3:$D$999="○")*(発送済Ｂ!$J$3:$J$999=21))+SUMPRODUCT((発送済Ｂ!$D$3:$D$999="○")*(発送済Ｂ!$J$3:$J$999=22)) -> 0 | G6: =SUM(E6:F6) -> 0 | H6: =SUMPRODUCT((発送済Ａ!$D$3:$D$999="○")*(発送済Ａ!$J$3:$J$999=50))+SUMPRODUCT((発送済Ａ!$D$3:$D$999="○")*(発送済Ａ!$J$3:$J$999=51))+SUMPRODUCT((発送済Ａ!$D$3:$D$999="○")*(発送済Ａ!$J$3:$J$999=52)) -> 0 | I6: =SUMPRODUCT((発送済Ｂ!$D$3:$D$999="○")*(発送済Ｂ!$J$3:$J$999=50))+SUMPRODUCT((発送済Ｂ!$D$3:$D$999="○")*(発送済Ｂ!$J$3:$J$999=51))+SUMPRODUCT((発送済Ｂ!$D$3:$D$999="○")*(発送済Ｂ!$J$3:$J$999=52)) -> 0 | J6: =SUM(H6:I6) -> 0 | K6: =SUMPRODUCT((発送済Ａ!$D$3:$D$999="○")*(発送済Ａ!$J$3:$J$999=30))+SUMPRODUCT((発送済Ａ!$D$3:$D$999="○")*(発送済Ａ!$J$3:$J$999=31))+SUMPRODUCT((発送済Ａ!$D$3:$D$999="○")*(発送済Ａ!$J$3:$J$999=32)) -> 0 | L6: =SUMPRODUCT((発送済Ｂ!$D$3:$D$999="○")*(発送済Ｂ!$J$3:$J$999=30))+SUMPRODUCT((発送済Ｂ!$D$3:$D$999="○")*(発送済Ｂ!$J$3:$J$999=31))+SUMPRODUCT((発送済Ｂ!$D$3:$D$999="○")*(発送済Ｂ!$J$3:$J$999=32)) -> 0 | M6: =SUM(K6:L6) -> 0 | N6: =SUMPRODUCT((発送済Ａ!$D$3:$D$999="○")*(発送済Ａ!$J$3:$J$999=40)) -> 0 | O6: =SUMPRODUCT((発送済Ｂ!$D$3:$D$999="○")*(発送済Ｂ!$J$3:$J$999=40)) -> 0 | P6: =SUM(N6:O6) -> 0 | Q6: =D6+G6+J6+M6+P6 -> 0
A7: 利尻町 | B7: =SUMPRODUCT((発送済Ａ!$C$3:$C$999="○")*(発送済Ａ!$J$3:$J$999=10)) -> 0 | C7: =SUMPRODUCT((発送済Ｂ!$C$3:$C$999="○")*(発送済Ｂ!$J$3:$J$999=10)) -> 0 | D7: =SUM(B7:C7) -> 0 | E7: =SUMPRODUCT((発送済Ａ!$C$3:$C$999="○")*(発送済Ａ!$J$3:$J$999=20))+SUMPRODUCT((発送済Ａ!$C$3:$C$999="○")*(発送済Ａ!$J$3:$J$999=21))+SUMPRODUCT((発送済Ａ!$C$3:$C$999="○")*(発送済Ａ!$J$3:$J$999=22)) -> 0 | F7: =SUMPRODUCT((発送済Ｂ!$C$3:$C$999="○")*(発送済Ｂ!$J$3:$J$999=20))+SUMPRODUCT((発送済Ｂ!$C$3:$C$999="○")*(発送済Ｂ!$J$3:$J$999=21))+SUMPRODUCT((発送済Ｂ!$C$3:$C$999="○")*(発送済Ｂ!$J$3:$J$999=22)) -> 0 | G7: =SUM(E7:F7) -> 0 | H7: =SUMPRODUCT((発送済Ａ!$C$3:$C$999="○")*(発送済Ａ!$J$3:$J$999=50))+SUMPRODUCT((発送済Ａ!$C$3:$C$999="○")*(発送済Ａ!$J$3:$J$999=51))+SUMPRODUCT((発送済Ａ!$C$3:$C$999="○")*(発送済Ａ!$J$3:$J$999=52)) -> 0 | I7: =SUMPRODUCT((発送済Ｂ!$C$3:$C$999="○")*(発送済Ｂ!$J$3:$J$999=50))+SUMPRODUCT((発送済Ｂ!$C$3:$C$999="○")*(発送済Ｂ!$J$3:$J$999=51))+SUMPRODUCT((発送済Ｂ!$C$3:$C$999="○")*(発送済Ｂ!$J$3:$J$999=52)) -> 0 | J7: =SUM(H7:I7) -> 0 | K7: =SUMPRODUCT((発送済Ａ!$C$3:$C$999="○")*(発送済Ａ!$J$3:$J$999=30))+SUMPRODUCT((発送済Ａ!$C$3:$C$999="○")*(発送済Ａ!$J$3:$J$999=31))+SUMPRODUCT((発送済Ａ!$C$3:$C$999="○")*(発送済Ａ!$J$3:$J$999=32)) -> 0 | L7: =SUMPRODUCT((発送済Ｂ!$C$3:$C$999="○")*(発送済Ｂ!$J$3:$J$999=30))+SUMPRODUCT((発送済Ｂ!$C$3:$C$999="○")*(発送済Ｂ!$J$3:$J$999=31))+SUMPRODUCT((発送済Ｂ!$C$3:$C$999="○")*(発送済Ｂ!$J$3:$J$999=32)) -> 0 | M7: =SUM(K7:L7) -> 0 | N7: =SUMPRODUCT((発送済Ａ!$C$3:$C$999="○")*(発送済Ａ!$J$3:$J$999=40)) -> 0 | O7: =SUMPRODUCT((発送済Ｂ!$C$3:$C$999="○")*(発送済Ｂ!$J$3:$J$999=40)) -> 0 | P7: =SUM(N7:O7) -> 0 | Q7: =D7+G7+J7+M7+P7 -> 0
A8: 本年度全体 | B8: =SUM(B6:B7) -> 0 | C8: =SUM(C6:C7) -> 0 | D8: =SUM(D6:D7) -> 0 | E8: =SUM(E6:E7) -> 0 | F8: =SUM(F6:F7) -> 0 | G8: =SUM(G6:G7) -> 0 | H8: =SUM(H6:H7) -> 0 | I8: =SUM(I6:I7) -> 0 | ... Q8: =SUM(Q6:Q7) -> 0
A9: 総 計 | B9: =SUM(B5:B7) -> 0 | C9: =SUM(C5:C7) -> 0 | D9: =SUM(D5:D7) -> 0 | E9: =SUM(E5:E7) -> 0 | F9: =SUM(F5:F7) -> 0 | G9: =SUM(G5:G7) -> 0 | H9: =SUM(H5:H7) -> 0 | I9: =SUM(I5:I7) -> 0 | ... Q9: =SUM(Q5:Q7) -> 0
A11: 発送前
A12: 品 目 | B12: エアコン | E12: テレビ | H12: 薄型テレビ | K12: 冷蔵・冷凍庫 | N12: 洗濯・乾燥機
A13: ｸﾞﾙｰﾌﾟ | B13: Ａ | C13: Ｂ | D13: 計 | E13: Ａ | F13: Ｂ | G13: 計 | H13: Ａ | I13: Ｂ | J13: 計 | K13: Ａ | L13: Ｂ | M13: 計 | N13: Ａ | O13: Ｂ | P13: 計 | Q13: 合計
A14: 前年度残 | D14: =SUM(B14:C14) -> 0 | G14: =SUM(E14:F14) -> 0 | J14: =SUM(H14:I14) -> 0 | M14: =SUM(K14:L14) -> 0 | P14: =SUM(N14:O14) -> 0 | Q14: =D14+G14+J14+M14+P14 -> 0
A15: 富士町 | B15: =SUMPRODUCT((発送前A!$D$10:$D$999="○")*(発送前A!$J$10:$J$999=10)) -> 0 | C15: =SUMPRODUCT((発送前Ｂ!$D$10:$D$966="○")*(発送前Ｂ!$J$10:$J$966=10)) -> 0 | D15: =SUM(B15:C15) -> 0 | E15: =SUMPRODUCT((発送前A!$D$10:$D$999="○")*(発送前A!$J$10:$J$999=20))+SUMPRODUCT((発送前A!$D$10:$D$999="○")*(発送前A!$J$10:$J$999=21))+SUMPRODUCT((発送前A!$D$10:$D$999="○")*(発送前A!$J$10:$J$999=22)) -> 0 | F15: =SUMPRODUCT((発送前Ｂ!$D$10:$D$966="○")*(発送前Ｂ!$J$10:$J$966=20))+SUMPRODUCT((発送前Ｂ!$D$10:$D$966="○")*(発送前Ｂ!$J$10:$J$966=21))+SUMPRODUCT((発送前Ｂ!$D$10:$D$966="○")*(発送前Ｂ!$J$10:$J$966=22)) -> 0 | G15: =SUM(E15:F15) -> 0 | H15: =SUMPRODUCT((発送前A!$D$10:$D$999="○")*(発送前A!$J$10:$J$999=50))+SUMPRODUCT((発送前A!$D$10:$D$999="○")*(発送前A!$J$10:$J$999=51))+SUMPRODUCT((発送前A!$D$10:$D$999="○")*(発送前A!$J$10:$J$999=52)) -> 0 | I15: =SUMPRODUCT((発送前Ｂ!$D$10:$D$966="○")*(発送前Ｂ!$J$10:$J$966=50))+SUMPRODUCT((発送前Ｂ!$D$10:$D$966="○")*(発送前Ｂ!$J$10:$J$966=51))+SUMPRODUCT((発送前Ｂ!$D$10:$D$966="○")*(発送前Ｂ!$J$10:$J$966=52)) -> 0 | J15: =SUM(H15:I15) -> 0 | K15: =SUMPRODUCT((発送前A!$D$10:$D$999="○")*(発送前A!$J$10:$J$999=30))+SUMPRODUCT((発送前A!$D$10:$D$999="○")*(発送前A!$J$10:$J$999=31))+SUMPRODUCT((発送前A!$D$10:$D$999="○")*(発送前A!$J$10:$J$999=32)) -> 0 | L15: =SUMPRODUCT((発送前Ｂ!$D$10:$D$966="○")*(発送前Ｂ!$J$10:$J$966=30))+SUMPRODUCT((発送前Ｂ!$D$10:$D$966="○")*(発送前Ｂ!$J$10:$J$966=31))+SUMPRODUCT((発送前Ｂ!$D$10:$D$966="○")*(発送前Ｂ!$J$10:$J$966=32)) -> 0 | M15: =SUM(K15:L15) -> 0 | N15: =SUMPRODUCT((発送前A!$D$10:$D$999="○")*(発送前A!$J$10:$J$999=40)) -> 0 | O15: =SUMPRODUCT((発送前Ｂ!$D$10:$D$966="○")*(発送前Ｂ!$J$10:$J$966=40)) -> 0 | P15: =SUM(N15:O15) -> 0 | Q15: =D15+G15+J15+M15+P15 -> 0
A16: 利尻町 | B16: =SUMPRODUCT((発送前A!$C$10:$C$999="○")*(発送前A!$J$10:$J$999=10)) -> 0 | C16: =SUMPRODUCT((発送前Ｂ!$C$10:$C$966="○")*(発送前Ｂ!$J$10:$J$966=10)) -> 0 | D16: =SUM(B16:C16) -> 0 | E16: =SUMPRODUCT((発送前A!$C$10:$C$999="○")*(発送前A!$J$10:$J$999=20))+SUMPRODUCT((発送前A!$C$10:$C$999="○")*(発送前A!$J$10:$J$999=21))+SUMPRODUCT((発送前A!$C$10:$C$999="○")*(発送前A!$J$10:$J$999=22)) -> 0 | F16: =SUMPRODUCT((発送前Ｂ!$C$10:$C$966="○")*(発送前Ｂ!$J$10:$J$966=20))+SUMPRODUCT((発送前Ｂ!$C$10:$C$966="○")*(発送前Ｂ!$J$10:$J$966=21))+SUMPRODUCT((発送前Ｂ!$C$10:$C$966="○")*(発送前Ｂ!$J$10:$J$966=22)) -> 0 | G16: =SUM(E16:F16) -> 0 | H16: =SUMPRODUCT((発送前A!$C$10:$C$999="○")*(発送前A!$J$10:$J$999=50))+SUMPRODUCT((発送前A!$C$10:$C$999="○")*(発送前A!$J$10:$J$999=51))+SUMPRODUCT((発送前A!$C$10:$C$999="○")*(発送前A!$J$10:$J$999=52)) -> 0 | I16: =SUMPRODUCT((発送前Ｂ!$C$10:$C$966="○")*(発送前Ｂ!$J$10:$J$966=50))+SUMPRODUCT((発送前Ｂ!$C$10:$C$966="○")*(発送前Ｂ!$J$10:$J$966=51))+SUMPRODUCT((発送前Ｂ!$C$10:$C$966="○")*(発送前Ｂ!$J$10:$J$966=52)) -> 0 | J16: =SUM(H16:I16) -> 0 | K16: =SUMPRODUCT((発送前A!$C$10:$C$999="○")*(発送前A!$J$10:$J$999=30))+SUMPRODUCT((発送前A!$C$10:$C$999="○")*(発送前A!$J$10:$J$999=31))+SUMPRODUCT((発送前A!$C$10:$C$999="○")*(発送前A!$J$10:$J$999=32)) -> 0 | L16: =SUMPRODUCT((発送前Ｂ!$C$10:$C$966="○")*(発送前Ｂ!$J$10:$J$966=30))+SUMPRODUCT((発送前Ｂ!$C$10:$C$966="○")*(発送前Ｂ!$J$10:$J$966=31))+SUMPRODUCT((発送前Ｂ!$C$10:$C$966="○")*(発送前Ｂ!$J$10:$J$966=32)) -> 0 | M16: =SUM(K16:L16) -> 0 | N16: =SUMPRODUCT((発送前A!$C$10:$C$999="○")*(発送前A!$J$10:$J$999=40)) -> 0 | O16: =SUMPRODUCT((発送前Ｂ!$C$10:$C$966="○")*(発送前Ｂ!$J$10:$J$966=40)) -> 0 | P16: =SUM(N16:O16) -> 0 | Q16: =D16+G16+J16+M16+P16 -> 0
A17: 両町全体 | B17: =SUM(B15:B16) -> 0 | C17: =SUM(C15:C16) -> 0 | D17: =SUM(D15:D16) -> 0 | E17: =SUM(E15:E16) -> 0 | F17: =SUM(F15:F16) -> 0 | G17: =SUM(G15:G16) -> 0 | H17: =SUM(H15:H16) -> 0 | I17: =SUM(I15:I16) -> 0 | ... P17: =SUM(P15:P16) -> 0 | Q17: =D17+G17+J17+M17+P17 -> 0
A19: 受付計
A20: 品 目 | B20: エアコン | E20: テレビ | H20: 薄型テレビ | K20: 冷蔵・冷凍庫 | N20: 洗濯・乾燥機
A21: ｸﾞﾙｰﾌﾟ | B21: Ａ | C21: Ｂ | D21: 計 | E21: Ａ | F21: Ｂ | G21: 計 | H21: Ａ | I21: Ｂ | J21: 計 | K21: Ａ | L21: Ｂ | M21: 計 | N21: Ａ | O21: Ｂ | P21: 計 | Q21: 合計
A22: 富士町 | B22: =B6+B15 -> 0 | C22: =C6+C15 -> 0 | D22: =SUM(B22:C22) -> 0 | E22: =E6+E15 -> 0 | F22: =F6+F15 -> 0 | G22: =SUM(E22:F22) -> 0 | H22: =H6+H15 -> 0 | I22: =I6+I15 -> 0 | J22: =SUM(H22:I22) -> 0 | K22: =K6+K15 -> 0 | L22: =L6+L15 -> 0 | M22: =SUM(K22:L22) -> 0 | N22: =N6+N15 -> 0 | O22: =O6+O15 -> 0 | P22: =SUM(N22:O22) -> 0 | Q22: =D22+G22+J22+M22+P22 -> 0
A23: 利尻町 | B23: =B7+B16 -> 0 | C23: =C7+C16 -> 0 | D23: =SUM(B23:C23) -> 0 | E23: =E7+E16 -> 0 | F23: =F7+F16 -> 0 | G23: =SUM(E23:F23) -> 0 | H23: =H7+H16 -> 0 | I23: =I7+I16 -> 0 | J23: =SUM(H23:I23) -> 0 | K23: =K7+K16 -> 0 | L23: =L7+L16 -> 0 | M23: =SUM(K23:L23) -> 0 | N23: =N7+N16 -> 0 | O23: =O7+O16 -> 0 | P23: =SUM(N23:O23) -> 0 | Q23: =D23+G23+J23+M23+P23 -> 0
A24: 両町全体 | B24: =SUM(B22:B23) -> 0 | C24: =SUM(C22:C23) -> 0 | D24: =SUM(D22:D23) -> 0 | E24: =SUM(E22:E23) -> 0 | F24: =SUM(F22:F23) -> 0 | G24: =SUM(G22:G23) -> 0 | H24: =SUM(H22:H23) -> 0 | I24: =SUM(I22:I23) -> 0 | ... P24: =SUM(P22:P23) -> 0 | Q24: =D24+G24+J24+M24+P24 -> 0
