Workbook

Sheet 1-1
A1: ="令和"&'[1]A-1'!$E$9-2018&"年度 一般廃棄物（ごみ）収集地区別集計表 【第1－1表】" -> 令和9年度 一般廃棄物（ごみ）収集地区別集計表 【第1－1表】
B3: 【収集可燃ごみ】 | K3: 【直搬可燃ごみ】 | Q3: 単位：トン
A5: 月別 | B5: 鬼 脇 | C5: 鴛 泊 | D5: 利尻富士計 | E5: 仙法志 | F5: 沓 形 | G5: 利尻計 | H5: 合 計 | J5: 月別 | K5: 鬼 脇 | L5: 鴛 泊 | M5: 利尻富士計 | N5: 仙法志 | O5: 沓 形 | P5: 利尻計 | Q5: 合 計
A6: 4 | J6: 4
B7: ='[1]収集（全般）'!$B$44 -> 0 | C7: ='[1]収集（全般）'!$C$44 -> 0 | D7: =SUM(B7:C7) -> 0 | E7: ='[1]収集（全般）'!$D$44 -> 0 | F7: ='[1]収集（全般）'!$E$44 -> 0 | G7: =SUM(E7:F7) -> 0 | H7: =ROUND(D7+G7,1) -> 0 | K7: =[1]可燃!$M$43 +[1]可燃!$R$43 -> 0 | L7: =[1]可燃!$N$43 +[1]可燃!$S$43 -> 0 | M7: =SUM(K7:L7) -> 0 | N7: =[1]可燃!$O$43 +[1]可燃!$T$43 -> 0 | O7: =[1]可燃!$P$43 +[1]可燃!$U$43 -> 0 | P7: =SUM(N7:O7) -> 0 | Q7: =ROUND(M7+P7,1) -> 0
A8: 5 | J8: 5
B9: ='[2]収集（全般）'!$B$44 -> 0 | C9: ='[2]収集（全般）'!$C$44 -> 0 | D9: =SUM(B9:C9) -> 0 | E9: ='[2]収集（全般）'!$D$44 -> 0 | F9: ='[2]収集（全般）'!$E$44 -> 0 | G9: =SUM(E9:F9) -> 0 | H9: =ROUND(D9+G9,1) -> 0 | K9: =[2]可燃!$M$43 +[2]可燃!$R$43 -> 0 | L9: =[2]可燃!$N$43 +[2]可燃!$S$43 -> 0 | M9: =SUM(K9:L9) -> 0 | N9: =[2]可燃!$O$43 +[2]可燃!$T$43 -> 0 | O9: =[2]可燃!$P$43 +[2]可燃!$U$43 -> 0 | P9: =SUM(N9:O9) -> 0 | Q9: =ROUND(M9+P9,1) -> 0
A10: 6 | J10: 6
B11: ='[3]収集（全般）'!$B$44 -> 0 | C11: ='[3]収集（全般）'!$C$44 -> 0 | D11: =SUM(B11:C11) -> 0 | E11: ='[3]収集（全般）'!$D$44 -> 0 | F11: ='[3]収集（全般）'!$E$44 -> 0 | G11: =SUM(E11:F11) -> 0 | H11: =ROUND(D11+G11,1) -> 0 | K11: =[3]可燃!$M$43 +[3]可燃!$R$43 -> 0 | L11: =[3]可燃!$N$43 +[3]可燃!$S$43 -> 0 | M11: =SUM(K11:L11) -> 0 | N11: =[3]可燃!$O$43 +[3]可燃!$T$43 -> 0 | O11: =[3]可燃!$P$43 +[3]可燃!$U$43 -> 0 | P11: =SUM(N11:O11) -> 0 | Q11: =ROUND(M11+P11,1) -> 0
A12: 7 | J12: 7
B13: ='[4]収集（全般）'!$B$44 -> 0 | C13: ='[4]収集（全般）'!$C$44 -> 0 | D13: =SUM(B13:C13) -> 0 | E13: ='[4]収集（全般）'!$D$44 -> 0 | F13: ='[4]収集（全般）'!$E$44 -> 0 | G13: =SUM(E13:F13) -> 0 | H13: =ROUND(D13+G13,1) -> 0 | K13: =[4]可燃!$M$43 +[4]可燃!$R$43 -> 0 | L13: =[4]可燃!$N$43 +[4]可燃!$S$43 -> 0 | M13: =SUM(K13:L13) -> 0 | N13: =[4]可燃!$O$43 +[4]可燃!$T$43 -> 0 | O13: =[4]可燃!$P$43 +[4]可燃!$U$43 -> 0 | P13: =SUM(N13:O13) -> 0 | Q13: =ROUND(M13+P13,1) -> 0
A14: 8 | J14: 8
B15: ='[5]収集（全般）'!$B$44 -> 0 | C15: ='[5]収集（全般）'!$C$44 -> 0 | D15: =SUM(B15:C15) -> 0 | E15: ='[5]収集（全般）'!$D$44 -> 0 | F15: ='[5]収集（全般）'!$E$44 -> 0 | G15: =SUM(E15:F15) -> 0 | H15: =ROUND(D15+G15,1) -> 0 | K15: =[5]可燃!$M$43 +[5]可燃!$R$43 -> 0 | L15: =[5]可燃!$N$43 +[5]可燃!$S$43 -> 0 | M15: =SUM(K15:L15) -> 0 | N15: =[5]可燃!$O$43 +[5]可燃!$T$43 -> 0 | O15: =[5]可燃!$P$43 +[5]可燃!$U$43 -> 0 | P15: =SUM(N15:O15) -> 0 | Q15: =ROUND(M15+P15,1) -> 0
A16: 9 | J16: 9
B17: ='[6]収集（全般）'!$B$44 -> 0 | C17: ='[6]収集（全般）'!$C$44 -> 0 | D17: =SUM(B17:C17) -> 0 | E17: ='[6]収集（全般）'!$D$44 -> 0 | F17: ='[6]収集（全般）'!$E$44 -> 0 | G17: =SUM(E17:F17) -> 0 | H17: =ROUND(D17+G17,1) -> 0 | K17: =[6]可燃!$M$43 +[6]可燃!$R$43 -> 0 | L17: =[6]可燃!$N$43 +[6]可燃!$S$43 -> 0 | M17: =SUM(K17:L17) -> 0 | N17: =[6]可燃!$O$43 +[6]可燃!$T$43 -> 0 | O17: =[6]可燃!$P$43 +[6]可燃!$U$43 -> 0 | P17: =SUM(N17:O17) -> 0 | Q17: =ROUND(M17+P17,1) -> 0
A18: 10 | J18: 10
B19: ='[7]収集（全般）'!$B$44 -> 0 | C19: ='[7]収集（全般）'!$C$44 -> 0 | D19: =SUM(B19:C19) -> 0 | E19: ='[7]収集（全般）'!$D$44 -> 0 | F19: ='[7]収集（全般）'!$E$44 -> 0 | G19: =SUM(E19:F19) -> 0 | H19: =ROUND(D19+G19,1) -> 0 | K19: =[7]可燃!$M$43 +[7]可燃!$R$43 -> 0 | L19: =[7]可燃!$N$43 +[7]可燃!$S$43 -> 0 | M19: =SUM(K19:L19) -> 0 | N19: =[7]可燃!$O$43 +[7]可燃!$T$43 -> 0 | O19: =[7]可燃!$P$43 +[7]可燃!$U$43 -> 0 | P19: =SUM(N19:O19) -> 0 | Q19: =ROUND(M19+P19,1) -> 0
A20: 11 | J20: 11
B21: ='[8]収集（全般）'!$B$44 -> 0 | C21: ='[8]収集（全般）'!$C$44 -> 0 | D21: =SUM(B21:C21) -> 0 | E21: ='[8]収集（全般）'!$D$44 -> 0 | F21: ='[8]収集（全般）'!$E$44 -> 0 | G21: =SUM(E21:F21) -> 0 | H21: =ROUND(D21+G21,1) -> 0 | K21: =[8]可燃!$M$43 +[8]可燃!$R$43 -> 0 | L21: =[8]可燃!$N$43 +[8]可燃!$S$43 -> 0 | M21: =SUM(K21:L21) -> 0 | N21: =[8]可燃!$O$43 +[8]可燃!$T$43 -> 0 | O21: =[8]可燃!$P$43 +[8]可燃!$U$43 -> 0 | P21: =SUM(N21:O21) -> 0 | Q21: =ROUND(M21+P21,1) -> 0
A22: 12 | J22: 12
B23: ='[9]収集（全般）'!$B$44 -> 0 | C23: ='[9]収集（全般）'!$C$44 -> 0 | D23: =SUM(B23:C23) -> 0 | E23: ='[9]収集（全般）'!$D$44 -> 0 | F23: ='[9]収集（全般）'!$E$44 -> 0 | G23: =SUM(E23:F23) -> 0 | H23: =ROUND(D23+G23,1) -> 0 | K23: =[9]可燃!$M$43 +[9]可燃!$R$43 -> 0 | L23: =[9]可燃!$N$43 +[9]可燃!$S$43 -> 0 | M23: =SUM(K23:L23) -> 0 | N23: =[9]可燃!$O$43 +[9]可燃!$T$43 -> 0 | O23: =[9]可燃!$P$43 +[9]可燃!$U$43 -> 0 | P23: =SUM(N23:O23) -> 0 | Q23: =ROUND(M23+P23,1) -> 0
A24: 1 | J24: 1
B25: ='[10]収集（全般）'!$B$44 -> 0 | C25: ='[10]収集（全般）'!$C$44 -> 0 | D25: =SUM(B25:C25) -> 0 | E25: ='[10]収集（全般）'!$D$44 -> 0 | F25: ='[10]収集（全般）'!$E$44 -> 0 | G25: =SUM(E25:F25) -> 0 | H25: =ROUND(D25+G25,1) -> 0 | K25: =[10]可燃!$M$43 +[10]可燃!$R$43 -> 0 | L25: =[10]可燃!$N$43 +[10]可燃!$S$43 -> 0 | M25: =SUM(K25:L25) -> 0 | N25: =[10]可燃!$O$43 +[10]可燃!$T$43 -> 0 | O25: =[10]可燃!$P$43 +[10]可燃!$U$43 -> 0 | P25: =SUM(N25:O25) -> 0 | Q25: =ROUND(M25+P25,1) -> 0
A26: 2 | J26: 2
B27: ='[11]収集（全般）'!$B$44 -> 0 | C27: ='[11]収集（全般）'!$C$44 -> 0 | D27: =SUM(B27:C27) -> 0 | E27: ='[11]収集（全般）'!$D$44 -> 0 | F27: ='[11]収集（全般）'!$E$44 -> 0 | G27: =SUM(E27:F27) -> 0 | H27: =ROUND(D27+G27,1) -> 0 | K27: =[11]可燃!$M$43 +[11]可燃!$R$43 -> 0 | L27: =[11]可燃!$N$43 +[11]可燃!$S$43 -> 0 | M27: =SUM(K27:L27) -> 0 | N27: =[11]可燃!$O$43 +[11]可燃!$T$43 -> 0 | O27: =[11]可燃!$P$43 +[11]可燃!$U$43 -> 0 | P27: =SUM(N27:O27) -> 0 | Q27: =ROUND(M27+P27,1) -> 0
A28: 3 | J28: 3
B29: ='[12]収集（全般）'!$B$44 -> 0 | C29: ='[12]収集（全般）'!$C$44 -> 0 | D29: =SUM(B29:C29) -> 0 | E29: ='[12]収集（全般）'!$D$44 -> 0 | F29: ='[12]収集（全般）'!$E$44 -> 0 | G29: =SUM(E29:F29) -> 0 | H29: =ROUND(D29+G29,1) -> 0 | K29: =[12]可燃!$M$43 +[12]可燃!$R$43 -> 0 | L29: =[12]可燃!$N$43 +[12]可燃!$S$43 -> 0 | M29: =SUM(K29:L29) -> 0 | N29: =[12]可燃!$O$43 +[12]可燃!$T$43 -> 0 | O29: =[12]可燃!$P$43 +[12]可燃!$U$43 -> 0 | P29: =SUM(N29:O29) -> 0 | Q29: =ROUND(M29+P29,1) -> 0
A31: 合計 | J31: 合計
B32: =SUM(B7+B9+B11+B13+B15+B17+B19+B21+B23+B25+B27+B29) -> 0 | C32: =SUM(C7+C9+C11+C13+C15+C17+C19+C21+C23+C25+C27+C29) -> 0 | D32: =SUM(D7+D9+D11+D13+D15+D17+D19+D21+D23+D25+D27+D29) -> 0 | E32: =SUM(E7+E9+E11+E13+E15+E17+E19+E21+E23+E25+E27+E29) -> 0 | F32: =SUM(F7+F9+F11+F13+F15+F17+F19+F21+F23+F25+F27+F29) -> 0 | G32: =SUM(G7+G9+G11+G13+G15+G17+G19+G21+G23+G25+G27+G29) -> 0 | H32: =SUM(H6:H29) -> 0 | K32: =SUM(K7+K9+K11+K13+K15+K17+K19+K21+K23+K25+K27+K29) -> 0 | L32: =SUM(L7+L9+L11+L13+L15+L17+L19+L21+L23+L25+L27+L29) -> 0 | M32: =SUM(M7+M9+M11+M13+M15+M17+M19+M21+M23+M25+M27+M29) -> 0 | N32: =SUM(N7+N9+N11+N13+N15+N17+N19+N21+N23+N25+N27+N29) -> 0 | O32: =SUM(O7+O9+O11+O13+O15+O17+O19+O21+O23+O25+O27+O29) -> 0 | P32: =SUM(P7+P9+P11+P13+P15+P17+P19+P21+P23+P25+P27+P29) -> 0 | Q32: =SUM(Q6:Q29) -> 0

Sheet 1-2
A1: ="令和"&'[1]A-1'!$E$9-2018&"年度 一般廃棄物（ごみ）収集地区別集計表 【第1－2表】" -> 令和9年度 一般廃棄物（ごみ）収集地区別集計表 【第1－2表】
B3: 【収集不燃ごみ】 | K3: 【直搬不燃ごみ】 | Q3: 単位：トン
A5: 月別 | B5: 鬼 脇 | C5: 鴛 泊 | D5: 利尻富士計 | E5: 仙法志 | F5: 沓 形 | G5: 利尻計 | H5: 合 計 | J5: 月別 | K5: 鬼 脇 | L5: 鴛 泊 | M5: 利尻富士計 | N5: 仙法志 | O5: 沓 形 | P5: 利尻計 | Q5: 合 計
A6: 4 | J6: 4
B7: ='[1]収集（全般）'!$G$44 -> 0 | C7: ='[1]収集（全般）'!$H$44 -> 0 | D7: =SUM(B7:C7) -> 0 | E7: ='[1]収集（全般）'!$I$44 -> 0 | F7: ='[1]収集（全般）'!$J$44 -> 0 | G7: =SUM(E7:F7) -> 0 | H7: =ROUND(D7+G7,1) -> 0 | K7: =[1]不燃・木くず・海岸清掃!$G$43 -> 0 | L7: =[1]不燃・木くず・海岸清掃!$H$43 -> 0 | M7: =SUM(K7:L7) -> 0 | N7: =[1]不燃・木くず・海岸清掃!$I$43 -> 0 | O7: =[1]不燃・木くず・海岸清掃!$J$43 -> 0 | P7: =SUM(N7:O7) -> 0 | Q7: =ROUND(M7+P7,1) -> 0
A8: 5 | J8: 5
B9: ='[2]収集（全般）'!$G$44 -> 0 | C9: ='[2]収集（全般）'!$H$44 -> 0 | D9: =SUM(B9:C9) -> 0 | E9: ='[2]収集（全般）'!$I$44 -> 0 | F9: ='[2]収集（全般）'!$J$44 -> 0 | G9: =SUM(E9:F9) -> 0 | H9: =ROUND(D9+G9,1) -> 0 | K9: =[2]不燃・木くず・海岸清掃!$G$43 -> 0 | L9: =[2]不燃・木くず・海岸清掃!$H$43 -> 0 | M9: =SUM(K9:L9) -> 0 | N9: =[2]不燃・木くず・海岸清掃!$I$43 -> 0 | O9: =[2]不燃・木くず・海岸清掃!$J$43 -> 0 | P9: =SUM(N9:O9) -> 0 | Q9: =ROUND(M9+P9,1) -> 0
A10: 6 | J10: 6
B11: ='[3]収集（全般）'!$G$44 -> 0 | C11: ='[3]収集（全般）'!$H$44 -> 0 | D11: =SUM(B11:C11) -> 0 | E11: ='[3]収集（全般）'!$I$44 -> 0 | F11: ='[3]収集（全般）'!$J$44 -> 0 | G11: =SUM(E11:F11) -> 0 | H11: =ROUND(D11+G11,1) -> 0 | K11: =[3]不燃・木くず・海岸清掃!$G$43 -> 0 | L11: =[3]不燃・木くず・海岸清掃!$H$43 -> 0 | M11: =SUM(K11:L11) -> 0 | N11: =[3]不燃・木くず・海岸清掃!$I$43 -> 0 | O11: =[3]不燃・木くず・海岸清掃!$J$43 -> 0 | P11: =SUM(N11:O11) -> 0 | Q11: =ROUND(M11+P11,1) -> 0
A12: 7 | J12: 7
B13: ='[4]収集（全般）'!$G$44 -> 0 | C13: ='[4]収集（全般）'!$H$44 -> 0 | D13: =SUM(B13:C13) -> 0 | E13: ='[4]収集（全般）'!$I$44 -> 0 | F13: ='[4]収集（全般）'!$J$44 -> 0 | G13: =SUM(E13:F13) -> 0 | H13: =ROUND(D13+G13,1) -> 0 | K13: =[4]不燃・木くず・海岸清掃!$G$43 -> 0 | L13: =[4]不燃・木くず・海岸清掃!$H$43 -> 0 | M13: =SUM(K13:L13) -> 0 | N13: =[4]不燃・木くず・海岸清掃!$I$43 -> 0 | O13: =[4]不燃・木くず・海岸清掃!$J$43 -> 0 | P13: =SUM(N13:O13) -> 0 | Q13: =ROUND(M13+P13,1) -> 0
A14: 8 | J14: 8
B15: ='[5]収集（全般）'!$G$44 -> 0 | C15: ='[5]収集（全般）'!$H$44 -> 0 | D15: =SUM(B15:C15) -> 0 | E15: ='[5]収集（全般）'!$I$44 -> 0 | F15: ='[5]収集（全般）'!$J$44 -> 0 | G15: =SUM(E15:F15) -> 0 | H15: =ROUND(D15+G15,1) -> 0 | K15: =[5]不燃・木くず・海岸清掃!$G$43 -> 0 | L15: =[5]不燃・木くず・海岸清掃!$H$43 -> 0 | M15: =SUM(K15:L15) -> 0 | N15: =[5]不燃・木くず・海岸清掃!$I$43 -> 0 | O15: =[5]不燃・木くず・海岸清掃!$J$43 -> 0 | P15: =SUM(N15:O15) -> 0 | Q15: =ROUND(M15+P15,1) -> 0
A16: 9 | J16: 9
B17: ='[6]収集（全般）'!$G$44 -> 0 | C17: ='[6]収集（全般）'!$H$44 -> 0 | D17: =SUM(B17:C17) -> 0 | E17: ='[6]収集（全般）'!$I$44 -> 0 | F17: ='[6]収集（全般）'!$J$44 -> 0 | G17: =SUM(E17:F17) -> 0 | H17: =ROUND(D17+G17,1) -> 0 | K17: =[6]不燃・木くず・海岸清掃!$G$43 -> 0 | L17: =[6]不燃・木くず・海岸清掃!$H$43 -> 0 | M17: =SUM(K17:L17) -> 0 | N17: =[6]不燃・木くず・海岸清掃!$I$43 -> 0 | O17: =[6]不燃・木くず・海岸清掃!$J$43 -> 0 | P17: =SUM(N17:O17) -> 0 | Q17: =ROUND(M17+P17,1) -> 0
A18: 10 | J18: 10
B19: ='[7]収集（全般）'!$G$44 -> 0 | C19: ='[7]収集（全般）'!$H$44 -> 0 | D19: =SUM(B19:C19) -> 0 | E19: ='[7]収集（全般）'!$I$44 -> 0 | F19: ='[7]収集（全般）'!$J$44 -> 0 | G19: =SUM(E19:F19) -> 0 | H19: =ROUND(D19+G19,1) -> 0 | K19: =[7]不燃・木くず・海岸清掃!$G$43 -> 0 | L19: =[7]不燃・木くず・海岸清掃!$H$43 -> 0 | M19: =SUM(K19:L19) -> 0 | N19: =[7]不燃・木くず・海岸清掃!$I$43 -> 0 | O19: =[7]不燃・木くず・海岸清掃!$J$43 -> 0 | P19: =SUM(N19:O19) -> 0 | Q19: =ROUND(M19+P19,1) -> 0
A20: 11 | J20: 11
B21: ='[8]収集（全般）'!$G$44 -> 0 | C21: ='[8]収集（全般）'!$H$44 -> 0 | D21: =SUM(B21:C21) -> 0 | E21: ='[8]収集（全般）'!$I$44 -> 0 | F21: ='[8]収集（全般）'!$J$44 -> 0 | G21: =SUM(E21:F21) -> 0 | H21: =ROUND(D21+G21,1) -> 0 | K21: =[8]不燃・木くず・海岸清掃!$G$43 -> 0 | L21: =[8]不燃・木くず・海岸清掃!$H$43 -> 0 | M21: =SUM(K21:L21) -> 0 | N21: =[8]不燃・木くず・海岸清掃!$I$43 -> 0 | O21: =[8]不燃・木くず・海岸清掃!$J$43 -> 0 | P21: =SUM(N21:O21) -> 0 | Q21: =ROUND(M21+P21,1) -> 0
A22: 12 | J22: 12
B23: ='[9]収集（全般）'!$G$44 -> 0 | C23: ='[9]収集（全般）'!$H$44 -> 0 | D23: =SUM(B23:C23) -> 0 | E23: ='[9]収集（全般）'!$I$44 -> 0 | F23: ='[9]収集（全般）'!$J$44 -> 0 | G23: =SUM(E23:F23) -> 0 | H23: =ROUND(D23+G23,1) -> 0 | K23: =[9]不燃・木くず・海岸清掃!$G$43 -> 0 | L23: =[9]不燃・木くず・海岸清掃!$H$43 -> 0 | M23: =SUM(K23:L23) -> 0 | N23: =[9]不燃・木くず・海岸清掃!$I$43 -> 0 | O23: =[9]不燃・木くず・海岸清掃!$J$43 -> 0 | P23: =SUM(N23:O23) -> 0 | Q23: =ROUND(M23+P23,1) -> 0
A24: 1 | J24: 1
B25: ='[10]収集（全般）'!$G$44 -> 0 | C25: ='[10]収集（全般）'!$H$44 -> 0 | D25: =SUM(B25:C25) -> 0 | E25: ='[10]収集（全般）'!$I$44 -> 0 | F25: ='[10]収集（全般）'!$J$44 -> 0 | G25: =SUM(E25:F25) -> 0 | H25: =ROUND(D25+G25,1) -> 0 | K25: =[10]不燃・木くず・海岸清掃!$G$43 -> 0 | L25: =[10]不燃・木くず・海岸清掃!$H$43 -> 0 | M25: =SUM(K25:L25) -> 0 | N25: =[10]不燃・木くず・海岸清掃!$I$43 -> 0 | O25: =[10]不燃・木くず・海岸清掃!$J$43 -> 0 | P25: =SUM(N25:O25) -> 0 | Q25: =ROUND(M25+P25,1) -> 0
A26: 2 | J26: 2
B27: ='[11]収集（全般）'!$G$44 -> 0 | C27: ='[11]収集（全般）'!$H$44 -> 0 | D27: =SUM(B27:C27) -> 0 | E27: ='[11]収集（全般）'!$I$44 -> 0 | F27: ='[11]収集（全般）'!$J$44 -> 0 | G27: =SUM(E27:F27) -> 0 | H27: =ROUND(D27+G27,1) -> 0 | K27: =[11]不燃・木くず・海岸清掃!$G$43 -> 0 | L27: =[11]不燃・木くず・海岸清掃!$H$43 -> 0 | M27: =SUM(K27:L27) -> 0 | N27: =[11]不燃・木くず・海岸清掃!$I$43 -> 0 | O27: =[11]不燃・木くず・海岸清掃!$J$43 -> 0 | P27: =SUM(N27:O27) -> 0 | Q27: =ROUND(M27+P27,1) -> 0
A28: 3 | J28: 3
B29: ='[12]収集（全般）'!$G$44 -> 0 | C29: ='[12]収集（全般）'!$H$44 -> 0 | D29: =SUM(B29:C29) -> 0 | E29: ='[12]収集（全般）'!$I$44 -> 0 | F29: ='[12]収集（全般）'!$J$44 -> 0 | G29: =SUM(E29:F29) -> 0 | H29: =ROUND(D29+G29,1) -> 0 | K29: =[12]不燃・木くず・海岸清掃!$G$43 -> 0 | L29: =[12]不燃・木くず・海岸清掃!$H$43 -> 0 | M29: =SUM(K29:L29) -> 0 | N29: =[12]不燃・木くず・海岸清掃!$I$43 -> 0 | O29: =[12]不燃・木くず・海岸清掃!$J$43 -> 0 | P29: =SUM(N29:O29) -> 0 | Q29: =ROUND(M29+P29,1) -> 0
A31: 合計 | J31: 合計
B32: =SUM(B7+B9+B11+B13+B15+B17+B19+B21+B23+B25+B27+B29) -> 0 | C32: =SUM(C7+C9+C11+C13+C15+C17+C19+C21+C23+C25+C27+C29) -> 0 | D32: =SUM(D7+D9+D11+D13+D15+D17+D19+D21+D23+D25+D27+D29) -> 0 | E32: =SUM(E7+E9+E11+E13+E15+E17+E19+E21+E23+E25+E27+E29) -> 0 | F32: =SUM(F7+F9+F11+F13+F15+F17+F19+F21+F23+F25+F27+F29) -> 0 | G32: =SUM(G7+G9+G11+G13+G15+G17+G19+G21+G23+G25+G27+G29) -> 0 | H32: =SUM(H6:H29) -> 0 | K32: =SUM(K7+K9+K11+K13+K15+K17+K19+K21+K23+K25+K27+K29) -> 0 | L32: =SUM(L7+L9+L11+L13+L15+L17+L19+L21+L23+L25+L27+L29) -> 0 | M32: =SUM(M7+M9+M11+M13+M15+M17+M19+M21+M23+M25+M27+M29) -> 0 | N32: =SUM(N7+N9+N11+N13+N15+N17+N19+N21+N23+N25+N27+N29) -> 0 | O32: =SUM(O7+O9+O11+O13+O15+O17+O19+O21+O23+O25+O27+O29) -> 0 | P32: =SUM(P7+P9+P11+P13+P15+P17+P19+P21+P23+P25+P27+P29) -> 0 | Q32: =SUM(Q6:Q29) -> 0

Sheet 1-3
A1: ="令和"&'[1]A-1'!$E$9-2018&"年度 一般廃棄物（ごみ）収集地区別集計表 【第1－3表】" -> 令和9年度 一般廃棄物（ごみ）収集地区別集計表 【第1－3表】
B3: 【収集びん類】 | K3: 【直搬びん類】 | Q3: 単位：トン
A5: 月別 | B5: 鬼 脇 | C5: 鴛 泊 | D5: 利尻富士計 | E5: 仙法志 | F5: 沓 形 | G5: 利尻計 | H5: 合 計 | J5: 月別 | K5: 鬼 脇 | L5: 鴛 泊 | M5: 利尻富士計 | N5: 仙法志 | O5: 沓 形 | P5: 利尻計 | Q5: 合 計
A6: 4 | J6: 4
B7: ='[1]収集（全般）'!$L$44 -> 0 | C7: ='[1]収集（全般）'!$M$44 -> 0 | D7: =SUM(B7:C7) -> 0 | E7: ='[1]収集（全般）'!$N$44 -> 0 | F7: ='[1]収集（全般）'!$O$44 -> 0 | G7: =SUM(E7:F7) -> 0 | H7: =ROUND(D7+G7,1) -> 0 | K7: =[1]ビン類!$M$43 +[1]ビン類!$R$43 -> 0 | L7: =[1]ビン類!$N$43 +[1]ビン類!$S$43 -> 0 | M7: =SUM(K7:L7) -> 0 | N7: =[1]ビン類!$O$43 +[1]ビン類!$T$43 -> 0 | O7: =[1]ビン類!$P$43 +[1]ビン類!$U$43 -> 0 | P7: =SUM(N7:O7) -> 0 | Q7: =ROUND(M7+P7,1) -> 0
A8: 5 | J8: 5
B9: ='[2]収集（全般）'!$L$44 -> 0 | C9: ='[2]収集（全般）'!$M$44 -> 0 | D9: =SUM(B9:C9) -> 0 | E9: ='[2]収集（全般）'!$N$44 -> 0 | F9: ='[2]収集（全般）'!$O$44 -> 0 | G9: =SUM(E9:F9) -> 0 | H9: =ROUND(D9+G9,1) -> 0 | K9: =[2]ビン類!$M$43 +[2]ビン類!$R$43 -> 0 | L9: =[2]ビン類!$N$43 +[2]ビン類!$S$43 -> 0 | M9: =SUM(K9:L9) -> 0 | N9: =[2]ビン類!$O$43 +[2]ビン類!$T$43 -> 0 | O9: =[2]ビン類!$P$43 +[2]ビン類!$U$43 -> 0 | P9: =SUM(N9:O9) -> 0 | Q9: =ROUND(M9+P9,1) -> 0
A10: 6 | J10: 6
B11: ='[3]収集（全般）'!$L$44 -> 0 | C11: ='[3]収集（全般）'!$M$44 -> 0 | D11: =SUM(B11:C11) -> 0 | E11: ='[3]収集（全般）'!$N$44 -> 0 | F11: ='[3]収集（全般）'!$O$44 -> 0 | G11: =SUM(E11:F11) -> 0 | H11: =ROUND(D11+G11,1) -> 0 | K11: =[3]ビン類!$M$43 +[3]ビン類!$R$43 -> 0 | L11: =[3]ビン類!$N$43 +[3]ビン類!$S$43 -> 0 | M11: =SUM(K11:L11) -> 0 | N11: =[3]ビン類!$O$43 +[3]ビン類!$T$43 -> 0 | O11: =[3]ビン類!$P$43 +[3]ビン類!$U$43 -> 0 | P11: =SUM(N11:O11) -> 0 | Q11: =ROUND(M11+P11,1) -> 0
A12: 7 | J12: 7
B13: ='[4]収集（全般）'!$L$44 -> 0 | C13: ='[4]収集（全般）'!$M$44 -> 0 | D13: =SUM(B13:C13) -> 0 | E13: ='[4]収集（全般）'!$N$44 -> 0 | F13: ='[4]収集（全般）'!$O$44 -> 0 | G13: =SUM(E13:F13) -> 0 | H13: =ROUND(D13+G13,1) -> 0 | K13: =[4]ビン類!$M$43 +[4]ビン類!$R$43 -> 0 | L13: =[4]ビン類!$N$43 +[4]ビン類!$S$43 -> 0 | M13: =SUM(K13:L13) -> 0 | N13: =[4]ビン類!$O$43 +[4]ビン類!$T$43 -> 0 | O13: =[4]ビン類!$P$43 +[4]ビン類!$U$43 -> 0 | P13: =SUM(N13:O13) -> 0 | Q13: =ROUND(M13+P13,1) -> 0
A14: 8 | J14: 8
B15: ='[5]収集（全般）'!$L$44 -> 0 | C15: ='[5]収集（全般）'!$M$44 -> 0 | D15: =SUM(B15:C15) -> 0 | E15: ='[5]収集（全般）'!$N$44 -> 0 | F15: ='[5]収集（全般）'!$O$44 -> 0 | G15: =SUM(E15:F15) -> 0 | H15: =ROUND(D15+G15,1) -> 0 | K15: =[5]ビン類!$M$43 +[5]ビン類!$R$43 -> 0 | L15: =[5]ビン類!$N$43 +[5]ビン類!$S$43 -> 0 | M15: =SUM(K15:L15) -> 0 | N15: =[5]ビン類!$O$43 +[5]ビン類!$T$43 -> 0 | O15: =[5]ビン類!$P$43 +[5]ビン類!$U$43 -> 0 | P15: =SUM(N15:O15) -> 0 | Q15: =ROUND(M15+P15,1) -> 0
A16: 9 | J16: 9
B17: ='[6]収集（全般）'!$L$44 -> 0 | C17: ='[6]収集（全般）'!$M$44 -> 0 | D17: =SUM(B17:C17) -> 0 | E17: ='[6]収集（全般）'!$N$44 -> 0 | F17: ='[6]収集（全般）'!$O$44 -> 0 | G17: =SUM(E17:F17) -> 0 | H17: =ROUND(D17+G17,1) -> 0 | K17: =[6]ビン類!$M$43 +[6]ビン類!$R$43 -> 0 | L17: =[6]ビン類!$N$43 +[6]ビン類!$S$43 -> 0 | M17: =SUM(K17:L17) -> 0 | N17: =[6]ビン類!$O$43 +[6]ビン類!$T$43 -> 0 | O17: =[6]ビン類!$P$43 +[6]ビン類!$U$43 -> 0 | P17: =SUM(N17:O17) -> 0 | Q17: =ROUND(M17+P17,1) -> 0
A18: 10 | J18: 10
B19: ='[7]収集（全般）'!$L$44 -> 0 | C19: ='[7]収集（全般）'!$M$44 -> 0 | D19: =SUM(B19:C19) -> 0 | E19: ='[7]収集（全般）'!$N$44 -> 0 | F19: ='[7]収集（全般）'!$O$44 -> 0 | G19: =SUM(E19:F19) -> 0 | H19: =ROUND(D19+G19,1) -> 0 | K19: =[7]ビン類!$M$43 +[7]ビン類!$R$43 -> 0 | L19: =[7]ビン類!$N$43 +[7]ビン類!$S$43 -> 0 | M19: =SUM(K19:L19) -> 0 | N19: =[7]ビン類!$O$43 +[7]ビン類!$T$43 -> 0 | O19: =[7]ビン類!$P$43 +[7]ビン類!$U$43 -> 0 | P19: =SUM(N19:O19) -> 0 | Q19: =ROUND(M19+P19,1) -> 0
A20: 11 | J20: 11
B21: ='[8]収集（全般）'!$L$44 -> 0 | C21: ='[8]収集（全般）'!$M$44 -> 0 | D21: =SUM(B21:C21) -> 0 | E21: ='[8]収集（全般）'!$N$44 -> 0 | F21: ='[8]収集（全般）'!$O$44 -> 0 | G21: =SUM(E21:F21) -> 0 | H21: =ROUND(D21+G21,1) -> 0 | K21: =[8]ビン類!$M$43 +[8]ビン類!$R$43 -> 0 | L21: =[8]ビン類!$N$43 +[8]ビン類!$S$43 -> 0 | M21: =SUM(K21:L21) -> 0 | N21: =[8]ビン類!$O$43 +[8]ビン類!$T$43 -> 0 | O21: =[8]ビン類!$P$43 +[8]ビン類!$U$43 -> 0 | P21: =SUM(N21:O21) -> 0 | Q21: =ROUND(M21+P21,1) -> 0
A22: 12 | J22: 12
B23: ='[9]収集（全般）'!$L$44 -> 0 | C23: ='[9]収集（全般）'!$M$44 -> 0 | D23: =SUM(B23:C23) -> 0 | E23: ='[9]収集（全般）'!$N$44 -> 0 | F23: ='[9]収集（全般）'!$O$44 -> 0 | G23: =SUM(E23:F23) -> 0 | H23: =ROUND(D23+G23,1) -> 0 | K23: =[9]ビン類!$M$43 +[9]ビン類!$R$43 -> 0 | L23: =[9]ビン類!$N$43 +[9]ビン類!$S$43 -> 0 | M23: =SUM(K23:L23) -> 0 | N23: =[9]ビン類!$O$43 +[9]ビン類!$T$43 -> 0 | O23: =[9]ビン類!$P$43 +[9]ビン類!$U$43 -> 0 | P23: =SUM(N23:O23) -> 0 | Q23: =ROUND(M23+P23,1) -> 0
A24: 1 | J24: 1
B25: ='[10]収集（全般）'!$L$44 -> 0 | C25: ='[10]収集（全般）'!$M$44 -> 0 | D25: =SUM(B25:C25) -> 0 | E25: ='[10]収集（全般）'!$N$44 -> 0 | F25: ='[10]収集（全般）'!$O$44 -> 0 | G25: =SUM(E25:F25) -> 0 | H25: =ROUND(D25+G25,1) -> 0 | K25: =[10]ビン類!$M$43 +[10]ビン類!$R$43 -> 0 | L25: =[10]ビン類!$N$43 +[10]ビン類!$S$43 -> 0 | M25: =SUM(K25:L25) -> 0 | N25: =[10]ビン類!$O$43 +[10]ビン類!$T$43 -> 0 | O25: =[10]ビン類!$P$43 +[10]ビン類!$U$43 -> 0 | P25: =SUM(N25:O25) -> 0 | Q25: =ROUND(M25+P25,1) -> 0
A26: 2 | J26: 2
B27: ='[11]収集（全般）'!$L$44 -> 0 | C27: ='[11]収集（全般）'!$M$44 -> 0 | D27: =SUM(B27:C27) -> 0 | E27: ='[11]収集（全般）'!$N$44 -> 0 | F27: ='[11]収集（全般）'!$O$44 -> 0 | G27: =SUM(E27:F27) -> 0 | H27: =ROUND(D27+G27,1) -> 0 | K27: =[11]ビン類!$M$43 +[11]ビン類!$R$43 -> 0 | L27: =[11]ビン類!$N$43 +[11]ビン類!$S$43 -> 0 | M27: =SUM(K27:L27) -> 0 | N27: =[11]ビン類!$O$43 +[11]ビン類!$T$43 -> 0 | O27: =[11]ビン類!$P$43 +[11]ビン類!$U$43 -> 0 | P27: =SUM(N27:O27) -> 0 | Q27: =ROUND(M27+P27,1) -> 0
A28: 3 | J28: 3
B29: ='[12]収集（全般）'!$L$44 -> 0 | C29: ='[12]収集（全般）'!$M$44 -> 0 | D29: =SUM(B29:C29) -> 0 | E29: ='[12]収集（全般）'!$N$44 -> 0 | F29: ='[12]収集（全般）'!$O$44 -> 0 | G29: =SUM(E29:F29) -> 0 | H29: =ROUND(D29+G29,1) -> 0 | K29: =[12]ビン類!$M$43 +[12]ビン類!$R$43 -> 0 | L29: =[12]ビン類!$N$43 +[12]ビン類!$S$43 -> 0 | M29: =SUM(K29:L29) -> 0 | N29: =[12]ビン類!$O$43 +[12]ビン類!$T$43 -> 0 | O29: =[12]ビン類!$P$43 +[12]ビン類!$U$43 -> 0 | P29: =SUM(N29:O29) -> 0 | Q29: =ROUND(M29+P29,1) -> 0
A31: 合計 | J31: 合計
B32: =SUM(B7+B9+B11+B13+B15+B17+B19+B21+B23+B25+B27+B29) -> 0 | C32: =SUM(C7+C9+C11+C13+C15+C17+C19+C21+C23+C25+C27+C29) -> 0 | D32: =SUM(D7+D9+D11+D13+D15+D17+D19+D21+D23+D25+D27+D29) -> 0 | E32: =SUM(E7+E9+E11+E13+E15+E17+E19+E21+E23+E25+E27+E29) -> 0 | F32: =SUM(F7+F9+F11+F13+F15+F17+F19+F21+F23+F25+F27+F29) -> 0 | G32: =SUM(G7+G9+G11+G13+G15+G17+G19+G21+G23+G25+G27+G29) -> 0 | H32: =SUM(H6:H29) -> 0 | K32: =SUM(K7+K9+K11+K13+K15+K17+K19+K21+K23+K25+K27+K29) -> 0 | L32: =SUM(L7+L9+L11+L13+L15+L17+L19+L21+L23+L25+L27+L29) -> 0 | M32: =SUM(M7+M9+M11+M13+M15+M17+M19+M21+M23+M25+M27+M29) -> 0 | N32: =SUM(N7+N9+N11+N13+N15+N17+N19+N21+N23+N25+N27+N29) -> 0 | O32: =SUM(O7+O9+O11+O13+O15+O17+O19+O21+O23+O25+O27+O29) -> 0 | P32: =SUM(P7+P9+P11+P13+P15+P17+P19+P21+P23+P25+P27+P29) -> 0 | Q32: =SUM(Q6:Q29) -> 0

Sheet 1-4
A1: ="令和"&'[1]A-1'!$E$9-2018&"年度 一般廃棄物（ごみ）収集地区別集計表 【第1－4表】" -> 令和9年度 一般廃棄物（ごみ）収集地区別集計表 【第1－4表】
B3: 【収集缶類】 | K3: 【直搬缶類】 | Q3: 単位：トン
A5: 月別 | B5: 鬼 脇 | C5: 鴛 泊 | D5: 利尻富士計 | E5: 仙法志 | F5: 沓 形 | G5: 利尻計 | H5: 合 計 | J5: 月別 | K5: 鬼 脇 | L5: 鴛 泊 | M5: 利尻富士計 | N5: 仙法志 | O5: 沓 形 | P5: 利尻計 | Q5: 合 計
A6: 4 | J6: 4
B7: ='[1]収集（全般）'!$Q$44 -> 0 | C7: ='[1]収集（全般）'!$R$44 -> 0 | D7: =SUM(B7:C7) -> 0 | E7: ='[1]収集（全般）'!$S$44 -> 0 | F7: ='[1]収集（全般）'!$T$44 -> 0 | G7: =SUM(E7:F7) -> 0 | H7: =ROUND(D7+G7,1) -> 0 | K7: =[1]缶類!$M$43 +[1]缶類!$R$43 -> 0 | L7: =[1]缶類!$N$43 +[1]缶類!$S$43 -> 0 | M7: =SUM(K7:L7) -> 0 | N7: =[1]缶類!$O$43 +[1]缶類!$T$43 -> 0 | O7: =[1]缶類!$P$43 +[1]缶類!$U$43 -> 0 | P7: =SUM(N7:O7) -> 0 | Q7: =ROUND(M7+P7,1) -> 0
A8: 5 | J8: 5
B9: ='[2]収集（全般）'!$Q$44 -> 0 | C9: ='[2]収集（全般）'!$R$44 -> 0 | D9: =SUM(B9:C9) -> 0 | E9: ='[2]収集（全般）'!$S$44 -> 0 | F9: ='[2]収集（全般）'!$T$44 -> 0 | G9: =SUM(E9:F9) -> 0 | H9: =ROUND(D9+G9,1) -> 0 | K9: =[2]缶類!$M$43 +[2]缶類!$R$43 -> 0 | L9: =[2]缶類!$N$43 +[2]缶類!$S$43 -> 0 | M9: =SUM(K9:L9) -> 0 | N9: =[2]缶類!$O$43 +[2]缶類!$T$43 -> 0 | O9: =[2]缶類!$P$43 +[2]缶類!$U$43 -> 0 | P9: =SUM(N9:O9) -> 0 | Q9: =ROUND(M9+P9,1) -> 0
A10: 6 | J10: 6
B11: ='[3]収集（全般）'!$Q$44 -> 0 | C11: ='[3]収集（全般）'!$R$44 -> 0 | D11: =SUM(B11:C11) -> 0 | E11: ='[3]収集（全般）'!$S$44 -> 0 | F11: ='[3]収集（全般）'!$T$44 -> 0 | G11: =SUM(E11:F11) -> 0 | H11: =ROUND(D11+G11,1) -> 0 | K11: =[3]缶類!$M$43 +[3]缶類!$R$43 -> 0 | L11: =[3]缶類!$N$43 +[3]缶類!$S$43 -> 0 | M11: =SUM(K11:L11) -> 0 | N11: =[3]缶類!$O$43 +[3]缶類!$T$43 -> 0 | O11: =[3]缶類!$P$43 +[3]缶類!$U$43 -> 0 | P11: =SUM(N11:O11) -> 0 | Q11: =ROUND(M11+P11,1) -> 0
A12: 7 | J12: 7
B13: ='[4]収集（全般）'!$Q$44 -> 0 | C13: ='[4]収集（全般）'!$R$44 -> 0 | D13: =SUM(B13:C13) -> 0 | E13: ='[4]収集（全般）'!$S$44 -> 0 | F13: ='[4]収集（全般）'!$T$44 -> 0 | G13: =SUM(E13:F13) -> 0 | H13: =ROUND(D13+G13,1) -> 0 | K13: =[4]缶類!$M$43 +[4]缶類!$R$43 -> 0 | L13: =[4]缶類!$N$43 +[4]缶類!$S$43 -> 0 | M13: =SUM(K13:L13) -> 0 | N13: =[4]缶類!$O$43 +[4]缶類!$T$43 -> 0 | O13: =[4]缶類!$P$43 +[4]缶類!$U$43 -> 0 | P13: =SUM(N13:O13) -> 0 | Q13: =ROUND(M13+P13,1) -> 0
A14: 8 | J14: 8
B15: ='[5]収集（全般）'!$Q$44 -> 0 | C15: ='[5]収集（全般）'!$R$44 -> 0 | D15: =SUM(B15:C15) -> 0 | E15: ='[5]収集（全般）'!$S$44 -> 0 | F15: ='[5]収集（全般）'!$T$44 -> 0 | G15: =SUM(E15:F15) -> 0 | H15: =ROUND(D15+G15,1) -> 0 | K15: =[5]缶類!$M$43 +[5]缶類!$R$43 -> 0 | L15: =[5]缶類!$N$43 +[5]缶類!$S$43 -> 0 | M15: =SUM(K15:L15) -> 0 | N15: =[5]缶類!$O$43 +[5]缶類!$T$43 -> 0 | O15: =[5]缶類!$P$43 +[5]缶類!$U$43 -> 0 | P15: =SUM(N15:O15) -> 0 | Q15: =ROUND(M15+P15,1) -> 0
A16: 9 | J16: 9
B17: ='[6]収集（全般）'!$Q$44 -> 0 | C17: ='[6]収集（全般）'!$R$44 -> 0 | D17: =SUM(B17:C17) -> 0 | E17: ='[6]収集（全般）'!$S$44 -> 0 | F17: ='[6]収集（全般）'!$T$44 -> 0 | G17: =SUM(E17:F17) -> 0 | H17: =ROUND(D17+G17,1) -> 0 | K17: =[6]缶類!$M$43 +[6]缶類!$R$43 -> 0 | L17: =[6]缶類!$N$43 +[6]缶類!$S$43 -> 0 | M17: =SUM(K17:L17) -> 0 | N17: =[6]缶類!$O$43 +[6]缶類!$T$43 -> 0 | O17: =[6]缶類!$P$43 +[6]缶類!$U$43 -> 0 | P17: =SUM(N17:O17) -> 0 | Q17: =ROUND(M17+P17,1) -> 0
A18: 10 | J18: 10
B19: ='[7]収集（全般）'!$Q$44 -> 0 | C19: ='[7]収集（全般）'!$R$44 -> 0 | D19: =SUM(B19:C19) -> 0 | E19: ='[7]収集（全般）'!$S$44 -> 0 | F19: ='[7]収集（全般）'!$T$44 -> 0 | G19: =SUM(E19:F19) -> 0 | H19: =ROUND(D19+G19,1) -> 0 | K19: =[7]缶類!$M$43 +[7]缶類!$R$43 -> 0 | L19: =[7]缶類!$N$43 +[7]缶類!$S$43 -> 0 | M19: =SUM(K19:L19) -> 0 | N19: =[7]缶類!$O$43 +[7]缶類!$T$43 -> 0 | O19: =[7]缶類!$P$43 +[7]缶類!$U$43 -> 0 | P19: =SUM(N19:O19) -> 0 | Q19: =ROUND(M19+P19,1) -> 0
A20: 11 | J20: 11
B21: ='[8]収集（全般）'!$Q$44 -> 0 | C21: ='[8]収集（全般）'!$R$44 -> 0 | D21: =SUM(B21:C21) -> 0 | E21: ='[8]収集（全般）'!$S$44 -> 0 | F21: ='[8]収集（全般）'!$T$44 -> 0 | G21: =SUM(E21:F21) -> 0 | H21: =ROUND(D21+G21,1) -> 0 | K21: =[8]缶類!$M$43 +[8]缶類!$R$43 -> 0 | L21: =[8]缶類!$N$43 +[8]缶類!$S$43 -> 0 | M21: =SUM(K21:L21) -> 0 | N21: =[8]缶類!$O$43 +[8]缶類!$T$43 -> 0 | O21: =[8]缶類!$P$43 +[8]缶類!$U$43 -> 0 | P21: =SUM(N21:O21) -> 0 | Q21: =ROUND(M21+P21,1) -> 0
A22: 12 | J22: 12
B23: ='[9]収集（全般）'!$Q$44 -> 0 | C23: ='[9]収集（全般）'!$R$44 -> 0 | D23: =SUM(B23:C23) -> 0 | E23: ='[9]収集（全般）'!$S$44 -> 0 | F23: ='[9]収集（全般）'!$T$44 -> 0 | G23: =SUM(E23:F23) -> 0 | H23: =ROUND(D23+G23,1) -> 0 | K23: =[9]缶類!$M$43 +[9]缶類!$R$43 -> 0 | L23: =[9]缶類!$N$43 +[9]缶類!$S$43 -> 0 | M23: =SUM(K23:L23) -> 0 | N23: =[9]缶類!$O$43 +[9]缶類!$T$43 -> 0 | O23: =[9]缶類!$P$43 +[9]缶類!$U$43 -> 0 | P23: =SUM(N23:O23) -> 0 | Q23: =ROUND(M23+P23,1) -> 0
A24: 1 | J24: 1
B25: ='[10]収集（全般）'!$Q$44 -> 0 | C25: ='[10]収集（全般）'!$R$44 -> 0 | D25: =SUM(B25:C25) -> 0 | E25: ='[10]収集（全般）'!$S$44 -> 0 | F25: ='[10]収集（全般）'!$T$44 -> 0 | G25: =SUM(E25:F25) -> 0 | H25: =ROUND(D25+G25,1) -> 0 | K25: =[10]缶類!$M$43 +[10]缶類!$R$43 -> 0 | L25: =[10]缶類!$N$43 +[10]缶類!$S$43 -> 0 | M25: =SUM(K25:L25) -> 0 | N25: =[10]缶類!$O$43 +[10]缶類!$T$43 -> 0 | O25: =[10]缶類!$P$43 +[10]缶類!$U$43 -> 0 | P25: =SUM(N25:O25) -> 0 | Q25: =ROUND(M25+P25,1) -> 0
A26: 2 | J26: 2
B27: ='[11]収集（全般）'!$Q$44 -> 0 | C27: ='[11]収集（全般）'!$R$44 -> 0 | D27: =SUM(B27:C27) -> 0 | E27: ='[11]収集（全般）'!$S$44 -> 0 | F27: ='[11]収集（全般）'!$T$44 -> 0 | G27: =SUM(E27:F27) -> 0 | H27: =ROUND(D27+G27,1) -> 0 | K27: =[11]缶類!$M$43 +[11]缶類!$R$43 -> 0 | L27: =[11]缶類!$N$43 +[11]缶類!$S$43 -> 0 | M27: =SUM(K27:L27) -> 0 | N27: =[11]缶類!$O$43 +[11]缶類!$T$43 -> 0 | O27: =[11]缶類!$P$43 +[11]缶類!$U$43 -> 0 | P27: =SUM(N27:O27) -> 0 | Q27: =ROUND(M27+P27,1) -> 0
A28: 3 | J28: 3
B29: ='[12]収集（全般）'!$Q$44 -> 0 | C29: ='[12]収集（全般）'!$R$44 -> 0 | D29: =SUM(B29:C29) -> 0 | E29: ='[12]収集（全般）'!$S$44 -> 0 | F29: ='[12]収集（全般）'!$T$44 -> 0 | G29: =SUM(E29:F29) -> 0 | H29: =ROUND(D29+G29,1) -> 0 | K29: =[12]缶類!$M$43 +[12]缶類!$R$43 -> 0 | L29: =[12]缶類!$N$43 +[12]缶類!$S$43 -> 0 | M29: =SUM(K29:L29) -> 0 | N29: =[12]缶類!$O$43 +[12]缶類!$T$43 -> 0 | O29: =[12]缶類!$P$43 +[12]缶類!$U$43 -> 0 | P29: =SUM(N29:O29) -> 0 | Q29: =ROUND(M29+P29,1) -> 0
A31: 合計 | J31: 合計
B32: =SUM(B7+B9+B11+B13+B15+B17+B19+B21+B23+B25+B27+B29) -> 0 | C32: =SUM(C7+C9+C11+C13+C15+C17+C19+C21+C23+C25+C27+C29) -> 0 | D32: =SUM(D7+D9+D11+D13+D15+D17+D19+D21+D23+D25+D27+D29) -> 0 | E32: =SUM(E7+E9+E11+E13+E15+E17+E19+E21+E23+E25+E27+E29) -> 0 | F32: =SUM(F7+F9+F11+F13+F15+F17+F19+F21+F23+F25+F27+F29) -> 0 | G32: =SUM(G7+G9+G11+G13+G15+G17+G19+G21+G23+G25+G27+G29) -> 0 | H32: =SUM(H6:H29) -> 0 | K32: =SUM(K7+K9+K11+K13+K15+K17+K19+K21+K23+K25+K27+K29) -> 0 | L32: =SUM(L7+L9+L11+L13+L15+L17+L19+L21+L23+L25+L27+L29) -> 0 | M32: =SUM(M7+M9+M11+M13+M15+M17+M19+M21+M23+M25+M27+M29) -> 0 | N32: =SUM(N7+N9+N11+N13+N15+N17+N19+N21+N23+N25+N27+N29) -> 0 | O32: =SUM(O7+O9+O11+O13+O15+O17+O19+O21+O23+O25+O27+O29) -> 0 | P32: =SUM(P7+P9+P11+P13+P15+P17+P19+P21+P23+P25+P27+P29) -> 0 | Q32: =SUM(Q6:Q29) -> 0

Sheet 1-5
A1: ="令和"&'[1]A-1'!$E$9-2018&"年度 一般廃棄物（ごみ）収集地区別集計表 【第1－5表】" -> 令和9年度 一般廃棄物（ごみ）収集地区別集計表 【第1－5表】
B3: 【収集ペットボトル】 | K3: 【直搬ペットボトル】 | Q3: 単位：トン
A5: 月別 | B5: 鬼 脇 | C5: 鴛 泊 | D5: 利尻富士計 | E5: 仙法志 | F5: 沓 形 | G5: 利尻計 | H5: 合 計 | J5: 月別 | K5: 鬼 脇 | L5: 鴛 泊 | M5: 利尻富士計 | N5: 仙法志 | O5: 沓 形 | P5: 利尻計 | Q5: 合 計
A6: 4 | J6: 4
B7: ='[1]収集（全般）'!$V$44 -> 0 | C7: ='[1]収集（全般）'!$W$44 -> 0 | D7: =SUM(B7:C7) -> 0 | E7: ='[1]収集（全般）'!$X$44 -> 0 | F7: ='[1]収集（全般）'!$Y$44 -> 0 | G7: =SUM(E7:F7) -> 0 | H7: =ROUND(D7+G7,1) -> 0 | K7: =[1]ペットボトル!$M$43 +[1]ペットボトル!$R$43 -> 0 | L7: =[1]ペットボトル!$N$43 +[1]ペットボトル!$S$43 -> 0 | M7: =SUM(K7:L7) -> 0 | N7: =[1]ペットボトル!$O$43 +[1]ペットボトル!$T$43 -> 0 | O7: =[1]ペットボトル!$P$43 +[1]ペットボトル!$U$43 -> 0 | P7: =SUM(N7:O7) -> 0 | Q7: =ROUND(M7+P7,1) -> 0
A8: 5 | J8: 5
B9: ='[2]収集（全般）'!$V$44 -> 0 | C9: ='[2]収集（全般）'!$W$44 -> 0 | D9: =SUM(B9:C9) -> 0 | E9: ='[2]収集（全般）'!$X$44 -> 0 | F9: ='[2]収集（全般）'!$Y$44 -> 0 | G9: =SUM(E9:F9) -> 0 | H9: =ROUND(D9+G9,1) -> 0 | K9: =[2]ペットボトル!$M$43 +[2]ペットボトル!$R$43 -> 0 | L9: =[2]ペットボトル!$N$43 +[2]ペットボトル!$S$43 -> 0 | M9: =SUM(K9:L9) -> 0 | N9: =[2]ペットボトル!$O$43 +[2]ペットボトル!$T$43 -> 0 | O9: =[2]ペットボトル!$P$43 +[2]ペットボトル!$U$43 -> 0 | P9: =SUM(N9:O9) -> 0 | Q9: =ROUND(M9+P9,1) -> 0
A10: 6 | J10: 6
B11: ='[3]収集（全般）'!$V$44 -> 0 | C11: ='[3]収集（全般）'!$W$44 -> 0 | D11: =SUM(B11:C11) -> 0 | E11: ='[3]収集（全般）'!$X$44 -> 0 | F11: ='[3]収集（全般）'!$Y$44 -> 0 | G11: =SUM(E11:F11) -> 0 | H11: =ROUND(D11+G11,1) -> 0 | K11: =[3]ペットボトル!$M$43 +[2]ペットボトル!$R$43 -> 0 | L11: =[3]ペットボトル!$N$43 +[2]ペットボトル!$S$43 -> 0 | M11: =SUM(K11:L11) -> 0 | N11: =[3]ペットボトル!$O$43 +[2]ペットボトル!$T$43 -> 0 | O11: =[3]ペットボトル!$P$43 +[2]ペットボトル!$U$43 -> 0 | P11: =SUM(N11:O11) -> 0 | Q11: =ROUND(M11+P11,1) -> 0
A12: 7 | J12: 7
B13: ='[4]収集（全般）'!$V$44 -> 0 | C13: ='[4]収集（全般）'!$W$44 -> 0 | D13: =SUM(B13:C13) -> 0 | E13: ='[4]収集（全般）'!$X$44 -> 0 | F13: ='[4]収集（全般）'!$Y$44 -> 0 | G13: =SUM(E13:F13) -> 0 | H13: =ROUND(D13+G13,1) -> 0 | K13: =[4]ペットボトル!$M$43 +[4]ペットボトル!$R$43 -> 0 | L13: =[4]ペットボトル!$N$43 +[4]ペットボトル!$S$43 -> 0 | M13: =SUM(K13:L13) -> 0 | N13: =[4]ペットボトル!$O$43 +[4]ペットボトル!$T$43 -> 0 | O13: =[4]ペットボトル!$P$43 +[4]ペットボトル!$U$43 -> 0 | P13: =SUM(N13:O13) -> 0 | Q13: =ROUND(M13+P13,1) -> 0
A14: 8 | J14: 8
B15: ='[5]収集（全般）'!$V$44 -> 0 | C15: ='[5]収集（全般）'!$W$44 -> 0 | D15: =SUM(B15:C15) -> 0 | E15: ='[5]収集（全般）'!$X$44 -> 0 | F15: ='[5]収集（全般）'!$Y$44 -> 0 | G15: =SUM(E15:F15) -> 0 | H15: =ROUND(D15+G15,1) -> 0 | K15: =[5]ペットボトル!$M$43 +[5]ペットボトル!$R$43 -> 0 | L15: =[5]ペットボトル!$N$43 +[5]ペットボトル!$S$43 -> 0 | M15: =SUM(K15:L15) -> 0 | N15: =[5]ペットボトル!$O$43 +[5]ペットボトル!$T$43 -> 0 | O15: =[5]ペットボトル!$P$43 +[5]ペットボトル!$U$43 -> 0 | P15: =SUM(N15:O15) -> 0 | Q15: =ROUND(M15+P15,1) -> 0
A16: 9 | J16: 9
B17: ='[6]収集（全般）'!$V$44 -> 0 | C17: ='[6]収集（全般）'!$W$44 -> 0 | D17: =SUM(B17:C17) -> 0 | E17: ='[6]収集（全般）'!$X$44 -> 0 | F17: ='[6]収集（全般）'!$Y$44 -> 0 | G17: =SUM(E17:F17) -> 0 | H17: =ROUND(D17+G17,1) -> 0 | K17: =[6]ペットボトル!$M$43 +[6]ペットボトル!$R$43 -> 0 | L17: =[6]ペットボトル!$N$43 +[6]ペットボトル!$S$43 -> 0 | M17: =SUM(K17:L17) -> 0 | N17: =[6]ペットボトル!$O$43 +[6]ペットボトル!$T$43 -> 0 | O17: =[6]ペットボトル!$P$43 +[6]ペットボトル!$U$43 -> 0 | P17: =SUM(N17:O17) -> 0 | Q17: =ROUND(M17+P17,1) -> 0
A18: 10 | J18: 10
B19: ='[7]収集（全般）'!$V$44 -> 0 | C19: ='[7]収集（全般）'!$W$44 -> 0 | D19: =SUM(B19:C19) -> 0 | E19: ='[7]収集（全般）'!$X$44 -> 0 | F19: ='[7]収集（全般）'!$Y$44 -> 0 | G19: =SUM(E19:F19) -> 0 | H19: =ROUND(D19+G19,1) -> 0 | K19: =[7]ペットボトル!$M$43 +[6]ペットボトル!$R$43 -> 0 | L19: =[7]ペットボトル!$M$43 +[6]ペットボトル!$R$43 -> 0 | M19: =SUM(K19:L19) -> 0 | N19: =[7]ペットボトル!$M$43 +[6]ペットボトル!$R$43 -> 0 | O19: =[7]ペットボトル!$M$43 +[6]ペットボトル!$R$43 -> 0 | P19: =SUM(N19:O19) -> 0 | Q19: =ROUND(M19+P19,1) -> 0
A20: 11 | J20: 11
B21: ='[8]収集（全般）'!$V$44 -> 0 | C21: ='[8]収集（全般）'!$W$44 -> 0 | D21: =SUM(B21:C21) -> 0 | E21: ='[8]収集（全般）'!$X$44 -> 0 | F21: ='[8]収集（全般）'!$Y$44 -> 0 | G21: =SUM(E21:F21) -> 0 | H21: =ROUND(D21+G21,1) -> 0 | K21: =[8]ペットボトル!$M$43 +[8]ペットボトル!$R$43 -> 0 | L21: =[8]ペットボトル!$N$43 +[8]ペットボトル!$S$43 -> 0 | M21: =SUM(K21:L21) -> 0 | N21: =[8]ペットボトル!$O$43 +[8]ペットボトル!$T$43 -> 0 | O21: =[8]ペットボトル!$P$43 +[8]ペットボトル!$U$43 -> 0 | P21: =SUM(N21:O21) -> 0 | Q21: =ROUND(M21+P21,1) -> 0
A22: 12 | J22: 12
B23: ='[9]収集（全般）'!$V$44 -> 0 | C23: ='[9]収集（全般）'!$W$44 -> 0 | D23: =SUM(B23:C23) -> 0 | E23: ='[9]収集（全般）'!$X$44 -> 0 | F23: ='[9]収集（全般）'!$Y$44 -> 0 | G23: =SUM(E23:F23) -> 0 | H23: =ROUND(D23+G23,1) -> 0 | K23: =[9]ペットボトル!$M$43 +[9]ペットボトル!$R$43 -> 0 | L23: =[9]ペットボトル!$N$43 +[9]ペットボトル!$S$43 -> 0 | M23: =SUM(K23:L23) -> 0 | N23: =[9]ペットボトル!$O$43 +[9]ペットボトル!$T$43 -> 0 | O23: =[9]ペットボトル!$P$43 +[9]ペットボトル!$U$43 -> 0 | P23: =SUM(N23:O23) -> 0 | Q23: =ROUND(M23+P23,1) -> 0
A24: 1 | J24: 1
B25: ='[10]収集（全般）'!$V$44 -> 0 | C25: ='[10]収集（全般）'!$W$44 -> 0 | D25: =SUM(B25:C25) -> 0 | E25: ='[10]収集（全般）'!$X$44 -> 0 | F25: ='[10]収集（全般）'!$Y$44 -> 0 | G25: =SUM(E25:F25) -> 0 | H25: =ROUND(D25+G25,1) -> 0 | K25: =[10]ペットボトル!$M$43 +[10]ペットボトル!$R$43 -> 0 | L25: =[10]ペットボトル!$N$43 +[10]ペットボトル!$S$43 -> 0 | M25: =SUM(K25:L25) -> 0 | N25: =[10]ペットボトル!$O$43 +[10]ペットボトル!$T$43 -> 0 | O25: =[10]ペットボトル!$P$43 +[10]ペットボトル!$U$43 -> 0 | P25: =SUM(N25:O25) -> 0 | Q25: =ROUND(M25+P25,1) -> 0
A26: 2 | J26: 2
B27: ='[11]収集（全般）'!$V$44 -> 0 | C27: ='[11]収集（全般）'!$W$44 -> 0 | D27: =SUM(B27:C27) -> 0 | E27: ='[11]収集（全般）'!$X$44 -> 0 | F27: ='[11]収集（全般）'!$Y$44 -> 0 | G27: =SUM(E27:F27) -> 0 | H27: =ROUND(D27+G27,1) -> 0 | K27: =[11]ペットボトル!$M$43 +[11]ペットボトル!$R$43 -> 0 | L27: =[11]ペットボトル!$N$43 +[11]ペットボトル!$S$43 -> 0 | M27: =SUM(K27:L27) -> 0 | N27: =[11]ペットボトル!$O$43 +[11]ペットボトル!$T$43 -> 0 | O27: =[11]ペットボトル!$P$43 +[11]ペットボトル!$U$43 -> 0 | P27: =SUM(N27:O27) -> 0 | Q27: =ROUND(M27+P27,1) -> 0
A28: 3 | J28: 3
B29: ='[12]収集（全般）'!$V$44 -> 0 | C29: ='[12]収集（全般）'!$W$44 -> 0 | D29: =SUM(B29:C29) -> 0 | E29: ='[12]収集（全般）'!$X$44 -> 0 | F29: ='[12]収集（全般）'!$Y$44 -> 0 | G29: =SUM(E29:F29) -> 0 | H29: =ROUND(D29+G29,1) -> 0 | K29: =[12]ペットボトル!$M$43 +[12]ペットボトル!$R$43 -> 0 | L29: =[12]ペットボトル!$N$43 +[12]ペットボトル!$S$43 -> 0 | M29: =SUM(K29:L29) -> 0 | N29: =[12]ペットボトル!$O$43 +[12]ペットボトル!$T$43 -> 0 | O29: =[12]ペットボトル!$P$43 +[12]ペットボトル!$U$43 -> 0 | P29: =SUM(N29:O29) -> 0 | Q29: =ROUND(M29+P29,1) -> 0
A31: 合計 | J31: 合計
B32: =SUM(B7+B9+B11+B13+B15+B17+B19+B21+B23+B25+B27+B29) -> 0 | C32: =SUM(C7+C9+C11+C13+C15+C17+C19+C21+C23+C25+C27+C29) -> 0 | D32: =SUM(D7+D9+D11+D13+D15+D17+D19+D21+D23+D25+D27+D29) -> 0 | E32: =SUM(E7+E9+E11+E13+E15+E17+E19+E21+E23+E25+E27+E29) -> 0 | F32: =SUM(F7+F9+F11+F13+F15+F17+F19+F21+F23+F25+F27+F29) -> 0 | G32: =SUM(G7+G9+G11+G13+G15+G17+G19+G21+G23+G25+G27+G29) -> 0 | H32: =SUM(H6:H29) -> 0 | K32: =SUM(K7+K9+K11+K13+K15+K17+K19+K21+K23+K25+K27+K29) -> 0 | L32: =SUM(L7+L9+L11+L13+L15+L17+L19+L21+L23+L25+L27+L29) -> 0 | M32: =SUM(M7+M9+M11+M13+M15+M17+M19+M21+M23+M25+M27+M29) -> 0 | N32: =SUM(N7+N9+N11+N13+N15+N17+N19+N21+N23+N25+N27+N29) -> 0 | O32: =SUM(O7+O9+O11+O13+O15+O17+O19+O21+O23+O25+O27+O29) -> 0 | P32: =SUM(P7+P9+P11+P13+P15+P17+P19+P21+P23+P25+P27+P29) -> 0 | Q32: =SUM(Q6:Q29) -> 0

Sheet 1-6
A1: ="令和"&'[1]A-1'!$E$9-2018&"年度 一般廃棄物（ごみ）収集地区別集計表 【第1－6表】" -> 令和9年度 一般廃棄物（ごみ）収集地区別集計表 【第1－6表】
B3: 【収集紙類】 | K3: 【直搬紙類】 | Q3: 単位：トン
A5: 月別 | B5: 鬼 脇 | C5: 鴛 泊 | D5: 利尻富士計 | E5: 仙法志 | F5: 沓 形 | G5: 利尻計 | H5: 合 計 | J5: 月別 | K5: 鬼 脇 | L5: 鴛 泊 | M5: 利尻富士計 | N5: 仙法志 | O5: 沓 形 | P5: 利尻計 | Q5: 合 計
A6: 4 | J6: 4
B7: ='[1]収集（全般）'!$AA$44 -> 0 | C7: ='[1]収集（全般）'!$AB$44 -> 0 | D7: =SUM(B7:C7) -> 0 | E7: ='[1]収集（全般）'!$AC$44 -> 0 | F7: ='[1]収集（全般）'!$AD$44 -> 0 | G7: =SUM(E7:F7) -> 0 | H7: =ROUND(D7+G7,1) -> 0 | K7: =[1]紙類!$R$43 -> 0 | L7: =[1]紙類!$S$43 -> 0 | M7: =SUM(K7:L7) -> 0 | N7: =[1]紙類!$T$43 -> 0 | O7: =[1]紙類!$U$43 -> 0 | P7: =SUM(N7:O7) -> 0 | Q7: =ROUND(M7+P7,1) -> 0
A8: 5 | J8: 5
B9: ='[2]収集（全般）'!$AA$44 -> 0 | C9: ='[2]収集（全般）'!$AB$44 -> 0 | D9: =SUM(B9:C9) -> 0 | E9: ='[2]収集（全般）'!$AC$44 -> 0 | F9: ='[2]収集（全般）'!$AD$44 -> 0 | G9: =SUM(E9:F9) -> 0 | H9: =ROUND(D9+G9,1) -> 0 | K9: =[2]紙類!$R$43 -> 0 | L9: =[2]紙類!$S$43 -> 0 | M9: =SUM(K9:L9) -> 0 | N9: =[2]紙類!$T$43 -> 0 | O9: =[2]紙類!$U$43 -> 0 | P9: =SUM(N9:O9) -> 0 | Q9: =ROUND(M9+P9,1) -> 0
A10: 6 | J10: 6
B11: ='[3]収集（全般）'!$AA$44 -> 0 | C11: ='[3]収集（全般）'!$AB$44 -> 0 | D11: =SUM(B11:C11) -> 0 | E11: ='[3]収集（全般）'!$AC$44 -> 0 | F11: ='[3]収集（全般）'!$AD$44 -> 0 | G11: =SUM(E11:F11) -> 0 | H11: =ROUND(D11+G11,1) -> 0 | K11: =[3]紙類!$R$43 -> 0 | L11: =[3]紙類!$S$43 -> 0 | M11: =SUM(K11:L11) -> 0 | N11: =[3]紙類!$T$43 -> 0 | O11: =[3]紙類!$U$43 -> 0 | P11: =SUM(N11:O11) -> 0 | Q11: =ROUND(M11+P11,1) -> 0
A12: 7 | J12: 7
B13: ='[4]収集（全般）'!$AA$44 -> 0 | C13: ='[4]収集（全般）'!$AB$44 -> 0 | D13: =SUM(B13:C13) -> 0 | E13: ='[4]収集（全般）'!$AC$44 -> 0 | F13: ='[4]収集（全般）'!$AD$44 -> 0 | G13: =SUM(E13:F13) -> 0 | H13: =ROUND(D13+G13,1) -> 0 | K13: =[4]紙類!$R$43 -> 0 | L13: =[4]紙類!$S$43 -> 0 | M13: =SUM(K13:L13) -> 0 | N13: =[4]紙類!$T$43 -> 0 | O13: =[4]紙類!$U$43 -> 0 | P13: =SUM(N13:O13) -> 0 | Q13: =ROUND(M13+P13,1) -> 0
A14: 8 | J14: 8
B15: ='[5]収集（全般）'!$AA$44 -> 0 | C15: ='[5]収集（全般）'!$AB$44 -> 0 | D15: =SUM(B15:C15) -> 0 | E15: ='[5]収集（全般）'!$AC$44 -> 0 | F15: ='[5]収集（全般）'!$AD$44 -> 0 | G15: =SUM(E15:F15) -> 0 | H15: =ROUND(D15+G15,1) -> 0 | K15: =[5]紙類!$R$43 -> 0 | L15: =[5]紙類!$S$43 -> 0 | M15: =SUM(K15:L15) -> 0 | N15: =[5]紙類!$T$43 -> 0 | O15: =[5]紙類!$U$43 -> 0 | P15: =SUM(N15:O15) -> 0 | Q15: =ROUND(M15+P15,1) -> 0
A16: 9 | J16: 9
B17: ='[6]収集（全般）'!$AA$44 -> 0 | C17: ='[6]収集（全般）'!$AB$44 -> 0 | D17: =SUM(B17:C17) -> 0 | E17: ='[6]収集（全般）'!$AC$44 -> 0 | F17: ='[6]収集（全般）'!$AD$44 -> 0 | G17: =SUM(E17:F17) -> 0 | H17: =ROUND(D17+G17,1) -> 0 | K17: =[6]紙類!$R$43 -> 0 | L17: =[6]紙類!$S$43 -> 0 | M17: =SUM(K17:L17) -> 0 | N17: =[6]紙類!$T$43 -> 0 | O17: =[6]紙類!$U$43 -> 0 | P17: =SUM(N17:O17) -> 0 | Q17: =ROUND(M17+P17,1) -> 0
A18: 10 | J18: 10
B19: ='[7]収集（全般）'!$AA$44 -> 0 | C19: ='[7]収集（全般）'!$AB$44 -> 0 | D19: =SUM(B19:C19) -> 0 | E19: ='[7]収集（全般）'!$AC$44 -> 0 | F19: ='[7]収集（全般）'!$AD$44 -> 0 | G19: =SUM(E19:F19) -> 0 | H19: =ROUND(D19+G19,1) -> 0 | K19: =[7]紙類!$R$43 -> 0 | L19: =[7]紙類!$S$43 -> 0 | M19: =SUM(K19:L19) -> 0 | N19: =[7]紙類!$T$43 -> 0 | O19: =[7]紙類!$U$43 -> 0 | P19: =SUM(N19:O19) -> 0 | Q19: =ROUND(M19+P19,1) -> 0
A20: 11 | J20: 11
B21: ='[8]収集（全般）'!$AA$44 -> 0 | C21: ='[8]収集（全般）'!$AB$44 -> 0 | D21: =SUM(B21:C21) -> 0 | E21: ='[8]収集（全般）'!$AC$44 -> 0 | F21: ='[8]収集（全般）'!$AD$44 -> 0 | G21: =SUM(E21:F21) -> 0 | H21: =ROUND(D21+G21,1) -> 0 | K21: =[8]紙類!$R$43 -> 0 | L21: =[8]紙類!$S$43 -> 0 | M21: =SUM(K21:L21) -> 0 | N21: =[8]紙類!$T$43 -> 0 | O21: =[8]紙類!$U$43 -> 0 | P21: =SUM(N21:O21) -> 0 | Q21: =ROUND(M21+P21,1) -> 0
A22: 12 | J22: 12
B23: ='[9]収集（全般）'!$AA$44 -> 0 | C23: ='[9]収集（全般）'!$AB$44 -> 0 | D23: =SUM(B23:C23) -> 0 | E23: ='[9]収集（全般）'!$AC$44 -> 0 | F23: ='[9]収集（全般）'!$AD$44 -> 0 | G23: =SUM(E23:F23) -> 0 | H23: =ROUND(D23+G23,1) -> 0 | K23: =[9]紙類!$R$43 -> 0 | L23: =[9]紙類!$S$43 -> 0 | M23: =SUM(K23:L23) -> 0 | N23: =[9]紙類!$T$43 -> 0 | O23: =[9]紙類!$U$43 -> 0 | P23: =SUM(N23:O23) -> 0 | Q23: =ROUND(M23+P23,1) -> 0
A24: 1 | J24: 1
B25: ='[10]収集（全般）'!$AA$44 -> 0 | C25: ='[10]収集（全般）'!$AB$44 -> 0 | D25: =SUM(B25:C25) -> 0 | E25: ='[10]収集（全般）'!$AC$44 -> 0 | F25: ='[10]収集（全般）'!$AD$44 -> 0 | G25: =SUM(E25:F25) -> 0 | H25: =ROUND(D25+G25,1) -> 0 | K25: =[10]紙類!$R$43 -> 0 | L25: =[10]紙類!$S$43 -> 0 | M25: =SUM(K25:L25) -> 0 | N25: =[10]紙類!$T$43 -> 0 | O25: =[10]紙類!$U$43 -> 0 | P25: =SUM(N25:O25) -> 0 | Q25: =ROUND(M25+P25,1) -> 0
A26: 2 | J26: 2
B27: ='[11]収集（全般）'!$AA$44 -> 0 | C27: ='[11]収集（全般）'!$AB$44 -> 0 | D27: =SUM(B27:C27) -> 0 | E27: ='[11]収集（全般）'!$AC$44 -> 0 | F27: ='[11]収集（全般）'!$AD$44 -> 0 | G27: =SUM(E27:F27) -> 0 | H27: =ROUND(D27+G27,1) -> 0 | K27: =[11]紙類!$R$43 -> 0 | L27: =[11]紙類!$S$43 -> 0 | M27: =SUM(K27:L27) -> 0 | N27: =[11]紙類!$T$43 -> 0 | O27: =[11]紙類!$U$43 -> 0 | P27: =SUM(N27:O27) -> 0 | Q27: =ROUND(M27+P27,1) -> 0
A28: 3 | J28: 3
B29: ='[12]収集（全般）'!$AA$44 -> 0 | C29: ='[12]収集（全般）'!$AB$44 -> 0 | D29: =SUM(B29:C29) -> 0 | E29: ='[12]収集（全般）'!$AC$44 -> 0 | F29: ='[12]収集（全般）'!$AD$44 -> 0 | G29: =SUM(E29:F29) -> 0 | H29: =ROUND(D29+G29,1) -> 0 | K29: =[12]紙類!$R$43 -> 0 | L29: =[12]紙類!$S$43 -> 0 | M29: =SUM(K29:L29) -> 0 | N29: =[12]紙類!$T$43 -> 0 | O29: =[12]紙類!$U$43 -> 0 | P29: =SUM(N29:O29) -> 0 | Q29: =ROUND(M29+P29,1) -> 0
A31: 合計 | J31: 合計
B32: =SUM(B7+B9+B11+B13+B15+B17+B19+B21+B23+B25+B27+B29) -> 0 | C32: =SUM(C7+C9+C11+C13+C15+C17+C19+C21+C23+C25+C27+C29) -> 0 | D32: =SUM(D7+D9+D11+D13+D15+D17+D19+D21+D23+D25+D27+D29) -> 0 | E32: =SUM(E7+E9+E11+E13+E15+E17+E19+E21+E23+E25+E27+E29) -> 0 | F32: =SUM(F7+F9+F11+F13+F15+F17+F19+F21+F23+F25+F27+F29) -> 0 | G32: =SUM(G7+G9+G11+G13+G15+G17+G19+G21+G23+G25+G27+G29) -> 0 | H32: =SUM(H6:H29) -> 0 | K32: =SUM(K7+K9+K11+K13+K15+K17+K19+K21+K23+K25+K27+K29) -> 0 | L32: =SUM(L7+L9+L11+L13+L15+L17+L19+L21+L23+L25+L27+L29) -> 0 | M32: =SUM(M7+M9+M11+M13+M15+M17+M19+M21+M23+M25+M27+M29) -> 0 | N32: =SUM(N7+N9+N11+N13+N15+N17+N19+N21+N23+N25+N27+N29) -> 0 | O32: =SUM(O7+O9+O11+O13+O15+O17+O19+O21+O23+O25+O27+O29) -> 0 | P32: =SUM(P7+P9+P11+P13+P15+P17+P19+P21+P23+P25+P27+P29) -> 0 | Q32: =SUM(Q6:Q29) -> 0

Sheet 1-7
A1: ="令和"&'[1]A-1'!$E$9-2018&"年度 一般廃棄物（ごみ）収集地区別集計表 【第1－7表】" -> 令和9年度 一般廃棄物（ごみ）収集地区別集計表 【第1－7表】
B3: 【収集粗大ごみ】 | K3: 【直搬粗大ごみ】 | Q3: 単位：トン
A5: 月別 | B5: 鬼 脇 | C5: 鴛 泊 | D5: 利尻富士計 | E5: 仙法志 | F5: 沓 形 | G5: 利尻計 | H5: 合 計 | J5: 月別 | K5: 鬼 脇 | L5: 鴛 泊 | M5: 利尻富士計 | N5: 仙法志 | O5: 沓 形 | P5: 利尻計 | Q5: 合 計
A6: 4 | J6: 4
B7: =[1]粗大!$B$43 -> 0 | C7: =[1]粗大!$C$43 -> 0 | D7: =SUM(B7:C7) -> 0 | E7: =[1]粗大!$D$43 -> 0 | F7: =[1]粗大!$E$43 -> 0 | G7: =SUM(E7:F7) -> 0 | H7: =ROUND(D7+G7,1) -> 0 | K7: =[1]粗大!$Q$43 +[1]粗大!$V$43 -> 0 | L7: =[1]粗大!$R$43 +[1]粗大!$W$43 -> 0 | M7: =SUM(K7:L7) -> 0 | N7: =[1]粗大!$S$43 +[1]粗大!$X$43 -> 0 | O7: =[1]粗大!$T$43 +[1]粗大!$Y$43 -> 0 | P7: =SUM(N7:O7) -> 0 | Q7: =[1]粗大!$U$43 +[1]粗大!$Z$43 -> 0
A8: 5 | J8: 5
B9: =[2]粗大!$B$43 -> 0 | C9: =[2]粗大!$C$43 -> 0 | D9: =SUM(B9:C9) -> 0 | E9: =[2]粗大!$D$43 -> 0 | F9: =[2]粗大!$E$43 -> 0 | G9: =SUM(E9:F9) -> 0 | H9: =ROUND(D9+G9,1) -> 0 | K9: =[2]粗大!$Q$43 +[2]粗大!$V$43 -> 0 | L9: =[2]粗大!$R$43 +[2]粗大!$W$43 -> 0 | M9: =SUM(K9:L9) -> 0 | N9: =[2]粗大!$S$43 +[2]粗大!$X$43 -> 0 | O9: =[2]粗大!$T$43 +[2]粗大!$Y$43 -> 0 | P9: =SUM(N9:O9) -> 0 | Q9: =[2]粗大!$U$43 +[2]粗大!$Z$43 -> 0
A10: 6 | J10: 6
B11: =[3]粗大!$B$43 -> 0 | C11: =[3]粗大!$C$43 -> 0 | D11: =SUM(B11:C11) -> 0 | E11: =[3]粗大!$D$43 -> 0 | F11: =[3]粗大!$E$43 -> 0 | G11: =SUM(E11:F11) -> 0 | H11: =ROUND(D11+G11,1) -> 0 | K11: =[3]粗大!$Q$43 +[3]粗大!$V$43 -> 0 | L11: =[3]粗大!$R$43 +[3]粗大!$W$43 -> 0 | M11: =SUM(K11:L11) -> 0 | N11: =[3]粗大!$S$43 +[3]粗大!$X$43 -> 0 | O11: =[3]粗大!$T$43 +[3]粗大!$Y$43 -> 0 | P11: =SUM(N11:O11) -> 0 | Q11: =[3]粗大!$U$43 +[3]粗大!$Z$43 -> 0
A12: 7 | J12: 7
B13: =[4]粗大!$B$43 -> 0 | C13: =[4]粗大!$C$43 -> 0 | D13: =SUM(B13:C13) -> 0 | E13: =[4]粗大!$D$43 -> 0 | F13: =[4]粗大!$E$43 -> 0 | G13: =SUM(E13:F13) -> 0 | H13: =ROUND(D13+G13,1) -> 0 | K13: =[4]粗大!$Q$43 +[4]粗大!$V$43 -> 0 | L13: =[4]粗大!$R$43 +[4]粗大!$W$43 -> 0 | M13: =SUM(K13:L13) -> 0 | N13: =[4]粗大!$S$43 +[4]粗大!$X$43 -> 0 | O13: =[4]粗大!$T$43 +[4]粗大!$Y$43 -> 0 | P13: =SUM(N13:O13) -> 0 | Q13: =[4]粗大!$U$43 +[4]粗大!$Z$43 -> 0
A14: 8 | J14: 8
B15: =[5]粗大!$B$43 -> 0 | C15: =[5]粗大!$C$43 -> 0 | D15: =SUM(B15:C15) -> 0 | E15: =[5]粗大!$D$43 -> 0 | F15: =[5]粗大!$E$43 -> 0 | G15: =SUM(E15:F15) -> 0 | H15: =ROUND(D15+G15,1) -> 0 | K15: =[5]粗大!$Q$43 +[5]粗大!$V$43 -> 0 | L15: =[5]粗大!$R$43 +[5]粗大!$W$43 -> 0 | M15: =SUM(K15:L15) -> 0 | N15: =[5]粗大!$S$43 +[5]粗大!$X$43 -> 0 | O15: =[5]粗大!$T$43 +[5]粗大!$Y$43 -> 0 | P15: =SUM(N15:O15) -> 0 | Q15: =[5]粗大!$U$43 +[5]粗大!$Z$43 -> 0
A16: 9 | J16: 9
B17: =[6]粗大!$B$43 -> 0 | C17: =[6]粗大!$C$43 -> 0 | D17: =SUM(B17:C17) -> 0 | E17: =[6]粗大!$D$43 -> 0 | F17: =[6]粗大!$E$43 -> 0 | G17: =SUM(E17:F17) -> 0 | H17: =ROUND(D17+G17,1) -> 0 | K17: =[6]粗大!$Q$43 +[6]粗大!$V$43 -> 0 | L17: =[6]粗大!$R$43 +[6]粗大!$W$43 -> 0 | M17: =SUM(K17:L17) -> 0 | N17: =[6]粗大!$S$43 +[6]粗大!$X$43 -> 0 | O17: =[6]粗大!$T$43 +[6]粗大!$Y$43 -> 0 | P17: =SUM(N17:O17) -> 0 | Q17: =[6]粗大!$U$43 +[6]粗大!$Z$43 -> 0
A18: 10 | J18: 10
B19: =[7]粗大!$B$43 -> 0 | C19: =[7]粗大!$C$43 -> 0 | D19: =SUM(B19:C19) -> 0 | E19: =[7]粗大!$D$43 -> 0 | F19: =[7]粗大!$E$43 -> 0 | G19: =SUM(E19:F19) -> 0 | H19: =ROUND(D19+G19,1) -> 0 | K19: =[7]粗大!$Q$43 +[7]粗大!$V$43 -> 0 | L19: =[7]粗大!$R$43 +[7]粗大!$W$43 -> 0 | M19: =SUM(K19:L19) -> 0 | N19: =[7]粗大!$S$43 +[7]粗大!$X$43 -> 0 | O19: =[7]粗大!$T$43 +[7]粗大!$Y$43 -> 0 | P19: =SUM(N19:O19) -> 0 | Q19: =[7]粗大!$U$43 +[7]粗大!$Z$43 -> 0
A20: 11 | J20: 11
B21: =[8]粗大!$B$43 -> 0 | C21: =[8]粗大!$C$43 -> 0 | D21: =SUM(B21:C21) -> 0 | E21: =[8]粗大!$D$43 -> 0 | F21: =[8]粗大!$E$43 -> 0 | G21: =SUM(E21:F21) -> 0 | H21: =ROUND(D21+G21,1) -> 0 | K21: =[8]粗大!$Q$43 +[8]粗大!$V$43 -> 0 | L21: =[8]粗大!$R$43 +[8]粗大!$W$43 -> 0 | M21: =SUM(K21:L21) -> 0 | N21: =[8]粗大!$S$43 +[8]粗大!$X$43 -> 0 | O21: =[8]粗大!$T$43 +[8]粗大!$Y$43 -> 0 | P21: =SUM(N21:O21) -> 0 | Q21: =[8]粗大!$U$43 +[8]粗大!$Z$43 -> 0
A22: 12 | J22: 12
B23: =[9]粗大!$B$43 -> 0 | C23: =[9]粗大!$C$43 -> 0 | D23: =SUM(B23:C23) -> 0 | E23: =[9]粗大!$D$43 -> 0 | F23: =[9]粗大!$E$43 -> 0 | G23: =SUM(E23:F23) -> 0 | H23: =ROUND(D23+G23,1) -> 0 | K23: =[9]粗大!$Q$43 +[9]粗大!$V$43 -> 0 | L23: =[9]粗大!$R$43 +[9]粗大!$W$43 -> 0 | M23: =SUM(K23:L23) -> 0 | N23: =[9]粗大!$S$43 +[9]粗大!$X$43 -> 0 | O23: =[9]粗大!$T$43 +[9]粗大!$Y$43 -> 0 | P23: =SUM(N23:O23) -> 0 | Q23: =[9]粗大!$U$43 +[9]粗大!$Z$43 -> 0
A24: 1 | J24: 1
B25: =[10]粗大!$B$43 -> 0 | C25: =[10]粗大!$C$43 -> 0 | D25: =SUM(B25:C25) -> 0 | E25: =[10]粗大!$D$43 -> 0 | F25: =[10]粗大!$E$43 -> 0 | G25: =SUM(E25:F25) -> 0 | H25: =ROUND(D25+G25,1) -> 0 | K25: =[10]粗大!$Q$43 +[10]粗大!$V$43 -> 0 | L25: =[10]粗大!$R$43 +[10]粗大!$W$43 -> 0 | M25: =SUM(K25:L25) -> 0 | N25: =[10]粗大!$S$43 +[10]粗大!$X$43 -> 0 | O25: =[10]粗大!$T$43 +[10]粗大!$Y$43 -> 0 | P25: =SUM(N25:O25) -> 0 | Q25: =[10]粗大!$U$43 +[10]粗大!$Z$43 -> 0
A26: 2 | J26: 2
B27: =[11]粗大!$B$43 -> 0 | C27: =[11]粗大!$C$43 -> 0 | D27: =SUM(B27:C27) -> 0 | E27: =[11]粗大!$D$43 -> 0 | F27: =[11]粗大!$E$43 -> 0 | G27: =SUM(E27:F27) -> 0 | H27: =ROUND(D27+G27,1) -> 0 | K27: =[11]粗大!$Q$43 +[11]粗大!$V$43 -> 0 | L27: =[11]粗大!$R$43 +[11]粗大!$W$43 -> 0 | M27: =SUM(K27:L27) -> 0 | N27: =[11]粗大!$S$43 +[11]粗大!$X$43 -> 0 | O27: =[11]粗大!$T$43 +[11]粗大!$Y$43 -> 0 | P27: =SUM(N27:O27) -> 0 | Q27: =[11]粗大!$U$43 +[11]粗大!$Z$43 -> 0
A28: 3 | J28: 3
B29: =[12]粗大!$B$43 -> 0 | C29: =[12]粗大!$C$43 -> 0 | D29: =SUM(B29:C29) -> 0 | E29: =[12]粗大!$D$43 -> 0 | F29: =[12]粗大!$E$43 -> 0 | G29: =SUM(E29:F29) -> 0 | H29: =ROUND(D29+G29,1) -> 0 | K29: =[12]粗大!$Q$43 +[12]粗大!$V$43 -> 0 | L29: =[12]粗大!$R$43 +[12]粗大!$W$43 -> 0 | M29: =SUM(K29:L29) -> 0 | N29: =[12]粗大!$S$43 +[12]粗大!$X$43 -> 0 | O29: =[12]粗大!$T$43 +[12]粗大!$Y$43 -> 0 | P29: =SUM(N29:O29) -> 0 | Q29: =[12]粗大!$U$43 +[12]粗大!$Z$43 -> 0
A31: 合計 | J31: 合計
B32: =SUM(B7+B9+B11+B13+B15+B17+B19+B21+B23+B25+B27+B29) -> 0 | C32: =SUM(C7+C9+C11+C13+C15+C17+C19+C21+C23+C25+C27+C29) -> 0 | D32: =SUM(D7+D9+D11+D13+D15+D17+D19+D21+D23+D25+D27+D29) -> 0 | E32: =SUM(E7+E9+E11+E13+E15+E17+E19+E21+E23+E25+E27+E29) -> 0 | F32: =SUM(F7+F9+F11+F13+F15+F17+F19+F21+F23+F25+F27+F29) -> 0 | G32: =SUM(G7+G9+G11+G13+G15+G17+G19+G21+G23+G25+G27+G29) -> 0 | H32: =SUM(H6:H29) -> 0 | K32: =SUM(K7+K9+K11+K13+K15+K17+K19+K21+K23+K25+K27+K29) -> 0 | L32: =SUM(L7+L9+L11+L13+L15+L17+L19+L21+L23+L25+L27+L29) -> 0 | M32: =SUM(M7+M9+M11+M13+M15+M17+M19+M21+M23+M25+M27+M29) -> 0 | N32: =SUM(N7+N9+N11+N13+N15+N17+N19+N21+N23+N25+N27+N29) -> 0 | O32: =SUM(O7+O9+O11+O13+O15+O17+O19+O21+O23+O25+O27+O29) -> 0 | P32: =SUM(P7+P9+P11+P13+P15+P17+P19+P21+P23+P25+P27+P29) -> 0 | Q32: =SUM(Q6:Q29) -> 0

Sheet 2-1
A1: ="令和"&'[1]A-1'!$E$9-2018&"年度 一般産業廃棄物(焼却)処理地区別集計表 【第2－1表】" -> 令和9年度 一般産業廃棄物(焼却)処理地区別集計表 【第2－1表】
B3: 【収集可燃ごみ】 | K3: 【直搬可燃ごみ】 | Q3: 単位：トン
A5: 月別 | B5: 鬼 脇 | C5: 鴛 泊 | D5: 利尻富士計 | E5: 仙法志 | F5: 沓 形 | G5: 利尻計 | H5: 合 計 | J5: 月別 | K5: 鬼 脇 | L5: 鴛 泊 | M5: 利尻富士計 | N5: 仙法志 | O5: 沓 形 | P5: 利尻計 | Q5: 合 計
A6: 4 | J6: 4
B7: =[1]可燃!$B$43 -> 0 | C7: =[1]可燃!$C$43 -> 0 | D7: =SUM(B7:C7) -> 0 | E7: =[1]可燃!$D$43 -> 0 | F7: =[1]可燃!$E$43 -> 0 | G7: =SUM(E7:F7) -> 0 | H7: =ROUND(D7+G7,1) -> 0 | K7: =[1]可燃!$M$43 -> 0 | L7: =[1]可燃!$N$43 -> 0 | M7: =SUM(K7:L7) -> 0 | N7: =[1]可燃!$O$43 -> 0 | O7: =[1]可燃!$P$43 -> 0 | P7: =SUM(N7:O7) -> 0 | Q7: =ROUND(M7+P7,1) -> 0
A8: 5 | J8: 5
B9: =[2]可燃!$B$43 -> 0 | C9: =[2]可燃!$C$43 -> 0 | D9: =SUM(B9:C9) -> 0 | E9: =[2]可燃!$D$43 -> 0 | F9: =[2]可燃!$E$43 -> 0 | G9: =SUM(E9:F9) -> 0 | H9: =ROUND(D9+G9,1) -> 0 | K9: =[2]可燃!$M$43 -> 0 | L9: =[2]可燃!$N$43 -> 0 | M9: =SUM(K9:L9) -> 0 | N9: =[2]可燃!$O$43 -> 0 | O9: =[2]可燃!$P$43 -> 0 | P9: =SUM(N9:O9) -> 0 | Q9: =ROUND(M9+P9,1) -> 0
A10: 6 | J10: 6
B11: =[3]可燃!$B$43 -> 0 | C11: =[3]可燃!$C$43 -> 0 | D11: =SUM(B11:C11) -> 0 | E11: =[3]可燃!$D$43 -> 0 | F11: =[3]可燃!$E$43 -> 0 | G11: =SUM(E11:F11) -> 0 | H11: =ROUND(D11+G11,1) -> 0 | K11: =[3]可燃!$M$43 -> 0 | L11: =[3]可燃!$N$43 -> 0 | M11: =SUM(K11:L11) -> 0 | N11: =[3]可燃!$O$43 -> 0 | O11: =[3]可燃!$P$43 -> 0 | P11: =SUM(N11:O11) -> 0 | Q11: =ROUND(M11+P11,1) -> 0
A12: 7 | J12: 7
B13: =[4]可燃!$B$43 -> 0 | C13: =[4]可燃!$C$43 -> 0 | D13: =SUM(B13:C13) -> 0 | E13: =[4]可燃!$D$43 -> 0 | F13: =[4]可燃!$E$43 -> 0 | G13: =SUM(E13:F13) -> 0 | H13: =ROUND(D13+G13,1) -> 0 | K13: =[4]可燃!$M$43 -> 0 | L13: =[4]可燃!$N$43 -> 0 | M13: =SUM(K13:L13) -> 0 | N13: =[4]可燃!$O$43 -> 0 | O13: =[4]可燃!$P$43 -> 0 | P13: =SUM(N13:O13) -> 0 | Q13: =ROUND(M13+P13,1) -> 0
A14: 8 | J14: 8
B15: =[5]可燃!$B$43 -> 0 | C15: =[5]可燃!$C$43 -> 0 | D15: =SUM(B15:C15) -> 0 | E15: =[5]可燃!$D$43 -> 0 | F15: =[5]可燃!$E$43 -> 0 | G15: =SUM(E15:F15) -> 0 | H15: =ROUND(D15+G15,1) -> 0 | K15: =[5]可燃!$M$43 -> 0 | L15: =[5]可燃!$N$43 -> 0 | M15: =SUM(K15:L15) -> 0 | N15: =[5]可燃!$O$43 -> 0 | O15: =[5]可燃!$P$43 -> 0 | P15: =SUM(N15:O15) -> 0 | Q15: =ROUND(M15+P15,1) -> 0
A16: 9 | J16: 9
B17: =[6]可燃!$B$43 -> 0 | C17: =[6]可燃!$C$43 -> 0 | D17: =SUM(B17:C17) -> 0 | E17: =[6]可燃!$D$43 -> 0 | F17: =[6]可燃!$E$43 -> 0 | G17: =SUM(E17:F17) -> 0 | H17: =ROUND(D17+G17,1) -> 0 | K17: =[6]可燃!$M$43 -> 0 | L17: =[6]可燃!$N$43 -> 0 | M17: =SUM(K17:L17) -> 0 | N17: =[6]可燃!$O$43 -> 0 | O17: =[6]可燃!$P$43 -> 0 | P17: =SUM(N17:O17) -> 0 | Q17: =ROUND(M17+P17,1) -> 0
A18: 10 | J18: 10
B19: =[7]可燃!$B$43 -> 0 | C19: =[7]可燃!$C$43 -> 0 | D19: =SUM(B19:C19) -> 0 | E19: =[7]可燃!$D$43 -> 0 | F19: =[7]可燃!$E$43 -> 0 | G19: =SUM(E19:F19) -> 0 | H19: =ROUND(D19+G19,1) -> 0 | K19: =[7]可燃!$M$43 -> 0 | L19: =[7]可燃!$N$43 -> 0 | M19: =SUM(K19:L19) -> 0 | N19: =[7]可燃!$O$43 -> 0 | O19: =[7]可燃!$P$43 -> 0 | P19: =SUM(N19:O19) -> 0 | Q19: =ROUND(M19+P19,1) -> 0
A20: 11 | J20: 11
B21: =[8]可燃!$B$43 -> 0 | C21: =[8]可燃!$C$43 -> 0 | D21: =SUM(B21:C21) -> 0 | E21: =[8]可燃!$D$43 -> 0 | F21: =[8]可燃!$E$43 -> 0 | G21: =SUM(E21:F21) -> 0 | H21: =ROUND(D21+G21,1) -> 0 | K21: =[8]可燃!$M$43 -> 0 | L21: =[8]可燃!$N$43 -> 0 | M21: =SUM(K21:L21) -> 0 | N21: =[8]可燃!$O$43 -> 0 | O21: =[8]可燃!$P$43 -> 0 | P21: =SUM(N21:O21) -> 0 | Q21: =ROUND(M21+P21,1) -> 0
A22: 12 | J22: 12
B23: =[9]可燃!$B$43 -> 0 | C23: =[9]可燃!$C$43 -> 0 | D23: =SUM(B23:C23) -> 0 | E23: =[9]可燃!$D$43 -> 0 | F23: =[9]可燃!$E$43 -> 0 | G23: =SUM(E23:F23) -> 0 | H23: =ROUND(D23+G23,1) -> 0 | K23: =[9]可燃!$M$43 -> 0 | L23: =[9]可燃!$N$43 -> 0 | M23: =SUM(K23:L23) -> 0 | N23: =[9]可燃!$O$43 -> 0 | O23: =[9]可燃!$P$43 -> 0 | P23: =SUM(N23:O23) -> 0 | Q23: =ROUND(M23+P23,1) -> 0
A24: 1 | J24: 1
B25: =[10]可燃!$B$43 -> 0 | C25: =[10]可燃!$C$43 -> 0 | D25: =SUM(B25:C25) -> 0 | E25: =[10]可燃!$D$43 -> 0 | F25: =[10]可燃!$E$43 -> 0 | G25: =SUM(E25:F25) -> 0 | H25: =ROUND(D25+G25,1) -> 0 | K25: =[10]可燃!$M$43 -> 0 | L25: =[10]可燃!$N$43 -> 0 | M25: =SUM(K25:L25) -> 0 | N25: =[10]可燃!$O$43 -> 0 | O25: =[10]可燃!$P$43 -> 0 | P25: =SUM(N25:O25) -> 0 | Q25: =ROUND(M25+P25,1) -> 0
A26: 2 | J26: 2
B27: =[11]可燃!$B$43 -> 0 | C27: =[11]可燃!$C$43 -> 0 | D27: =SUM(B27:C27) -> 0 | E27: =[11]可燃!$D$43 -> 0 | F27: =[11]可燃!$E$43 -> 0 | G27: =SUM(E27:F27) -> 0 | H27: =ROUND(D27+G27,1) -> 0 | K27: =[11]可燃!$M$43 -> 0 | L27: =[11]可燃!$N$43 -> 0 | M27: =SUM(K27:L27) -> 0 | N27: =[11]可燃!$O$43 -> 0 | O27: =[11]可燃!$P$43 -> 0 | P27: =SUM(N27:O27) -> 0 | Q27: =ROUND(M27+P27,1) -> 0
A28: 3 | J28: 3
B29: =[12]可燃!$B$43 -> 0 | C29: =[12]可燃!$C$43 -> 0 | D29: =SUM(B29:C29) -> 0 | E29: =[12]可燃!$D$43 -> 0 | F29: =[12]可燃!$E$43 -> 0 | G29: =SUM(E29:F29) -> 0 | H29: =ROUND(D29+G29,1) -> 0 | K29: =[12]可燃!$M$43 -> 0 | L29: =[12]可燃!$N$43 -> 0 | M29: =SUM(K29:L29) -> 0 | N29: =[12]可燃!$O$43 -> 0 | O29: =[12]可燃!$P$43 -> 0 | P29: =SUM(N29:O29) -> 0 | Q29: =ROUND(M29+P29,1) -> 0
A31: 合計 | J31: 合計
B32: =SUM(B7+B9+B11+B13+B15+B17+B19+B21+B23+B25+B27+B29) -> 0 | C32: =SUM(C7+C9+C11+C13+C15+C17+C19+C21+C23+C25+C27+C29) -> 0 | D32: =SUM(D7+D9+D11+D13+D15+D17+D19+D21+D23+D25+D27+D29) -> 0 | E32: =SUM(E7+E9+E11+E13+E15+E17+E19+E21+E23+E25+E27+E29) -> 0 | F32: =SUM(F7+F9+F11+F13+F15+F17+F19+F21+F23+F25+F27+F29) -> 0 | G32: =SUM(G7+G9+G11+G13+G15+G17+G19+G21+G23+G25+G27+G29) -> 0 | H32: =SUM(H6:H29) -> 0 | K32: =SUM(K7+K9+K11+K13+K15+K17+K19+K21+K23+K25+K27+K29) -> 0 | L32: =SUM(L7+L9+L11+L13+L15+L17+L19+L21+L23+L25+L27+L29) -> 0 | M32: =SUM(M7+M9+M11+M13+M15+M17+M19+M21+M23+M25+M27+M29) -> 0 | N32: =SUM(N7+N9+N11+N13+N15+N17+N19+N21+N23+N25+N27+N29) -> 0 | O32: =SUM(O7+O9+O11+O13+O15+O17+O19+O21+O23+O25+O27+O29) -> 0 | P32: =SUM(P7+P9+P11+P13+P15+P17+P19+P21+P23+P25+P27+P29) -> 0 | Q32: =SUM(Q6:Q29) -> 0

Sheet 2-2
A1: ="令和"&'[1]A-1'!$E$9-2018&"年度 一般産業廃棄物(焼却)処理地区別集計表 【第2－2表】" -> 令和9年度 一般産業廃棄物(焼却)処理地区別集計表 【第2－2表】
B3: 【水産系産廃】 | K3: 【医療系産廃】 | Q3: 単位：トン
A5: 月別 | B5: 鬼 脇 | C5: 鴛 泊 | D5: 利尻富士計 | E5: 仙法志 | F5: 沓 形 | G5: 利尻計 | H5: 合 計 | J5: 月別 | K5: 鬼 脇 | L5: 鴛 泊 | M5: 利尻富士計 | N5: 仙法志 | O5: 沓 形 | P5: 利尻計 | Q5: 合 計
A6: 4 | J6: 4
B7: =[1]産廃水産・医療・汚泥!$B$43 -> 0 | C7: =[1]産廃水産・医療・汚泥!$C$43 -> 0 | D7: =SUM(B7:C7) -> 0 | E7: =[1]産廃水産・医療・汚泥!$D$43 -> 0 | F7: =[1]産廃水産・医療・汚泥!$E$43 -> 0 | G7: =SUM(E7:F7) -> 0 | H7: =ROUND(D7+G7,1) -> 0 | K7: =[1]産廃水産・医療・汚泥!$Q$43 -> 0 | L7: =[1]産廃水産・医療・汚泥!$R$43 -> 0 | M7: =SUM(K7:L7) -> 0 | N7: =[1]産廃水産・医療・汚泥!$S$43 -> 0 | O7: =[1]産廃水産・医療・汚泥!$T$43 -> 0 | P7: =SUM(N7:O7) -> 0 | Q7: =ROUND(M7+P7,1) -> 0
A8: 5 | J8: 5
B9: =[2]産廃水産・医療・汚泥!$B$43 -> 0 | C9: =[2]産廃水産・医療・汚泥!$C$43 -> 0 | D9: =SUM(B9:C9) -> 0 | E9: =[2]産廃水産・医療・汚泥!$D$43 -> 0 | F9: =[2]産廃水産・医療・汚泥!$E$43 -> 0 | G9: =SUM(E9:F9) -> 0 | H9: =ROUND(D9+G9,1) -> 0 | K9: =[2]産廃水産・医療・汚泥!$Q$43 -> 0 | L9: =[2]産廃水産・医療・汚泥!$R$43 -> 0 | M9: =SUM(K9:L9) -> 0 | N9: =[2]産廃水産・医療・汚泥!$S$43 -> 0 | O9: =[2]産廃水産・医療・汚泥!$T$43 -> 0 | P9: =SUM(N9:O9) -> 0 | Q9: =ROUND(M9+P9,1) -> 0
A10: 6 | J10: 6
B11: =[3]産廃水産・医療・汚泥!$B$43 -> 0 | C11: =[3]産廃水産・医療・汚泥!$C$43 -> 0 | D11: =SUM(B11:C11) -> 0 | E11: =[3]産廃水産・医療・汚泥!$D$43 -> 0 | F11: =[3]産廃水産・医療・汚泥!$E$43 -> 0 | G11: =SUM(E11:F11) -> 0 | H11: =ROUND(D11+G11,1) -> 0 | K11: =[3]産廃水産・医療・汚泥!$Q$43 -> 0 | L11: =[3]産廃水産・医療・汚泥!$R$43 -> 0 | M11: =SUM(K11:L11) -> 0 | N11: =[3]産廃水産・医療・汚泥!$S$43 -> 0 | O11: =[3]産廃水産・医療・汚泥!$T$43 -> 0 | P11: =SUM(N11:O11) -> 0 | Q11: =ROUND(M11+P11,1) -> 0
A12: 7 | J12: 7
B13: =[4]産廃水産・医療・汚泥!$B$43 -> 0 | C13: =[4]産廃水産・医療・汚泥!$C$43 -> 0 | D13: =SUM(B13:C13) -> 0 | E13: =[4]産廃水産・医療・汚泥!$D$43 -> 0 | F13: =[4]産廃水産・医療・汚泥!$E$43 -> 0 | G13: =SUM(E13:F13) -> 0 | H13: =ROUND(D13+G13,1) -> 0 | K13: =[4]産廃水産・医療・汚泥!$Q$43 -> 0 | L13: =[4]産廃水産・医療・汚泥!$R$43 -> 0 | M13: =SUM(K13:L13) -> 0 | N13: =[4]産廃水産・医療・汚泥!$S$43 -> 0 | O13: =[4]産廃水産・医療・汚泥!$T$43 -> 0 | P13: =SUM(N13:O13) -> 0 | Q13: =ROUND(M13+P13,1) -> 0
A14: 8 | J14: 8
B15: =[5]産廃水産・医療・汚泥!$B$43 -> 0 | C15: =[5]産廃水産・医療・汚泥!$C$43 -> 0 | D15: =SUM(B15:C15) -> 0 | E15: =[5]産廃水産・医療・汚泥!$D$43 -> 0 | F15: =[5]産廃水産・医療・汚泥!$E$43 -> 0 | G15: =SUM(E15:F15) -> 0 | H15: =ROUND(D15+G15,1) -> 0 | K15: =[5]産廃水産・医療・汚泥!$Q$43 -> 0 | L15: =[5]産廃水産・医療・汚泥!$R$43 -> 0 | M15: =SUM(K15:L15) -> 0 | N15: =[5]産廃水産・医療・汚泥!$S$43 -> 0 | O15: =[5]産廃水産・医療・汚泥!$T$43 -> 0 | P15: =SUM(N15:O15) -> 0 | Q15: =ROUND(M15+P15,1) -> 0
A16: 9 | J16: 9
B17: =[6]産廃水産・医療・汚泥!$B$43 -> 0 | C17: =[6]産廃水産・医療・汚泥!$C$43 -> 0 | D17: =SUM(B17:C17) -> 0 | E17: =[6]産廃水産・医療・汚泥!$D$43 -> 0 | F17: =[6]産廃水産・医療・汚泥!$E$43 -> 0 | G17: =SUM(E17:F17) -> 0 | H17: =ROUND(D17+G17,1) -> 0 | K17: =[6]産廃水産・医療・汚泥!$Q$43 -> 0 | L17: =[6]産廃水産・医療・汚泥!$R$43 -> 0 | M17: =SUM(K17:L17) -> 0 | N17: =[6]産廃水産・医療・汚泥!$S$43 -> 0 | O17: =[6]産廃水産・医療・汚泥!$T$43 -> 0 | P17: =SUM(N17:O17) -> 0 | Q17: =ROUND(M17+P17,1) -> 0
A18: 10 | J18: 10
B19: =[7]産廃水産・医療・汚泥!$B$43 -> 0 | C19: =[7]産廃水産・医療・汚泥!$C$43 -> 0 | D19: =SUM(B19:C19) -> 0 | E19: =[7]産廃水産・医療・汚泥!$D$43 -> 0 | F19: =[7]産廃水産・医療・汚泥!$E$43 -> 0 | G19: =SUM(E19:F19) -> 0 | H19: =ROUND(D19+G19,1) -> 0 | K19: =[7]産廃水産・医療・汚泥!$Q$43 -> 0 | L19: =[7]産廃水産・医療・汚泥!$R$43 -> 0 | M19: =SUM(K19:L19) -> 0 | N19: =[7]産廃水産・医療・汚泥!$S$43 -> 0 | O19: =[7]産廃水産・医療・汚泥!$T$43 -> 0 | P19: =SUM(N19:O19) -> 0 | Q19: =ROUND(M19+P19,1) -> 0
A20: 11 | J20: 11
B21: =[8]産廃水産・医療・汚泥!$B$43 -> 0 | C21: =[8]産廃水産・医療・汚泥!$C$43 -> 0 | D21: =SUM(B21:C21) -> 0 | E21: =[8]産廃水産・医療・汚泥!$D$43 -> 0 | F21: =[8]産廃水産・医療・汚泥!$E$43 -> 0 | G21: =SUM(E21:F21) -> 0 | H21: =ROUND(D21+G21,1) -> 0 | K21: =[8]産廃水産・医療・汚泥!$Q$43 -> 0 | L21: =[8]産廃水産・医療・汚泥!$R$43 -> 0 | M21: =SUM(K21:L21) -> 0 | N21: =[8]産廃水産・医療・汚泥!$S$43 -> 0 | O21: =[8]産廃水産・医療・汚泥!$T$43 -> 0 | P21: =SUM(N21:O21) -> 0 | Q21: =ROUND(M21+P21,1) -> 0
A22: 12 | J22: 12
B23: =[9]産廃水産・医療・汚泥!$B$43 -> 0 | C23: =[9]産廃水産・医療・汚泥!$C$43 -> 0 | D23: =SUM(B23:C23) -> 0 | E23: =[9]産廃水産・医療・汚泥!$D$43 -> 0 | F23: =[9]産廃水産・医療・汚泥!$E$43 -> 0 | G23: =SUM(E23:F23) -> 0 | H23: =ROUND(D23+G23,1) -> 0 | K23: =[9]産廃水産・医療・汚泥!$Q$43 -> 0 | L23: =[9]産廃水産・医療・汚泥!$R$43 -> 0 | M23: =SUM(K23:L23) -> 0 | N23: =[9]産廃水産・医療・汚泥!$S$43 -> 0 | O23: =[9]産廃水産・医療・汚泥!$T$43 -> 0 | P23: =SUM(N23:O23) -> 0 | Q23: =ROUND(M23+P23,1) -> 0
A24: 1 | J24: 1
B25: =[10]産廃水産・医療・汚泥!$B$43 -> 0 | C25: =[10]産廃水産・医療・汚泥!$C$43 -> 0 | D25: =SUM(B25:C25) -> 0 | E25: =[10]産廃水産・医療・汚泥!$D$43 -> 0 | F25: =[10]産廃水産・医療・汚泥!$E$43 -> 0 | G25: =SUM(E25:F25) -> 0 | H25: =ROUND(D25+G25,1) -> 0 | K25: =[10]産廃水産・医療・汚泥!$Q$43 -> 0 | L25: =[10]産廃水産・医療・汚泥!$R$43 -> 0 | M25: =SUM(K25:L25) -> 0 | N25: =[10]産廃水産・医療・汚泥!$S$43 -> 0 | O25: =[10]産廃水産・医療・汚泥!$T$43 -> 0 | P25: =SUM(N25:O25) -> 0 | Q25: =ROUND(M25+P25,1) -> 0
A26: 2 | J26: 2
B27: =[11]産廃水産・医療・汚泥!$B$43 -> 0 | C27: =[11]産廃水産・医療・汚泥!$C$43 -> 0 | D27: =SUM(B27:C27) -> 0 | E27: =[11]産廃水産・医療・汚泥!$D$43 -> 0 | F27: =[11]産廃水産・医療・汚泥!$E$43 -> 0 | G27: =SUM(E27:F27) -> 0 | H27: =ROUND(D27+G27,1) -> 0 | K27: =[11]産廃水産・医療・汚泥!$Q$43 -> 0 | L27: =[11]産廃水産・医療・汚泥!$R$43 -> 0 | M27: =SUM(K27:L27) -> 0 | N27: =[11]産廃水産・医療・汚泥!$S$43 -> 0 | O27: =[11]産廃水産・医療・汚泥!$T$43 -> 0 | P27: =SUM(N27:O27) -> 0 | Q27: =ROUND(M27+P27,1) -> 0
A28: 3 | J28: 3
B29: =[12]産廃水産・医療・汚泥!$B$43 -> 0 | C29: =[12]産廃水産・医療・汚泥!$C$43 -> 0 | D29: =SUM(B29:C29) -> 0 | E29: =[12]産廃水産・医療・汚泥!$D$43 -> 0 | F29: =[12]産廃水産・医療・汚泥!$E$43 -> 0 | G29: =SUM(E29:F29) -> 0 | H29: =ROUND(D29+G29,1) -> 0 | K29: =[12]産廃水産・医療・汚泥!$Q$43 -> 0 | L29: =[12]産廃水産・医療・汚泥!$R$43 -> 0 | M29: =SUM(K29:L29) -> 0 | N29: =[12]産廃水産・医療・汚泥!$S$43 -> 0 | O29: =[12]産廃水産・医療・汚泥!$T$43 -> 0 | P29: =SUM(N29:O29) -> 0 | Q29: =ROUND(M29+P29,1) -> 0
A31: 合計 | J31: 合計
B32: =SUM(B7+B9+B11+B13+B15+B17+B19+B21+B23+B25+B27+B29) -> 0 | C32: =SUM(C7+C9+C11+C13+C15+C17+C19+C21+C23+C25+C27+C29) -> 0 | D32: =SUM(D7+D9+D11+D13+D15+D17+D19+D21+D23+D25+D27+D29) -> 0 | E32: =SUM(E7+E9+E11+E13+E15+E17+E19+E21+E23+E25+E27+E29) -> 0 | F32: =SUM(F7+F9+F11+F13+F15+F17+F19+F21+F23+F25+F27+F29) -> 0 | G32: =SUM(G7+G9+G11+G13+G15+G17+G19+G21+G23+G25+G27+G29) -> 0 | H32: =SUM(H6:H29) -> 0 | K32: =SUM(K7+K9+K11+K13+K15+K17+K19+K21+K23+K25+K27+K29) -> 0 | L32: =SUM(L7+L9+L11+L13+L15+L17+L19+L21+L23+L25+L27+L29) -> 0 | M32: =SUM(M7+M9+M11+M13+M15+M17+M19+M21+M23+M25+M27+M29) -> 0 | N32: =SUM(N7+N9+N11+N13+N15+N17+N19+N21+N23+N25+N27+N29) -> 0 | O32: =SUM(O7+O9+O11+O13+O15+O17+O19+O21+O23+O25+O27+O29) -> 0 | P32: =SUM(P7+P9+P11+P13+P15+P17+P19+P21+P23+P25+P27+P29) -> 0 | Q32: =SUM(Q6:Q29) -> 0

Sheet 2-3
A1: ="令和"&'[1]A-1'!$E$9-2018&"年度 一般産業廃棄物(焼却)処理地区別集計表 【第2－3表】" -> 令和9年度 一般産業廃棄物(焼却)処理地区別集計表 【第2－3表】
B3: 【収集紙類】 | K3: 【直搬紙類】 | Q3: 単位：トン
A5: 月別 | B5: 鬼 脇 | C5: 鴛 泊 | D5: 利尻富士計 | E5: 仙法志 | F5: 沓 形 | G5: 利尻計 | H5: 合 計 | J5: 月別 | K5: 鬼 脇 | L5: 鴛 泊 | M5: 利尻富士計 | N5: 仙法志 | O5: 沓 形 | P5: 利尻計 | Q5: 合 計
A6: 4 | J6: 4
B7: =[1]紙類!$G$43 -> 0 | C7: =[1]紙類!$H$43 -> 0 | D7: =SUM(B7:C7) -> 0 | E7: =[1]紙類!$I$43 -> 0 | F7: =[1]紙類!$J$43 -> 0 | G7: =SUM(E7:F7) -> 0 | H7: =ROUND(D7+G7,1) -> 0 | K7: =[1]紙類!$R$43 -> 0 | L7: =[1]紙類!$S$43 -> 0 | M7: =SUM(K7:L7) -> 0 | N7: =[1]紙類!$T$43 -> 0 | O7: =[1]紙類!$U$43 -> 0 | P7: =SUM(N7:O7) -> 0 | Q7: =ROUND(M7+P7,1) -> 0
A8: 5 | J8: 5
B9: =[2]紙類!$G$43 -> 0 | C9: =[2]紙類!$H$43 -> 0 | D9: =SUM(B9:C9) -> 0 | E9: =[2]紙類!$I$43 -> 0 | F9: =[2]紙類!$J$43 -> 0 | G9: =SUM(E9:F9) -> 0 | H9: =ROUND(D9+G9,1) -> 0 | K9: =[2]紙類!$R$43 -> 0 | L9: =[2]紙類!$S$43 -> 0 | M9: =SUM(K9:L9) -> 0 | N9: =[2]紙類!$T$43 -> 0 | O9: =[2]紙類!$U$43 -> 0 | P9: =SUM(N9:O9) -> 0 | Q9: =ROUND(M9+P9,1) -> 0
A10: 6 | J10: 6
B11: =[3]紙類!$G$43 -> 0 | C11: =[3]紙類!$H$43 -> 0 | D11: =SUM(B11:C11) -> 0 | E11: =[3]紙類!$I$43 -> 0 | F11: =[3]紙類!$J$43 -> 0 | G11: =SUM(E11:F11) -> 0 | H11: =ROUND(D11+G11,1) -> 0 | K11: =[3]紙類!$R$43 -> 0 | L11: =[3]紙類!$S$43 -> 0 | M11: =SUM(K11:L11) -> 0 | N11: =[3]紙類!$T$43 -> 0 | O11: =[3]紙類!$U$43 -> 0 | P11: =SUM(N11:O11) -> 0 | Q11: =ROUND(M11+P11,1) -> 0
A12: 7 | J12: 7
B13: =[4]紙類!$G$43 -> 0 | C13: =[4]紙類!$H$43 -> 0 | D13: =SUM(B13:C13) -> 0 | E13: =[4]紙類!$I$43 -> 0 | F13: =[4]紙類!$J$43 -> 0 | G13: =SUM(E13:F13) -> 0 | H13: =ROUND(D13+G13,1) -> 0 | K13: =[4]紙類!$R$43 -> 0 | L13: =[4]紙類!$S$43 -> 0 | M13: =SUM(K13:L13) -> 0 | N13: =[4]紙類!$T$43 -> 0 | O13: =[4]紙類!$U$43 -> 0 | P13: =SUM(N13:O13) -> 0 | Q13: =ROUND(M13+P13,1) -> 0
A14: 8 | J14: 8
B15: =[5]紙類!$G$43 -> 0 | C15: =[5]紙類!$H$43 -> 0 | D15: =SUM(B15:C15) -> 0 | E15: =[5]紙類!$I$43 -> 0 | F15: =[5]紙類!$J$43 -> 0 | G15: =SUM(E15:F15) -> 0 | H15: =ROUND(D15+G15,1) -> 0 | K15: =[5]紙類!$R$43 -> 0 | L15: =[5]紙類!$S$43 -> 0 | M15: =SUM(K15:L15) -> 0 | N15: =[5]紙類!$T$43 -> 0 | O15: =[5]紙類!$U$43 -> 0 | P15: =SUM(N15:O15) -> 0 | Q15: =ROUND(M15+P15,1) -> 0
A16: 9 | J16: 9
