Workbook

Sheet 別記様式１
A1: ="令和"&'[1]A-1'!$E$9-2018&"年度 ごみ焼却施設維持管理状況報告書" -> 令和9年度 ごみ焼却施設維持管理状況報告書
O2: 4月末現在
A3: 施設設置者名 | C3: 利 尻 郡 清 掃 施 設 組 合
A4: 施設名 | C4: 利 尻 郡 ご み 焼 却 処 理 場
A5: 施設所在地 | C5: 北海道利尻郡利尻富士町鴛泊字大磯443番地
A6: 許可(届出)年月日 | C6: 37070 | F6: 許可番号 | H6: 環廃第 13-3号
A7: 処理能力 | C7: 15ｔ／日 | F7: 排ガス処理方式 | H7: バグフィルタ、乾式有害ガス除去装置、活性炭噴霧装置
A8: ばいじんの処理方法 | C8: 添加水、セメント、薬剤固化（埋立） | H8: 焼却灰の処理方法 | J8: 灰バンカ（埋立）
A9: 焼却対象廃棄物 | C9: 一般廃棄物、感染性廃棄物、動植物廃棄物
A11: ○ ごみ搬入状況
C12: ４月 | D12: ５月 | E12: ６月 | F12: ７月 | G12: ８月 | H12: ９月 | I12: １０月 | J12: １１月 | K12: １２月 | L12: １月 | M12: ２月 | N12: ３月 | O12: 計
A13: 収集可燃ごみ量(t) | C13: =[1]可燃!$F$43 +[1]紙類!$K$43 -> 0 | D13: =[2]可燃!$F$43 +[2]紙類!$K$43 -> 0 | E13: =[3]可燃!$F$43 +[3]紙類!$K$43 -> 0 | F13: =[4]可燃!$F$43 +[4]紙類!$K$43 -> 0 | G13: =[5]可燃!$F$43 +[5]紙類!$K$43 -> 0 | H13: =[6]可燃!$F$43 +[6]紙類!$K$43 -> 0 | I13: =[7]可燃!$F$43 +[7]紙類!$K$43 -> 0 | J13: =[8]可燃!$F$43 +[8]紙類!$K$43 -> 0 | K13: =[9]可燃!$F$43 +[9]紙類!$K$43 -> 0 | L13: =[10]可燃!$F$43 +[10]紙類!$K$43 -> 0 | M13: =[11]可燃!$F$43 +[11]紙類!$K$43 -> 0 | N13: =[12]可燃!$F$43 +[12]紙類!$K$43 -> 0 | O13: =SUM(C13:N13) -> 0
A14: 直接搬入可燃ごみ量(t) | C14: =SUM(C15:C17) -> 0 | D14: =SUM(D15:D17) -> 0 | E14: =SUM(E15:E17) -> 0 | F14: =SUM(F15:F17) -> 0 | G14: =SUM(G15:G17) -> 0 | H14: =SUM(H15:H17) -> 0 | I14: =SUM(I15:I17) -> 0 | J14: =SUM(J15:J17) -> 0 | ... N14: =SUM(N15:N17) -> 0 | O14: =SUM(C14:N14) -> 0
B15: 一般廃棄物（可燃物） | C15: =[1]可燃!$Q$43 +[1]紙類!$V$43 -> 0 | D15: =[2]可燃!$Q$43 +[2]紙類!$V$43 -> 0 | E15: =[3]可燃!$Q$43 +[3]紙類!$V$43 -> 0 | F15: =[4]可燃!$Q$43 +[4]紙類!$V$43 -> 0 | G15: =[5]可燃!$Q$43 +[5]紙類!$V$43 -> 0 | H15: =[6]可燃!$Q$43 +[6]紙類!$V$43 -> 0 | I15: =[7]可燃!$Q$43 +[7]紙類!$V$43 -> 0 | J15: =[8]可燃!$Q$43 +[8]紙類!$V$43 -> 0 | K15: =[9]可燃!$Q$43 +[9]紙類!$V$43 -> 0 | L15: =[10]可燃!$Q$43 +[10]紙類!$V$43 -> 0 | M15: =[11]可燃!$Q$43 +[11]紙類!$V$43 -> 0 | N15: =[12]可燃!$Q$43 +[12]紙類!$V$43 -> 0 | O15: =SUM(C15:N15) -> 0
B16: 併せ産廃(医療系) | C16: =[1]産廃水産・医療・汚泥!$U$43 -> 0 | D16: =[2]産廃水産・医療・汚泥!$U$43 -> 0 | E16: =[3]産廃水産・医療・汚泥!$U$43 -> 0 | F16: =[4]産廃水産・医療・汚泥!$U$43 -> 0 | G16: =[5]産廃水産・医療・汚泥!$U$43 -> 0 | H16: =[6]産廃水産・医療・汚泥!$U$43 -> 0 | I16: =[7]産廃水産・医療・汚泥!$U$43 -> 0 | J16: =[8]産廃水産・医療・汚泥!$U$43 -> 0 | K16: =[9]産廃水産・医療・汚泥!$U$43 -> 0 | L16: =[10]産廃水産・医療・汚泥!$U$43 -> 0 | M16: =[11]産廃水産・医療・汚泥!$U$43 -> 0 | N16: =[12]産廃水産・医療・汚泥!$U$43 -> 0 | O16: =SUM(C16:N16) -> 0
B17: 併せ産廃(動植物性) | C17: =[1]産廃水産・医療・汚泥!$F$43 -> 0 | D17: =[2]産廃水産・医療・汚泥!$F$43 -> 0 | E17: =[3]産廃水産・医療・汚泥!$F$43 -> 0 | F17: =[4]産廃水産・医療・汚泥!$F$43 -> 0 | G17: =[5]産廃水産・医療・汚泥!$F$43 -> 0 | H17: =[6]産廃水産・医療・汚泥!$F$43 -> 0 | I17: =[7]産廃水産・医療・汚泥!$F$43 -> 0 | J17: =[8]産廃水産・医療・汚泥!$F$43 -> 0 | K17: =[9]産廃水産・医療・汚泥!$F$43 -> 0 | L17: =[10]産廃水産・医療・汚泥!$F$43 -> 0 | M17: =[11]産廃水産・医療・汚泥!$F$43 -> 0 | N17: =[12]産廃水産・医療・汚泥!$F$43 -> 0 | O17: =SUM(C17:N17) -> 0
A18: 計 | C18: =SUM(C13:C14) -> 0 | D18: =SUM(D13:D14) -> 0 | E18: =SUM(E13:E14) -> 0 | F18: =SUM(F13:F14) -> 0 | G18: =SUM(G13:G14) -> 0 | H18: =SUM(H13:H14) -> 0 | I18: =SUM(I13:I14) -> 0 | J18: =SUM(J13:J14) -> 0 | ... N18: =SUM(N13:N14) -> 0 | O18: =SUM(C18:N18) -> 0
A20: ○ 処理状況
C21: ４月 | D21: ５月 | E21: ６月 | F21: ７月 | G21: ８月 | H21: ９月 | I21: １０月 | J21: １１月 | K21: １２月 | L21: １月 | M21: ２月 | N21: ３月 | O21: 計
A22: １号炉 | B22: 処理量(t) | C22: ='[1]A-1'!$C$44 -> 0 | D22: ='[2]A-1'!$C$44 -> 0 | E22: ='[3]A-1'!$C$44 -> 0 | F22: ='[4]A-1'!$C$44 -> 0 | G22: ='[5]A-1'!$C$44 -> 0 | H22: ='[6]A-1'!$C$44 -> 0 | I22: ='[7]A-1'!$C$44 -> 0 | J22: ='[8]A-1'!$C$44 -> 0 | K22: ='[9]A-1'!$C$44 -> 0 | L22: ='[10]A-1'!$C$44 -> 0 | M22: ='[11]A-1'!$C$44 -> 0 | N22: ='[12]A-1'!$C$44 -> 0 | O22: =SUM(C22:N22) -> 0
B23: 運転日数（日） | C23: =COUNTA('[1]A-1'!$C$13:$C$43) -> 0 | D23: =COUNTA('[2]A-1'!$C$13:$C$43) -> 0 | E23: =COUNTA('[3]A-1'!$C$13:$C$43) -> 0 | F23: =COUNTA('[4]A-1'!$C$13:$C$43) -> 0 | G23: =COUNTA('[5]A-1'!$C$13:$C$43) -> 0 | H23: =COUNTA('[6]A-1'!$C$13:$C$43) -> 0 | I23: =COUNTA('[7]A-1'!$C$13:$C$43) -> 0 | J23: =COUNTA('[8]A-1'!$C$13:$C$43) -> 0 | K23: =COUNTA('[9]A-1'!$C$13:$C$43) -> 0 | L23: =COUNTA('[10]A-1'!$C$13:$C$43) -> 0 | M23: =COUNTA('[11]A-1'!$C$13:$C$43) -> 0 | N23: =COUNTA('[12]A-1'!$C$13:$C$43) -> 0 | O23: =SUM(C23:N23) -> 0
B24: 日平均処理量(t/日) | C24: =IF(C22=0,"",C22/C23) | D24: =IF(D22=0,"",D22/D23) | E24: =IF(E22=0,"",E22/E23) | F24: =IF(F22=0,"",F22/F23) | G24: =IF(G22=0,"",G22/G23) | H24: =IF(H22=0,"",H22/H23) | I24: =IF(I22=0,"",I22/I23) | J24: =IF(J22=0,"",J22/J23) | ... N24: =IF(N22=0,"",N22/N23) | O24: =IF(SUM(C24:N24)=0,"",AVERAGE(C24:N24))
A25: 計 | B25: 処理量(t) | C25: =C22 -> 0 | D25: =D22 -> 0 | E25: =E22 -> 0 | F25: =F22 -> 0 | G25: =G22 -> 0 | H25: =H22 -> 0 | I25: =I22 -> 0 | J25: =J22 -> 0 | ... N25: =N22 -> 0 | O25: =SUM(C25:N25) -> 0
B26: 延べ運転日数（日） | C26: =C23 -> 0 | D26: =D23 -> 0 | E26: =E23 -> 0 | F26: =F23 -> 0 | G26: =G23 -> 0 | H26: =H23 -> 0 | I26: =I23 -> 0 | J26: =J23 -> 0 | ... N26: =N23 -> 0 | O26: =SUM(C26:N26) -> 0
B27: 日平均処理量(t/日) | C27: =C24 | D27: =D24 | E27: =E24 | F27: =F24 | G27: =G24 | H27: =H24 | I27: =I24 | J27: =J24 | ... N27: =N24 | O27: =IF(SUM(C27:N27)=0,"",AVERAGE(C27:N27))
B28: ばいじん固化量(t) | C28: ='[1]A-1'!$E$44 -> 0 | D28: ='[2]A-1'!$E$44 -> 0 | E28: ='[3]A-1'!$E$44 -> 0 | F28: ='[4]A-1'!$E$44 -> 0 | G28: ='[5]A-1'!$E$44 -> 0 | H28: ='[6]A-1'!$E$44 -> 0 | I28: ='[7]A-1'!$E$44 -> 0 | J28: ='[8]A-1'!$E$44 -> 0 | K28: ='[9]A-1'!$E$44 -> 0 | L28: ='[10]A-1'!$E$44 -> 0 | M28: ='[11]A-1'!$E$44 -> 0 | N28: ='[12]A-1'!$E$44 -> 0 | O28: =SUM(C28:N28) -> 0
B29: 焼却灰量(t) | C29: ='[1]A-1'!$D$44 -> 0 | D29: ='[2]A-1'!$D$44 -> 0 | E29: ='[3]A-1'!$D$44 -> 0 | F29: ='[4]A-1'!$D$44 -> 0 | G29: ='[5]A-1'!$D$44 -> 0 | H29: ='[6]A-1'!$D$44 -> 0 | I29: ='[7]A-1'!$D$44 -> 0 | J29: ='[8]A-1'!$D$44 -> 0 | K29: ='[9]A-1'!$D$44 -> 0 | L29: ='[10]A-1'!$D$44 -> 0 | M29: ='[11]A-1'!$D$44 -> 0 | N29: ='[12]A-1'!$D$44 -> 0 | O29: =SUM(C29:N29) -> 0
A31: ○ 排ガスの状況
C32: ４月 | D32: ５月 | E32: ６月 | F32: ７月 | G32: ８月 | H32: ９月 | I32: １０月 | J32: １１月 | K32: １２月 | L32: １月 | M32: ２月 | N32: ３月
A33: 排ガスの状況 | B33: 燃焼室中の燃焼ガスの温度（℃） | C33: ='[1]A-1'!$H$46 -> 0 | D33: ='[2]A-1'!$H$46 -> 0 | E33: ='[3]A-1'!$H$46 -> 0 | F33: ='[4]A-1'!$H$46 -> 0 | G33: ='[5]A-1'!$H$46 -> 0 | H33: ='[6]A-1'!$H$46 -> 0 | I33: ='[7]A-1'!$H$46 -> 0 | J33: ='[8]A-1'!$H$46 -> 0 | K33: ='[9]A-1'!$H$46 -> 0 | L33: ='[10]A-1'!$H$46 -> 0 | M33: ='[11]A-1'!$H$46 -> 0 | N33: ='[12]A-1'!$H$46 -> 0 | O33: 最大
C34: ='[1]A-1'!$H$45 | D34: ='[2]A-1'!$H$45 | E34: ='[3]A-1'!$H$45 | F34: ='[4]A-1'!$H$45 | G34: ='[5]A-1'!$H$45 | H34: ='[6]A-1'!$H$45 | I34: ='[7]A-1'!$H$45 | J34: ='[8]A-1'!$H$45 | K34: ='[9]A-1'!$H$45 | L34: ='[10]A-1'!$H$45 | M34: ='[11]A-1'!$H$45 | N34: ='[12]A-1'!$H$45 | O34: 平均
C35: ='[1]A-1'!$H$47 -> 0 | D35: ='[2]A-1'!$H$47 -> 0 | E35: ='[3]A-1'!$H$47 -> 0 | F35: ='[4]A-1'!$H$47 -> 0 | G35: ='[5]A-1'!$H$47 -> 0 | H35: ='[6]A-1'!$H$47 -> 0 | I35: ='[7]A-1'!$H$47 -> 0 | J35: ='[8]A-1'!$H$47 -> 0 | K35: ='[9]A-1'!$H$47 -> 0 | L35: ='[10]A-1'!$H$47 -> 0 | M35: ='[11]A-1'!$H$47 -> 0 | N35: ='[12]A-1'!$H$47 -> 0 | O35: 最小
B36: 集じん器に流入する燃焼ガスの温度（℃） | C36: ='[1]A-1'!$L$46 -> 0 | D36: ='[2]A-1'!$L$46 -> 0 | E36: ='[3]A-1'!$L$46 -> 0 | F36: ='[4]A-1'!$L$46 -> 0 | G36: ='[5]A-1'!$L$46 -> 0 | H36: ='[6]A-1'!$L$46 -> 0 | I36: ='[7]A-1'!$L$46 -> 0 | J36: ='[8]A-1'!$L$46 -> 0 | K36: ='[9]A-1'!$L$46 -> 0 | L36: ='[10]A-1'!$L$46 -> 0 | M36: ='[11]A-1'!$L$46 -> 0 | N36: ='[12]A-1'!$L$46 -> 0 | O36: 最大
C37: ='[1]A-1'!$L$45 | D37: ='[2]A-1'!$L$45 | E37: ='[3]A-1'!$L$45 | F37: ='[4]A-1'!$L$45 | G37: ='[5]A-1'!$L$45 | H37: ='[6]A-1'!$L$45 | I37: ='[7]A-1'!$L$45 | J37: ='[8]A-1'!$L$45 | K37: ='[9]A-1'!$L$45 | L37: ='[10]A-1'!$L$45 | M37: ='[11]A-1'!$L$45 | N37: ='[12]A-1'!$L$45 | O37: 平均
B38: 煙突から排ガスの一酸化炭素の濃度（ppm） | C38: ='[1]A-1'!$N$46 -> 0 | D38: ='[2]A-1'!$N$46 -> 0 | E38: ='[3]A-1'!$N$46 -> 0 | F38: ='[4]A-1'!$N$46 -> 0 | G38: ='[5]A-1'!$N$46 -> 0 | H38: ='[6]A-1'!$N$46 -> 0 | I38: ='[7]A-1'!$N$46 -> 0 | J38: ='[8]A-1'!$N$46 -> 0 | K38: ='[9]A-1'!$N$46 -> 0 | L38: ='[10]A-1'!$N$46 -> 0 | M38: ='[11]A-1'!$N$46 -> 0 | N38: ='[12]A-1'!$N$46 -> 0 | O38: 最大
C39: ='[1]A-1'!$N$45 | D39: ='[2]A-1'!$N$45 | E39: ='[3]A-1'!$N$45 | F39: ='[4]A-1'!$N$45 | G39: ='[5]A-1'!$N$45 | H39: ='[6]A-1'!$N$45 | I39: ='[7]A-1'!$N$45 | J39: ='[8]A-1'!$N$45 | K39: ='[9]A-1'!$N$45 | L39: ='[10]A-1'!$N$45 | M39: ='[11]A-1'!$N$45 | N39: ='[12]A-1'!$N$45 | O39: 平均
A40: ○ 排ガス中のダイオキシン類濃度及びばい煙測定結果 | F40: 測定月日 令和5年4月25日
C41: ダイオキシン類 | E41: ばいじん | G41: 塩化水素 | I41: 硫黄酸化物 | K41: 窒素酸化物 | M41: 全水銀
C42: (ng-TEQ/m3N) | E42: (g/m3N) | G42: (mg/m3N) | I42: (m3N/h) | K42: (Vol ppm) | M42: (μg/m3N)
B43: 焼却炉 | E43: 0.001 | G43: 16 | I43: 0.03 | K43: 86 | M43: 0.29
...

Sheet 別記様式２
A2: ="令和"&'[1]A-1'!$E$9-2018&"年度 最終処分場維持管理状況報告書" -> 令和9年度 最終処分場維持管理状況報告書
O3: 月末現在
A4: 施設設置者名 | C4: 利 尻 郡 清 掃 施 設 組 合
A5: 施設名 | C5: 一 般 廃 棄 物 最 終 処 分 場
A6: 施設所在地 | C6: 北海道利尻郡利尻富士町鴛泊字大磯521番地
A7: 許可(届出)年月日 | C7: 42527 | F7: 許可番号 | H7: 循環第 330-2号
A8: 埋立地面積 | C8: 16,995㎡ | F8: 埋立容量 | H8: 55,300㎥ | K8: しゃ水工 | M8: 二重遮水シート工の準好気性
A9: 浸出水処理施設規模 | C9: 40㎥／日 | F9: 浸出水処理方式 | H9: 回転円板式生物処理＋凝集沈澱処理＋砂ろ過方式+接触曝気高度処理方式
A10: 埋立対象廃棄物 | C10: ①一般廃棄物、②産業廃棄物（動植物残渣、医療系廃棄物残渣、焼却残渣、処理水汚泥）、③下水道汚泥
A12: ○ 埋立状況
C13: ４月 | D13: ５月 | E13: ６月 | F13: ７月 | G13: ８月 | H13: ９月 | I13: １０月 | J13: １１月 | K13: １２月 | L13: １月 | M13: ２月 | N13: ３月 | O13: 計
A14: 直接埋立ごみ量（t) | C14: =SUM(C15:C17) -> 0 | D14: =SUM(D15:D17) -> 0 | E14: =SUM(E15:E17) -> 0 | F14: =SUM(F15:F17) -> 0 | G14: =SUM(G15:G17) -> 0 | H14: =SUM(H15:H17) -> 0 | I14: =SUM(I15:I17) -> 0 | J14: =SUM(J15:J17) -> 0 | ... N14: =SUM(N15:N17) -> 0 | O14: =SUM(C14:N14) -> 0
B15: 収集ごみ | C15: ='[1]B-1'!$C$45 -> 0 | D15: ='[2]B-1'!$C$45 -> 0 | E15: ='[3]B-1'!$C$45 -> 0 | F15: ='[4]B-1'!$C$45 -> 0 | G15: ='[5]B-1'!$C$45 -> 0 | H15: ='[6]B-1'!$C$45 -> 0 | I15: ='[7]B-1'!$C$45 -> 0 | J15: ='[8]B-1'!$C$45 -> 0 | K15: ='[9]B-1'!$C$45 -> 0 | L15: ='[10]B-1'!$C$45 -> 0 | M15: ='[11]B-1'!$C$45 -> 0 | N15: ='[12]B-1'!$C$45 -> 0 | O15: =SUM(C15:N15) -> 0
B16: 一般（直搬ごみ） | C16: ='[1]B-1'!$D$45 +'[1]B-1'!$E$45 +'[1]B-1'!$F$45 -> 0 | D16: ='[2]B-1'!$D$45 +'[2]B-1'!$E$45 +'[2]B-1'!$F$45 -> 0 | E16: ='[3]B-1'!$D$45 +'[3]B-1'!$E$45 +'[3]B-1'!$F$45 -> 0 | F16: ='[4]B-1'!$D$45 +'[4]B-1'!$E$45 +'[4]B-1'!$F$45 -> 0 | G16: ='[5]B-1'!$D$45 +'[5]B-1'!$E$45 +'[5]B-1'!$F$45 -> 0 | H16: ='[6]B-1'!$D$45 +'[6]B-1'!$E$45 +'[6]B-1'!$F$45 -> 0 | I16: ='[7]B-1'!$D$45 +'[7]B-1'!$E$45 +'[7]B-1'!$F$45 -> 0 | J16: ='[8]B-1'!$D$45 +'[8]B-1'!$E$45 +'[8]B-1'!$F$45 -> 0 | K16: ='[9]B-1'!$D$45 +'[9]B-1'!$E$45 +'[9]B-1'!$F$45 -> 0 | L16: ='[10]B-1'!$D$45 +'[10]B-1'!$E$45 +'[10]B-1'!$F$45 -> 0 | M16: ='[11]B-1'!$D$45 +'[11]B-1'!$E$45 +'[11]B-1'!$F$45 -> 0 | N16: ='[12]B-1'!$D$45 +'[12]B-1'!$E$45 +'[12]B-1'!$F$45 -> 0 | O16: =SUM(C16:N16) -> 0
B17: 併せ産廃(動植物性) | C17: ='[1]B-1'!$G$45 -> 0 | D17: ='[2]B-1'!$G$45 -> 0 | E17: ='[3]B-1'!$G$45 -> 0 | F17: ='[4]B-1'!$G$45 -> 0 | G17: ='[5]B-1'!$G$45 -> 0 | H17: ='[6]B-1'!$G$45 -> 0 | I17: ='[7]B-1'!$G$45 -> 0 | J17: ='[8]B-1'!$G$45 -> 0 | K17: ='[9]B-1'!$G$45 -> 0 | L17: ='[10]B-1'!$G$45 -> 0 | M17: ='[11]B-1'!$G$45 -> 0 | N17: ='[12]B-1'!$G$45 -> 0 | O17: =SUM(C17:N17) -> 0
A18: 焼却残渣（t) | C18: ='[1]B-1'!$H$45 -> 0 | D18: ='[2]B-1'!$H$45 -> 0 | E18: ='[3]B-1'!$H$45 -> 0 | F18: ='[4]B-1'!$H$45 -> 0 | G18: ='[5]B-1'!$H$45 -> 0 | H18: ='[6]B-1'!$H$45 -> 0 | I18: ='[7]B-1'!$H$45 -> 0 | J18: ='[8]B-1'!$H$45 -> 0 | K18: ='[9]B-1'!$H$45 -> 0 | L18: ='[10]B-1'!$H$45 -> 0 | M18: ='[11]B-1'!$H$45 -> 0 | N18: ='[12]B-1'!$H$45 -> 0 | O18: =SUM(C18:N18) -> 0
A19: 埋立ごみ量（ｔ） | C19: =SUM(C15:C18) -> 0 | D19: =SUM(D15:D18) -> 0 | E19: =SUM(E15:E18) -> 0 | F19: =SUM(F15:F18) -> 0 | G19: =SUM(G15:G18) -> 0 | H19: =SUM(H15:H18) -> 0 | I19: =SUM(I15:I18) -> 0 | J19: =SUM(J15:J18) -> 0 | ... N19: =SUM(N15:N18) -> 0 | O19: =SUM(C19:N19) -> 0
A20: 埋立ごみ量（m3） | C20: =ROUND(C19*1.5,1) -> 0 | D20: =ROUND(D19*1.5,1) -> 0 | E20: =ROUND(E19*1.5,1) -> 0 | F20: =ROUND(F19*1.5,1) -> 0 | G20: =ROUND(G19*1.5,1) -> 0 | H20: =ROUND(H19*1.5,1) -> 0 | I20: =ROUND(I19*1.5,1) -> 0 | J20: =ROUND(J19*1.5,1) -> 0 | ... N20: =ROUND(N19*1.5,1) -> 0 | O20: =SUM(C20:N20) -> 0
A21: 覆土量（m3） | C21: ='[1]B-1'!$I$45 -> 0 | D21: ='[2]B-1'!$I$45 -> 0 | E21: ='[3]B-1'!$I$45 -> 0 | F21: ='[4]B-1'!$I$45 -> 0 | G21: ='[5]B-1'!$I$45 -> 0 | H21: ='[6]B-1'!$I$45 -> 0 | I21: ='[7]B-1'!$I$45 -> 0 | J21: ='[8]B-1'!$I$45 -> 0 | K21: ='[9]B-1'!$I$45 -> 0 | L21: ='[10]B-1'!$I$45 -> 0 | M21: ='[11]B-1'!$I$45 -> 0 | N21: ='[12]B-1'!$I$45 -> 0 | O21: =SUM(C21:N21) -> 0
A22: 埋立容量（m3） | C22: =SUM(C20:C21) -> 0 | D22: =SUM(D20:D21) -> 0 | E22: =SUM(E20:E21) -> 0 | F22: =SUM(F20:F21) -> 0 | G22: =SUM(G20:G21) -> 0 | H22: =SUM(H20:H21) -> 0 | I22: =SUM(I20:I21) -> 0 | J22: =SUM(J20:J21) -> 0 | ... N22: =SUM(N20:N21) -> 0 | O22: =SUM(C22:N22) -> 0
A23: ○ 令和4年度末残量 34，962m3
A25: ○ 放流水等の状況
C26: ４月 | D26: ５月 | E26: ６月 | F26: ７月 | G26: ８月 | H26: ９月 | I26: １０月 | J26: １１月 | K26: １２月 | L26: １月 | M26: ２月 | N26: ３月 | O26: 平均値
A27: 浸出水 | B27: pH | O27: =IF(SUM(C27:N27)=0,"",AVERAGE(C27:N27))
B28: BOD又はCOD(mg/L） | O28: =IF(SUM(C28:N28)=0,"",AVERAGE(C28:N28))
B29: SS(mg/L) | O29: =IF(SUM(C29:N29)=0,"",AVERAGE(C29:N29))
A30: 放流水 | B30: pH | O30: =IF(SUM(C30:N30)=0,"",AVERAGE(C30:N30))
B31: BOD又はCOD(mg/L） | O31: =IF(SUM(C31:N31)=0,"",AVERAGE(C31:N31))
B32: SS(mg/L) | O32: =IF(SUM(C32:N32)=0,"",AVERAGE(C32:N32))
A36: ○ 擁壁、遮水工、調整池、浸出水処理設備、導水管、配管等設備の補修・更新時の状況
A37: 年 月 日 | C37: 設 備 | F37: 内 容
A38: 45036 | F38: 目視点検実施済 ㊜
A39: 45108 | F39: 目視点検実施済 ㊜

Sheet 一般廃棄物最終処分場水質検査状況
A1: 一般廃棄物最終処分場水質検査状況
A2: 採水年月日 令和 5 年 10 月 31日
A3: 放流水 | B3: 計量の結果 | C3: 単位 | D3: 大腸菌群数 | E3: 0 | F3: 個/cm3
A4: 水素イオン濃度ＰＨ（測定時水温） | B4: 7.5（21） | C4: -(℃) | D4: 水銀及びアルキル水銀その他の水銀化合物 | E4: 0.0005未満 | F4: mg/L
A5: 生物化学的酸素要求量（ＢＯＤ） | B5: 0.5 | C5: mg/L | D5: カドミウム及びその化合物 | E5: 0.003未満 | F5: mg/L
A6: 科学的酸素要求量（ＣＯＤ） | B6: 26.3 | C6: mg/L | D6: 鉛及びその化合物 | E6: 0.01未満 | F6: mg/L
A7: 浮遊物質量（ＳＳ） | B7: 0.5 | C7: mg/L | D7: シアン化合物 | E7: 0.1未満 | F7: mg/L
A8: 採水年月日 令和 5 年 5 月 31 日
A9: 放流水 | B9: 計量の結果 | C9: 単位 | D9: 放流水 | E9: 計量の結果 | F9: 単位
A10: 水素イオン濃度ＰＨ（測定時水温） | B10: 7.4（21） | C10: -(℃) | D10: 1,3-ジクロロプロペン | E10: 0.002未満 | F10: mg/L
A11: 生物化学的酸素要求量（ＢＯＤ） | B11: 0.7未満 | C11: mg/L | D11: チウラム | E11: 0.006未満 | F11: mg/L
A12: 化学的酸素要求量（ＣＯＤ） | B12: 19 | C12: mg/L | D12: シマジン | E12: 0.003未満 | F12: mg/L
A13: 浮遊物質量（ＳＳ） | B13: 2.7 | C13: mg/L | D13: チオベンカルブ | E13: 0.02未満 | F13: mg/L
A14: 大腸菌群数 | B14: 0 | C14: 個/cm3 | D14: ベンゼン | E14: 0.002未満 | F14: mg/L
A15: アルキル水銀化合物 | B15: 不検出 （0.0005未満） | C15: mg/L | D15: セレン及びその化合物 | E15: 0.001未満 | F15: mg/L
A16: 水銀及びアルキル水銀その他の水銀化合物 | B16: 0.0005未満 | C16: mg/L | D16: 1,4ジオキサン | E16: 0.05未満 | F16: mg/L
A17: カドミウム及びその化合物 | B17: 0.003未満 | C17: mg/L | D17: ほう素及びその化合物 | E17: 0.51 | F17: mg/L
A18: 鉛及びその化合物 | B18: 0.01未満 | C18: mg/L | D18: ふっ素及びその化合物 | E18: 0.06 | F18: mg/L
A19: 有機燐化合物 | B19: 0.1未満 | C19: mg/L | D19: アンモニア、アンモニウム化合物、亜硝酸化合物及び硝酸化合物 | E19: 51.1 | F19: mg/L
A20: 六価クロム化合物 | B20: 0.05未満 | C20: mg/L | D20: ノルマルヘキサン抽出物質含有量 鉱油類含有量 | E20: 1.0未満 | F20: mg/L
A21: 砒素及びその化合物 | B21: 0.001未満 | C21: mg/L | D21: ノルマルヘキサン抽出物質含有量 動植物油脂類含有量 | E21: 1.0未満 | F21: mg/L
A22: シアン化合物 | B22: 0.1未満 | C22: mg/L | D22: フェノール類含有量 | E22: 0.1未満 | F22: mg/L
A23: ポリ塩化ビフェニル | B23: 0.0005未満 | C23: mg/L | D23: 銅含有量 | E23: 0.01未満 | F23: mg/L
A24: トリクロロエチレン | B24: 0.002未満 | C24: mg/L | D24: 亜鉛含有量 | E24: 0.01 | F24: mg/L
A25: テトラクロロエチレン | B25: 0.002未満 | C25: mg/L | D25: 溶解性鉄含有量 | E25: 0.05 | F25: mg/L
A26: ジクロロメタン | B26: 0.002未満 | C26: mg/L | D26: 溶解性マンガン含有量 | E26: 0.45 | F26: mg/L
A27: 四塩化炭素 | B27: 0.002未満 | C27: mg/L | D27: クロム含有量 | E27: 0.01未満 | F27: mg/L
A28: 1,2-ジクロロエタン | B28: 0.002未満 | C28: mg/L | D28: 窒素含有量 | E28: 56.1 | F28: mg/L
A29: 1,1-ジクロロエチレン | B29: 0.002未満 | C29: mg/L | D29: 燐含有量 | E29: 0.05未満 | F29: mg/L
A30: シス-1,2-ジクロロエチレン | B30: 0.002未満 | C30: mg/L | D30: ダイオキシン類 | E30: 8.1e-05 | F30: Pg-TEQ/L
A31: 1,1,1-トリクロロエタン | B31: 0.002未満 | C31: mg/L
A32: 1,1,2-トリクロロエタン | B32: 0.002未満 | C32: mg/L
