Workbook
Name A: #REF!
Name aa: 可燃!$F:$F
Name B: #REF!
Name bb: 可燃!$Q:$Q
Name d: 産廃水産・医療・汚泥!$F:$F
Name e: 産廃水産・医療・汚泥!$U:$U
Name f: 'A-1'!$D:$D
Name g: 粗大!$K:$K
Name h: 粗大!$U:$U
Name i: 不燃・木くず・海岸清掃!$F:$F
Name i: ペットボトル!$F:$F
Name j: 不燃・木くず・海岸清掃!$O:$O
Name j: ペットボトル!$P:$P
Name k: 粗大!$P:$P
Name l: 不燃・木くず・海岸清掃!$K:$K
Name l: ペットボトル!$K:$K
Name m: #REF!
Name n: '収集（全般）'!$P:$P
Name o: '収集（全般）'!$Z:$Z
Name p: '収集（全般）'!$AE:$AE
Name q: 不燃・木くず・海岸清掃!$P:$P
Name q: ペットボトル!$Q:$Q
Name s: 粗大!$U:$U
Name t: 可燃!$U:$U
Name u: 粗大!$Z:$Z
Name v: 不燃・木くず・海岸清掃!$U:$U
Name v: ペットボトル!$V:$V
Name w: 産廃水産・医療・汚泥!$K:$K
Name x: 産廃水産・医療・汚泥!$X:$X
Name y: #REF!
Name z: #REF!

Sheet A-1
A4: ごみ焼却処理施設維持管理月報
I5: 設置主体名 | K5: 利尻郡清掃施設組合 | O5: 処 理 方 式 | Q5: 機械化バッチ燃焼式
I6: 施 設 名 | K6: 利尻郡ごみ焼却処理場 | O6: 処 理 能 力 | Q6: 15ｔ/日
I7: 技術管理者名 | K7: 柴田和彦 | O7: 放流水の有無 | Q7: 無
A9: A-1 | B9: ="("&TEXT(DATE('[1]A-1'!$E$9, 7, 1), "ggge年mm月")&")" -> (令和9年07月)
A10: 項目 | B10: ご み | C10: ご み | D10: 搬 出 | E10: ダスト | F10: 補助燃料 | G10: 稼動 | H10: 燃焼室 | I10: 炉内圧 | J10: 誘 引 | K10: 灰 熱 | L10: バグフィルタ | M10: 冷却 | N10: ばい煙
B11: 搬入量 | C11: 投入量 | D11: 残渣量 | E11: 排出量 | F11: 使用量 | G11: 時間 | H11: 出口温度 | J11: 吸引力 | K11: しゃく減量 | L11: 入口温度 | M11: 水量 | N11: CO | O11: NOx | P11: SOx | Q11: Dust | R11: HCl
A12: 日付 | B12: (t/日) | C12: (t/日) | D12: (t/日) | E12: (t/日) | F12: (l/日) | G12: (hr/日) | H12: (℃) | I12: (Pa) | J12: （ｋｐ） | K12: (%) | L12: (℃) | M12: (㎥/日) | N12: (ppm) | O12: (ppm) | P12: (ppm) | Q12: (mg/N㎥) | R12: (ppm)
A13: 1 | B13: =IF(可燃!F12+可燃!Q12+紙類!K12+紙類!V12+産廃水産・医療・汚泥!F12+産廃水産・医療・汚泥!U12=0,"",可燃!F12+可燃!Q12+紙類!K12+紙類!V12+産廃水産・医療・汚泥!F12+産廃水産・医療・汚泥!U12)
A14: 2 | B14: =IF(可燃!F13+可燃!Q13+紙類!K13+紙類!V13+産廃水産・医療・汚泥!F13+産廃水産・医療・汚泥!U13=0,"",可燃!F13+可燃!Q13+紙類!K13+紙類!V13+産廃水産・医療・汚泥!F13+産廃水産・医療・汚泥!U13)
A15: 3 | B15: =IF(可燃!F14+可燃!Q14+紙類!K14+紙類!V14+産廃水産・医療・汚泥!F14+産廃水産・医療・汚泥!U14=0,"",可燃!F14+可燃!Q14+紙類!K14+紙類!V14+産廃水産・医療・汚泥!F14+産廃水産・医療・汚泥!U14)
A16: 4 | B16: =IF(可燃!F15+可燃!Q15+紙類!K15+紙類!V15+産廃水産・医療・汚泥!F15+産廃水産・医療・汚泥!U15=0,"",可燃!F15+可燃!Q15+紙類!K15+紙類!V15+産廃水産・医療・汚泥!F15+産廃水産・医療・汚泥!U15)
A17: 5 | B17: =IF(可燃!F16+可燃!Q16+紙類!K16+紙類!V16+産廃水産・医療・汚泥!F16+産廃水産・医療・汚泥!U16=0,"",可燃!F16+可燃!Q16+紙類!K16+紙類!V16+産廃水産・医療・汚泥!F16+産廃水産・医療・汚泥!U16)
A18: 6 | B18: =IF(可燃!F17+可燃!Q17+紙類!K17+紙類!V17+産廃水産・医療・汚泥!F17+産廃水産・医療・汚泥!U17=0,"",可燃!F17+可燃!Q17+紙類!K17+紙類!V17+産廃水産・医療・汚泥!F17+産廃水産・医療・汚泥!U17)
A19: 7 | B19: =IF(可燃!F18+可燃!Q18+紙類!K18+紙類!V18+産廃水産・医療・汚泥!F18+産廃水産・医療・汚泥!U18=0,"",可燃!F18+可燃!Q18+紙類!K18+紙類!V18+産廃水産・医療・汚泥!F18+産廃水産・医療・汚泥!U18)
A20: 8 | B20: =IF(可燃!F19+可燃!Q19+紙類!K19+紙類!V19+産廃水産・医療・汚泥!F19+産廃水産・医療・汚泥!U19=0,"",可燃!F19+可燃!Q19+紙類!K19+紙類!V19+産廃水産・医療・汚泥!F19+産廃水産・医療・汚泥!U19)
A21: 9 | B21: =IF(可燃!F20+可燃!Q20+紙類!K20+紙類!V20+産廃水産・医療・汚泥!F20+産廃水産・医療・汚泥!U20=0,"",可燃!F20+可燃!Q20+紙類!K20+紙類!V20+産廃水産・医療・汚泥!F20+産廃水産・医療・汚泥!U20)
A22: 10 | B22: =IF(可燃!F21+可燃!Q21+紙類!K21+紙類!V21+産廃水産・医療・汚泥!F21+産廃水産・医療・汚泥!U21=0,"",可燃!F21+可燃!Q21+紙類!K21+紙類!V21+産廃水産・医療・汚泥!F21+産廃水産・医療・汚泥!U21)
A23: 11 | B23: =IF(可燃!F22+可燃!Q22+紙類!K22+紙類!V22+産廃水産・医療・汚泥!F22+産廃水産・医療・汚泥!U22=0,"",可燃!F22+可燃!Q22+紙類!K22+紙類!V22+産廃水産・医療・汚泥!F22+産廃水産・医療・汚泥!U22)
A24: 12 | B24: =IF(可燃!F23+可燃!Q23+紙類!K23+紙類!V23+産廃水産・医療・汚泥!F23+産廃水産・医療・汚泥!U23=0,"",可燃!F23+可燃!Q23+紙類!K23+紙類!V23+産廃水産・医療・汚泥!F23+産廃水産・医療・汚泥!U23)
... A43: 31 | B43: =IF(可燃!F42+可燃!Q42+紙類!K42+紙類!V42+産廃水産・医療・汚泥!F42+産廃水産・医療・汚泥!U42=0,"",可燃!F42+可燃!Q42+紙類!K42+紙類!V42+産廃水産・医療・汚泥!F42+産廃水産・医療・汚泥!U42)
A44: 合計 | B44: =ROUND(SUM(B13:B43),1) -> 0 | C44: =ROUND(SUM(C13:C43),1) -> 0 | D44: =ROUND(SUM(D13:D43),1) -> 0 | E44: =ROUND(SUM(E13:E43),1) -> 0 | F44: =SUM(F13:F43) -> 0 | G44: =SUM(G13:G43) -> 0 | M44: =SUM(M13:M43) -> 0
A45: 平均 | B45: =IF(COUNTIF(B13:B43,">0")=0,"",ROUND(B44/COUNTIF(B13:B43,">0"),1)) | C45: =IF(COUNTIF(C13:C43,">0")=0,"",ROUND(C44/COUNTIF(C13:C43,">0"),1)) | D45: =IF(COUNTIF(D13:D43,">0")=0,"",ROUND(D44/COUNTIF(D13:D43,">0"),1)) | E45: =IF(COUNTIF(E13:E43,">0")=0,"",ROUND(E44/COUNTIF(E13:E43,">0"),1)) | F45: =IF(SUM(F13:F43)=0,"",AVERAGE(F13:F43)) | G45: =IF(SUM(G13:G43)=0,"",AVERAGE(G13:G43)) | H45: =IF(SUM(H13:H43)=0,"",AVERAGE(H13:H43)) | I45: =IF(SUM(I13:I43)=0,"",AVERAGE(I13:I43)) | J45: 3.43 | K45: 10％以下 | L45: =IF(SUM(L13:L43)=0,"",AVERAGE(L13:L43)) | M45: =IF(SUM(M13:M43)=0,"",AVERAGE(M13:M43)) | N45: =IF(SUM(N13:N43)=0,"",AVERAGE(N13:N43)) | O45: =IF(SUM(O13:O43)=0,"",AVERAGE(O13:O43)) | P45: =IF(SUM(P13:P43)=0,"",AVERAGE(P13:P43)) | Q45: =IF(SUM(Q13:Q43)=0,"",AVERAGE(Q13:Q43)) | R45: =IF(SUM(R13:R43)=0,"",AVERAGE(R13:R43))
A46: 最大 | B46: =ROUND(MAX(B13:B43),1) -> 0 | C46: =ROUND(MAX(C13:C43),1) -> 0 | D46: =ROUND(MAX(D13:D43),1) -> 0 | E46: =ROUND(MAX(E13:E43),1) -> 0 | F46: =MAX(F13:F43) -> 0 | G46: =MAX(G13:G43) -> 0 | H46: =MAX(H13:H43) -> 0 | I46: =MAX(I13:I43) -> 0 | L46: =MAX(L13:L43) -> 0 | M46: =MAX(M13:M43) -> 0 | N46: =MAX(N13:N43) -> 0 | O46: =MAX(O13:O43) -> 0 | P46: =MAX(P13:P43) -> 0 | Q46: =MAX(Q13:Q43) -> 0 | R46: =MAX(R13:R43) -> 0
A47: 最小 | B47: =IF(COUNTIF(B13:B43,">0")=0,"",ROUND(LARGE(B13:B43,COUNTIF(B13:B43,">0")),1)) | C47: =IF(COUNTIF(C13:C43,">0")=0,"",ROUND(LARGE(C13:C43,COUNTIF(C13:C43,">0")),1)) | D47: =IF(COUNTIF(D13:D43,">0")=0,"",ROUND(LARGE(D13:D43,COUNTIF(D13:D43,">0")),1)) | E47: =IF(COUNTIF(E13:E43,">0")=0,"",ROUND(LARGE(E13:E43,COUNTIF(E13:E43,">0")),1)) | F47: =MIN(F13:F43) -> 0 | G47: =MIN(G13:G43) -> 0 | H47: =MIN(H13:H43) -> 0 | I47: =MIN(I13:I43) -> 0 | L47: =MIN(L13:L43) -> 0 | M47: =MIN(M13:M43) -> 0 | N47: =MIN(N13:N43) -> 0 | O47: =MIN(O13:O43) -> 0 | P47: =MIN(P13:P43) -> 0 | Q47: =MIN(Q13:Q43) -> 0 | R47: =MIN(R13:R43) -> 0

Sheet A-2
A1: 破砕・圧縮処理施設維持管理月報
F5: 設置主体名 | H5: 利尻郡清掃施設組合 | J5: 処 理 方 式 | L5: 衝撃剪断併用回転式
F6: 施 設 名 | H6: 利尻郡ごみ焼却処理場 | J6: 処 理 能 力 | L6: 6ｔ/日
F7: 技術管理者名 | H7: 柴田和彦 | J7: 放流水の有無 | L7: 無
A9: A-2 | B9: ='A-1'!B9:D9 -> (令和9年07月)
A10: 項目 | B10: ごみ | C10: ごみ | D10: ごみ投入量の内訳（ｔ/日） | J10: 稼動 | K10: 焼却対象 | L10: 埋立対象 | M10: 有価物回収量
B11: 搬入量 | C11: 投入量 | D11: 一般ごみ | G11: 収集ごみ | J11: 時間 | K11: ごみ量 | L11: ごみ量 | M11: 鉄 | N11: （ ）
A12: 日付 | B12: (t/日) | C12: (t/日) | D12: 資源 | E12: 不燃 | F12: 粗大 | G12: 資源 | H12: 不燃 | I12: 粗大 | J12: （ｈｒ/日） | K12: （ｔ/日） | L12: （ｔ/日） | M12: （ｔ/日） | N12: （ｔ/日）
A13: 1 | C13: =SUM(D13:I13) -> 0
A14: 2 | C14: =SUM(D14:I14) -> 0
A15: 3 | C15: =SUM(D15:I15) -> 0
A16: 4 | C16: =SUM(D16:I16) -> 0
A17: 5 | C17: =SUM(D17:I17) -> 0
A18: 6 | C18: =SUM(D18:I18) -> 0
A19: 7 | C19: =SUM(D19:I19) -> 0
A20: 8 | C20: =SUM(D20:I20) -> 0
A21: 9 | C21: =SUM(D21:I21) -> 0 | E21: =COUNTIF(F20:F25,">0") -> 0
A22: 10 | C22: =SUM(D22:I22) -> 0
A23: 11 | C23: =SUM(D23:I23) -> 0
A24: 12 | C24: =SUM(D24:I24) -> 0
A25: 13 | C25: =SUM(D25:I25) -> 0
A26: 14 | C26: =SUM(D26:I26) -> 0
A27: 15 | C27: =SUM(D27:I27) -> 0
A28: 16 | C28: =SUM(D28:I28) -> 0
A29: 17 | C29: =SUM(D29:I29) -> 0
A30: 18 | C30: =SUM(D30:I30) -> 0
A31: 19 | C31: =SUM(D31:I31) -> 0
A32: 20 | C32: =SUM(D32:I32) -> 0
A33: 21 | C33: =SUM(D33:I33) -> 0
... A42: 30 | C42: =SUM(D42:I42) -> 0
A43: 31
A44: 合計 | B44: =SUM(B13:B43) -> 0 | C44: =SUM(C13:C43) -> 0 | D44: =SUM(D13:D43) -> 0 | F44: =SUM(F13:F43) -> 0 | G44: =SUM(G13:G43) -> 0 | I44: =SUM(I13:I43) -> 0
A45: 平均 | B45: =IF(SUM(B13:B43)=0,"",AVERAGE(B13:B43)) | C45: =IF(SUM(C13:C43)=0,"",SUM(C13:C43)/COUNTIF(C13:C43,">0")) | D45: =IF(SUM(D13:D43)=0,"",AVERAGE(D13:D43)) | E45: =IF(SUM(E13:E43)=0,"",AVERAGE(E13:E43)) | F45: =IF(SUM(F13:F43)=0,"",AVERAGE(F13:F43)) | G45: =IF(SUM(G13:G43)=0,"",AVERAGE(G13:G43)) | H45: =IF(SUM(H13:H43)=0,"",AVERAGE(H13:H43)) | I45: =IF(SUM(I13:I43)=0,"",AVERAGE(I13:I43)) | J45: =IF(SUM(J13:J43)=0,"",AVERAGE(J13:J43)) | K45: =IF(SUM(K13:K43)=0,"",AVERAGE(K13:K43)) | ... N45: =IF(SUM(N13:N43)=0,"",AVERAGE(N13:N43))
A46: 最大 | B46: =MAX(B13:B43) -> 0 | C46: =MAX(C13:C43) -> 0 | D46: =MAX(D13:D43) -> 0 | F46: =MAX(F13:F43) -> 0 | G46: =MAX(G13:G43) -> 0 | I46: =MAX(I13:I43) -> 0
A47: 最小 | B47: =IF(COUNTIF(B13:B43,">0")=0,"",LARGE(B13:B43,COUNTIF(B13:B43,">0"))) | C47: =IF(COUNTIF(C13:C43,">0")=0,"",LARGE(C13:C43,COUNTIF(C13:C43,">0"))) | D47: =IF(COUNTIF(D13:D43,">0")=0,"",LARGE(D13:D43,COUNTIF(D13:D43,">0"))) | E47: =IF(COUNTIF(E13:E43,">0")=0,"",LARGE(E13:E43,COUNTIF(E13:E43,">0"))) | F47: =IF(COUNTIF(F13:F43,">0")=0,"",LARGE(F13:F43,COUNTIF(F13:F43,">0"))) | G47: =IF(COUNTIF(G13:G43,">0")=0,"",LARGE(G13:G43,COUNTIF(G13:G43,">0"))) | H47: =IF(COUNTIF(H13:H43,">0")=0,"",LARGE(H13:H43,COUNTIF(H13:H43,">0"))) | I47: =IF(COUNTIF(I13:I43,">0")=0,"",LARGE(I13:I43,COUNTIF(I13:I43,">0"))) | J47: =MIN(J13:J43) -> 0 | K47: =MIN(K13:K43) -> 0 | L47: =MIN(L13:L43) -> 0 | M47: =MIN(M13:M43) -> 0 | N47: =MIN(N13:N43) -> 0

Sheet B-1
A1: 最終処分場維持管理月報
H2: 設置主体名 | J2: 利尻郡清掃施設組合 | M2: 汚 水 処 理 方 式 | P2: 回転円盤式生物処理+凝集沈澱処理+砂ろ過方式
H3: 施 設 名 | J3: 一般廃棄物最終処分場 | M3: 汚 水 処 理 能 力 | P3: 35m3/日
H4: 埋立地面積 | J4: 16,500㎡ | M4: 汚 水 調 整 池 容 量 | P4: 3,360m3
H5: 埋立地容量 | J5: 55,300m3 | M5: 目 標 | O5: BOD | P5: 20mg/L以下
H6: 技術管理者名 | J6: 西 島 信 希 | M6: 水 質 | O6: SS | P6: 10mg/L以下
A9: B-1 | B9: ='A-1'!B9:D9 -> (令和9年07月)
A10: 項目 | C10: ごみ埋立量の内訳 | J10: 浸 出 液
B11: ごみ | C11: 収集 | D11: 直搬 | E11: 下水道 | F11: うに | G11: 動植物性 | H11: 焼却 | I11: 覆土量 | J11: 汚水 | K11: 処理 | L11: 原 水 | P11: 処 理 水
B12: 埋立量 | C12: ごみ | D12: ごみ | E12: 汚泥 | F12: 殻等 | G12: 産廃棄物 | H12: 残渣 | J12: 貯留量 | K12: 水量 | L12: pH | M12: BOD | N12: COD | O12: SS | P12: pH | Q12: BOD | R12: COD | S12: SS | T12: 大腸菌郡数
A13: 日 | B13: （ｔ/日） | C13: （ｔ/日） | D13: （ｔ/日） | E13: （ｔ/日） | F13: （ｔ/日） | G13: （ｔ/日） | H13: （ｔ/日） | I13: (m3/日） | J13: (m3/日） | K13: (m3/日） | L13: 5.8～8.6 | M13: 20mｇ/L以下 | N13: 60mg/L以下 | O13: 10mg/L以下 | P13: 5.8～8.6 | Q13: 20mｇ/L以下 | R13: 60mg/L以下 | S13: 10mg/L以下 | T13: 3000個/ml以下
A14: 1 | B14: =IF(SUM(C14:H14)=0,"",SUM(C14:H14)) | C14: =IF(可燃!K12+不燃・木くず・海岸清掃!F12+ビン類!K12+缶類!K12+ペットボトル!K12+粗大!P12+紙類!Q12=0,"",可燃!K12+不燃・木くず・海岸清掃!F12+ビン類!K12+缶類!K12+ペットボトル!K12+粗大!P12+紙類!Q12) | D14: =IF(不燃・木くず・海岸清掃!K12+不燃・木くず・海岸清掃!P12+不燃・木くず・海岸清掃!Z12+可燃!V12+ビン類!V12+缶類!V12+ペットボトル!V12+粗大!Z12=0,"",不燃・木くず・海岸清掃!K12+不燃・木くず・海岸清掃!P12+不燃・木くず・海岸清掃!Z12+可燃!V12+ビン類!V12+缶類!V12+ペットボトル!V12+粗大!Z12) | E14: =IF(産廃水産・医療・汚泥!X12=0,"",産廃水産・医療・汚泥!X12) | F14: =IF(産廃水産・医療・汚泥!P12=0,"",産廃水産・医療・汚泥!P12) | G14: =IF(産廃水産・医療・汚泥!K12=0,"",産廃水産・医療・汚泥!K12) | H14: =IF('A-1'!D13+'A-1'!E13=0,"",'A-1'!D13+'A-1'!E13) | I14: =IF(SUM(B14)*0.54=0,"",SUM(B14)*0.54)
A15: 2 | B15: =IF(SUM(C15:H15)=0,"",SUM(C15:H15)) | C15: =IF(可燃!K13+不燃・木くず・海岸清掃!F13+ビン類!K13+缶類!K13+ペットボトル!K13+粗大!P13+紙類!Q13=0,"",可燃!K13+不燃・木くず・海岸清掃!F13+ビン類!K13+缶類!K13+ペットボトル!K13+粗大!P13+紙類!Q13) | D15: =IF(不燃・木くず・海岸清掃!K13+不燃・木くず・海岸清掃!P13+不燃・木くず・海岸清掃!Z13+可燃!V13+ビン類!V13+缶類!V13+ペットボトル!V13+粗大!Z13=0,"",不燃・木くず・海岸清掃!K13+不燃・木くず・海岸清掃!P13+不燃・木くず・海岸清掃!Z13+可燃!V13+ビン類!V13+缶類!V13+ペットボトル!V13+粗大!Z13) | E15: =IF(産廃水産・医療・汚泥!X13=0,"",産廃水産・医療・汚泥!X13) | F15: =IF(産廃水産・医療・汚泥!P13=0,"",産廃水産・医療・汚泥!P13) | G15: =IF(産廃水産・医療・汚泥!K13=0,"",産廃水産・医療・汚泥!K13) | H15: =IF('A-1'!D14+'A-1'!E14=0,"",'A-1'!D14+'A-1'!E14) | I15: =IF(SUM(B15)*0.54=0,"",SUM(B15)*0.54)
A16: 3 | B16: =IF(SUM(C16:H16)=0,"",SUM(C16:H16)) | C16: =IF(可燃!K14+不燃・木くず・海岸清掃!F14+ビン類!K14+缶類!K14+ペットボトル!K14+粗大!P14+紙類!Q14=0,"",可燃!K14+不燃・木くず・海岸清掃!F14+ビン類!K14+缶類!K14+ペットボトル!K14+粗大!P14+紙類!Q14) | D16: =IF(不燃・木くず・海岸清掃!K14+不燃・木くず・海岸清掃!P14+不燃・木くず・海岸清掃!Z14+可燃!V14+ビン類!V14+缶類!V14+ペットボトル!V14+粗大!Z14=0,"",不燃・木くず・海岸清掃!K14+不燃・木くず・海岸清掃!P14+不燃・木くず・海岸清掃!Z14+可燃!V14+ビン類!V14+缶類!V14+ペットボトル!V14+粗大!Z14) | E16: =IF(産廃水産・医療・汚泥!X14=0,"",産廃水産・医療・汚泥!X14) | F16: =IF(産廃水産・医療・汚泥!P14=0,"",産廃水産・医療・汚泥!P14) | G16: =IF(産廃水産・医療・汚泥!K14=0,"",産廃水産・医療・汚泥!K14) | H16: =IF('A-1'!D15+'A-1'!E15=0,"",'A-1'!D15+'A-1'!E15) | I16: =IF(SUM(B16)*0.54=0,"",SUM(B16)*0.54)
A17: 4 | B17: =IF(SUM(C17:H17)=0,"",SUM(C17:H17)) | C17: =IF(可燃!K15+不燃・木くず・海岸清掃!F15+ビン類!K15+缶類!K15+ペットボトル!K15+粗大!P15+紙類!Q15=0,"",可燃!K15+不燃・木くず・海岸清掃!F15+ビン類!K15+缶類!K15+ペットボトル!K15+粗大!P15+紙類!Q15) | D17: =IF(不燃・木くず・海岸清掃!K15+不燃・木くず・海岸清掃!P15+不燃・木くず・海岸清掃!Z15+可燃!V15+ビン類!V15+缶類!V15+ペットボトル!V15+粗大!Z15=0,"",不燃・木くず・海岸清掃!K15+不燃・木くず・海岸清掃!P15+不燃・木くず・海岸清掃!Z15+可燃!V15+ビン類!V15+缶類!V15+ペットボトル!V15+粗大!Z15) | E17: =IF(産廃水産・医療・汚泥!X15=0,"",産廃水産・医療・汚泥!X15) | F17: =IF(産廃水産・医療・汚泥!P15=0,"",産廃水産・医療・汚泥!P15) | G17: =IF(産廃水産・医療・汚泥!K15=0,"",産廃水産・医療・汚泥!K15) | H17: =IF('A-1'!D16+'A-1'!E16=0,"",'A-1'!D16+'A-1'!E16) | I17: =IF(SUM(B17)*0.54=0,"",SUM(B17)*0.54)
A18: 5 | B18: =IF(SUM(C18:H18)=0,"",SUM(C18:H18)) | C18: =IF(可燃!K16+不燃・木くず・海岸清掃!F16+ビン類!K16+缶類!K16+ペットボトル!K16+粗大!P16+紙類!Q16=0,"",可燃!K16+不燃・木くず・海岸清掃!F16+ビン類!K16+缶類!K16+ペットボトル!K16+粗大!P16+紙類!Q16) | D18: =IF(不燃・木くず・海岸清掃!K16+不燃・木くず・海岸清掃!P16+不燃・木くず・海岸清掃!Z16+可燃!V16+ビン類!V16+缶類!V16+ペットボトル!V16+粗大!Z16=0,"",不燃・木くず・海岸清掃!K16+不燃・木くず・海岸清掃!P16+不燃・木くず・海岸清掃!Z16+可燃!V16+ビン類!V16+缶類!V16+ペットボトル!V16+粗大!Z16) | E18: =IF(産廃水産・医療・汚泥!X16=0,"",産廃水産・医療・汚泥!X16) | F18: =IF(産廃水産・医療・汚泥!P16=0,"",産廃水産・医療・汚泥!P16) | G18: =IF(産廃水産・医療・汚泥!K16=0,"",産廃水産・医療・汚泥!K16) | H18: =IF('A-1'!D17+'A-1'!E17=0,"",'A-1'!D17+'A-1'!E17) | I18: =IF(SUM(B18)*0.54=0,"",SUM(B18)*0.54)
A19: 6 | B19: =IF(SUM(C19:H19)=0,"",SUM(C19:H19)) | C19: =IF(可燃!K17+不燃・木くず・海岸清掃!F17+ビン類!K17+缶類!K17+ペットボトル!K17+粗大!P17+紙類!Q17=0,"",可燃!K17+不燃・木くず・海岸清掃!F17+ビン類!K17+缶類!K17+ペットボトル!K17+粗大!P17+紙類!Q17) | D19: =IF(不燃・木くず・海岸清掃!K17+不燃・木くず・海岸清掃!P17+不燃・木くず・海岸清掃!Z17+可燃!V17+ビン類!V17+缶類!V17+ペットボトル!V17+粗大!Z17=0,"",不燃・木くず・海岸清掃!K17+不燃・木くず・海岸清掃!P17+不燃・木くず・海岸清掃!Z17+可燃!V17+ビン類!V17+缶類!V17+ペットボトル!V17+粗大!Z17) | E19: =IF(産廃水産・医療・汚泥!X17=0,"",産廃水産・医療・汚泥!X17) | F19: =IF(産廃水産・医療・汚泥!P17=0,"",産廃水産・医療・汚泥!P17) | G19: =IF(産廃水産・医療・汚泥!K17=0,"",産廃水産・医療・汚泥!K17) | H19: =IF('A-1'!D18+'A-1'!E18=0,"",'A-1'!D18+'A-1'!E18) | I19: =IF(SUM(B19)*0.54=0,"",SUM(B19)*0.54)
A20: 7 | B20: =IF(SUM(C20:H20)=0,"",SUM(C20:H20)) | C20: =IF(可燃!K18+不燃・木くず・海岸清掃!F18+ビン類!K18+缶類!K18+ペットボトル!K18+粗大!P18+紙類!Q18=0,"",可燃!K18+不燃・木くず・海岸清掃!F18+ビン類!K18+缶類!K18+ペットボトル!K18+粗大!P18+紙類!Q18) | D20: =IF(不燃・木くず・海岸清掃!K18+不燃・木くず・海岸清掃!P18+不燃・木くず・海岸清掃!Z18+可燃!V18+ビン類!V18+缶類!V18+ペットボトル!V18+粗大!Z18=0,"",不燃・木くず・海岸清掃!K18+不燃・木くず・海岸清掃!P18+不燃・木くず・海岸清掃!Z18+可燃!V18+ビン類!V18+缶類!V18+ペットボトル!V18+粗大!Z18) | E20: =IF(産廃水産・医療・汚泥!X18=0,"",産廃水産・医療・汚泥!X18) | F20: =IF(産廃水産・医療・汚泥!P18=0,"",産廃水産・医療・汚泥!P18) | G20: =IF(産廃水産・医療・汚泥!K18=0,"",産廃水産・医療・汚泥!K18) | H20: =IF('A-1'!D19+'A-1'!E19=0,"",'A-1'!D19+'A-1'!E19) | I20: =IF(SUM(B20)*0.54=0,"",SUM(B20)*0.54) | K20: 75 | L20: 7.9 | N20: 20 | P20: 7.4 | R20: 15
A21: 8 | B21: =IF(SUM(C21:H21)=0,"",SUM(C21:H21)) | C21: =IF(可燃!K19+不燃・木くず・海岸清掃!F19+ビン類!K19+缶類!K19+ペットボトル!K19+粗大!P19+紙類!Q19=0,"",可燃!K19+不燃・木くず・海岸清掃!F19+ビン類!K19+缶類!K19+ペットボトル!K19+粗大!P19+紙類!Q19) | D21: =IF(不燃・木くず・海岸清掃!K19+不燃・木くず・海岸清掃!P19+不燃・木くず・海岸清掃!Z19+可燃!V19+ビン類!V19+缶類!V19+ペットボトル!V19+粗大!Z19=0,"",不燃・木くず・海岸清掃!K19+不燃・木くず・海岸清掃!P19+不燃・木くず・海岸清掃!Z19+可燃!V19+ビン類!V19+缶類!V19+ペットボトル!V19+粗大!Z19) | E21: =IF(産廃水産・医療・汚泥!X19=0,"",産廃水産・医療・汚泥!X19) | F21: =IF(産廃水産・医療・汚泥!P19=0,"",産廃水産・医療・汚泥!P19) | G21: =IF(産廃水産・医療・汚泥!K19=0,"",産廃水産・医療・汚泥!K19) | H21: =IF('A-1'!D20+'A-1'!E20=0,"",'A-1'!D20+'A-1'!E20) | I21: =IF(SUM(B21)*0.54=0,"",SUM(B21)*0.54)
A22: 9 | B22: =IF(SUM(C22:H22)=0,"",SUM(C22:H22)) | C22: =IF(可燃!K20+不燃・木くず・海岸清掃!F20+ビン類!K20+缶類!K20+ペットボトル!K20+粗大!P20+紙類!Q20=0,"",可燃!K20+不燃・木くず・海岸清掃!F20+ビン類!K20+缶類!K20+ペットボトル!K20+粗大!P20+紙類!Q20) | D22: =IF(不燃・木くず・海岸清掃!K20+不燃・木くず・海岸清掃!P20+不燃・木くず・海岸清掃!Z20+可燃!V20+ビン類!V20+缶類!V20+ペットボトル!V20+粗大!Z20=0,"",不燃・木くず・海岸清掃!K20+不燃・木くず・海岸清掃!P20+不燃・木くず・海岸清掃!Z20+可燃!V20+ビン類!V20+缶類!V20+ペットボトル!V20+粗大!Z20) | E22: =IF(産廃水産・医療・汚泥!X20=0,"",産廃水産・医療・汚泥!X20) | F22: =IF(産廃水産・医療・汚泥!P20=0,"",産廃水産・医療・汚泥!P20) | G22: =IF(産廃水産・医療・汚泥!K20=0,"",産廃水産・医療・汚泥!K20) | H22: =IF('A-1'!D21+'A-1'!E21=0,"",'A-1'!D21+'A-1'!E21) | I22: =IF(SUM(B22)*0.54=0,"",SUM(B22)*0.54)
A23: 10 | B23: =IF(SUM(C23:H23)=0,"",SUM(C23:H23)) | C23: =IF(可燃!K21+不燃・木くず・海岸清掃!F21+ビン類!K21+缶類!K21+ペットボトル!K21+粗大!P21+紙類!Q21=0,"",可燃!K21+不燃・木くず・海岸清掃!F21+ビン類!K21+缶類!K21+ペットボトル!K21+粗大!P21+紙類!Q21) | D23: =IF(不燃・木くず・海岸清掃!K21+不燃・木くず・海岸清掃!P21+不燃・木くず・海岸清掃!Z21+可燃!V21+ビン類!V21+缶類!V21+ペットボトル!V21+粗大!Z21=0,"",不燃・木くず・海岸清掃!K21+不燃・木くず・海岸清掃!P21+不燃・木くず・海岸清掃!Z21+可燃!V21+ビン類!V21+缶類!V21+ペットボトル!V21+粗大!Z21) | E23: =IF(産廃水産・医療・汚泥!X21=0,"",産廃水産・医療・汚泥!X21) | F23: =IF(産廃水産・医療・汚泥!P21=0,"",産廃水産・医療・汚泥!P21) | G23: =IF(産廃水産・医療・汚泥!K21=0,"",産廃水産・医療・汚泥!K21) | H23: =IF('A-1'!D22+'A-1'!E22=0,"",'A-1'!D22+'A-1'!E22) | I23: =IF(SUM(B23)*0.54=0,"",SUM(B23)*0.54)
A24: 11 | B24: =IF(SUM(C24:H24)=0,"",SUM(C24:H24)) | C24: =IF(可燃!K22+不燃・木くず・海岸清掃!F22+ビン類!K22+缶類!K22+ペットボトル!K22+粗大!P22+紙類!Q22=0,"",可燃!K22+不燃・木くず・海岸清掃!F22+ビン類!K22+缶類!K22+ペットボトル!K22+粗大!P22+紙類!Q22) | D24: =IF(不燃・木くず・海岸清掃!K22+不燃・木くず・海岸清掃!P22+不燃・木くず・海岸清掃!Z22+可燃!V22+ビン類!V22+缶類!V22+ペットボトル!V22+粗大!Z22=0,"",不燃・木くず・海岸清掃!K22+不燃・木くず・海岸清掃!P22+不燃・木くず・海岸清掃!Z22+可燃!V22+ビン類!V22+缶類!V22+ペットボトル!V22+粗大!Z22) | E24: =IF(産廃水産・医療・汚泥!X22=0,"",産廃水産・医療・汚泥!X22) | F24: =IF(産廃水産・医療・汚泥!P22=0,"",産廃水産・医療・汚泥!P22) | G24: =IF(産廃水産・医療・汚泥!K22=0,"",産廃水産・医療・汚泥!K22) | H24: =IF('A-1'!D23+'A-1'!E23=0,"",'A-1'!D23+'A-1'!E23) | I24: =IF(SUM(B24)*0.54=0,"",SUM(B24)*0.54)
A25: 12 | B25: =IF(SUM(C25:H25)=0,"",SUM(C25:H25)) | C25: =IF(可燃!K23+不燃・木くず・海岸清掃!F23+ビン類!K23+缶類!K23+ペットボトル!K23+粗大!P23+紙類!Q23=0,"",可燃!K23+不燃・木くず・海岸清掃!F23+ビン類!K23+缶類!K23+ペットボトル!K23+粗大!P23+紙類!Q23) | D25: =IF(不燃・木くず・海岸清掃!K23+不燃・木くず・海岸清掃!P23+不燃・木くず・海岸清掃!Z23+可燃!V23+ビン類!V23+缶類!V23+ペットボトル!V23+粗大!Z23=0,"",不燃・木くず・海岸清掃!K23+不燃・木くず・海岸清掃!P23+不燃・木くず・海岸清掃!Z23+可燃!V23+ビン類!V23+缶類!V23+ペットボトル!V23+粗大!Z23) | E25: =IF(産廃水産・医療・汚泥!X23=0,"",産廃水産・医療・汚泥!X23) | F25: =IF(産廃水産・医療・汚泥!P23=0,"",産廃水産・医療・汚泥!P23) | G25: =IF(産廃水産・医療・汚泥!K23=0,"",産廃水産・医療・汚泥!K23) | H25: =IF('A-1'!D24+'A-1'!E24=0,"",'A-1'!D24+'A-1'!E24) | I25: =IF(SUM(B25)*0.54=0,"",SUM(B25)*0.54) | L25: 7.3 | M25: 9.8 | N25: 21.3 | O25: 6 | P25: 7.2 | Q25: 1.9 | R25: 14.7 | S25: 1.6 | T25: 0
A26: 13 | B26: =IF(SUM(C26:H26)=0,"",SUM(C26:H26)) | C26: =IF(可燃!K24+不燃・木くず・海岸清掃!F24+ビン類!K24+缶類!K24+ペットボトル!K24+粗大!P24+紙類!Q24=0,"",可燃!K24+不燃・木くず・海岸清掃!F24+ビン類!K24+缶類!K24+ペットボトル!K24+粗大!P24+紙類!Q24) | D26: =IF(不燃・木くず・海岸清掃!K24+不燃・木くず・海岸清掃!P24+不燃・木くず・海岸清掃!Z24+可燃!V24+ビン類!V24+缶類!V24+ペットボトル!V24+粗大!Z24=0,"",不燃・木くず・海岸清掃!K24+不燃・木くず・海岸清掃!P24+不燃・木くず・海岸清掃!Z24+可燃!V24+ビン類!V24+缶類!V24+ペットボトル!V24+粗大!Z24) | E26: =IF(産廃水産・医療・汚泥!X24=0,"",産廃水産・医療・汚泥!X24) | F26: =IF(産廃水産・医療・汚泥!P24=0,"",産廃水産・医療・汚泥!P24) | G26: =IF(産廃水産・医療・汚泥!K24=0,"",産廃水産・医療・汚泥!K24) | H26: =IF('A-1'!D25+'A-1'!E25=0,"",'A-1'!D25+'A-1'!E25) | I26: =IF(SUM(B26)*0.54=0,"",SUM(B26)*0.54)
A27: 14 | B27: =IF(SUM(C27:H27)=0,"",SUM(C27:H27)) | C27: =IF(可燃!K25+不燃・木くず・海岸清掃!F25+ビン類!K25+缶類!K25+ペットボトル!K25+粗大!P25+紙類!Q25=0,"",可燃!K25+不燃・木くず・海岸清掃!F25+ビン類!K25+缶類!K25+ペットボトル!K25+粗大!P25+紙類!Q25) | D27: =IF(不燃・木くず・海岸清掃!K25+不燃・木くず・海岸清掃!P25+不燃・木くず・海岸清掃!Z25+可燃!V25+ビン類!V25+缶類!V25+ペットボトル!V25+粗大!Z25=0,"",不燃・木くず・海岸清掃!K25+不燃・木くず・海岸清掃!P25+不燃・木くず・海岸清掃!Z25+可燃!V25+ビン類!V25+缶類!V25+ペットボトル!V25+粗大!Z25) | E27: =IF(産廃水産・医療・汚泥!X25=0,"",産廃水産・医療・汚泥!X25) | F27: =IF(産廃水産・医療・汚泥!P25=0,"",産廃水産・医療・汚泥!P25) | G27: =IF(産廃水産・医療・汚泥!K25=0,"",産廃水産・医療・汚泥!K25) | H27: =IF('A-1'!D26+'A-1'!E26=0,"",'A-1'!D26+'A-1'!E26) | I27: =IF(SUM(B27)*0.54=0,"",SUM(B27)*0.54) | K27: 75 | L27: 7.9 | N27: 20 | P27: 7.3 | R27: 15
A28: 15 | B28: =IF(SUM(C28:H28)=0,"",SUM(C28:H28)) | C28: =IF(可燃!K26+不燃・木くず・海岸清掃!F26+ビン類!K26+缶類!K26+ペットボトル!K26+粗大!P26+紙類!Q26=0,"",可燃!K26+不燃・木くず・海岸清掃!F26+ビン類!K26+缶類!K26+ペットボトル!K26+粗大!P26+紙類!Q26) | D28: =IF(不燃・木くず・海岸清掃!K26+不燃・木くず・海岸清掃!P26+不燃・木くず・海岸清掃!Z26+可燃!V26+ビン類!V26+缶類!V26+ペットボトル!V26+粗大!Z26=0,"",不燃・木くず・海岸清掃!K26+不燃・木くず・海岸清掃!P26+不燃・木くず・海岸清掃!Z26+可燃!V26+ビン類!V26+缶類!V26+ペットボトル!V26+粗大!Z26) | E28: =IF(産廃水産・医療・汚泥!X26=0,"",産廃水産・医療・汚泥!X26) | F28: =IF(産廃水産・医療・汚泥!P26=0,"",産廃水産・医療・汚泥!P26) | G28: =IF(産廃水産・医療・汚泥!K26=0,"",産廃水産・医療・汚泥!K26) | H28: =IF('A-1'!D27+'A-1'!E27=0,"",'A-1'!D27+'A-1'!E27) | I28: =IF(SUM(B28)*0.54=0,"",SUM(B28)*0.54)
A29: 16 | B29: =IF(SUM(C29:H29)=0,"",SUM(C29:H29)) | C29: =IF(可燃!K27+不燃・木くず・海岸清掃!F27+ビン類!K27+缶類!K27+ペットボトル!K27+粗大!P27+紙類!Q27=0,"",可燃!K27+不燃・木くず・海岸清掃!F27+ビン類!K27+缶類!K27+ペットボトル!K27+粗大!P27+紙類!Q27) | D29: =IF(不燃・木くず・海岸清掃!K27+不燃・木くず・海岸清掃!P27+不燃・木くず・海岸清掃!Z27+可燃!V27+ビン類!V27+缶類!V27+ペットボトル!V27+粗大!Z27=0,"",不燃・木くず・海岸清掃!K27+不燃・木くず・海岸清掃!P27+不燃・木くず・海岸清掃!Z27+可燃!V27+ビン類!V27+缶類!V27+ペットボトル!V27+粗大!Z27) | E29: =IF(産廃水産・医療・汚泥!X27=0,"",産廃水産・医療・汚泥!X27) | F29: =IF(産廃水産・医療・汚泥!P27=0,"",産廃水産・医療・汚泥!P27) | G29: =IF(産廃水産・医療・汚泥!K27=0,"",産廃水産・医療・汚泥!K27) | H29: =IF('A-1'!D28+'A-1'!E28=0,"",'A-1'!D28+'A-1'!E28) | I29: =IF(SUM(B29)*0.54=0,"",SUM(B29)*0.54)
A30: 17 | B30: =IF(SUM(C30:H30)=0,"",SUM(C30:H30)) | C30: =IF(可燃!K28+不燃・木くず・海岸清掃!F28+ビン類!K28+缶類!K28+ペットボトル!K28+粗大!P28+紙類!Q28=0,"",可燃!K28+不燃・木くず・海岸清掃!F28+ビン類!K28+缶類!K28+ペットボトル!K28+粗大!P28+紙類!Q28) | D30: =IF(不燃・木くず・海岸清掃!K28+不燃・木くず・海岸清掃!P28+不燃・木くず・海岸清掃!Z28+可燃!V28+ビン類!V28+缶類!V28+ペットボトル!V28+粗大!Z28=0,"",不燃・木くず・海岸清掃!K28+不燃・木くず・海岸清掃!P28+不燃・木くず・海岸清掃!Z28+可燃!V28+ビン類!V28+缶類!V28+ペットボトル!V28+粗大!Z28) | E30: =IF(産廃水産・医療・汚泥!X28=0,"",産廃水産・医療・汚泥!X28) | F30: =IF(産廃水産・医療・汚泥!P28=0,"",産廃水産・医療・汚泥!P28) | G30: =IF(産廃水産・医療・汚泥!K28=0,"",産廃水産・医療・汚泥!K28) | H30: =IF('A-1'!D29+'A-1'!E29=0,"",'A-1'!D29+'A-1'!E29) | I30: =IF(SUM(B30)*0.54=0,"",SUM(B30)*0.54)
A31: 18 | B31: =IF(SUM(C31:H31)=0,"",SUM(C31:H31)) | C31: =IF(可燃!K29+不燃・木くず・海岸清掃!F29+ビン類!K29+缶類!K29+ペットボトル!K29+粗大!P29+紙類!Q29=0,"",可燃!K29+不燃・木くず・海岸清掃!F29+ビン類!K29+缶類!K29+ペットボトル!K29+粗大!P29+紙類!Q29) | D31: =IF(不燃・木くず・海岸清掃!K29+不燃・木くず・海岸清掃!P29+不燃・木くず・海岸清掃!Z29+可燃!V29+ビン類!V29+缶類!V29+ペットボトル!V29+粗大!Z29=0,"",不燃・木くず・海岸清掃!K29+不燃・木くず・海岸清掃!P29+不燃・木くず・海岸清掃!Z29+可燃!V29+ビン類!V29+缶類!V29+ペットボトル!V29+粗大!Z29) | E31: =IF(産廃水産・医療・汚泥!X29=0,"",産廃水産・医療・汚泥!X29) | F31: =IF(産廃水産・医療・汚泥!P29=0,"",産廃水産・医療・汚泥!P29) | G31: =IF(産廃水産・医療・汚泥!K29=0,"",産廃水産・医療・汚泥!K29) | H31: =IF('A-1'!D30+'A-1'!E30=0,"",'A-1'!D30+'A-1'!E30) | I31: =IF(SUM(B31)*0.54=0,"",SUM(B31)*0.54)
A32: 19 | B32: =IF(SUM(C32:H32)=0,"",SUM(C32:H32)) | C32: =IF(可燃!K30+不燃・木くず・海岸清掃!F30+ビン類!K30+缶類!K30+ペットボトル!K30+粗大!P30+紙類!Q30=0,"",可燃!K30+不燃・木くず・海岸清掃!F30+ビン類!K30+缶類!K30+ペットボトル!K30+粗大!P30+紙類!Q30) | D32: =IF(不燃・木くず・海岸清掃!K30+不燃・木くず・海岸清掃!P30+不燃・木くず・海岸清掃!Z30+可燃!V30+ビン類!V30+缶類!V30+ペットボトル!V30+粗大!Z30=0,"",不燃・木くず・海岸清掃!K30+不燃・木くず・海岸清掃!P30+不燃・木くず・海岸清掃!Z30+可燃!V30+ビン類!V30+缶類!V30+ペットボトル!V30+粗大!Z30) | E32: =IF(産廃水産・医療・汚泥!X30=0,"",産廃水産・医療・汚泥!X30) | F32: =IF(産廃水産・医療・汚泥!P30=0,"",産廃水産・医療・汚泥!P30) | G32: =IF(産廃水産・医療・汚泥!K30=0,"",産廃水産・医療・汚泥!K30) | H32: =IF('A-1'!D31+'A-1'!E31=0,"",'A-1'!D31+'A-1'!E31) | I32: =IF(SUM(B32)*0.54=0,"",SUM(B32)*0.54)
A33: 20 | B33: =IF(SUM(C33:H33)=0,"",SUM(C33:H33)) | C33: =IF(可燃!K31+不燃・木くず・海岸清掃!F31+ビン類!K31+缶類!K31+ペットボトル!K31+粗大!P31+紙類!Q31=0,"",可燃!K31+不燃・木くず・海岸清掃!F31+ビン類!K31+缶類!K31+ペットボトル!K31+粗大!P31+紙類!Q31) | D33: =IF(不燃・木くず・海岸清掃!K31+不燃・木くず・海岸清掃!P31+不燃・木くず・海岸清掃!Z31+可燃!V31+ビン類!V31+缶類!V31+ペットボトル!V31+粗大!Z31=0,"",不燃・木くず・海岸清掃!K31+不燃・木くず・海岸清掃!P31+不燃・木くず・海岸清掃!Z31+可燃!V31+ビン類!V31+缶類!V31+ペットボトル!V31+粗大!Z31) | E33: =IF(産廃水産・医療・汚泥!X31=0,"",産廃水産・医療・汚泥!X31) | F33: =IF(産廃水産・医療・汚泥!P31=0,"",産廃水産・医療・汚泥!P31) | G33: =IF(産廃水産・医療・汚泥!K31=0,"",産廃水産・医療・汚泥!K31) | H33: =IF('A-1'!D32+'A-1'!E32=0,"",'A-1'!D32+'A-1'!E32) | I33: =IF(SUM(B33)*0.54=0,"",SUM(B33)*0.54)
A34: 21 | B34: =IF(SUM(C34:H34)=0,"",SUM(C34:H34)) | C34: =IF(可燃!K32+不燃・木くず・海岸清掃!F32+ビン類!K32+缶類!K32+ペットボトル!K32+粗大!P32+紙類!Q32=0,"",可燃!K32+不燃・木くず・海岸清掃!F32+ビン類!K32+缶類!K32+ペットボトル!K32+粗大!P32+紙類!Q32) | D34: =IF(不燃・木くず・海岸清掃!K32+不燃・木くず・海岸清掃!P32+不燃・木くず・海岸清掃!Z32+可燃!V32+ビン類!V32+缶類!V32+ペットボトル!V32+粗大!Z32=0,"",不燃・木くず・海岸清掃!K32+不燃・木くず・海岸清掃!P32+不燃・木くず・海岸清掃!Z32+可燃!V32+ビン類!V32+缶類!V32+ペットボトル!V32+粗大!Z32) | E34: =IF(産廃水産・医療・汚泥!X32=0,"",産廃水産・医療・汚泥!X32) | F34: =IF(産廃水産・医療・汚泥!P32=0,"",産廃水産・医療・汚泥!P32) | G34: =IF(産廃水産・医療・汚泥!K32=0,"",産廃水産・医療・汚泥!K32) | H34: =IF('A-1'!D33+'A-1'!E33=0,"",'A-1'!D33+'A-1'!E33) | I34: =IF(SUM(B34)*0.54=0,"",SUM(B34)*0.54) | K34: 75 | L34: 7.9 | N34: 23 | P34: 7.4 | R34: 15
A35: 22 | B35: =IF(SUM(C35:H35)=0,"",SUM(C35:H35)) | C35: =IF(可燃!K33+不燃・木くず・海岸清掃!F33+ビン類!K33+缶類!K33+ペットボトル!K33+粗大!P33+紙類!Q33=0,"",可燃!K33+不燃・木くず・海岸清掃!F33+ビン類!K33+缶類!K33+ペットボトル!K33+粗大!P33+紙類!Q33) | D35: =IF(不燃・木くず・海岸清掃!K33+不燃・木くず・海岸清掃!P33+不燃・木くず・海岸清掃!Z33+可燃!V33+ビン類!V33+缶類!V33+ペットボトル!V33+粗大!Z33=0,"",不燃・木くず・海岸清掃!K33+不燃・木くず・海岸清掃!P33+不燃・木くず・海岸清掃!Z33+可燃!V33+ビン類!V33+缶類!V33+ペットボトル!V33+粗大!Z33) | E35: =IF(産廃水産・医療・汚泥!X33=0,"",産廃水産・医療・汚泥!X33) | F35: =IF(産廃水産・医療・汚泥!P33=0,"",産廃水産・医療・汚泥!P33) | G35: =IF(産廃水産・医療・汚泥!K33=0,"",産廃水産・医療・汚泥!K33) | H35: =IF('A-1'!D34+'A-1'!E34=0,"",'A-1'!D34+'A-1'!E34) | I35: =IF(SUM(B35)*0.54=0,"",SUM(B35)*0.54)
A36: 23 | B36: =IF(SUM(C36:H36)=0,"",SUM(C36:H36)) | C36: =IF(可燃!K34+不燃・木くず・海岸清掃!F34+ビン類!K34+缶類!K34+ペットボトル!K34+粗大!P34+紙類!Q34=0,"",可燃!K34+不燃・木くず・海岸清掃!F34+ビン類!K34+缶類!K34+ペットボトル!K34+粗大!P34+紙類!Q34) | D36: =IF(不燃・木くず・海岸清掃!K34+不燃・木くず・海岸清掃!P34+不燃・木くず・海岸清掃!Z34+可燃!V34+ビン類!V34+缶類!V34+ペットボトル!V34+粗大!Z34=0,"",不燃・木くず・海岸清掃!K34+不燃・木くず・海岸清掃!P34+不燃・木くず・海岸清掃!Z34+可燃!V34+ビン類!V34+缶類!V34+ペットボトル!V34+粗大!Z34) | E36: =IF(産廃水産・医療・汚泥!X34=0,"",産廃水産・医療・汚泥!X34) | F36: =IF(産廃水産・医療・汚泥!P34=0,"",産廃水産・医療・汚泥!P34) | G36: =IF(産廃水産・医療・汚泥!K34=0,"",産廃水産・医療・汚泥!K34) | H36: =IF('A-1'!D35+'A-1'!E35=0,"",'A-1'!D35+'A-1'!E35) | I36: =IF(SUM(B36)*0.54=0,"",SUM(B36)*0.54)
A37: 24 | B37: =IF(SUM(C37:H37)=0,"",SUM(C37:H37)) | C37: =IF(可燃!K35+不燃・木くず・海岸清掃!F35+ビン類!K35+缶類!K35+ペットボトル!K35+粗大!P35+紙類!Q35=0,"",可燃!K35+不燃・木くず・海岸清掃!F35+ビン類!K35+缶類!K35+ペットボトル!K35+粗大!P35+紙類!Q35) | D37: =IF(不燃・木くず・海岸清掃!K35+不燃・木くず・海岸清掃!P35+不燃・木くず・海岸清掃!Z35+可燃!V35+ビン類!V35+缶類!V35+ペットボトル!V35+粗大!Z35=0,"",不燃・木くず・海岸清掃!K35+不燃・木くず・海岸清掃!P35+不燃・木くず・海岸清掃!Z35+可燃!V35+ビン類!V35+缶類!V35+ペットボトル!V35+粗大!Z35) | E37: =IF(産廃水産・医療・汚泥!X35=0,"",産廃水産・医療・汚泥!X35) | F37: =IF(産廃水産・医療・汚泥!P35=0,"",産廃水産・医療・汚泥!P35) | G37: =IF(産廃水産・医療・汚泥!K35=0,"",産廃水産・医療・汚泥!K35) | H37: =IF('A-1'!D36+'A-1'!E36=0,"",'A-1'!D36+'A-1'!E36) | I37: =IF(SUM(B37)*0.54=0,"",SUM(B37)*0.54)
A38: 25 | B38: =IF(SUM(C38:H38)=0,"",SUM(C38:H38)) | C38: =IF(可燃!K36+不燃・木くず・海岸清掃!F36+ビン類!K36+缶類!K36+ペットボトル!K36+粗大!P36+紙類!Q36=0,"",可燃!K36+不燃・木くず・海岸清掃!F36+ビン類!K36+缶類!K36+ペットボトル!K36+粗大!P36+紙類!Q36) | D38: =IF(不燃・木くず・海岸清掃!K36+不燃・木くず・海岸清掃!P36+不燃・木くず・海岸清掃!Z36+可燃!V36+ビン類!V36+缶類!V36+ペットボトル!V36+粗大!Z36=0,"",不燃・木くず・海岸清掃!K36+不燃・木くず・海岸清掃!P36+不燃・木くず・海岸清掃!Z36+可燃!V36+ビン類!V36+缶類!V36+ペットボトル!V36+粗大!Z36) | E38: =IF(産廃水産・医療・汚泥!X36=0,"",産廃水産・医療・汚泥!X36) | F38: =IF(産廃水産・医療・汚泥!P36=0,"",産廃水産・医療・汚泥!P36) | G38: =IF(産廃水産・医療・汚泥!K36=0,"",産廃水産・医療・汚泥!K36) | H38: =IF('A-1'!D37+'A-1'!E37=0,"",'A-1'!D37+'A-1'!E37) | I38: =IF(SUM(B38)*0.54=0,"",SUM(B38)*0.54)
A39: 26 | B39: =IF(SUM(C39:H39)=0,"",SUM(C39:H39)) | C39: =IF(可燃!K37+不燃・木くず・海岸清掃!F37+ビン類!K37+缶類!K37+ペットボトル!K37+粗大!P37+紙類!Q37=0,"",可燃!K37+不燃・木くず・海岸清掃!F37+ビン類!K37+缶類!K37+ペットボトル!K37+粗大!P37+紙類!Q37) | D39: =IF(不燃・木くず・海岸清掃!K37+不燃・木くず・海岸清掃!P37+不燃・木くず・海岸清掃!Z37+可燃!V37+ビン類!V37+缶類!V37+ペットボトル!V37+粗大!Z37=0,"",不燃・木くず・海岸清掃!K37+不燃・木くず・海岸清掃!P37+不燃・木くず・海岸清掃!Z37+可燃!V37+ビン類!V37+缶類!V37+ペットボトル!V37+粗大!Z37) | E39: =IF(産廃水産・医療・汚泥!X37=0,"",産廃水産・医療・汚泥!X37) | F39: =IF(産廃水産・医療・汚泥!P37=0,"",産廃水産・医療・汚泥!P37) | G39: =IF(産廃水産・医療・汚泥!K37=0,"",産廃水産・医療・汚泥!K37) | H39: =IF('A-1'!D38+'A-1'!E38=0,"",'A-1'!D38+'A-1'!E38) | I39: =IF(SUM(B39)*0.54=0,"",SUM(B39)*0.54)
A40: 27 | B40: =IF(SUM(C40:H40)=0,"",SUM(C40:H40)) | C40: =IF(可燃!K38+不燃・木くず・海岸清掃!F38+ビン類!K38+缶類!K38+ペットボトル!K38+粗大!P38+紙類!Q38=0,"",可燃!K38+不燃・木くず・海岸清掃!F38+ビン類!K38+缶類!K38+ペットボトル!K38+粗大!P38+紙類!Q38) | D40: =IF(不燃・木くず・海岸清掃!K38+不燃・木くず・海岸清掃!P38+不燃・木くず・海岸清掃!Z38+可燃!V38+ビン類!V38+缶類!V38+ペットボトル!V38+粗大!Z38=0,"",不燃・木くず・海岸清掃!K38+不燃・木くず・海岸清掃!P38+不燃・木くず・海岸清掃!Z38+可燃!V38+ビン類!V38+缶類!V38+ペットボトル!V38+粗大!Z38) | E40: =IF(産廃水産・医療・汚泥!X38=0,"",産廃水産・医療・汚泥!X38) | F40: =IF(産廃水産・医療・汚泥!P38=0,"",産廃水産・医療・汚泥!P38) | G40: =IF(産廃水産・医療・汚泥!K38=0,"",産廃水産・医療・汚泥!K38) | H40: =IF('A-1'!D39+'A-1'!E39=0,"",'A-1'!D39+'A-1'!E39) | I40: =IF(SUM(B40)*0.54=0,"",SUM(B40)*0.54)
A41: 28 | B41: =IF(SUM(C41:H41)=0,"",SUM(C41:H41)) | C41: =IF(可燃!K39+不燃・木くず・海岸清掃!F39+ビン類!K39+缶類!K39+ペットボトル!K39+粗大!P39+紙類!Q39=0,"",可燃!K39+不燃・木くず・海岸清掃!F39+ビン類!K39+缶類!K39+ペットボトル!K39+粗大!P39+紙類!Q39) | D41: =IF(不燃・木くず・海岸清掃!K39+不燃・木くず・海岸清掃!P39+不燃・木くず・海岸清掃!Z39+可燃!V39+ビン類!V39+缶類!V39+ペットボトル!V39+粗大!Z39=0,"",不燃・木くず・海岸清掃!K39+不燃・木くず・海岸清掃!P39+不燃・木くず・海岸清掃!Z39+可燃!V39+ビン類!V39+缶類!V39+ペットボトル!V39+粗大!Z39) | E41: =IF(産廃水産・医療・汚泥!X39=0,"",産廃水産・医療・汚泥!X39) | F41: =IF(産廃水産・医療・汚泥!P39=0,"",産廃水産・医療・汚泥!P39) | G41: =IF(産廃水産・医療・汚泥!K39=0,"",産廃水産・医療・汚泥!K39) | H41: =IF('A-1'!D40+'A-1'!E40=0,"",'A-1'!D40+'A-1'!E40) | I41: =IF(SUM(B41)*0.54=0,"",SUM(B41)*0.54) | K41: 75 | L41: 7.7 | N41: 20 | P41: 7.4 | R41: 30
A42: 29 | B42: =IF(SUM(C42:H42)=0,"",SUM(C42:H42)) | C42: =IF(可燃!K40+不燃・木くず・海岸清掃!F40+ビン類!K40+缶類!K40+ペットボトル!K40+粗大!P40+紙類!Q40=0,"",可燃!K40+不燃・木くず・海岸清掃!F40+ビン類!K40+缶類!K40+ペットボトル!K40+粗大!P40+紙類!Q40) | D42: =IF(不燃・木くず・海岸清掃!K40+不燃・木くず・海岸清掃!P40+不燃・木くず・海岸清掃!Z40+可燃!V40+ビン類!V40+缶類!V40+ペットボトル!V40+粗大!Z40=0,"",不燃・木くず・海岸清掃!K40+不燃・木くず・海岸清掃!P40+不燃・木くず・海岸清掃!Z40+可燃!V40+ビン類!V40+缶類!V40+ペットボトル!V40+粗大!Z40) | E42: =IF(産廃水産・医療・汚泥!X40=0,"",産廃水産・医療・汚泥!X40) | F42: =IF(産廃水産・医療・汚泥!P40=0,"",産廃水産・医療・汚泥!P40) | G42: =IF(産廃水産・医療・汚泥!K40=0,"",産廃水産・医療・汚泥!K40) | H42: =IF('A-1'!D41+'A-1'!E41=0,"",'A-1'!D41+'A-1'!E41) | I42: =IF(SUM(B42)*0.54=0,"",SUM(B42)*0.54)
...

Sheet 収集（全般）
A1: 収集可燃・資源となるごみ・燃やせないごみの内訳表
B9: ='A-1'!B9:D9 -> (令和9年07月)
B10: 収 集 | G10: 収 集 | L10: 収 集 | Q10: 収 集 | V10: 収 集 | AA10: 収 集
A11: 日 | B11: 燃やせるごみ | G11: 燃やせないごみ | L11: 資源ごみ（ビン類） | Q11: 資源ごみ（缶類） | V11: 資源ごみ（ペットボトル） | AA11: 資源ごみ（紙類）
B12: 鬼脇 | C12: 鴛泊 | D12: 仙法志 | E12: 沓形 | F12: 合計 | G12: 鬼脇 | H12: 鴛泊 | I12: 仙法志 | J12: 沓形 | K12: 合計 | L12: 鬼脇 | M12: 鴛泊 | N12: 仙法志 | O12: 沓形 | P12: 合計 | Q12: 鬼脇 | R12: 鴛泊 | S12: 仙法志 | T12: 沓形 | U12: 合計 | V12: 鬼脇 | W12: 鴛泊 | X12: 仙法志 | Y12: 沓形 | Z12: 合計 | AA12: 鬼脇 | AB12: 鴛泊 | AC12: 仙法志 | AD12: 沓形 | AE12: 合計
A13: 1 | F13: =SUM(B13:E13) -> 0 | K13: =SUM(G13:J13) -> 0 | P13: =SUM(L13:O13) -> 0 | U13: =SUM(Q13:T13) -> 0 | Z13: =SUM(V13:Y13) -> 0 | AE13: =SUM(AA13:AD13) -> 0
A14: 2 | F14: =SUM(B14:E14) -> 0 | K14: =SUM(G14:J14) -> 0 | P14: =SUM(L14:O14) -> 0 | U14: =SUM(Q14:T14) -> 0 | Z14: =SUM(V14:Y14) -> 0 | AE14: =SUM(AA14:AD14) -> 0
A15: 3 | F15: =SUM(B15:E15) -> 0 | K15: =SUM(G15:J15) -> 0 | P15: =SUM(L15:O15) -> 0 | U15: =SUM(Q15:T15) -> 0 | Z15: =SUM(V15:Y15) -> 0 | AE15: =SUM(AA15:AD15) -> 0
A16: 4 | F16: =SUM(B16:E16) -> 0 | K16: =SUM(G16:J16) -> 0 | P16: =SUM(L16:O16) -> 0 | U16: =SUM(Q16:T16) -> 0 | Z16: =SUM(V16:Y16) -> 0 | AE16: =SUM(AA16:AD16) -> 0
A17: 5 | F17: =SUM(B17:E17) -> 0 | K17: =SUM(G17:J17) -> 0 | P17: =SUM(L17:O17) -> 0 | U17: =SUM(Q17:T17) -> 0 | Z17: =SUM(V17:Y17) -> 0 | AE17: =SUM(AA17:AD17) -> 0
A18: 6 | F18: =SUM(B18:E18) -> 0 | K18: =SUM(G18:J18) -> 0 | P18: =SUM(L18:O18) -> 0 | U18: =SUM(Q18:T18) -> 0 | Z18: =SUM(V18:Y18) -> 0 | AE18: =SUM(AA18:AD18) -> 0
A19: 7 | F19: =SUM(B19:E19) -> 0 | K19: =SUM(G19:J19) -> 0 | P19: =SUM(L19:O19) -> 0 | U19: =SUM(Q19:T19) -> 0 | Z19: =SUM(V19:Y19) -> 0 | AE19: =SUM(AA19:AD19) -> 0
A20: 8 | F20: =SUM(B20:E20) -> 0 | K20: =SUM(G20:J20) -> 0 | P20: =SUM(L20:O20) -> 0 | U20: =SUM(Q20:T20) -> 0 | Z20: =SUM(V20:Y20) -> 0 | AE20: =SUM(AA20:AD20) -> 0
A21: 9 | F21: =SUM(B21:E21) -> 0 | K21: =SUM(G21:J21) -> 0 | P21: =SUM(L21:O21) -> 0 | U21: =SUM(Q21:T21) -> 0 | Z21: =SUM(V21:Y21) -> 0 | AE21: =SUM(AA21:AD21) -> 0
A22: 10 | F22: =SUM(B22:E22) -> 0 | K22: =SUM(G22:J22) -> 0 | P22: =SUM(L22:O22) -> 0 | U22: =SUM(Q22:T22) -> 0 | Z22: =SUM(V22:Y22) -> 0 | AE22: =SUM(AA22:AD22) -> 0
A23: 11 | F23: =SUM(B23:E23) -> 0 | K23: =SUM(G23:J23) -> 0 | P23: =SUM(L23:O23) -> 0 | U23: =SUM(Q23:T23) -> 0 | Z23: =SUM(V23:Y23) -> 0 | AE23: =SUM(AA23:AD23) -> 0
A24: 12 | F24: =SUM(B24:E24) -> 0 | K24: =SUM(G24:J24) -> 0 | P24: =SUM(L24:O24) -> 0 | U24: =SUM(Q24:T24) -> 0 | Z24: =SUM(V24:Y24) -> 0 | AE24: =SUM(AA24:AD24) -> 0
... A43: 31 | F43: =SUM(B43:E43) -> 0 | K43: =SUM(G43:J43) -> 0 | P43: =SUM(L43:O43) -> 0 | U43: =SUM(Q43:T43) -> 0 | Z43: =SUM(V43:Y43) -> 0 | AE43: =SUM(AA43:AD43) -> 0
A44: 合計 | B44: =SUM(B13:B43) -> 0 | C44: =SUM(C13:C43) -> 0 | D44: =SUM(D13:D43) -> 0 | E44: =SUM(E13:E43) -> 0 | F44: =SUM(F13:F43) -> 0 | G44: =SUM(G13:G43) -> 0 | H44: =SUM(H13:H43) -> 0 | I44: =SUM(I13:I43) -> 0 | ... AE44: =SUM(AE13:AE43) -> 0

Sheet 可燃
A1: 収集・直搬燃やせるごみ・木片
B9: ='A-1'!B9:D9 -> (令和9年07月)
B10: 収集燃やせるごみ（焼却） | G10: 収集燃やせるごみ（埋立） | M10: 直搬燃やせるごみ・木片等(焼却） | R10: 直搬燃やせるごみ・木片等（埋立）
A11: 日 | B11: 鬼脇 | C11: 鴛泊 | D11: 仙法志 | E11: 沓形 | F11: 計 | G11: 鬼脇 | H11: 鴛泊 | I11: 仙法志 | J11: 沓形 | K11: 計 | L11: 日 | M11: 鬼脇 | N11: 鴛泊 | O11: 仙法志 | P11: 沓形 | Q11: 計 | R11: 鬼脇 | S11: 鴛泊 | T11: 仙法志 | U11: 沓形 | V11: 計
A12: 1 | F12: =SUM(B12:E12) -> 0 | K12: =SUM(G12:J12) -> 0 | L12: 1 | Q12: =SUM(M12:P12) -> 0 | V12: =SUM(R12:U12) -> 0
A13: 2 | F13: =SUM(B13:E13) -> 0 | K13: =SUM(G13:J13) -> 0 | L13: 2 | Q13: =SUM(M13:P13) -> 0 | V13: =SUM(R13:U13) -> 0
A14: 3 | F14: =SUM(B14:E14) -> 0 | K14: =SUM(G14:J14) -> 0 | L14: 3 | Q14: =SUM(M14:P14) -> 0 | V14: =SUM(R14:U14) -> 0
A15: 4 | F15: =SUM(B15:E15) -> 0 | K15: =SUM(G15:J15) -> 0 | L15: 4 | Q15: =SUM(M15:P15) -> 0 | V15: =SUM(R15:U15) -> 0
A16: 5 | F16: =SUM(B16:E16) -> 0 | K16: =SUM(G16:J16) -> 0 | L16: 5 | Q16: =SUM(M16:P16) -> 0 | V16: =SUM(R16:U16) -> 0
A17: 6 | F17: =SUM(B17:E17) -> 0 | K17: =SUM(G17:J17) -> 0 | L17: 6 | Q17: =SUM(M17:P17) -> 0 | V17: =SUM(R17:U17) -> 0
A18: 7 | F18: =SUM(B18:E18) -> 0 | K18: =SUM(G18:J18) -> 0 | L18: 7 | Q18: =SUM(M18:P18) -> 0 | V18: =SUM(R18:U18) -> 0
A19: 8 | F19: =SUM(B19:E19) -> 0 | K19: =SUM(G19:J19) -> 0 | L19: 8 | Q19: =SUM(M19:P19) -> 0 | V19: =SUM(R19:U19) -> 0
A20: 9 | F20: =SUM(B20:E20) -> 0 | K20: =SUM(G20:J20) -> 0 | L20: 9 | Q20: =SUM(M20:P20) -> 0 | V20: =SUM(R20:U20) -> 0
A21: 10 | F21: =SUM(B21:E21) -> 0 | K21: =SUM(G21:J21) -> 0 | L21: 10 | Q21: =SUM(M21:P21) -> 0 | V21: =SUM(R21:U21) -> 0
A22: 11 | F22: =SUM(B22:E22) -> 0 | K22: =SUM(G22:J22) -> 0 | L22: 11 | Q22: =SUM(M22:P22) -> 0 | V22: =SUM(R22:U22) -> 0
A23: 12 | F23: =SUM(B23:E23) -> 0 | K23: =SUM(G23:J23) -> 0 | L23: 12 | Q23: =SUM(M23:P23) -> 0 | V23: =SUM(R23:U23) -> 0
... A42: 31 | F42: =SUM(B42:E42) -> 0 | K42: =SUM(G42:J42) -> 0 | L42: 31 | Q42: =SUM(M42:P42) -> 0 | V42: =SUM(R42:U42) -> 0
A43: 合計 | B43: =SUM(B12:B42) -> 0 | C43: =SUM(C12:C42) -> 0 | D43: =SUM(D12:D42) -> 0 | E43: =SUM(E12:E42) -> 0 | F43: =ROUND(SUM(F12:F42),1) -> 0 | G43: =SUM(G12:G42) -> 0 | H43: =SUM(H12:H42) -> 0 | I43: =SUM(I12:I42) -> 0 | J43: =SUM(J12:J42) -> 0 | K43: =ROUND(SUM(K12:K42),1) -> 0 | L43: 合計 | M43: =SUM(M12:M42) -> 0 | N43: =SUM(N12:N42) -> 0 | O43: =SUM(O12:O42) -> 0 | P43: =SUM(P12:P42) -> 0 | Q43: =ROUND(SUM(Q12:Q42),1) -> 0 | R43: =SUM(R12:R42) -> 0 | S43: =SUM(S12:S42) -> 0 | T43: =SUM(T12:T42) -> 0 | U43: =SUM(U12:U42) -> 0 | V43: =ROUND(SUM(V12:V42),1) -> 0

Sheet 不燃・木くず・海岸清掃
A1: 燃やせないごみ・木くず・海岸清掃
B9: ='A-1'!B9:D9 -> (令和9年07月)
B10: 収集燃やせないごみ（埋立） | G10: 直搬燃やせないごみ（埋立） | L10: 木くず 埋立 | Q10: 海岸清掃 有価 | V10: 海岸清掃 埋立
A11: 日 | B11: 鬼脇 | C11: 鴛泊 | D11: 仙法志 | E11: 沓形 | F11: 計 | G11: 鬼脇 | H11: 鴛泊 | I11: 仙法志 | J11: 沓形 | K11: 計 | L11: 鬼脇 | M11: 鴛泊 | N11: 仙法志 | O11: 沓形 | P11: 計 | Q11: 鬼脇 | R11: 鴛泊 | S11: 仙法志 | T11: 沓形 | U11: 計 | V11: 鬼脇 | W11: 鴛泊 | X11: 仙法志 | Y11: 沓形 | Z11: 計
A12: 1 | F12: =SUM(B12:E12) -> 0 | K12: =SUM(G12:J12) -> 0 | P12: =SUM(L12:O12) -> 0 | U12: =SUM(Q12:T12) -> 0 | Z12: =SUM(V12:Y12) -> 0
A13: 2 | F13: =SUM(B13:E13) -> 0 | K13: =SUM(G13:J13) -> 0 | P13: =SUM(L13:O13) -> 0 | U13: =SUM(Q13:T13) -> 0 | Z13: =SUM(V13:Y13) -> 0
A14: 3 | F14: =SUM(B14:E14) -> 0 | K14: =SUM(G14:J14) -> 0 | P14: =SUM(L14:O14) -> 0 | U14: =SUM(Q14:T14) -> 0 | Z14: =SUM(V14:Y14) -> 0
A15: 4 | F15: =SUM(B15:E15) -> 0 | K15: =SUM(G15:J15) -> 0 | P15: =SUM(L15:O15) -> 0 | U15: =SUM(Q15:T15) -> 0 | Z15: =SUM(V15:Y15) -> 0
A16: 5 | F16: =SUM(B16:E16) -> 0 | K16: =SUM(G16:J16) -> 0 | P16: =SUM(L16:O16) -> 0 | U16: =SUM(Q16:T16) -> 0 | Z16: =SUM(V16:Y16) -> 0
A17: 6 | F17: =SUM(B17:E17) -> 0 | K17: =SUM(G17:J17) -> 0 | P17: =SUM(L17:O17) -> 0 | U17: =SUM(Q17:T17) -> 0 | Z17: =SUM(V17:Y17) -> 0
A18: 7 | F18: =SUM(B18:E18) -> 0 | K18: =SUM(G18:J18) -> 0 | P18: =SUM(L18:O18) -> 0 | U18: =SUM(Q18:T18) -> 0 | Z18: =SUM(V18:Y18) -> 0
A19: 8 | F19: =SUM(B19:E19) -> 0 | K19: =SUM(G19:J19) -> 0 | P19: =SUM(L19:O19) -> 0 | U19: =SUM(Q19:T19) -> 0 | Z19: =SUM(V19:Y19) -> 0
A20: 9 | F20: =SUM(B20:E20) -> 0 | K20: =SUM(G20:J20) -> 0 | P20: =SUM(L20:O20) -> 0 | U20: =SUM(Q20:T20) -> 0 | Z20: =SUM(V20:Y20) -> 0
A21: 10 | F21: =SUM(B21:E21) -> 0 | K21: =SUM(G21:J21) -> 0 | P21: =SUM(L21:O21) -> 0 | U21: =SUM(Q21:T21) -> 0 | Z21: =SUM(V21:Y21) -> 0
A22: 11 | F22: =SUM(B22:E22) -> 0 | K22: =SUM(G22:J22) -> 0 | P22: =SUM(L22:O22) -> 0 | U22: =SUM(Q22:T22) -> 0 | Z22: =SUM(V22:Y22) -> 0
A23: 12 | F23: =SUM(B23:E23) -> 0 | K23: =SUM(G23:J23) -> 0 | P23: =SUM(L23:O23) -> 0 | U23: =SUM(Q23:T23) -> 0 | Z23: =SUM(V23:Y23) -> 0
... A37: 26 | F37: =SUM(B37:E37) -> 0 | K37: =SUM(G37:J37) -> 0 | P37: =SUM(L37:O37) -> 0 | U37: =SUM(Q37:T37) -> 0 | Z37: =SUM(V37:Y37) -> 0
A38: 27 | F38: =SUM(B38:E38) -> 0 | K38: =SUM(G38:J38) -> 0 | P38: =SUM(L38:O38) -> 0 | Z38: =SUM(V38:Y38) -> 0
A39: 28 | F39: =SUM(B39:E39) -> 0 | K39: =SUM(G39:J39) -> 0 | P39: =SUM(L39:O39) -> 0 | Z39: =SUM(V39:Y39) -> 0
A40: 29 | F40: =SUM(B40:E40) -> 0 | K40: =SUM(G40:J40) -> 0 | P40: =SUM(L40:O40) -> 0 | Z40: =SUM(V40:Y40) -> 0
A41: 30 | F41: =SUM(B41:E41) -> 0 | K41: =SUM(G41:J41) -> 0 | P41: =SUM(L41:O41) -> 0 | Z41: =SUM(V41:Y41) -> 0
A42: 31 | F42: =SUM(B42:E42) -> 0 | K42: =SUM(G42:J42) -> 0 | P42: =SUM(L42:O42) -> 0 | U42: =SUM(Q42:T42) -> 0 | Z42: =SUM(V42:Y42) -> 0
A43: 合計 | B43: =SUM(B12:B42) -> 0 | C43: =SUM(C12:C42) -> 0 | D43: =SUM(D12:D42) -> 0 | E43: =SUM(E12:E42) -> 0 | F43: =ROUND(SUM(F12:F42),1) -> 0 | G43: =SUM(G12:G42) -> 0 | H43: =SUM(H12:H42) -> 0 | I43: =SUM(I12:I42) -> 0 | J43: =SUM(J12:J42) -> 0 | K43: =ROUND(SUM(K12:K42),1) -> 0 | L43: =SUM(L12:L42) -> 0 | M43: =SUM(M12:M42) -> 0 | N43: =SUM(N12:N42) -> 0 | O43: =SUM(O12:O42) -> 0 | P43: =ROUND(SUM(P12:P42),1) -> 0 | Q43: =SUM(Q12:Q42) -> 0 | R43: =SUM(R12:R42) -> 0 | S43: =SUM(S12:S42) -> 0 | T43: =SUM(T12:T42) -> 0 | U43: =ROUND(SUM(U12:U42),1) -> 0 | V43: =SUM(V12:V42) -> 0 | W43: =SUM(W12:W42) -> 0 | X43: =SUM(X12:X42) -> 0 | Y43: =SUM(Y12:Y42) -> 0 | Z43: =ROUND(SUM(Z12:Z42),1) -> 0

Sheet ビン類
A1: 収集・直搬 ビン類
B9: ='A-1'!B9:D9 -> (令和9年07月)
B10: 収集ビン類 有価 | G10: 収集ビン類 埋立 | M10: 直搬ビン類 有価 | R10: 直搬ビン類 埋立
A11: 日 | B11: 鬼脇 | C11: 鴛泊 | D11: 仙法志 | E11: 沓形 | F11: 計 | G11: 鬼脇 | H11: 鴛泊 | I11: 仙法志 | J11: 沓形 | K11: 計 | L11: 日 | M11: 鬼脇 | N11: 鴛泊 | O11: 仙法志 | P11: 沓形 | Q11: 計 | R11: 鬼脇 | S11: 鴛泊 | T11: 仙法志 | U11: 沓形 | V11: 計
A12: 1 | F12: =SUM(B12:E12) -> 0 | K12: =SUM(G12:J12) -> 0 | L12: 1 | Q12: =SUM(M12:P12) -> 0 | V12: =SUM(R12:U12) -> 0
A13: 2 | F13: =SUM(B13:E13) -> 0 | K13: =SUM(G13:J13) -> 0 | L13: 2 | Q13: =SUM(M13:P13) -> 0 | V13: =SUM(R13:U13) -> 0
A14: 3 | F14: =SUM(B14:E14) -> 0 | K14: =SUM(G14:J14) -> 0 | L14: 3 | Q14: =SUM(M14:P14) -> 0 | V14: =SUM(R14:U14) -> 0
A15: 4 | F15: =SUM(B15:E15) -> 0 | K15: =SUM(G15:J15) -> 0 | L15: 4 | Q15: =SUM(M15:P15) -> 0 | V15: =SUM(R15:U15) -> 0
A16: 5 | F16: =SUM(B16:E16) -> 0 | K16: =SUM(G16:J16) -> 0 | L16: 5 | Q16: =SUM(M16:P16) -> 0 | V16: =SUM(R16:U16) -> 0
A17: 6 | F17: =SUM(B17:E17) -> 0 | K17: =SUM(G17:J17) -> 0 | L17: 6 | Q17: =SUM(M17:P17) -> 0 | V17: =SUM(R17:U17) -> 0
A18: 7 | F18: =SUM(B18:E18) -> 0 | K18: =SUM(G18:J18) -> 0 | L18: 7 | Q18: =SUM(M18:P18) -> 0 | V18: =SUM(R18:U18) -> 0
A19: 8 | F19: =SUM(B19:E19) -> 0 | K19: =SUM(G19:J19) -> 0 | L19: 8 | Q19: =SUM(M19:P19) -> 0 | V19: =SUM(R19:U19) -> 0
A20: 9 | F20: =SUM(B20:E20) -> 0 | K20: =SUM(G20:J20) -> 0 | L20: 9 | Q20: =SUM(M20:P20) -> 0 | V20: =SUM(R20:U20) -> 0
A21: 10 | F21: =SUM(B21:E21) -> 0 | K21: =SUM(G21:J21) -> 0 | L21: 10 | Q21: =SUM(M21:P21) -> 0 | V21: =SUM(R21:U21) -> 0
A22: 11 | F22: =SUM(B22:E22) -> 0 | K22: =SUM(G22:J22) -> 0 | L22: 11 | Q22: =SUM(M22:P22) -> 0 | V22: =SUM(R22:U22) -> 0
A23: 12 | F23: =SUM(B23:E23) -> 0 | K23: =SUM(G23:J23) -> 0 | L23: 12 | Q23: =SUM(M23:P23) -> 0 | V23: =SUM(R23:U23) -> 0
... A42: 31 | F42: =SUM(B42:E42) -> 0 | K42: =SUM(G42:J42) -> 0 | L42: 31 | Q42: =SUM(M42:P42) -> 0 | V42: =SUM(R42:U42) -> 0
A43: 合計 | B43: =SUM(B12:B42) -> 0 | C43: =SUM(C12:C42) -> 0 | D43: =SUM(D12:D42) -> 0 | E43: =SUM(E12:E42) -> 0 | F43: =SUM(B43:E43) -> 0 | G43: =SUM(G12:G42) -> 0 | H43: =SUM(H12:H42) -> 0 | I43: =SUM(I12:I42) -> 0 | J43: =SUM(J12:J42) -> 0 | K43: =SUM(G43:J43) -> 0 | L43: 合計 | M43: =SUM(M12:M42) -> 0 | N43: =SUM(N12:N42) -> 0 | O43: =SUM(O12:O42) -> 0 | P43: =SUM(P12:P42) -> 0 | Q43: =ROUND(SUM(Q12:Q42),1) -> 0 | R43: =SUM(R12:R42) -> 0 | S43: =SUM(S12:S42) -> 0 | T43: =SUM(T12:T42) -> 0 | U43: =SUM(U12:U42) -> 0 | V43: =ROUND(SUM(V12:V42),1) -> 0

Sheet 缶類
A1: 収集・直搬 缶類
B9: ='A-1'!B9:D9 -> (令和9年07月)
B10: 収集缶類 有価 | G10: 収集缶類 埋立 | M10: 直搬缶類 有価 | R10: 直搬缶類 埋立
A11: 日 | B11: 鬼脇 | C11: 鴛泊 | D11: 仙法志 | E11: 沓形 | F11: 計 | G11: 鬼脇 | H11: 鴛泊 | I11: 仙法志 | J11: 沓形 | K11: 計 | L11: 日 | M11: 鬼脇 | N11: 鴛泊 | O11: 仙法志 | P11: 沓形 | Q11: 計 | R11: 鬼脇 | S11: 鴛泊 | T11: 仙法志 | U11: 沓形 | V11: 計
A12: 1 | F12: =SUM(B12:E12) -> 0 | K12: =SUM(G12:J12) -> 0 | L12: 1 | Q12: =SUM(M12:P12) -> 0 | V12: =SUM(R12:U12) -> 0
A13: 2 | F13: =SUM(B13:E13) -> 0 | K13: =SUM(G13:J13) -> 0 | L13: 2 | Q13: =SUM(M13:P13) -> 0 | V13: =SUM(R13:U13) -> 0
A14: 3 | F14: =SUM(B14:E14) -> 0 | L14: 3 | Q14: =SUM(M14:P14) -> 0 | V14: =SUM(R14:U14) -> 0
A15: 4 | F15: =SUM(B15:E15) -> 0 | L15: 4 | Q15: =SUM(M15:P15) -> 0 | V15: =SUM(R15:U15) -> 0
A16: 5 | F16: =SUM(B16:E16) -> 0 | L16: 5 | Q16: =SUM(M16:P16) -> 0 | V16: =SUM(R16:U16) -> 0
A17: 6 | F17: =SUM(B17:E17) -> 0 | L17: 6 | Q17: =SUM(M17:P17) -> 0 | V17: =SUM(R17:U17) -> 0
A18: 7 | F18: =SUM(B18:E18) -> 0 | L18: 7 | Q18: =SUM(M18:P18) -> 0 | V18: =SUM(R18:U18) -> 0
A19: 8 | F19: =SUM(B19:E19) -> 0 | L19: 8 | Q19: =SUM(M19:P19) -> 0 | V19: =SUM(R19:U19) -> 0
A20: 9 | F20: =SUM(B20:E20) -> 0 | L20: 9 | Q20: =SUM(M20:P20) -> 0 | V20: =SUM(R20:U20) -> 0
A21: 10 | F21: =SUM(B21:E21) -> 0 | L21: 10 | Q21: =SUM(M21:P21) -> 0 | V21: =SUM(R21:U21) -> 0
A22: 11 | F22: =SUM(B22:E22) -> 0 | L22: 11 | Q22: =SUM(M22:P22) -> 0 | V22: =SUM(R22:U22) -> 0
A23: 12 | F23: =SUM(B23:E23) -> 0 | L23: 12 | Q23: =SUM(M23:P23) -> 0 | V23: =SUM(R23:U23) -> 0
A24: 13 | F24: =SUM(B24:E24) -> 0 | L24: 13 | Q24: =SUM(M24:P24) -> 0 | V24: =SUM(R24:U24) -> 0
A25: 14 | F25: =SUM(B25:E25) -> 0 | L25: 14 | Q25: =SUM(M25:P25) -> 0 | V25: =SUM(R25:U25) -> 0
... A34: 23 | F34: =SUM(B34:E34) -> 0 | L34: 23 | Q34: =SUM(M34:P34) -> 0 | V34: =SUM(R34:U34) -> 0
A35: 24 | F35: =SUM(B35:E35) -> 0 | K35: =SUM(G35:J35) -> 0 | L35: 24 | Q35: =SUM(M35:P35) -> 0 | V35: =SUM(R35:U35) -> 0
A36: 25 | F36: =SUM(B36:E36) -> 0 | K36: =SUM(G36:J36) -> 0 | L36: 25 | Q36: =SUM(M36:P36) -> 0 | V36: =SUM(R36:U36) -> 0
A37: 26 | F37: =SUM(B37:E37) -> 0 | K37: =SUM(G37:J37) -> 0 | L37: 26 | Q37: =SUM(M37:P37) -> 0 | V37: =SUM(R37:U37) -> 0
A38: 27 | F38: =SUM(B38:E38) -> 0 | K38: =SUM(G38:J38) -> 0 | L38: 27 | Q38: =SUM(M38:P38) -> 0 | V38: =SUM(R38:U38) -> 0
A39: 28 | F39: =SUM(B39:E39) -> 0 | K39: =SUM(G39:J39) -> 0 | L39: 28 | Q39: =SUM(M39:P39) -> 0 | V39: =SUM(R39:U39) -> 0
A40: 29 | F40: =SUM(B40:E40) -> 0 | K40: =SUM(G40:J40) -> 0 | L40: 29 | Q40: =SUM(M40:P40) -> 0 | V40: =SUM(R40:U40) -> 0
A41: 30 | F41: =SUM(B41:E41) -> 0 | K41: =SUM(G41:J41) -> 0 | L41: 30 | Q41: =SUM(M41:P41) -> 0 | V41: =SUM(R41:U41) -> 0
A42: 31 | F42: =SUM(B42:E42) -> 0 | K42: =SUM(G42:J42) -> 0 | L42: 31 | Q42: =SUM(M42:P42) -> 0 | V42: =SUM(R42:U42) -> 0
A43: 合計 | B43: =SUM(B12:B42) -> 0 | C43: =SUM(C12:C42) -> 0 | D43: =SUM(D12:D42) -> 0 | E43: =SUM(E12:E42) -> 0 | F43: =ROUND(SUM(F12:F42),1) -> 0 | G43: =SUM(G12:G42) -> 0 | H43: =SUM(H12:H42) -> 0 | I43: =SUM(I12:I42) -> 0 | J43: =SUM(J12:J42) -> 0 | K43: =ROUND(SUM(K12:K42),1) -> 0 | L43: 合計 | M43: =SUM(M12:M42) -> 0 | N43: =SUM(N12:N42) -> 0 | O43: =SUM(O12:O42) -> 0 | P43: =SUM(P12:P42) -> 0 | Q43: =ROUND(SUM(Q12:Q42),1) -> 0 | R43: =SUM(R12:R42) -> 0 | S43: =SUM(S12:S42) -> 0 | T43: =SUM(T12:T42) -> 0 | U43: =SUM(U12:U42) -> 0 | V43: =ROUND(SUM(V12:V42),1) -> 0

Sheet ペットボトル
A1: 収集・直搬資源ごみペットボトル（有価・埋立）
B9: ='A-1'!B9:D9 -> (令和9年07月)
B10: 収集資源ペットボトル（有価） | G10: 収集資源ペットボトル（埋立） | M10: 直搬資源ペットボトル（有価） | R10: 直搬資源ペットボトル（埋立）
A11: 日 | B11: 鬼脇 | C11: 鴛泊 | D11: 仙法志 | E11: 沓形 | F11: 計 | G11: 鬼脇 | H11: 鴛泊 | I11: 仙法志 | J11: 沓形 | K11: 計 | L11: 日 | M11: 鬼脇 | N11: 鴛泊 | O11: 仙法志 | P11: 沓形 | Q11: 計 | R11: 鬼脇 | S11: 鴛泊 | T11: 仙法志 | U11: 沓形 | V11: 計
A12: 1 | F12: =SUM(B12:E12) -> 0 | K12: =SUM(G12:J12) -> 0 | L12: 1 | Q12: =SUM(M12:P12) -> 0 | V12: =SUM(R12:U12) -> 0
A13: 2 | F13: =SUM(B13:E13) -> 0 | K13: =SUM(G13:J13) -> 0 | L13: 2 | Q13: =SUM(M13:P13) -> 0 | V13: =SUM(R13:U13) -> 0
A14: 3 | F14: =SUM(B14:E14) -> 0 | K14: =SUM(G14:J14) -> 0 | L14: 3 | Q14: =SUM(M14:P14) -> 0 | V14: =SUM(R14:U14) -> 0
A15: 4 | F15: =SUM(B15:E15) -> 0 | K15: =SUM(G15:J15) -> 0 | L15: 4 | Q15: =SUM(M15:P15) -> 0 | V15: =SUM(R15:U15) -> 0
A16: 5 | F16: =SUM(B16:E16) -> 0 | K16: =SUM(G16:J16) -> 0 | L16: 5 | Q16: =SUM(M16:P16) -> 0 | V16: =SUM(R16:U16) -> 0
A17: 6 | F17: =SUM(B17:E17) -> 0 | K17: =SUM(G17:J17) -> 0 | L17: 6 | Q17: =SUM(M17:P17) -> 0 | V17: =SUM(R17:U17) -> 0
A18: 7 | F18: =SUM(B18:E18) -> 0 | K18: =SUM(G18:J18) -> 0 | L18: 7 | Q18: =SUM(M18:P18) -> 0 | V18: =SUM(R18:U18) -> 0
A19: 8 | F19: =SUM(B19:E19) -> 0 | K19: =SUM(G19:J19) -> 0 | L19: 8 | Q19: =SUM(M19:P19) -> 0 | V19: =SUM(R19:U19) -> 0
A20: 9 | F20: =SUM(B20:E20) -> 0 | K20: =SUM(G20:J20) -> 0 | L20: 9 | Q20: =SUM(M20:P20) -> 0 | V20: =SUM(R20:U20) -> 0
A21: 10 | F21: =SUM(B21:E21) -> 0 | K21: =SUM(G21:J21) -> 0 | L21: 10 | Q21: =SUM(M21:P21) -> 0 | V21: =SUM(R21:U21) -> 0
A22: 11 | F22: =SUM(B22:E22) -> 0 | K22: =SUM(G22:J22) -> 0 | L22: 11 | Q22: =SUM(M22:P22) -> 0 | V22: =SUM(R22:U22) -> 0
A23: 12 | F23: =SUM(B23:E23) -> 0 | K23: =SUM(G23:J23) -> 0 | L23: 12 | Q23: =SUM(M23:P23) -> 0 | V23: =SUM(R23:U23) -> 0
... A42: 31 | F42: =SUM(B42:E42) -> 0 | K42: =SUM(G42:J42) -> 0 | L42: 31 | Q42: =SUM(M42:P42) -> 0 | V42: =SUM(R42:U42) -> 0
A43: 合計 | B43: =SUM(B12:B42) -> 0 | C43: =SUM(C12:C42) -> 0 | D43: =SUM(D12:D42) -> 0 | E43: =SUM(E12:E42) -> 0 | F43: =SUM(B43:E43) -> 0 | G43: =SUM(G12:G42) -> 0 | H43: =SUM(H12:H42) -> 0 | I43: =SUM(I12:I42) -> 0 | J43: =SUM(J12:J42) -> 0 | K43: =SUM(G43:J43) -> 0 | L43: 合計 | M43: =SUM(M12:M42) -> 0 | N43: =SUM(N12:N42) -> 0 | O43: =SUM(O12:O42) -> 0 | P43: =SUM(P12:P42) -> 0 | Q43: =ROUND(SUM(Q12:Q42),1) -> 0 | R43: =SUM(R12:R42) -> 0 | S43: =SUM(S12:S42) -> 0 | T43: =SUM(T12:T42) -> 0 | U43: =SUM(U12:U42) -> 0 | V43: =ROUND(SUM(V12:V42),1) -> 0

Sheet 紙類
A1: 収集・直搬 紙類
B9: ='A-1'!B9:D9 -> (令和9年07月)
B10: 収集紙類 有価 | G10: 収集紙類 焼却 | M10: 収集紙類 埋立 | R10: 直搬紙類 焼却
A11: 日 | B11: 鬼脇 | C11: 鴛泊 | D11: 仙法志 | E11: 沓形 | F11: 計 | G11: 鬼脇 | H11: 鴛泊 | I11: 仙法志 | J11: 沓形 | K11: 計 | L11: 日 | M11: 鬼脇 | N11: 鴛泊 | O11: 仙法志 | P11: 沓形 | Q11: 計 | R11: 鬼脇 | S11: 鴛泊 | T11: 仙法志 | U11: 沓形 | V11: 計
A12: 1 | F12: =SUM(B12:E12) -> 0 | K12: =SUM(G12:J12) -> 0 | L12: 1 | Q12: =SUM(M12:P12) -> 0 | V12: =SUM(R12:U12) -> 0
A13: 2 | F13: =SUM(B13:E13) -> 0 | K13: =SUM(G13:J13) -> 0 | L13: 2 | Q13: =SUM(M13:P13) -> 0 | V13: =SUM(R13:U13) -> 0
A14: 3 | F14: =SUM(B14:E14) -> 0 | K14: =SUM(G14:J14) -> 0 | L14: 3 | Q14: =SUM(M14:P14) -> 0 | V14: =SUM(R14:U14) -> 0
A15: 4 | F15: =SUM(B15:E15) -> 0 | K15: =SUM(G15:J15) -> 0 | L15: 4 | Q15: =SUM(M15:P15) -> 0 | V15: =SUM(R15:U15) -> 0
A16: 5 | F16: =SUM(B16:E16) -> 0 | K16: =SUM(G16:J16) -> 0 | L16: 5 | Q16: =SUM(M16:P16) -> 0 | V16: =SUM(R16:U16) -> 0
A17: 6 | F17: =SUM(B17:E17) -> 0 | K17: =SUM(G17:J17) -> 0 | L17: 6 | Q17: =SUM(M17:P17) -> 0 | V17: =SUM(R17:U17) -> 0
A18: 7 | F18: =SUM(B18:E18) -> 0 | K18: =SUM(G18:J18) -> 0 | L18: 7 | Q18: =SUM(M18:P18) -> 0 | V18: =SUM(R18:U18) -> 0
A19: 8 | F19: =SUM(B19:E19) -> 0 | K19: =SUM(G19:J19) -> 0 | L19: 8 | Q19: =SUM(M19:P19) -> 0 | V19: =SUM(R19:U19) -> 0
A20: 9 | F20: =SUM(B20:E20) -> 0 | K20: =SUM(G20:J20) -> 0 | L20: 9 | Q20: =SUM(M20:P20) -> 0 | V20: =SUM(R20:U20) -> 0
A21: 10 | F21: =SUM(B21:E21) -> 0 | K21: =SUM(G21:J21) -> 0 | L21: 10 | Q21: =SUM(M21:P21) -> 0 | V21: =SUM(R21:U21) -> 0
A22: 11 | F22: =SUM(B22:E22) -> 0 | K22: =SUM(G22:J22) -> 0 | L22: 11 | Q22: =SUM(M22:P22) -> 0 | V22: =SUM(R22:U22) -> 0
A23: 12 | F23: =SUM(B23:E23) -> 0 | K23: =SUM(G23:J23) -> 0 | L23: 12 | Q23: =SUM(M23:P23) -> 0 | V23: =SUM(R23:U23) -> 0
... A42: 31 | F42: =SUM(B42:E42) -> 0 | K42: =SUM(G42:J42) -> 0 | L42: 31 | Q42: =SUM(M42:P42) -> 0 | V42: =SUM(R42:U42) -> 0
A43: 合計 | B43: =SUM(B12:B42) -> 0 | C43: =SUM(C12:C42) -> 0 | D43: =SUM(D12:D42) -> 0 | E43: =SUM(E12:E42) -> 0 | F43: =SUM(B43:E43) -> 0 | G43: =SUM(G12:G42) -> 0 | H43: =SUM(H12:H42) -> 0 | I43: =SUM(I12:I42) -> 0 | J43: =SUM(J12:J42) -> 0 | K43: =SUM(G43:J43) -> 0 | L43: 合計 | M43: =SUM(M12:M42) -> 0 | N43: =SUM(N12:N42) -> 0 | O43: =SUM(O12:O42) -> 0 | P43: =SUM(P12:P42) -> 0 | Q43: =ROUND(SUM(Q12:Q42),1) -> 0 | R43: =SUM(R12:R42) -> 0 | S43: =SUM(S12:S42) -> 0 | T43: =SUM(T12:T42) -> 0 | U43: =SUM(U12:U42) -> 0 | V43: =ROUND(SUM(V12:V42),1) -> 0

Sheet 粗大
A1: 収集・直搬粗大ごみ
B9: ='A-1'!B9:D9 -> (令和9年07月)
B10: 収集粗大ごみ 総量 | G10: 収集粗大ごみ 有価 | L10: 収集粗大ごみ 埋立 | Q10: 直搬粗大ごみ 有価 | V10: 直搬粗大ごみ 埋立
A11: 日 | B11: 鬼脇 | C11: 鴛泊 | D11: 仙法志 | E11: 沓形 | F11: 計 | G11: 鬼脇 | H11: 鴛泊 | I11: 仙法志 | J11: 沓形 | K11: 計 | L11: 鬼脇 | M11: 鴛泊 | N11: 仙法志 | O11: 沓形 | P11: 計 | Q11: 鬼脇 | R11: 鴛泊 | S11: 仙法志 | T11: 沓形 | U11: 計 | V11: 鬼脇 | W11: 鴛泊 | X11: 仙法志 | Y11: 沓形 | Z11: 計
A12: 1 | F12: =SUM(B12:E12) -> 0 | K12: =SUM(G12:J12) -> 0 | P12: =SUM(L12:O12) -> 0 | U12: =SUM(Q12:T12) -> 0 | Z12: =SUM(V12:Y12) -> 0
A13: 2 | F13: =SUM(B13:E13) -> 0 | K13: =SUM(G13:J13) -> 0 | P13: =SUM(L13:O13) -> 0 | U13: =SUM(Q13:T13) -> 0 | Z13: =SUM(V13:Y13) -> 0
A14: 3 | F14: =SUM(B14:E14) -> 0 | K14: =SUM(G14:J14) -> 0 | P14: =SUM(L14:O14) -> 0 | U14: =SUM(Q14:T14) -> 0 | Z14: =SUM(V14:Y14) -> 0
A15: 4 | F15: =SUM(B15:E15) -> 0 | K15: =SUM(G15:J15) -> 0 | P15: =SUM(L15:O15) -> 0 | U15: =SUM(Q15:T15) -> 0 | Z15: =SUM(V15:Y15) -> 0
A16: 5 | F16: =SUM(B16:E16) -> 0 | K16: =SUM(G16:J16) -> 0 | P16: =SUM(L16:O16) -> 0 | U16: =SUM(Q16:T16) -> 0 | Z16: =SUM(V16:Y16) -> 0
A17: 6 | F17: =SUM(B17:E17) -> 0 | K17: =SUM(G17:J17) -> 0 | P17: =SUM(L17:O17) -> 0 | U17: =SUM(Q17:T17) -> 0 | Z17: =SUM(V17:Y17) -> 0
A18: 7 | F18: =SUM(B18:E18) -> 0 | K18: =SUM(G18:J18) -> 0 | P18: =SUM(L18:O18) -> 0 | U18: =SUM(Q18:T18) -> 0 | Z18: =SUM(V18:Y18) -> 0
A19: 8 | F19: =SUM(B19:E19) -> 0 | K19: =SUM(G19:J19) -> 0 | P19: =SUM(L19:O19) -> 0 | U19: =SUM(Q19:T19) -> 0 | Z19: =SUM(V19:Y19) -> 0
A20: 9 | F20: =SUM(B20:E20) -> 0 | K20: =SUM(G20:J20) -> 0 | P20: =SUM(L20:O20) -> 0 | U20: =SUM(Q20:T20) -> 0 | Z20: =SUM(V20:Y20) -> 0
A21: 10 | F21: =SUM(B21:E21) -> 0 | K21: =SUM(G21:J21) -> 0 | P21: =SUM(L21:O21) -> 0 | U21: =SUM(Q21:T21) -> 0 | Z21: =SUM(V21:Y21) -> 0
A22: 11 | F22: =SUM(B22:E22) -> 0 | K22: =SUM(G22:J22) -> 0 | P22: =SUM(L22:O22) -> 0 | U22: =SUM(Q22:T22) -> 0 | Z22: =SUM(V22:Y22) -> 0
A23: 12 | F23: =SUM(B23:E23) -> 0 | K23: =SUM(G23:J23) -> 0 | P23: =SUM(L23:O23) -> 0 | U23: =SUM(Q23:T23) -> 0 | Z23: =SUM(V23:Y23) -> 0
... A42: 31 | F42: =SUM(B42:E42) -> 0 | K42: =SUM(G42:J42) -> 0 | P42: =SUM(L42:O42) -> 0 | U42: =SUM(Q42:T42) -> 0 | Z42: =SUM(V42:Y42) -> 0
A43: 合計 | B43: =SUM(B12:B42) -> 0 | C43: =SUM(C12:C42) -> 0 | D43: =SUM(D12:D42) -> 0 | E43: =SUM(E12:E42) -> 0 | F43: =ROUND(SUM(F12:F42),1) -> 0 | G43: =SUM(G12:G42) -> 0 | H43: =SUM(H12:H42) -> 0 | I43: =SUM(I12:I42) -> 0 | J43: =SUM(J12:J42) -> 0 | K43: =ROUND(SUM(K12:K42),1) -> 0 | L43: =SUM(L12:L42) -> 0 | M43: =SUM(M12:M42) -> 0 | N43: =SUM(N12:N42) -> 0 | O43: =SUM(O12:O42) -> 0 | P43: =ROUND(SUM(P12:P42),1) -> 0 | Q43: =SUM(Q12:Q42) -> 0 | R43: =SUM(R12:R42) -> 0 | S43: =SUM(S12:S42) -> 0 | T43: =SUM(T12:T42) -> 0 | U43: =ROUND(SUM(U12:U42),1) -> 0 | V43: =SUM(V12:V42) -> 0 | W43: =SUM(W12:W42) -> 0 | X43: =SUM(X12:X42) -> 0 | Y43: =SUM(Y12:Y42) -> 0 | Z43: =ROUND(SUM(Z12:Z42),1) -> 0

Sheet 産廃水産・医療・汚泥
A1: 水産物・医療廃棄物・汚泥焼却埋立
B9: ='A-1'!B9:D9 -> (令和9年07月)
B10: 併せ産廃（動植物性） 焼却 | G10: 併せ産廃（動植物性） 埋立 | L10: うに殻等 埋立 | Q10: 併せ産廃（医療系） 焼却 | V10: 下水道汚泥 埋立
A11: 日 | B11: 鬼脇 | C11: 鴛泊 | D11: 仙法志 | E11: 沓形 | F11: 計 | G11: 鬼脇 | H11: 鴛泊 | I11: 仙法志 | J11: 沓形 | K11: 計 | L11: 鬼脇 | M11: 鴛泊 | N11: 仙法志 | O11: 沓形 | P11: 計 | Q11: 鬼脇 | R11: 鴛泊 | S11: 仙法志 | T11: 沓形 | U11: 計 | V11: 富士町 | W11: 利尻町 | X11: 計
A12: 1 | F12: =SUM(B12:E12) -> 0 | K12: =SUM(G12:J12) -> 0 | P12: =SUM(L12:O12) -> 0 | U12: =SUM(Q12:T12) -> 0 | X12: =SUM(V12:W12) -> 0
A13: 2 | F13: =SUM(B13:E13) -> 0 | K13: =SUM(G13:J13) -> 0 | P13: =SUM(L13:O13) -> 0 | U13: =SUM(Q13:T13) -> 0 | X13: =SUM(V13:W13) -> 0
A14: 3 | F14: =SUM(B14:E14) -> 0 | K14: =SUM(G14:J14) -> 0 | P14: =SUM(L14:O14) -> 0 | U14: =SUM(Q14:T14) -> 0 | X14: =SUM(V14:W14) -> 0
A15: 4 | F15: =SUM(B15:E15) -> 0 | K15: =SUM(G15:J15) -> 0 | P15: =SUM(L15:O15) -> 0 | U15: =SUM(Q15:T15) -> 0 | X15: =SUM(V15:W15) -> 0
A16: 5 | F16: =SUM(B16:E16) -> 0 | K16: =SUM(G16:J16) -> 0 | P16: =SUM(L16:O16) -> 0 | U16: =SUM(Q16:T16) -> 0 | X16: =SUM(V16:W16) -> 0
A17: 6 | F17: =SUM(B17:E17) -> 0 | K17: =SUM(G17:J17) -> 0 | P17: =SUM(L17:O17) -> 0 | U17: =SUM(Q17:T17) -> 0 | X17: =SUM(V17:W17) -> 0
A18: 7 | F18: =SUM(B18:E18) -> 0 | K18: =SUM(G18:J18) -> 0 | P18: =SUM(L18:O18) -> 0 | U18: =SUM(Q18:T18) -> 0 | X18: =SUM(V18:W18) -> 0
A19: 8 | F19: =SUM(B19:E19) -> 0 | K19: =SUM(G19:J19) -> 0 | P19: =SUM(L19:O19) -> 0 | U19: =SUM(Q19:T19) -> 0 | X19: =SUM(V19:W19) -> 0
A20: 9 | F20: =SUM(B20:E20) -> 0 | K20: =SUM(G20:J20) -> 0 | P20: =SUM(L20:O20) -> 0 | U20: =SUM(Q20:T20) -> 0 | X20: =SUM(V20:W20) -> 0
A21: 10 | F21: =SUM(B21:E21) -> 0 | K21: =SUM(G21:J21) -> 0 | P21: =SUM(L21:O21) -> 0 | U21: =SUM(Q21:T21) -> 0 | X21: =SUM(V21:W21) -> 0
A22: 11 | F22: =SUM(B22:E22) -> 0 | K22: =SUM(G22:J22) -> 0 | P22: =SUM(L22:O22) -> 0 | U22: =SUM(Q22:T22) -> 0 | X22: =SUM(V22:W22) -> 0
A23: 12 | F23: =SUM(B23:E23) -> 0 | K23: =SUM(G23:J23) -> 0 | P23: =SUM(L23:O23) -> 0 | U23: =SUM(Q23:T23) -> 0 | X23: =SUM(V23:W23) -> 0
... A42: 31 | F42: =SUM(B42:E42) -> 0 | K42: =SUM(G42:J42) -> 0 | P42: =SUM(L42:O42) -> 0 | U42: =SUM(Q42:T42) -> 0 | X42: =SUM(V42:W42) -> 0
A43: 合計 | B43: =SUM(B12:B42) -> 0 | C43: =SUM(C12:C42) -> 0 | D43: =SUM(D12:D42) -> 0 | E43: =SUM(E12:E42) -> 0 | F43: =ROUND(SUM(F12:F42),1) -> 0 | G43: =SUM(G12:G42) -> 0 | H43: =SUM(H12:H42) -> 0 | I43: =SUM(I12:I42) -> 0 | J43: =SUM(J12:J42) -> 0 | K43: =ROUND(SUM(K12:K42),1) -> 0 | L43: =SUM(L12:L42) -> 0 | M43: =SUM(M12:M42) -> 0 | N43: =SUM(N12:N42) -> 0 | O43: =SUM(O12:O42) -> 0 | P43: =ROUND(SUM(P12:P42),1) -> 0 | Q43: =SUM(Q12:Q42) -> 0 | R43: =SUM(R12:R42) -> 0 | S43: =SUM(S12:S42) -> 0 | T43: =SUM(T12:T42) -> 0 | U43: =ROUND(SUM(U12:U42),1) -> 0 | V43: =SUM(V12:V42) -> 0 | W43: =SUM(W12:W42) -> 0 | X43: =ROUND(SUM(X12:X42),1) -> 0
